<!doctype html>
<html>
  <head>
    <title>LGSF Dashboard</title>
    <link rel="stylesheet"  href="/lgsf-dashboard/assets/css/styles.css">
    <link rel="shortcut icon" href="https://democracyclub.org.uk/static/images/logo_icon.png">
  </head>
  <body>
    <div class="ds-page">
      <a class="ds-skip-link" href="#main">skip to content</a>

      <header class="ds-header">
        <a class="ds-skip-link" href="#main">skip to content</a>
        <a class="ds-logo" href="/lgsf-dashboard/">
          <img src="https://DemocracyClub.github.io/design-system/images/logo_icon.svg" alt="" />
          <span>LGSF Logbooks</span>
        </a>

      </header>


      <main id="main" tabindex="-1" class="ds-stack">

        
<style>

    pre {
        height:400px;
        overflow-x: scroll;
        width:100%
    }
</style>




  


  <h2 id="2024-03-29-10-23">2024-03-29</h2>
  <div class="ds-card">
  <div class="ds-card-body">
    <dl class="ds-descriptions">
      <div>
        <dt>Duration</dt>
        <dd>131 seconds</dd>
      </div>
      <div>
        <dt>Start</dt>
        <dd>2024-03-29 10:23:00.384679</dd>
      </div>
      <div>
        <dt>End</dt>
        <dd>2024-03-29 10:25:11.937227</dd>
      </div>
      <div>
        <dt>Status code</dt>
        <dd>1</dd>
      </div>
      <div>
        <dt>Error</dt>
        <dd>Traceback (most recent call last):
  File "/opt/python/urllib3/connection.py", line 203, in _new_conn
    sock = connection.create_connection(
  File "/opt/python/urllib3/util/connection.py", line 85, in create_connection
    raise err
  File "/opt/python/urllib3/util/connection.py", line 73, in create_connection
    sock.connect(sa)
TimeoutError: [Errno 110] Connection timed out

The above exception was the direct cause of the following exception:

Traceback (most recent call last):
  File "/opt/python/urllib3/connectionpool.py", line 791, in urlopen
    response = self._make_request(
  File "/opt/python/urllib3/connectionpool.py", line 497, in _make_request
    conn.request(
  File "/opt/python/urllib3/connection.py", line 395, in request
    self.endheaders()
  File "/var/lang/lib/python3.10/http/client.py", line 1278, in endheaders
    self._send_output(message_body, encode_chunked=encode_chunked)
  File "/var/lang/lib/python3.10/http/client.py", line 1038, in _send_output
    self.send(msg)
  File "/var/lang/lib/python3.10/http/client.py", line 976, in send
    self.connect()
  File "/opt/python/urllib3/connection.py", line 243, in connect
    self.sock = self._new_conn()
  File "/opt/python/urllib3/connection.py", line 212, in _new_conn
    raise ConnectTimeoutError(
urllib3.exceptions.ConnectTimeoutError: (<urllib3.connection.HTTPConnection object at 0x7f2c03633460>, 'Connection to democracy.canterbury.gov.uk timed out. (connect timeout=None)')

The above exception was the direct cause of the following exception:

Traceback (most recent call last):
  File "/opt/python/requests/adapters.py", line 486, in send
    resp = conn.urlopen(
  File "/opt/python/urllib3/connectionpool.py", line 845, in urlopen
    retries = retries.increment(
  File "/opt/python/urllib3/util/retry.py", line 515, in increment
    raise MaxRetryError(_pool, url, reason) from reason  # type: ignore[arg-type]
urllib3.exceptions.MaxRetryError: HTTPConnectionPool(host='democracy.canterbury.gov.uk', port=80): Max retries exceeded with url: /mgWebService.asmx/GetCouncillorsByWard (Caused by ConnectTimeoutError(<urllib3.connection.HTTPConnection object at 0x7f2c03633460>, 'Connection to democracy.canterbury.gov.uk timed out. (connect timeout=None)'))

During handling of the above exception, another exception occurred:

Traceback (most recent call last):
  File "/var/task/lgsf/aws_lambda/handlers.py", line 32, in scraper_worker_handler
    scraper.run(run_log)
  File "/var/task/lgsf/councillors/scrapers.py", line 200, in run
    wards = self.get_councillors()
  File "/var/task/lgsf/councillors/scrapers.py", line 219, in get_councillors
    req = self.get(
  File "/var/task/lgsf/scrapers/base.py", line 47, in get
    response = self.requests_session.get(
  File "/opt/python/requests/sessions.py", line 602, in get
    return self.request("GET", url, **kwargs)
  File "/opt/python/requests/sessions.py", line 589, in request
    resp = self.send(prep, **send_kwargs)
  File "/opt/python/requests/sessions.py", line 703, in send
    r = adapter.send(request, **kwargs)
  File "/opt/python/requests/adapters.py", line 507, in send
    raise ConnectTimeout(e, request=request)
requests.exceptions.ConnectTimeout: HTTPConnectionPool(host='democracy.canterbury.gov.uk', port=80): Max retries exceeded with url: /mgWebService.asmx/GetCouncillorsByWard (Caused by ConnectTimeoutError(<urllib3.connection.HTTPConnection object at 0x7f2c03633460>, 'Connection to democracy.canterbury.gov.uk timed out. (connect timeout=None)'))
</dd>
      </div>
    </dl>
  </div>
  </div>

  <h3>Run log</h3>
  <pre>[10:23:00] Fetching Scraper for: CAT                              handlers.py:23
           Begin attempting to scrape: CAT                        handlers.py:27
           Deleting existing data...                                 base.py:251
[10:23:01] Getting all files in Councillors...                       base.py:203
           ...found 1 files in Councillors                           base.py:219
           Deleting batch no. 1 consisting of 1 files                base.py:230
[10:23:02] ...data deleted.                                          base.py:258
           Scraping from                                              base.py:41
           http://democracy.canterbury.gov.uk/mgWebService.asmx/GetCo           
           uncillorsByWard                                                      
[10:25:11] HTTPConnectionPool(host='democracy.canterbury.gov.uk', handlers.py:36
           port=80): Max retries exceeded with url:                             
           /mgWebService.asmx/GetCouncillorsByWard (Caused by                   
           ConnectTimeoutError(<urllib3.connection.HTTPConnection               
           object at 0x7f2c03633460>, 'Connection to                            
           democracy.canterbury.gov.uk timed out. (connect                      
           timeout=None)'))                                                     
           Finished attempting to scrape: CAT                        base.py:339
</pre>
  

  


  <h2 id="2024-03-28-09-58">2024-03-28</h2>
  <div class="ds-card">
  <div class="ds-card-body">
    <dl class="ds-descriptions">
      <div>
        <dt>Duration</dt>
        <dd>133 seconds</dd>
      </div>
      <div>
        <dt>Start</dt>
        <dd>2024-03-28 09:58:08.042449</dd>
      </div>
      <div>
        <dt>End</dt>
        <dd>2024-03-28 10:00:21.410517</dd>
      </div>
      <div>
        <dt>Status code</dt>
        <dd>1</dd>
      </div>
      <div>
        <dt>Error</dt>
        <dd>Traceback (most recent call last):
  File "/opt/python/urllib3/connection.py", line 203, in _new_conn
    sock = connection.create_connection(
  File "/opt/python/urllib3/util/connection.py", line 85, in create_connection
    raise err
  File "/opt/python/urllib3/util/connection.py", line 73, in create_connection
    sock.connect(sa)
TimeoutError: [Errno 110] Connection timed out

The above exception was the direct cause of the following exception:

Traceback (most recent call last):
  File "/opt/python/urllib3/connectionpool.py", line 791, in urlopen
    response = self._make_request(
  File "/opt/python/urllib3/connectionpool.py", line 497, in _make_request
    conn.request(
  File "/opt/python/urllib3/connection.py", line 395, in request
    self.endheaders()
  File "/var/lang/lib/python3.10/http/client.py", line 1278, in endheaders
    self._send_output(message_body, encode_chunked=encode_chunked)
  File "/var/lang/lib/python3.10/http/client.py", line 1038, in _send_output
    self.send(msg)
  File "/var/lang/lib/python3.10/http/client.py", line 976, in send
    self.connect()
  File "/opt/python/urllib3/connection.py", line 243, in connect
    self.sock = self._new_conn()
  File "/opt/python/urllib3/connection.py", line 212, in _new_conn
    raise ConnectTimeoutError(
urllib3.exceptions.ConnectTimeoutError: (<urllib3.connection.HTTPConnection object at 0x7f8a87e2fe50>, 'Connection to democracy.canterbury.gov.uk timed out. (connect timeout=None)')

The above exception was the direct cause of the following exception:

Traceback (most recent call last):
  File "/opt/python/requests/adapters.py", line 486, in send
    resp = conn.urlopen(
  File "/opt/python/urllib3/connectionpool.py", line 845, in urlopen
    retries = retries.increment(
  File "/opt/python/urllib3/util/retry.py", line 515, in increment
    raise MaxRetryError(_pool, url, reason) from reason  # type: ignore[arg-type]
urllib3.exceptions.MaxRetryError: HTTPConnectionPool(host='democracy.canterbury.gov.uk', port=80): Max retries exceeded with url: /mgWebService.asmx/GetCouncillorsByWard (Caused by ConnectTimeoutError(<urllib3.connection.HTTPConnection object at 0x7f8a87e2fe50>, 'Connection to democracy.canterbury.gov.uk timed out. (connect timeout=None)'))

During handling of the above exception, another exception occurred:

Traceback (most recent call last):
  File "/var/task/lgsf/aws_lambda/handlers.py", line 32, in scraper_worker_handler
    scraper.run(run_log)
  File "/var/task/lgsf/councillors/scrapers.py", line 200, in run
    wards = self.get_councillors()
  File "/var/task/lgsf/councillors/scrapers.py", line 219, in get_councillors
    req = self.get(
  File "/var/task/lgsf/scrapers/base.py", line 47, in get
    response = self.requests_session.get(
  File "/opt/python/requests/sessions.py", line 602, in get
    return self.request("GET", url, **kwargs)
  File "/opt/python/requests/sessions.py", line 589, in request
    resp = self.send(prep, **send_kwargs)
  File "/opt/python/requests/sessions.py", line 703, in send
    r = adapter.send(request, **kwargs)
  File "/opt/python/requests/adapters.py", line 507, in send
    raise ConnectTimeout(e, request=request)
requests.exceptions.ConnectTimeout: HTTPConnectionPool(host='democracy.canterbury.gov.uk', port=80): Max retries exceeded with url: /mgWebService.asmx/GetCouncillorsByWard (Caused by ConnectTimeoutError(<urllib3.connection.HTTPConnection object at 0x7f8a87e2fe50>, 'Connection to democracy.canterbury.gov.uk timed out. (connect timeout=None)'))
</dd>
      </div>
    </dl>
  </div>
  </div>

  <h3>Run log</h3>
  <pre>[09:58:08] Fetching Scraper for: CAT                              handlers.py:23
           Begin attempting to scrape: CAT                        handlers.py:27
           Deleting existing data...                                 base.py:251
           Getting all files in Councillors...                       base.py:203
[09:58:09] ...found 1 files in Councillors                           base.py:219
           Deleting batch no. 1 consisting of 1 files                base.py:230
           ...data deleted.                                          base.py:258
           Scraping from                                              base.py:41
           http://democracy.canterbury.gov.uk/mgWebService.asmx/GetCo           
           uncillorsByWard                                                      
[10:00:21] HTTPConnectionPool(host='democracy.canterbury.gov.uk', handlers.py:36
           port=80): Max retries exceeded with url:                             
           /mgWebService.asmx/GetCouncillorsByWard (Caused by                   
           ConnectTimeoutError(<urllib3.connection.HTTPConnection               
           object at 0x7f8a87e2fe50>, 'Connection to                            
           democracy.canterbury.gov.uk timed out. (connect                      
           timeout=None)'))                                                     
           Finished attempting to scrape: CAT                        base.py:339
</pre>
  

  


  <h2 id="2024-03-27-08-48">2024-03-27</h2>
  <div class="ds-card">
  <div class="ds-card-body">
    <dl class="ds-descriptions">
      <div>
        <dt>Duration</dt>
        <dd>132 seconds</dd>
      </div>
      <div>
        <dt>Start</dt>
        <dd>2024-03-27 08:48:45.062050</dd>
      </div>
      <div>
        <dt>End</dt>
        <dd>2024-03-27 08:50:57.982960</dd>
      </div>
      <div>
        <dt>Status code</dt>
        <dd>1</dd>
      </div>
      <div>
        <dt>Error</dt>
        <dd>Traceback (most recent call last):
  File "/opt/python/urllib3/connection.py", line 203, in _new_conn
    sock = connection.create_connection(
  File "/opt/python/urllib3/util/connection.py", line 85, in create_connection
    raise err
  File "/opt/python/urllib3/util/connection.py", line 73, in create_connection
    sock.connect(sa)
TimeoutError: [Errno 110] Connection timed out

The above exception was the direct cause of the following exception:

Traceback (most recent call last):
  File "/opt/python/urllib3/connectionpool.py", line 791, in urlopen
    response = self._make_request(
  File "/opt/python/urllib3/connectionpool.py", line 497, in _make_request
    conn.request(
  File "/opt/python/urllib3/connection.py", line 395, in request
    self.endheaders()
  File "/var/lang/lib/python3.10/http/client.py", line 1278, in endheaders
    self._send_output(message_body, encode_chunked=encode_chunked)
  File "/var/lang/lib/python3.10/http/client.py", line 1038, in _send_output
    self.send(msg)
  File "/var/lang/lib/python3.10/http/client.py", line 976, in send
    self.connect()
  File "/opt/python/urllib3/connection.py", line 243, in connect
    self.sock = self._new_conn()
  File "/opt/python/urllib3/connection.py", line 212, in _new_conn
    raise ConnectTimeoutError(
urllib3.exceptions.ConnectTimeoutError: (<urllib3.connection.HTTPConnection object at 0x7fab2ae81750>, 'Connection to democracy.canterbury.gov.uk timed out. (connect timeout=None)')

The above exception was the direct cause of the following exception:

Traceback (most recent call last):
  File "/opt/python/requests/adapters.py", line 486, in send
    resp = conn.urlopen(
  File "/opt/python/urllib3/connectionpool.py", line 845, in urlopen
    retries = retries.increment(
  File "/opt/python/urllib3/util/retry.py", line 515, in increment
    raise MaxRetryError(_pool, url, reason) from reason  # type: ignore[arg-type]
urllib3.exceptions.MaxRetryError: HTTPConnectionPool(host='democracy.canterbury.gov.uk', port=80): Max retries exceeded with url: /mgWebService.asmx/GetCouncillorsByWard (Caused by ConnectTimeoutError(<urllib3.connection.HTTPConnection object at 0x7fab2ae81750>, 'Connection to democracy.canterbury.gov.uk timed out. (connect timeout=None)'))

During handling of the above exception, another exception occurred:

Traceback (most recent call last):
  File "/var/task/lgsf/aws_lambda/handlers.py", line 32, in scraper_worker_handler
    scraper.run(run_log)
  File "/var/task/lgsf/councillors/scrapers.py", line 200, in run
    wards = self.get_councillors()
  File "/var/task/lgsf/councillors/scrapers.py", line 219, in get_councillors
    req = self.get(
  File "/var/task/lgsf/scrapers/base.py", line 47, in get
    response = self.requests_session.get(
  File "/opt/python/requests/sessions.py", line 602, in get
    return self.request("GET", url, **kwargs)
  File "/opt/python/requests/sessions.py", line 589, in request
    resp = self.send(prep, **send_kwargs)
  File "/opt/python/requests/sessions.py", line 703, in send
    r = adapter.send(request, **kwargs)
  File "/opt/python/requests/adapters.py", line 507, in send
    raise ConnectTimeout(e, request=request)
requests.exceptions.ConnectTimeout: HTTPConnectionPool(host='democracy.canterbury.gov.uk', port=80): Max retries exceeded with url: /mgWebService.asmx/GetCouncillorsByWard (Caused by ConnectTimeoutError(<urllib3.connection.HTTPConnection object at 0x7fab2ae81750>, 'Connection to democracy.canterbury.gov.uk timed out. (connect timeout=None)'))
</dd>
      </div>
    </dl>
  </div>
  </div>

  <h3>Run log</h3>
  <pre>[08:48:45] Fetching Scraper for: CAT                              handlers.py:23
           Begin attempting to scrape: CAT                        handlers.py:27
           Deleting existing data...                                 base.py:251
           Getting all files in Councillors...                       base.py:203
[08:48:46] ...found 1 files in Councillors                           base.py:219
           Deleting batch no. 1 consisting of 1 files                base.py:230
           ...data deleted.                                          base.py:258
           Scraping from                                              base.py:41
           http://democracy.canterbury.gov.uk/mgWebService.asmx/GetCo           
           uncillorsByWard                                                      
[08:50:57] HTTPConnectionPool(host='democracy.canterbury.gov.uk', handlers.py:36
           port=80): Max retries exceeded with url:                             
           /mgWebService.asmx/GetCouncillorsByWard (Caused by                   
           ConnectTimeoutError(<urllib3.connection.HTTPConnection               
           object at 0x7fab2ae81750>, 'Connection to                            
           democracy.canterbury.gov.uk timed out. (connect                      
           timeout=None)'))                                                     
           Finished attempting to scrape: CAT                        base.py:339
</pre>
  

  


  <h2 id="2024-03-26-08-18">2024-03-26</h2>
  <div class="ds-card">
  <div class="ds-card-body">
    <dl class="ds-descriptions">
      <div>
        <dt>Duration</dt>
        <dd>132 seconds</dd>
      </div>
      <div>
        <dt>Start</dt>
        <dd>2024-03-26 08:18:23.960331</dd>
      </div>
      <div>
        <dt>End</dt>
        <dd>2024-03-26 08:20:36.788135</dd>
      </div>
      <div>
        <dt>Status code</dt>
        <dd>1</dd>
      </div>
      <div>
        <dt>Error</dt>
        <dd>Traceback (most recent call last):
  File "/opt/python/urllib3/connection.py", line 203, in _new_conn
    sock = connection.create_connection(
  File "/opt/python/urllib3/util/connection.py", line 85, in create_connection
    raise err
  File "/opt/python/urllib3/util/connection.py", line 73, in create_connection
    sock.connect(sa)
TimeoutError: [Errno 110] Connection timed out

The above exception was the direct cause of the following exception:

Traceback (most recent call last):
  File "/opt/python/urllib3/connectionpool.py", line 791, in urlopen
    response = self._make_request(
  File "/opt/python/urllib3/connectionpool.py", line 497, in _make_request
    conn.request(
  File "/opt/python/urllib3/connection.py", line 395, in request
    self.endheaders()
  File "/var/lang/lib/python3.10/http/client.py", line 1278, in endheaders
    self._send_output(message_body, encode_chunked=encode_chunked)
  File "/var/lang/lib/python3.10/http/client.py", line 1038, in _send_output
    self.send(msg)
  File "/var/lang/lib/python3.10/http/client.py", line 976, in send
    self.connect()
  File "/opt/python/urllib3/connection.py", line 243, in connect
    self.sock = self._new_conn()
  File "/opt/python/urllib3/connection.py", line 212, in _new_conn
    raise ConnectTimeoutError(
urllib3.exceptions.ConnectTimeoutError: (<urllib3.connection.HTTPConnection object at 0x7f4662cc3880>, 'Connection to democracy.canterbury.gov.uk timed out. (connect timeout=None)')

The above exception was the direct cause of the following exception:

Traceback (most recent call last):
  File "/opt/python/requests/adapters.py", line 486, in send
    resp = conn.urlopen(
  File "/opt/python/urllib3/connectionpool.py", line 845, in urlopen
    retries = retries.increment(
  File "/opt/python/urllib3/util/retry.py", line 515, in increment
    raise MaxRetryError(_pool, url, reason) from reason  # type: ignore[arg-type]
urllib3.exceptions.MaxRetryError: HTTPConnectionPool(host='democracy.canterbury.gov.uk', port=80): Max retries exceeded with url: /mgWebService.asmx/GetCouncillorsByWard (Caused by ConnectTimeoutError(<urllib3.connection.HTTPConnection object at 0x7f4662cc3880>, 'Connection to democracy.canterbury.gov.uk timed out. (connect timeout=None)'))

During handling of the above exception, another exception occurred:

Traceback (most recent call last):
  File "/var/task/lgsf/aws_lambda/handlers.py", line 32, in scraper_worker_handler
    scraper.run(run_log)
  File "/var/task/lgsf/councillors/scrapers.py", line 200, in run
    wards = self.get_councillors()
  File "/var/task/lgsf/councillors/scrapers.py", line 219, in get_councillors
    req = self.get(
  File "/var/task/lgsf/scrapers/base.py", line 47, in get
    response = self.requests_session.get(
  File "/opt/python/requests/sessions.py", line 602, in get
    return self.request("GET", url, **kwargs)
  File "/opt/python/requests/sessions.py", line 589, in request
    resp = self.send(prep, **send_kwargs)
  File "/opt/python/requests/sessions.py", line 703, in send
    r = adapter.send(request, **kwargs)
  File "/opt/python/requests/adapters.py", line 507, in send
    raise ConnectTimeout(e, request=request)
requests.exceptions.ConnectTimeout: HTTPConnectionPool(host='democracy.canterbury.gov.uk', port=80): Max retries exceeded with url: /mgWebService.asmx/GetCouncillorsByWard (Caused by ConnectTimeoutError(<urllib3.connection.HTTPConnection object at 0x7f4662cc3880>, 'Connection to democracy.canterbury.gov.uk timed out. (connect timeout=None)'))
</dd>
      </div>
    </dl>
  </div>
  </div>

  <h3>Run log</h3>
  <pre>[08:18:23] Fetching Scraper for: CAT                              handlers.py:23
           Begin attempting to scrape: CAT                        handlers.py:27
[08:18:24] Deleting existing data...                                 base.py:251
           Getting all files in Councillors...                       base.py:203
           ...found 1 files in Councillors                           base.py:219
           Deleting batch no. 1 consisting of 1 files                base.py:230
[08:18:25] ...data deleted.                                          base.py:258
           Scraping from                                              base.py:41
           http://democracy.canterbury.gov.uk/mgWebService.asmx/GetCo           
           uncillorsByWard                                                      
[08:20:36] HTTPConnectionPool(host='democracy.canterbury.gov.uk', handlers.py:36
           port=80): Max retries exceeded with url:                             
           /mgWebService.asmx/GetCouncillorsByWard (Caused by                   
           ConnectTimeoutError(<urllib3.connection.HTTPConnection               
           object at 0x7f4662cc3880>, 'Connection to                            
           democracy.canterbury.gov.uk timed out. (connect                      
           timeout=None)'))                                                     
           Finished attempting to scrape: CAT                        base.py:339
</pre>
  

  


  <h2 id="2024-03-25-09-18">2024-03-25</h2>
  <div class="ds-card">
  <div class="ds-card-body">
    <dl class="ds-descriptions">
      <div>
        <dt>Duration</dt>
        <dd>131 seconds</dd>
      </div>
      <div>
        <dt>Start</dt>
        <dd>2024-03-25 09:18:43.148438</dd>
      </div>
      <div>
        <dt>End</dt>
        <dd>2024-03-25 09:20:54.714676</dd>
      </div>
      <div>
        <dt>Status code</dt>
        <dd>1</dd>
      </div>
      <div>
        <dt>Error</dt>
        <dd>Traceback (most recent call last):
  File "/opt/python/urllib3/connection.py", line 203, in _new_conn
    sock = connection.create_connection(
  File "/opt/python/urllib3/util/connection.py", line 85, in create_connection
    raise err
  File "/opt/python/urllib3/util/connection.py", line 73, in create_connection
    sock.connect(sa)
TimeoutError: [Errno 110] Connection timed out

The above exception was the direct cause of the following exception:

Traceback (most recent call last):
  File "/opt/python/urllib3/connectionpool.py", line 791, in urlopen
    response = self._make_request(
  File "/opt/python/urllib3/connectionpool.py", line 497, in _make_request
    conn.request(
  File "/opt/python/urllib3/connection.py", line 395, in request
    self.endheaders()
  File "/var/lang/lib/python3.10/http/client.py", line 1278, in endheaders
    self._send_output(message_body, encode_chunked=encode_chunked)
  File "/var/lang/lib/python3.10/http/client.py", line 1038, in _send_output
    self.send(msg)
  File "/var/lang/lib/python3.10/http/client.py", line 976, in send
    self.connect()
  File "/opt/python/urllib3/connection.py", line 243, in connect
    self.sock = self._new_conn()
  File "/opt/python/urllib3/connection.py", line 212, in _new_conn
    raise ConnectTimeoutError(
urllib3.exceptions.ConnectTimeoutError: (<urllib3.connection.HTTPConnection object at 0x7fb0fdf7c910>, 'Connection to democracy.canterbury.gov.uk timed out. (connect timeout=None)')

The above exception was the direct cause of the following exception:

Traceback (most recent call last):
  File "/opt/python/requests/adapters.py", line 486, in send
    resp = conn.urlopen(
  File "/opt/python/urllib3/connectionpool.py", line 845, in urlopen
    retries = retries.increment(
  File "/opt/python/urllib3/util/retry.py", line 515, in increment
    raise MaxRetryError(_pool, url, reason) from reason  # type: ignore[arg-type]
urllib3.exceptions.MaxRetryError: HTTPConnectionPool(host='democracy.canterbury.gov.uk', port=80): Max retries exceeded with url: /mgWebService.asmx/GetCouncillorsByWard (Caused by ConnectTimeoutError(<urllib3.connection.HTTPConnection object at 0x7fb0fdf7c910>, 'Connection to democracy.canterbury.gov.uk timed out. (connect timeout=None)'))

During handling of the above exception, another exception occurred:

Traceback (most recent call last):
  File "/var/task/lgsf/aws_lambda/handlers.py", line 32, in scraper_worker_handler
    scraper.run(run_log)
  File "/var/task/lgsf/councillors/scrapers.py", line 200, in run
    wards = self.get_councillors()
  File "/var/task/lgsf/councillors/scrapers.py", line 219, in get_councillors
    req = self.get(
  File "/var/task/lgsf/scrapers/base.py", line 47, in get
    response = self.requests_session.get(
  File "/opt/python/requests/sessions.py", line 602, in get
    return self.request("GET", url, **kwargs)
  File "/opt/python/requests/sessions.py", line 589, in request
    resp = self.send(prep, **send_kwargs)
  File "/opt/python/requests/sessions.py", line 703, in send
    r = adapter.send(request, **kwargs)
  File "/opt/python/requests/adapters.py", line 507, in send
    raise ConnectTimeout(e, request=request)
requests.exceptions.ConnectTimeout: HTTPConnectionPool(host='democracy.canterbury.gov.uk', port=80): Max retries exceeded with url: /mgWebService.asmx/GetCouncillorsByWard (Caused by ConnectTimeoutError(<urllib3.connection.HTTPConnection object at 0x7fb0fdf7c910>, 'Connection to democracy.canterbury.gov.uk timed out. (connect timeout=None)'))
</dd>
      </div>
    </dl>
  </div>
  </div>

  <h3>Run log</h3>
  <pre>[09:18:43] Fetching Scraper for: CAT                              handlers.py:23
           Begin attempting to scrape: CAT                        handlers.py:27
           Deleting existing data...                                 base.py:251
           Getting all files in Councillors...                       base.py:203
[09:18:44] ...found 1 files in Councillors                           base.py:219
           Deleting batch no. 1 consisting of 1 files                base.py:230
           ...data deleted.                                          base.py:258
           Scraping from                                              base.py:41
           http://democracy.canterbury.gov.uk/mgWebService.asmx/GetCo           
           uncillorsByWard                                                      
[09:20:54] HTTPConnectionPool(host='democracy.canterbury.gov.uk', handlers.py:36
           port=80): Max retries exceeded with url:                             
           /mgWebService.asmx/GetCouncillorsByWard (Caused by                   
           ConnectTimeoutError(<urllib3.connection.HTTPConnection               
           object at 0x7fb0fdf7c910>, 'Connection to                            
           democracy.canterbury.gov.uk timed out. (connect                      
           timeout=None)'))                                                     
           Finished attempting to scrape: CAT                        base.py:339
</pre>
  

  


  <h2 id="2024-03-24-09-57">2024-03-24</h2>
  <div class="ds-card">
  <div class="ds-card-body">
    <dl class="ds-descriptions">
      <div>
        <dt>Duration</dt>
        <dd>131 seconds</dd>
      </div>
      <div>
        <dt>Start</dt>
        <dd>2024-03-24 09:57:42.919211</dd>
      </div>
      <div>
        <dt>End</dt>
        <dd>2024-03-24 09:59:54.729641</dd>
      </div>
      <div>
        <dt>Status code</dt>
        <dd>1</dd>
      </div>
      <div>
        <dt>Error</dt>
        <dd>Traceback (most recent call last):
  File "/opt/python/urllib3/connection.py", line 203, in _new_conn
    sock = connection.create_connection(
  File "/opt/python/urllib3/util/connection.py", line 85, in create_connection
    raise err
  File "/opt/python/urllib3/util/connection.py", line 73, in create_connection
    sock.connect(sa)
TimeoutError: [Errno 110] Connection timed out

The above exception was the direct cause of the following exception:

Traceback (most recent call last):
  File "/opt/python/urllib3/connectionpool.py", line 791, in urlopen
    response = self._make_request(
  File "/opt/python/urllib3/connectionpool.py", line 497, in _make_request
    conn.request(
  File "/opt/python/urllib3/connection.py", line 395, in request
    self.endheaders()
  File "/var/lang/lib/python3.10/http/client.py", line 1278, in endheaders
    self._send_output(message_body, encode_chunked=encode_chunked)
  File "/var/lang/lib/python3.10/http/client.py", line 1038, in _send_output
    self.send(msg)
  File "/var/lang/lib/python3.10/http/client.py", line 976, in send
    self.connect()
  File "/opt/python/urllib3/connection.py", line 243, in connect
    self.sock = self._new_conn()
  File "/opt/python/urllib3/connection.py", line 212, in _new_conn
    raise ConnectTimeoutError(
urllib3.exceptions.ConnectTimeoutError: (<urllib3.connection.HTTPConnection object at 0x7f3f0a424940>, 'Connection to democracy.canterbury.gov.uk timed out. (connect timeout=None)')

The above exception was the direct cause of the following exception:

Traceback (most recent call last):
  File "/opt/python/requests/adapters.py", line 486, in send
    resp = conn.urlopen(
  File "/opt/python/urllib3/connectionpool.py", line 845, in urlopen
    retries = retries.increment(
  File "/opt/python/urllib3/util/retry.py", line 515, in increment
    raise MaxRetryError(_pool, url, reason) from reason  # type: ignore[arg-type]
urllib3.exceptions.MaxRetryError: HTTPConnectionPool(host='democracy.canterbury.gov.uk', port=80): Max retries exceeded with url: /mgWebService.asmx/GetCouncillorsByWard (Caused by ConnectTimeoutError(<urllib3.connection.HTTPConnection object at 0x7f3f0a424940>, 'Connection to democracy.canterbury.gov.uk timed out. (connect timeout=None)'))

During handling of the above exception, another exception occurred:

Traceback (most recent call last):
  File "/var/task/lgsf/aws_lambda/handlers.py", line 32, in scraper_worker_handler
    scraper.run(run_log)
  File "/var/task/lgsf/councillors/scrapers.py", line 200, in run
    wards = self.get_councillors()
  File "/var/task/lgsf/councillors/scrapers.py", line 219, in get_councillors
    req = self.get(
  File "/var/task/lgsf/scrapers/base.py", line 47, in get
    response = self.requests_session.get(
  File "/opt/python/requests/sessions.py", line 602, in get
    return self.request("GET", url, **kwargs)
  File "/opt/python/requests/sessions.py", line 589, in request
    resp = self.send(prep, **send_kwargs)
  File "/opt/python/requests/sessions.py", line 703, in send
    r = adapter.send(request, **kwargs)
  File "/opt/python/requests/adapters.py", line 507, in send
    raise ConnectTimeout(e, request=request)
requests.exceptions.ConnectTimeout: HTTPConnectionPool(host='democracy.canterbury.gov.uk', port=80): Max retries exceeded with url: /mgWebService.asmx/GetCouncillorsByWard (Caused by ConnectTimeoutError(<urllib3.connection.HTTPConnection object at 0x7f3f0a424940>, 'Connection to democracy.canterbury.gov.uk timed out. (connect timeout=None)'))
</dd>
      </div>
    </dl>
  </div>
  </div>

  <h3>Run log</h3>
  <pre>[09:57:42] Fetching Scraper for: CAT                              handlers.py:23
           Begin attempting to scrape: CAT                        handlers.py:27
[09:57:43] Deleting existing data...                                 base.py:251
           Getting all files in Councillors...                       base.py:203
           ...found 1 files in Councillors                           base.py:219
           Deleting batch no. 1 consisting of 1 files                base.py:230
[09:57:44] ...data deleted.                                          base.py:258
           Scraping from                                              base.py:41
           http://democracy.canterbury.gov.uk/mgWebService.asmx/GetCo           
           uncillorsByWard                                                      
[09:59:54] HTTPConnectionPool(host='democracy.canterbury.gov.uk', handlers.py:36
           port=80): Max retries exceeded with url:                             
           /mgWebService.asmx/GetCouncillorsByWard (Caused by                   
           ConnectTimeoutError(<urllib3.connection.HTTPConnection               
           object at 0x7f3f0a424940>, 'Connection to                            
           democracy.canterbury.gov.uk timed out. (connect                      
           timeout=None)'))                                                     
           Finished attempting to scrape: CAT                        base.py:339
</pre>
  

  


  <h2 id="2024-03-23-08-27">2024-03-23</h2>
  <div class="ds-card">
  <div class="ds-card-body">
    <dl class="ds-descriptions">
      <div>
        <dt>Duration</dt>
        <dd>133 seconds</dd>
      </div>
      <div>
        <dt>Start</dt>
        <dd>2024-03-23 08:27:52.797890</dd>
      </div>
      <div>
        <dt>End</dt>
        <dd>2024-03-23 08:30:05.847924</dd>
      </div>
      <div>
        <dt>Status code</dt>
        <dd>1</dd>
      </div>
      <div>
        <dt>Error</dt>
        <dd>Traceback (most recent call last):
  File "/opt/python/urllib3/connection.py", line 203, in _new_conn
    sock = connection.create_connection(
  File "/opt/python/urllib3/util/connection.py", line 85, in create_connection
    raise err
  File "/opt/python/urllib3/util/connection.py", line 73, in create_connection
    sock.connect(sa)
TimeoutError: [Errno 110] Connection timed out

The above exception was the direct cause of the following exception:

Traceback (most recent call last):
  File "/opt/python/urllib3/connectionpool.py", line 791, in urlopen
    response = self._make_request(
  File "/opt/python/urllib3/connectionpool.py", line 497, in _make_request
    conn.request(
  File "/opt/python/urllib3/connection.py", line 395, in request
    self.endheaders()
  File "/var/lang/lib/python3.10/http/client.py", line 1278, in endheaders
    self._send_output(message_body, encode_chunked=encode_chunked)
  File "/var/lang/lib/python3.10/http/client.py", line 1038, in _send_output
    self.send(msg)
  File "/var/lang/lib/python3.10/http/client.py", line 976, in send
    self.connect()
  File "/opt/python/urllib3/connection.py", line 243, in connect
    self.sock = self._new_conn()
  File "/opt/python/urllib3/connection.py", line 212, in _new_conn
    raise ConnectTimeoutError(
urllib3.exceptions.ConnectTimeoutError: (<urllib3.connection.HTTPConnection object at 0x7f5ab2812110>, 'Connection to democracy.canterbury.gov.uk timed out. (connect timeout=None)')

The above exception was the direct cause of the following exception:

Traceback (most recent call last):
  File "/opt/python/requests/adapters.py", line 486, in send
    resp = conn.urlopen(
  File "/opt/python/urllib3/connectionpool.py", line 845, in urlopen
    retries = retries.increment(
  File "/opt/python/urllib3/util/retry.py", line 515, in increment
    raise MaxRetryError(_pool, url, reason) from reason  # type: ignore[arg-type]
urllib3.exceptions.MaxRetryError: HTTPConnectionPool(host='democracy.canterbury.gov.uk', port=80): Max retries exceeded with url: /mgWebService.asmx/GetCouncillorsByWard (Caused by ConnectTimeoutError(<urllib3.connection.HTTPConnection object at 0x7f5ab2812110>, 'Connection to democracy.canterbury.gov.uk timed out. (connect timeout=None)'))

During handling of the above exception, another exception occurred:

Traceback (most recent call last):
  File "/var/task/lgsf/aws_lambda/handlers.py", line 32, in scraper_worker_handler
    scraper.run(run_log)
  File "/var/task/lgsf/councillors/scrapers.py", line 200, in run
    wards = self.get_councillors()
  File "/var/task/lgsf/councillors/scrapers.py", line 219, in get_councillors
    req = self.get(
  File "/var/task/lgsf/scrapers/base.py", line 47, in get
    response = self.requests_session.get(
  File "/opt/python/requests/sessions.py", line 602, in get
    return self.request("GET", url, **kwargs)
  File "/opt/python/requests/sessions.py", line 589, in request
    resp = self.send(prep, **send_kwargs)
  File "/opt/python/requests/sessions.py", line 703, in send
    r = adapter.send(request, **kwargs)
  File "/opt/python/requests/adapters.py", line 507, in send
    raise ConnectTimeout(e, request=request)
requests.exceptions.ConnectTimeout: HTTPConnectionPool(host='democracy.canterbury.gov.uk', port=80): Max retries exceeded with url: /mgWebService.asmx/GetCouncillorsByWard (Caused by ConnectTimeoutError(<urllib3.connection.HTTPConnection object at 0x7f5ab2812110>, 'Connection to democracy.canterbury.gov.uk timed out. (connect timeout=None)'))
</dd>
      </div>
    </dl>
  </div>
  </div>

  <h3>Run log</h3>
  <pre>[08:27:52] Fetching Scraper for: CAT                              handlers.py:23
           Begin attempting to scrape: CAT                        handlers.py:27
[08:27:53] Deleting existing data...                                 base.py:251
           Getting all files in Councillors...                       base.py:203
           ...found 1 files in Councillors                           base.py:219
           Deleting batch no. 1 consisting of 1 files                base.py:230
[08:27:54] ...data deleted.                                          base.py:258
           Scraping from                                              base.py:41
           http://democracy.canterbury.gov.uk/mgWebService.asmx/GetCo           
           uncillorsByWard                                                      
[08:30:05] HTTPConnectionPool(host='democracy.canterbury.gov.uk', handlers.py:36
           port=80): Max retries exceeded with url:                             
           /mgWebService.asmx/GetCouncillorsByWard (Caused by                   
           ConnectTimeoutError(<urllib3.connection.HTTPConnection               
           object at 0x7f5ab2812110>, 'Connection to                            
           democracy.canterbury.gov.uk timed out. (connect                      
           timeout=None)'))                                                     
           Finished attempting to scrape: CAT                        base.py:339
</pre>
  

  


  <h2 id="2024-03-22-10-09">2024-03-22</h2>
  <div class="ds-card">
  <div class="ds-card-body">
    <dl class="ds-descriptions">
      <div>
        <dt>Duration</dt>
        <dd>132 seconds</dd>
      </div>
      <div>
        <dt>Start</dt>
        <dd>2024-03-22 10:09:16.454863</dd>
      </div>
      <div>
        <dt>End</dt>
        <dd>2024-03-22 10:11:29.102670</dd>
      </div>
      <div>
        <dt>Status code</dt>
        <dd>1</dd>
      </div>
      <div>
        <dt>Error</dt>
        <dd>Traceback (most recent call last):
  File "/opt/python/urllib3/connection.py", line 203, in _new_conn
    sock = connection.create_connection(
  File "/opt/python/urllib3/util/connection.py", line 85, in create_connection
    raise err
  File "/opt/python/urllib3/util/connection.py", line 73, in create_connection
    sock.connect(sa)
TimeoutError: [Errno 110] Connection timed out

The above exception was the direct cause of the following exception:

Traceback (most recent call last):
  File "/opt/python/urllib3/connectionpool.py", line 791, in urlopen
    response = self._make_request(
  File "/opt/python/urllib3/connectionpool.py", line 497, in _make_request
    conn.request(
  File "/opt/python/urllib3/connection.py", line 395, in request
    self.endheaders()
  File "/var/lang/lib/python3.10/http/client.py", line 1278, in endheaders
    self._send_output(message_body, encode_chunked=encode_chunked)
  File "/var/lang/lib/python3.10/http/client.py", line 1038, in _send_output
    self.send(msg)
  File "/var/lang/lib/python3.10/http/client.py", line 976, in send
    self.connect()
  File "/opt/python/urllib3/connection.py", line 243, in connect
    self.sock = self._new_conn()
  File "/opt/python/urllib3/connection.py", line 212, in _new_conn
    raise ConnectTimeoutError(
urllib3.exceptions.ConnectTimeoutError: (<urllib3.connection.HTTPConnection object at 0x7fba158017e0>, 'Connection to democracy.canterbury.gov.uk timed out. (connect timeout=None)')

The above exception was the direct cause of the following exception:

Traceback (most recent call last):
  File "/opt/python/requests/adapters.py", line 486, in send
    resp = conn.urlopen(
  File "/opt/python/urllib3/connectionpool.py", line 845, in urlopen
    retries = retries.increment(
  File "/opt/python/urllib3/util/retry.py", line 515, in increment
    raise MaxRetryError(_pool, url, reason) from reason  # type: ignore[arg-type]
urllib3.exceptions.MaxRetryError: HTTPConnectionPool(host='democracy.canterbury.gov.uk', port=80): Max retries exceeded with url: /mgWebService.asmx/GetCouncillorsByWard (Caused by ConnectTimeoutError(<urllib3.connection.HTTPConnection object at 0x7fba158017e0>, 'Connection to democracy.canterbury.gov.uk timed out. (connect timeout=None)'))

During handling of the above exception, another exception occurred:

Traceback (most recent call last):
  File "/var/task/lgsf/aws_lambda/handlers.py", line 32, in scraper_worker_handler
    scraper.run(run_log)
  File "/var/task/lgsf/councillors/scrapers.py", line 200, in run
    wards = self.get_councillors()
  File "/var/task/lgsf/councillors/scrapers.py", line 219, in get_councillors
    req = self.get(
  File "/var/task/lgsf/scrapers/base.py", line 47, in get
    response = self.requests_session.get(
  File "/opt/python/requests/sessions.py", line 602, in get
    return self.request("GET", url, **kwargs)
  File "/opt/python/requests/sessions.py", line 589, in request
    resp = self.send(prep, **send_kwargs)
  File "/opt/python/requests/sessions.py", line 703, in send
    r = adapter.send(request, **kwargs)
  File "/opt/python/requests/adapters.py", line 507, in send
    raise ConnectTimeout(e, request=request)
requests.exceptions.ConnectTimeout: HTTPConnectionPool(host='democracy.canterbury.gov.uk', port=80): Max retries exceeded with url: /mgWebService.asmx/GetCouncillorsByWard (Caused by ConnectTimeoutError(<urllib3.connection.HTTPConnection object at 0x7fba158017e0>, 'Connection to democracy.canterbury.gov.uk timed out. (connect timeout=None)'))
</dd>
      </div>
    </dl>
  </div>
  </div>

  <h3>Run log</h3>
  <pre>[10:09:16] Fetching Scraper for: CAT                              handlers.py:23
           Begin attempting to scrape: CAT                        handlers.py:27
           Deleting existing data...                                 base.py:251
[10:09:17] Getting all files in Councillors...                       base.py:203
           ...found 1 files in Councillors                           base.py:219
           Deleting batch no. 1 consisting of 1 files                base.py:230
[10:09:18] ...data deleted.                                          base.py:258
           Scraping from                                              base.py:41
           http://democracy.canterbury.gov.uk/mgWebService.asmx/GetCo           
           uncillorsByWard                                                      
[10:11:28] HTTPConnectionPool(host='democracy.canterbury.gov.uk', handlers.py:36
           port=80): Max retries exceeded with url:                             
           /mgWebService.asmx/GetCouncillorsByWard (Caused by                   
           ConnectTimeoutError(<urllib3.connection.HTTPConnection               
           object at 0x7fba158017e0>, 'Connection to                            
           democracy.canterbury.gov.uk timed out. (connect                      
           timeout=None)'))                                                     
[10:11:29] Finished attempting to scrape: CAT                        base.py:339
</pre>
  

  


  <h2 id="2024-03-21-09-03">2024-03-21</h2>
  <div class="ds-card">
  <div class="ds-card-body">
    <dl class="ds-descriptions">
      <div>
        <dt>Duration</dt>
        <dd>132 seconds</dd>
      </div>
      <div>
        <dt>Start</dt>
        <dd>2024-03-21 09:03:14.562951</dd>
      </div>
      <div>
        <dt>End</dt>
        <dd>2024-03-21 09:05:27.253343</dd>
      </div>
      <div>
        <dt>Status code</dt>
        <dd>1</dd>
      </div>
      <div>
        <dt>Error</dt>
        <dd>Traceback (most recent call last):
  File "/opt/python/urllib3/connection.py", line 203, in _new_conn
    sock = connection.create_connection(
  File "/opt/python/urllib3/util/connection.py", line 85, in create_connection
    raise err
  File "/opt/python/urllib3/util/connection.py", line 73, in create_connection
    sock.connect(sa)
TimeoutError: [Errno 110] Connection timed out

The above exception was the direct cause of the following exception:

Traceback (most recent call last):
  File "/opt/python/urllib3/connectionpool.py", line 791, in urlopen
    response = self._make_request(
  File "/opt/python/urllib3/connectionpool.py", line 497, in _make_request
    conn.request(
  File "/opt/python/urllib3/connection.py", line 395, in request
    self.endheaders()
  File "/var/lang/lib/python3.10/http/client.py", line 1278, in endheaders
    self._send_output(message_body, encode_chunked=encode_chunked)
  File "/var/lang/lib/python3.10/http/client.py", line 1038, in _send_output
    self.send(msg)
  File "/var/lang/lib/python3.10/http/client.py", line 976, in send
    self.connect()
  File "/opt/python/urllib3/connection.py", line 243, in connect
    self.sock = self._new_conn()
  File "/opt/python/urllib3/connection.py", line 212, in _new_conn
    raise ConnectTimeoutError(
urllib3.exceptions.ConnectTimeoutError: (<urllib3.connection.HTTPConnection object at 0x7fea2ca447f0>, 'Connection to democracy.canterbury.gov.uk timed out. (connect timeout=None)')

The above exception was the direct cause of the following exception:

Traceback (most recent call last):
  File "/opt/python/requests/adapters.py", line 486, in send
    resp = conn.urlopen(
  File "/opt/python/urllib3/connectionpool.py", line 845, in urlopen
    retries = retries.increment(
  File "/opt/python/urllib3/util/retry.py", line 515, in increment
    raise MaxRetryError(_pool, url, reason) from reason  # type: ignore[arg-type]
urllib3.exceptions.MaxRetryError: HTTPConnectionPool(host='democracy.canterbury.gov.uk', port=80): Max retries exceeded with url: /mgWebService.asmx/GetCouncillorsByWard (Caused by ConnectTimeoutError(<urllib3.connection.HTTPConnection object at 0x7fea2ca447f0>, 'Connection to democracy.canterbury.gov.uk timed out. (connect timeout=None)'))

During handling of the above exception, another exception occurred:

Traceback (most recent call last):
  File "/var/task/lgsf/aws_lambda/handlers.py", line 32, in scraper_worker_handler
    scraper.run(run_log)
  File "/var/task/lgsf/councillors/scrapers.py", line 200, in run
    wards = self.get_councillors()
  File "/var/task/lgsf/councillors/scrapers.py", line 219, in get_councillors
    req = self.get(
  File "/var/task/lgsf/scrapers/base.py", line 47, in get
    response = self.requests_session.get(
  File "/opt/python/requests/sessions.py", line 602, in get
    return self.request("GET", url, **kwargs)
  File "/opt/python/requests/sessions.py", line 589, in request
    resp = self.send(prep, **send_kwargs)
  File "/opt/python/requests/sessions.py", line 703, in send
    r = adapter.send(request, **kwargs)
  File "/opt/python/requests/adapters.py", line 507, in send
    raise ConnectTimeout(e, request=request)
requests.exceptions.ConnectTimeout: HTTPConnectionPool(host='democracy.canterbury.gov.uk', port=80): Max retries exceeded with url: /mgWebService.asmx/GetCouncillorsByWard (Caused by ConnectTimeoutError(<urllib3.connection.HTTPConnection object at 0x7fea2ca447f0>, 'Connection to democracy.canterbury.gov.uk timed out. (connect timeout=None)'))
</dd>
      </div>
    </dl>
  </div>
  </div>

  <h3>Run log</h3>
  <pre>[09:03:14] Fetching Scraper for: CAT                              handlers.py:23
           Begin attempting to scrape: CAT                        handlers.py:27
           Deleting existing data...                                 base.py:251
[09:03:15] Getting all files in Councillors...                       base.py:203
           ...found 1 files in Councillors                           base.py:219
           Deleting batch no. 1 consisting of 1 files                base.py:230
[09:03:16] ...data deleted.                                          base.py:258
           Scraping from                                              base.py:41
           http://democracy.canterbury.gov.uk/mgWebService.asmx/GetCo           
           uncillorsByWard                                                      
[09:05:26] HTTPConnectionPool(host='democracy.canterbury.gov.uk', handlers.py:36
           port=80): Max retries exceeded with url:                             
           /mgWebService.asmx/GetCouncillorsByWard (Caused by                   
           ConnectTimeoutError(<urllib3.connection.HTTPConnection               
           object at 0x7fea2ca447f0>, 'Connection to                            
           democracy.canterbury.gov.uk timed out. (connect                      
           timeout=None)'))                                                     
[09:05:27] Finished attempting to scrape: CAT                        base.py:339
</pre>
  

  


  <h2 id="2024-03-20-10-04">2024-03-20</h2>
  <div class="ds-card">
  <div class="ds-card-body">
    <dl class="ds-descriptions">
      <div>
        <dt>Duration</dt>
        <dd>133 seconds</dd>
      </div>
      <div>
        <dt>Start</dt>
        <dd>2024-03-20 10:04:10.410062</dd>
      </div>
      <div>
        <dt>End</dt>
        <dd>2024-03-20 10:06:23.518653</dd>
      </div>
      <div>
        <dt>Status code</dt>
        <dd>1</dd>
      </div>
      <div>
        <dt>Error</dt>
        <dd>Traceback (most recent call last):
  File "/opt/python/urllib3/connection.py", line 203, in _new_conn
    sock = connection.create_connection(
  File "/opt/python/urllib3/util/connection.py", line 85, in create_connection
    raise err
  File "/opt/python/urllib3/util/connection.py", line 73, in create_connection
    sock.connect(sa)
TimeoutError: [Errno 110] Connection timed out

The above exception was the direct cause of the following exception:

Traceback (most recent call last):
  File "/opt/python/urllib3/connectionpool.py", line 791, in urlopen
    response = self._make_request(
  File "/opt/python/urllib3/connectionpool.py", line 497, in _make_request
    conn.request(
  File "/opt/python/urllib3/connection.py", line 395, in request
    self.endheaders()
  File "/var/lang/lib/python3.10/http/client.py", line 1278, in endheaders
    self._send_output(message_body, encode_chunked=encode_chunked)
  File "/var/lang/lib/python3.10/http/client.py", line 1038, in _send_output
    self.send(msg)
  File "/var/lang/lib/python3.10/http/client.py", line 976, in send
    self.connect()
  File "/opt/python/urllib3/connection.py", line 243, in connect
    self.sock = self._new_conn()
  File "/opt/python/urllib3/connection.py", line 212, in _new_conn
    raise ConnectTimeoutError(
urllib3.exceptions.ConnectTimeoutError: (<urllib3.connection.HTTPConnection object at 0x7fd3e1520eb0>, 'Connection to democracy.canterbury.gov.uk timed out. (connect timeout=None)')

The above exception was the direct cause of the following exception:

Traceback (most recent call last):
  File "/opt/python/requests/adapters.py", line 486, in send
    resp = conn.urlopen(
  File "/opt/python/urllib3/connectionpool.py", line 845, in urlopen
    retries = retries.increment(
  File "/opt/python/urllib3/util/retry.py", line 515, in increment
    raise MaxRetryError(_pool, url, reason) from reason  # type: ignore[arg-type]
urllib3.exceptions.MaxRetryError: HTTPConnectionPool(host='democracy.canterbury.gov.uk', port=80): Max retries exceeded with url: /mgWebService.asmx/GetCouncillorsByWard (Caused by ConnectTimeoutError(<urllib3.connection.HTTPConnection object at 0x7fd3e1520eb0>, 'Connection to democracy.canterbury.gov.uk timed out. (connect timeout=None)'))

During handling of the above exception, another exception occurred:

Traceback (most recent call last):
  File "/var/task/lgsf/aws_lambda/handlers.py", line 32, in scraper_worker_handler
    scraper.run(run_log)
  File "/var/task/lgsf/councillors/scrapers.py", line 200, in run
    wards = self.get_councillors()
  File "/var/task/lgsf/councillors/scrapers.py", line 219, in get_councillors
    req = self.get(
  File "/var/task/lgsf/scrapers/base.py", line 47, in get
    response = self.requests_session.get(
  File "/opt/python/requests/sessions.py", line 602, in get
    return self.request("GET", url, **kwargs)
  File "/opt/python/requests/sessions.py", line 589, in request
    resp = self.send(prep, **send_kwargs)
  File "/opt/python/requests/sessions.py", line 703, in send
    r = adapter.send(request, **kwargs)
  File "/opt/python/requests/adapters.py", line 507, in send
    raise ConnectTimeout(e, request=request)
requests.exceptions.ConnectTimeout: HTTPConnectionPool(host='democracy.canterbury.gov.uk', port=80): Max retries exceeded with url: /mgWebService.asmx/GetCouncillorsByWard (Caused by ConnectTimeoutError(<urllib3.connection.HTTPConnection object at 0x7fd3e1520eb0>, 'Connection to democracy.canterbury.gov.uk timed out. (connect timeout=None)'))
</dd>
      </div>
    </dl>
  </div>
  </div>

  <h3>Run log</h3>
  <pre>[10:04:10] Fetching Scraper for: CAT                              handlers.py:23
           Begin attempting to scrape: CAT                        handlers.py:27
           Deleting existing data...                                 base.py:251
[10:04:11] Getting all files in Councillors...                       base.py:203
           ...found 1 files in Councillors                           base.py:219
           Deleting batch no. 1 consisting of 1 files                base.py:230
[10:04:12] ...data deleted.                                          base.py:258
           Scraping from                                              base.py:41
           http://democracy.canterbury.gov.uk/mgWebService.asmx/GetCo           
           uncillorsByWard                                                      
[10:06:23] HTTPConnectionPool(host='democracy.canterbury.gov.uk', handlers.py:36
           port=80): Max retries exceeded with url:                             
           /mgWebService.asmx/GetCouncillorsByWard (Caused by                   
           ConnectTimeoutError(<urllib3.connection.HTTPConnection               
           object at 0x7fd3e1520eb0>, 'Connection to                            
           democracy.canterbury.gov.uk timed out. (connect                      
           timeout=None)'))                                                     
           Finished attempting to scrape: CAT                        base.py:339
</pre>
  

  


  <h2 id="2024-03-19-10-01">2024-03-19</h2>
  <div class="ds-card">
  <div class="ds-card-body">
    <dl class="ds-descriptions">
      <div>
        <dt>Duration</dt>
        <dd>132 seconds</dd>
      </div>
      <div>
        <dt>Start</dt>
        <dd>2024-03-19 10:01:38.255556</dd>
      </div>
      <div>
        <dt>End</dt>
        <dd>2024-03-19 10:03:50.358725</dd>
      </div>
      <div>
        <dt>Status code</dt>
        <dd>1</dd>
      </div>
      <div>
        <dt>Error</dt>
        <dd>Traceback (most recent call last):
  File "/opt/python/urllib3/connection.py", line 203, in _new_conn
    sock = connection.create_connection(
  File "/opt/python/urllib3/util/connection.py", line 85, in create_connection
    raise err
  File "/opt/python/urllib3/util/connection.py", line 73, in create_connection
    sock.connect(sa)
TimeoutError: [Errno 110] Connection timed out

The above exception was the direct cause of the following exception:

Traceback (most recent call last):
  File "/opt/python/urllib3/connectionpool.py", line 791, in urlopen
    response = self._make_request(
  File "/opt/python/urllib3/connectionpool.py", line 497, in _make_request
    conn.request(
  File "/opt/python/urllib3/connection.py", line 395, in request
    self.endheaders()
  File "/var/lang/lib/python3.10/http/client.py", line 1278, in endheaders
    self._send_output(message_body, encode_chunked=encode_chunked)
  File "/var/lang/lib/python3.10/http/client.py", line 1038, in _send_output
    self.send(msg)
  File "/var/lang/lib/python3.10/http/client.py", line 976, in send
    self.connect()
  File "/opt/python/urllib3/connection.py", line 243, in connect
    self.sock = self._new_conn()
  File "/opt/python/urllib3/connection.py", line 212, in _new_conn
    raise ConnectTimeoutError(
urllib3.exceptions.ConnectTimeoutError: (<urllib3.connection.HTTPConnection object at 0x7f2471dede40>, 'Connection to democracy.canterbury.gov.uk timed out. (connect timeout=None)')

The above exception was the direct cause of the following exception:

Traceback (most recent call last):
  File "/opt/python/requests/adapters.py", line 486, in send
    resp = conn.urlopen(
  File "/opt/python/urllib3/connectionpool.py", line 845, in urlopen
    retries = retries.increment(
  File "/opt/python/urllib3/util/retry.py", line 515, in increment
    raise MaxRetryError(_pool, url, reason) from reason  # type: ignore[arg-type]
urllib3.exceptions.MaxRetryError: HTTPConnectionPool(host='democracy.canterbury.gov.uk', port=80): Max retries exceeded with url: /mgWebService.asmx/GetCouncillorsByWard (Caused by ConnectTimeoutError(<urllib3.connection.HTTPConnection object at 0x7f2471dede40>, 'Connection to democracy.canterbury.gov.uk timed out. (connect timeout=None)'))

During handling of the above exception, another exception occurred:

Traceback (most recent call last):
  File "/var/task/lgsf/aws_lambda/handlers.py", line 32, in scraper_worker_handler
    scraper.run(run_log)
  File "/var/task/lgsf/councillors/scrapers.py", line 200, in run
    wards = self.get_councillors()
  File "/var/task/lgsf/councillors/scrapers.py", line 219, in get_councillors
    req = self.get(
  File "/var/task/lgsf/scrapers/base.py", line 47, in get
    response = self.requests_session.get(
  File "/opt/python/requests/sessions.py", line 602, in get
    return self.request("GET", url, **kwargs)
  File "/opt/python/requests/sessions.py", line 589, in request
    resp = self.send(prep, **send_kwargs)
  File "/opt/python/requests/sessions.py", line 703, in send
    r = adapter.send(request, **kwargs)
  File "/opt/python/requests/adapters.py", line 507, in send
    raise ConnectTimeout(e, request=request)
requests.exceptions.ConnectTimeout: HTTPConnectionPool(host='democracy.canterbury.gov.uk', port=80): Max retries exceeded with url: /mgWebService.asmx/GetCouncillorsByWard (Caused by ConnectTimeoutError(<urllib3.connection.HTTPConnection object at 0x7f2471dede40>, 'Connection to democracy.canterbury.gov.uk timed out. (connect timeout=None)'))
</dd>
      </div>
    </dl>
  </div>
  </div>

  <h3>Run log</h3>
  <pre>[10:01:38] Fetching Scraper for: CAT                              handlers.py:23
           Begin attempting to scrape: CAT                        handlers.py:27
           Deleting existing data...                                 base.py:251
[10:01:39] Getting all files in Councillors...                       base.py:203
           ...found 1 files in Councillors                           base.py:219
           Deleting batch no. 1 consisting of 1 files                base.py:230
[10:01:40] ...data deleted.                                          base.py:258
           Scraping from                                              base.py:41
           http://democracy.canterbury.gov.uk/mgWebService.asmx/GetCo           
           uncillorsByWard                                                      
[10:03:49] HTTPConnectionPool(host='democracy.canterbury.gov.uk', handlers.py:36
           port=80): Max retries exceeded with url:                             
           /mgWebService.asmx/GetCouncillorsByWard (Caused by                   
           ConnectTimeoutError(<urllib3.connection.HTTPConnection               
           object at 0x7f2471dede40>, 'Connection to                            
           democracy.canterbury.gov.uk timed out. (connect                      
           timeout=None)'))                                                     
[10:03:50] Finished attempting to scrape: CAT                        base.py:339
</pre>
  

  


  <h2 id="2024-03-18-09-00">2024-03-18</h2>
  <div class="ds-card">
  <div class="ds-card-body">
    <dl class="ds-descriptions">
      <div>
        <dt>Duration</dt>
        <dd>132 seconds</dd>
      </div>
      <div>
        <dt>Start</dt>
        <dd>2024-03-18 09:00:29.269114</dd>
      </div>
      <div>
        <dt>End</dt>
        <dd>2024-03-18 09:02:41.463402</dd>
      </div>
      <div>
        <dt>Status code</dt>
        <dd>1</dd>
      </div>
      <div>
        <dt>Error</dt>
        <dd>Traceback (most recent call last):
  File "/opt/python/urllib3/connection.py", line 203, in _new_conn
    sock = connection.create_connection(
  File "/opt/python/urllib3/util/connection.py", line 85, in create_connection
    raise err
  File "/opt/python/urllib3/util/connection.py", line 73, in create_connection
    sock.connect(sa)
TimeoutError: [Errno 110] Connection timed out

The above exception was the direct cause of the following exception:

Traceback (most recent call last):
  File "/opt/python/urllib3/connectionpool.py", line 791, in urlopen
    response = self._make_request(
  File "/opt/python/urllib3/connectionpool.py", line 497, in _make_request
    conn.request(
  File "/opt/python/urllib3/connection.py", line 395, in request
    self.endheaders()
  File "/var/lang/lib/python3.10/http/client.py", line 1278, in endheaders
    self._send_output(message_body, encode_chunked=encode_chunked)
  File "/var/lang/lib/python3.10/http/client.py", line 1038, in _send_output
    self.send(msg)
  File "/var/lang/lib/python3.10/http/client.py", line 976, in send
    self.connect()
  File "/opt/python/urllib3/connection.py", line 243, in connect
    self.sock = self._new_conn()
  File "/opt/python/urllib3/connection.py", line 212, in _new_conn
    raise ConnectTimeoutError(
urllib3.exceptions.ConnectTimeoutError: (<urllib3.connection.HTTPConnection object at 0x7f7460431300>, 'Connection to democracy.canterbury.gov.uk timed out. (connect timeout=None)')

The above exception was the direct cause of the following exception:

Traceback (most recent call last):
  File "/opt/python/requests/adapters.py", line 486, in send
    resp = conn.urlopen(
  File "/opt/python/urllib3/connectionpool.py", line 845, in urlopen
    retries = retries.increment(
  File "/opt/python/urllib3/util/retry.py", line 515, in increment
    raise MaxRetryError(_pool, url, reason) from reason  # type: ignore[arg-type]
urllib3.exceptions.MaxRetryError: HTTPConnectionPool(host='democracy.canterbury.gov.uk', port=80): Max retries exceeded with url: /mgWebService.asmx/GetCouncillorsByWard (Caused by ConnectTimeoutError(<urllib3.connection.HTTPConnection object at 0x7f7460431300>, 'Connection to democracy.canterbury.gov.uk timed out. (connect timeout=None)'))

During handling of the above exception, another exception occurred:

Traceback (most recent call last):
  File "/var/task/lgsf/aws_lambda/handlers.py", line 32, in scraper_worker_handler
    scraper.run(run_log)
  File "/var/task/lgsf/councillors/scrapers.py", line 200, in run
    wards = self.get_councillors()
  File "/var/task/lgsf/councillors/scrapers.py", line 219, in get_councillors
    req = self.get(
  File "/var/task/lgsf/scrapers/base.py", line 47, in get
    response = self.requests_session.get(
  File "/opt/python/requests/sessions.py", line 602, in get
    return self.request("GET", url, **kwargs)
  File "/opt/python/requests/sessions.py", line 589, in request
    resp = self.send(prep, **send_kwargs)
  File "/opt/python/requests/sessions.py", line 703, in send
    r = adapter.send(request, **kwargs)
  File "/opt/python/requests/adapters.py", line 507, in send
    raise ConnectTimeout(e, request=request)
requests.exceptions.ConnectTimeout: HTTPConnectionPool(host='democracy.canterbury.gov.uk', port=80): Max retries exceeded with url: /mgWebService.asmx/GetCouncillorsByWard (Caused by ConnectTimeoutError(<urllib3.connection.HTTPConnection object at 0x7f7460431300>, 'Connection to democracy.canterbury.gov.uk timed out. (connect timeout=None)'))
</dd>
      </div>
    </dl>
  </div>
  </div>

  <h3>Run log</h3>
  <pre>[09:00:29] Fetching Scraper for: CAT                              handlers.py:23
           Begin attempting to scrape: CAT                        handlers.py:27
           Deleting existing data...                                 base.py:251
[09:00:30] Getting all files in Councillors...                       base.py:203
           ...found 1 files in Councillors                           base.py:219
           Deleting batch no. 1 consisting of 1 files                base.py:230
           ...data deleted.                                          base.py:258
           Scraping from                                              base.py:41
           http://democracy.canterbury.gov.uk/mgWebService.asmx/GetCo           
           uncillorsByWard                                                      
[09:02:41] HTTPConnectionPool(host='democracy.canterbury.gov.uk', handlers.py:36
           port=80): Max retries exceeded with url:                             
           /mgWebService.asmx/GetCouncillorsByWard (Caused by                   
           ConnectTimeoutError(<urllib3.connection.HTTPConnection               
           object at 0x7f7460431300>, 'Connection to                            
           democracy.canterbury.gov.uk timed out. (connect                      
           timeout=None)'))                                                     
           Finished attempting to scrape: CAT                        base.py:339
</pre>
  

  


  <h2 id="2024-03-17-08-43">2024-03-17</h2>
  <div class="ds-card">
  <div class="ds-card-body">
    <dl class="ds-descriptions">
      <div>
        <dt>Duration</dt>
        <dd>132 seconds</dd>
      </div>
      <div>
        <dt>Start</dt>
        <dd>2024-03-17 08:43:33.790890</dd>
      </div>
      <div>
        <dt>End</dt>
        <dd>2024-03-17 08:45:45.842688</dd>
      </div>
      <div>
        <dt>Status code</dt>
        <dd>1</dd>
      </div>
      <div>
        <dt>Error</dt>
        <dd>Traceback (most recent call last):
  File "/opt/python/urllib3/connection.py", line 203, in _new_conn
    sock = connection.create_connection(
  File "/opt/python/urllib3/util/connection.py", line 85, in create_connection
    raise err
  File "/opt/python/urllib3/util/connection.py", line 73, in create_connection
    sock.connect(sa)
TimeoutError: [Errno 110] Connection timed out

The above exception was the direct cause of the following exception:

Traceback (most recent call last):
  File "/opt/python/urllib3/connectionpool.py", line 791, in urlopen
    response = self._make_request(
  File "/opt/python/urllib3/connectionpool.py", line 497, in _make_request
    conn.request(
  File "/opt/python/urllib3/connection.py", line 395, in request
    self.endheaders()
  File "/var/lang/lib/python3.10/http/client.py", line 1278, in endheaders
    self._send_output(message_body, encode_chunked=encode_chunked)
  File "/var/lang/lib/python3.10/http/client.py", line 1038, in _send_output
    self.send(msg)
  File "/var/lang/lib/python3.10/http/client.py", line 976, in send
    self.connect()
  File "/opt/python/urllib3/connection.py", line 243, in connect
    self.sock = self._new_conn()
  File "/opt/python/urllib3/connection.py", line 212, in _new_conn
    raise ConnectTimeoutError(
urllib3.exceptions.ConnectTimeoutError: (<urllib3.connection.HTTPConnection object at 0x7f3399ba2740>, 'Connection to democracy.canterbury.gov.uk timed out. (connect timeout=None)')

The above exception was the direct cause of the following exception:

Traceback (most recent call last):
  File "/opt/python/requests/adapters.py", line 486, in send
    resp = conn.urlopen(
  File "/opt/python/urllib3/connectionpool.py", line 845, in urlopen
    retries = retries.increment(
  File "/opt/python/urllib3/util/retry.py", line 515, in increment
    raise MaxRetryError(_pool, url, reason) from reason  # type: ignore[arg-type]
urllib3.exceptions.MaxRetryError: HTTPConnectionPool(host='democracy.canterbury.gov.uk', port=80): Max retries exceeded with url: /mgWebService.asmx/GetCouncillorsByWard (Caused by ConnectTimeoutError(<urllib3.connection.HTTPConnection object at 0x7f3399ba2740>, 'Connection to democracy.canterbury.gov.uk timed out. (connect timeout=None)'))

During handling of the above exception, another exception occurred:

Traceback (most recent call last):
  File "/var/task/lgsf/aws_lambda/handlers.py", line 32, in scraper_worker_handler
    scraper.run(run_log)
  File "/var/task/lgsf/councillors/scrapers.py", line 200, in run
    wards = self.get_councillors()
  File "/var/task/lgsf/councillors/scrapers.py", line 219, in get_councillors
    req = self.get(
  File "/var/task/lgsf/scrapers/base.py", line 47, in get
    response = self.requests_session.get(
  File "/opt/python/requests/sessions.py", line 602, in get
    return self.request("GET", url, **kwargs)
  File "/opt/python/requests/sessions.py", line 589, in request
    resp = self.send(prep, **send_kwargs)
  File "/opt/python/requests/sessions.py", line 703, in send
    r = adapter.send(request, **kwargs)
  File "/opt/python/requests/adapters.py", line 507, in send
    raise ConnectTimeout(e, request=request)
requests.exceptions.ConnectTimeout: HTTPConnectionPool(host='democracy.canterbury.gov.uk', port=80): Max retries exceeded with url: /mgWebService.asmx/GetCouncillorsByWard (Caused by ConnectTimeoutError(<urllib3.connection.HTTPConnection object at 0x7f3399ba2740>, 'Connection to democracy.canterbury.gov.uk timed out. (connect timeout=None)'))
</dd>
      </div>
    </dl>
  </div>
  </div>

  <h3>Run log</h3>
  <pre>[08:43:33] Fetching Scraper for: CAT                              handlers.py:23
           Begin attempting to scrape: CAT                        handlers.py:27
[08:43:34] Deleting existing data...                                 base.py:251
           Getting all files in Councillors...                       base.py:203
           ...found 1 files in Councillors                           base.py:219
           Deleting batch no. 1 consisting of 1 files                base.py:230
[08:43:35] ...data deleted.                                          base.py:258
           Scraping from                                              base.py:41
           http://democracy.canterbury.gov.uk/mgWebService.asmx/GetCo           
           uncillorsByWard                                                      
[08:45:45] HTTPConnectionPool(host='democracy.canterbury.gov.uk', handlers.py:36
           port=80): Max retries exceeded with url:                             
           /mgWebService.asmx/GetCouncillorsByWard (Caused by                   
           ConnectTimeoutError(<urllib3.connection.HTTPConnection               
           object at 0x7f3399ba2740>, 'Connection to                            
           democracy.canterbury.gov.uk timed out. (connect                      
           timeout=None)'))                                                     
           Finished attempting to scrape: CAT                        base.py:339
</pre>
  

  


  <h2 id="2024-03-16-08-52">2024-03-16</h2>
  <div class="ds-card">
  <div class="ds-card-body">
    <dl class="ds-descriptions">
      <div>
        <dt>Duration</dt>
        <dd>132 seconds</dd>
      </div>
      <div>
        <dt>Start</dt>
        <dd>2024-03-16 08:52:07.309104</dd>
      </div>
      <div>
        <dt>End</dt>
        <dd>2024-03-16 08:54:20.111886</dd>
      </div>
      <div>
        <dt>Status code</dt>
        <dd>1</dd>
      </div>
      <div>
        <dt>Error</dt>
        <dd>Traceback (most recent call last):
  File "/opt/python/urllib3/connection.py", line 203, in _new_conn
    sock = connection.create_connection(
  File "/opt/python/urllib3/util/connection.py", line 85, in create_connection
    raise err
  File "/opt/python/urllib3/util/connection.py", line 73, in create_connection
    sock.connect(sa)
TimeoutError: [Errno 110] Connection timed out

The above exception was the direct cause of the following exception:

Traceback (most recent call last):
  File "/opt/python/urllib3/connectionpool.py", line 791, in urlopen
    response = self._make_request(
  File "/opt/python/urllib3/connectionpool.py", line 497, in _make_request
    conn.request(
  File "/opt/python/urllib3/connection.py", line 395, in request
    self.endheaders()
  File "/var/lang/lib/python3.10/http/client.py", line 1278, in endheaders
    self._send_output(message_body, encode_chunked=encode_chunked)
  File "/var/lang/lib/python3.10/http/client.py", line 1038, in _send_output
    self.send(msg)
  File "/var/lang/lib/python3.10/http/client.py", line 976, in send
    self.connect()
  File "/opt/python/urllib3/connection.py", line 243, in connect
    self.sock = self._new_conn()
  File "/opt/python/urllib3/connection.py", line 212, in _new_conn
    raise ConnectTimeoutError(
urllib3.exceptions.ConnectTimeoutError: (<urllib3.connection.HTTPConnection object at 0x7fe27ed8f3d0>, 'Connection to democracy.canterbury.gov.uk timed out. (connect timeout=None)')

The above exception was the direct cause of the following exception:

Traceback (most recent call last):
  File "/opt/python/requests/adapters.py", line 486, in send
    resp = conn.urlopen(
  File "/opt/python/urllib3/connectionpool.py", line 845, in urlopen
    retries = retries.increment(
  File "/opt/python/urllib3/util/retry.py", line 515, in increment
    raise MaxRetryError(_pool, url, reason) from reason  # type: ignore[arg-type]
urllib3.exceptions.MaxRetryError: HTTPConnectionPool(host='democracy.canterbury.gov.uk', port=80): Max retries exceeded with url: /mgWebService.asmx/GetCouncillorsByWard (Caused by ConnectTimeoutError(<urllib3.connection.HTTPConnection object at 0x7fe27ed8f3d0>, 'Connection to democracy.canterbury.gov.uk timed out. (connect timeout=None)'))

During handling of the above exception, another exception occurred:

Traceback (most recent call last):
  File "/var/task/lgsf/aws_lambda/handlers.py", line 32, in scraper_worker_handler
    scraper.run(run_log)
  File "/var/task/lgsf/councillors/scrapers.py", line 200, in run
    wards = self.get_councillors()
  File "/var/task/lgsf/councillors/scrapers.py", line 219, in get_councillors
    req = self.get(
  File "/var/task/lgsf/scrapers/base.py", line 47, in get
    response = self.requests_session.get(
  File "/opt/python/requests/sessions.py", line 602, in get
    return self.request("GET", url, **kwargs)
  File "/opt/python/requests/sessions.py", line 589, in request
    resp = self.send(prep, **send_kwargs)
  File "/opt/python/requests/sessions.py", line 703, in send
    r = adapter.send(request, **kwargs)
  File "/opt/python/requests/adapters.py", line 507, in send
    raise ConnectTimeout(e, request=request)
requests.exceptions.ConnectTimeout: HTTPConnectionPool(host='democracy.canterbury.gov.uk', port=80): Max retries exceeded with url: /mgWebService.asmx/GetCouncillorsByWard (Caused by ConnectTimeoutError(<urllib3.connection.HTTPConnection object at 0x7fe27ed8f3d0>, 'Connection to democracy.canterbury.gov.uk timed out. (connect timeout=None)'))
</dd>
      </div>
    </dl>
  </div>
  </div>

  <h3>Run log</h3>
  <pre>[08:52:07] Fetching Scraper for: CAT                              handlers.py:23
           Begin attempting to scrape: CAT                        handlers.py:27
           Deleting existing data...                                 base.py:251
[08:52:08] Getting all files in Councillors...                       base.py:203
           ...found 1 files in Councillors                           base.py:219
           Deleting batch no. 1 consisting of 1 files                base.py:230
[08:52:09] ...data deleted.                                          base.py:258
           Scraping from                                              base.py:41
           http://democracy.canterbury.gov.uk/mgWebService.asmx/GetCo           
           uncillorsByWard                                                      
[08:54:19] HTTPConnectionPool(host='democracy.canterbury.gov.uk', handlers.py:36
           port=80): Max retries exceeded with url:                             
           /mgWebService.asmx/GetCouncillorsByWard (Caused by                   
           ConnectTimeoutError(<urllib3.connection.HTTPConnection               
           object at 0x7fe27ed8f3d0>, 'Connection to                            
           democracy.canterbury.gov.uk timed out. (connect                      
           timeout=None)'))                                                     
[08:54:20] Finished attempting to scrape: CAT                        base.py:339
</pre>
  

  


  <h2 id="2024-03-15-09-33">2024-03-15</h2>
  <div class="ds-card">
  <div class="ds-card-body">
    <dl class="ds-descriptions">
      <div>
        <dt>Duration</dt>
        <dd>132 seconds</dd>
      </div>
      <div>
        <dt>Start</dt>
        <dd>2024-03-15 09:33:53.062165</dd>
      </div>
      <div>
        <dt>End</dt>
        <dd>2024-03-15 09:36:05.471357</dd>
      </div>
      <div>
        <dt>Status code</dt>
        <dd>1</dd>
      </div>
      <div>
        <dt>Error</dt>
        <dd>Traceback (most recent call last):
  File "/opt/python/urllib3/connection.py", line 203, in _new_conn
    sock = connection.create_connection(
  File "/opt/python/urllib3/util/connection.py", line 85, in create_connection
    raise err
  File "/opt/python/urllib3/util/connection.py", line 73, in create_connection
    sock.connect(sa)
TimeoutError: [Errno 110] Connection timed out

The above exception was the direct cause of the following exception:

Traceback (most recent call last):
  File "/opt/python/urllib3/connectionpool.py", line 791, in urlopen
    response = self._make_request(
  File "/opt/python/urllib3/connectionpool.py", line 497, in _make_request
    conn.request(
  File "/opt/python/urllib3/connection.py", line 395, in request
    self.endheaders()
  File "/var/lang/lib/python3.10/http/client.py", line 1278, in endheaders
    self._send_output(message_body, encode_chunked=encode_chunked)
  File "/var/lang/lib/python3.10/http/client.py", line 1038, in _send_output
    self.send(msg)
  File "/var/lang/lib/python3.10/http/client.py", line 976, in send
    self.connect()
  File "/opt/python/urllib3/connection.py", line 243, in connect
    self.sock = self._new_conn()
  File "/opt/python/urllib3/connection.py", line 212, in _new_conn
    raise ConnectTimeoutError(
urllib3.exceptions.ConnectTimeoutError: (<urllib3.connection.HTTPConnection object at 0x7fc897404280>, 'Connection to democracy.canterbury.gov.uk timed out. (connect timeout=None)')

The above exception was the direct cause of the following exception:

Traceback (most recent call last):
  File "/opt/python/requests/adapters.py", line 486, in send
    resp = conn.urlopen(
  File "/opt/python/urllib3/connectionpool.py", line 845, in urlopen
    retries = retries.increment(
  File "/opt/python/urllib3/util/retry.py", line 515, in increment
    raise MaxRetryError(_pool, url, reason) from reason  # type: ignore[arg-type]
urllib3.exceptions.MaxRetryError: HTTPConnectionPool(host='democracy.canterbury.gov.uk', port=80): Max retries exceeded with url: /mgWebService.asmx/GetCouncillorsByWard (Caused by ConnectTimeoutError(<urllib3.connection.HTTPConnection object at 0x7fc897404280>, 'Connection to democracy.canterbury.gov.uk timed out. (connect timeout=None)'))

During handling of the above exception, another exception occurred:

Traceback (most recent call last):
  File "/var/task/lgsf/aws_lambda/handlers.py", line 32, in scraper_worker_handler
    scraper.run(run_log)
  File "/var/task/lgsf/councillors/scrapers.py", line 200, in run
    wards = self.get_councillors()
  File "/var/task/lgsf/councillors/scrapers.py", line 219, in get_councillors
    req = self.get(
  File "/var/task/lgsf/scrapers/base.py", line 47, in get
    response = self.requests_session.get(
  File "/opt/python/requests/sessions.py", line 602, in get
    return self.request("GET", url, **kwargs)
  File "/opt/python/requests/sessions.py", line 589, in request
    resp = self.send(prep, **send_kwargs)
  File "/opt/python/requests/sessions.py", line 703, in send
    r = adapter.send(request, **kwargs)
  File "/opt/python/requests/adapters.py", line 507, in send
    raise ConnectTimeout(e, request=request)
requests.exceptions.ConnectTimeout: HTTPConnectionPool(host='democracy.canterbury.gov.uk', port=80): Max retries exceeded with url: /mgWebService.asmx/GetCouncillorsByWard (Caused by ConnectTimeoutError(<urllib3.connection.HTTPConnection object at 0x7fc897404280>, 'Connection to democracy.canterbury.gov.uk timed out. (connect timeout=None)'))
</dd>
      </div>
    </dl>
  </div>
  </div>

  <h3>Run log</h3>
  <pre>[09:33:53] Fetching Scraper for: CAT                              handlers.py:23
           Begin attempting to scrape: CAT                        handlers.py:27
           Deleting existing data...                                 base.py:251
           Getting all files in Councillors...                       base.py:203
[09:33:54] ...found 1 files in Councillors                           base.py:219
           Deleting batch no. 1 consisting of 1 files                base.py:230
           ...data deleted.                                          base.py:258
           Scraping from                                              base.py:41
           http://democracy.canterbury.gov.uk/mgWebService.asmx/GetCo           
           uncillorsByWard                                                      
[09:36:05] HTTPConnectionPool(host='democracy.canterbury.gov.uk', handlers.py:36
           port=80): Max retries exceeded with url:                             
           /mgWebService.asmx/GetCouncillorsByWard (Caused by                   
           ConnectTimeoutError(<urllib3.connection.HTTPConnection               
           object at 0x7fc897404280>, 'Connection to                            
           democracy.canterbury.gov.uk timed out. (connect                      
           timeout=None)'))                                                     
           Finished attempting to scrape: CAT                        base.py:339
</pre>
  

  


  <h2 id="2024-03-14-08-29">2024-03-14</h2>
  <div class="ds-card">
  <div class="ds-card-body">
    <dl class="ds-descriptions">
      <div>
        <dt>Duration</dt>
        <dd>132 seconds</dd>
      </div>
      <div>
        <dt>Start</dt>
        <dd>2024-03-14 08:29:50.795187</dd>
      </div>
      <div>
        <dt>End</dt>
        <dd>2024-03-14 08:32:03.230580</dd>
      </div>
      <div>
        <dt>Status code</dt>
        <dd>1</dd>
      </div>
      <div>
        <dt>Error</dt>
        <dd>Traceback (most recent call last):
  File "/opt/python/urllib3/connection.py", line 203, in _new_conn
    sock = connection.create_connection(
  File "/opt/python/urllib3/util/connection.py", line 85, in create_connection
    raise err
  File "/opt/python/urllib3/util/connection.py", line 73, in create_connection
    sock.connect(sa)
TimeoutError: [Errno 110] Connection timed out

The above exception was the direct cause of the following exception:

Traceback (most recent call last):
  File "/opt/python/urllib3/connectionpool.py", line 791, in urlopen
    response = self._make_request(
  File "/opt/python/urllib3/connectionpool.py", line 497, in _make_request
    conn.request(
  File "/opt/python/urllib3/connection.py", line 395, in request
    self.endheaders()
  File "/var/lang/lib/python3.10/http/client.py", line 1278, in endheaders
    self._send_output(message_body, encode_chunked=encode_chunked)
  File "/var/lang/lib/python3.10/http/client.py", line 1038, in _send_output
    self.send(msg)
  File "/var/lang/lib/python3.10/http/client.py", line 976, in send
    self.connect()
  File "/opt/python/urllib3/connection.py", line 243, in connect
    self.sock = self._new_conn()
  File "/opt/python/urllib3/connection.py", line 212, in _new_conn
    raise ConnectTimeoutError(
urllib3.exceptions.ConnectTimeoutError: (<urllib3.connection.HTTPConnection object at 0x7f12f453d6f0>, 'Connection to democracy.canterbury.gov.uk timed out. (connect timeout=None)')

The above exception was the direct cause of the following exception:

Traceback (most recent call last):
  File "/opt/python/requests/adapters.py", line 486, in send
    resp = conn.urlopen(
  File "/opt/python/urllib3/connectionpool.py", line 845, in urlopen
    retries = retries.increment(
  File "/opt/python/urllib3/util/retry.py", line 515, in increment
    raise MaxRetryError(_pool, url, reason) from reason  # type: ignore[arg-type]
urllib3.exceptions.MaxRetryError: HTTPConnectionPool(host='democracy.canterbury.gov.uk', port=80): Max retries exceeded with url: /mgWebService.asmx/GetCouncillorsByWard (Caused by ConnectTimeoutError(<urllib3.connection.HTTPConnection object at 0x7f12f453d6f0>, 'Connection to democracy.canterbury.gov.uk timed out. (connect timeout=None)'))

During handling of the above exception, another exception occurred:

Traceback (most recent call last):
  File "/var/task/lgsf/aws_lambda/handlers.py", line 32, in scraper_worker_handler
    scraper.run(run_log)
  File "/var/task/lgsf/councillors/scrapers.py", line 200, in run
    wards = self.get_councillors()
  File "/var/task/lgsf/councillors/scrapers.py", line 219, in get_councillors
    req = self.get(
  File "/var/task/lgsf/scrapers/base.py", line 47, in get
    response = self.requests_session.get(
  File "/opt/python/requests/sessions.py", line 602, in get
    return self.request("GET", url, **kwargs)
  File "/opt/python/requests/sessions.py", line 589, in request
    resp = self.send(prep, **send_kwargs)
  File "/opt/python/requests/sessions.py", line 703, in send
    r = adapter.send(request, **kwargs)
  File "/opt/python/requests/adapters.py", line 507, in send
    raise ConnectTimeout(e, request=request)
requests.exceptions.ConnectTimeout: HTTPConnectionPool(host='democracy.canterbury.gov.uk', port=80): Max retries exceeded with url: /mgWebService.asmx/GetCouncillorsByWard (Caused by ConnectTimeoutError(<urllib3.connection.HTTPConnection object at 0x7f12f453d6f0>, 'Connection to democracy.canterbury.gov.uk timed out. (connect timeout=None)'))
</dd>
      </div>
    </dl>
  </div>
  </div>

  <h3>Run log</h3>
  <pre>[08:29:50] Fetching Scraper for: CAT                              handlers.py:23
           Begin attempting to scrape: CAT                        handlers.py:27
[08:29:51] Deleting existing data...                                 base.py:251
           Getting all files in Councillors...                       base.py:203
           ...found 1 files in Councillors                           base.py:219
           Deleting batch no. 1 consisting of 1 files                base.py:230
[08:29:52] ...data deleted.                                          base.py:258
           Scraping from                                              base.py:41
           http://democracy.canterbury.gov.uk/mgWebService.asmx/GetCo           
           uncillorsByWard                                                      
[08:32:02] HTTPConnectionPool(host='democracy.canterbury.gov.uk', handlers.py:36
           port=80): Max retries exceeded with url:                             
           /mgWebService.asmx/GetCouncillorsByWard (Caused by                   
           ConnectTimeoutError(<urllib3.connection.HTTPConnection               
           object at 0x7f12f453d6f0>, 'Connection to                            
           democracy.canterbury.gov.uk timed out. (connect                      
           timeout=None)'))                                                     
[08:32:03] Finished attempting to scrape: CAT                        base.py:339
</pre>
  

  


  <h2 id="2024-03-13-10-30">2024-03-13</h2>
  <div class="ds-card">
  <div class="ds-card-body">
    <dl class="ds-descriptions">
      <div>
        <dt>Duration</dt>
        <dd>132 seconds</dd>
      </div>
      <div>
        <dt>Start</dt>
        <dd>2024-03-13 10:30:22.975354</dd>
      </div>
      <div>
        <dt>End</dt>
        <dd>2024-03-13 10:32:35.348165</dd>
      </div>
      <div>
        <dt>Status code</dt>
        <dd>1</dd>
      </div>
      <div>
        <dt>Error</dt>
        <dd>Traceback (most recent call last):
  File "/opt/python/urllib3/connection.py", line 203, in _new_conn
    sock = connection.create_connection(
  File "/opt/python/urllib3/util/connection.py", line 85, in create_connection
    raise err
  File "/opt/python/urllib3/util/connection.py", line 73, in create_connection
    sock.connect(sa)
TimeoutError: [Errno 110] Connection timed out

The above exception was the direct cause of the following exception:

Traceback (most recent call last):
  File "/opt/python/urllib3/connectionpool.py", line 791, in urlopen
    response = self._make_request(
  File "/opt/python/urllib3/connectionpool.py", line 497, in _make_request
    conn.request(
  File "/opt/python/urllib3/connection.py", line 395, in request
    self.endheaders()
  File "/var/lang/lib/python3.10/http/client.py", line 1278, in endheaders
    self._send_output(message_body, encode_chunked=encode_chunked)
  File "/var/lang/lib/python3.10/http/client.py", line 1038, in _send_output
    self.send(msg)
  File "/var/lang/lib/python3.10/http/client.py", line 976, in send
    self.connect()
  File "/opt/python/urllib3/connection.py", line 243, in connect
    self.sock = self._new_conn()
  File "/opt/python/urllib3/connection.py", line 212, in _new_conn
    raise ConnectTimeoutError(
urllib3.exceptions.ConnectTimeoutError: (<urllib3.connection.HTTPConnection object at 0x7f4db9eebee0>, 'Connection to democracy.canterbury.gov.uk timed out. (connect timeout=None)')

The above exception was the direct cause of the following exception:

Traceback (most recent call last):
  File "/opt/python/requests/adapters.py", line 486, in send
    resp = conn.urlopen(
  File "/opt/python/urllib3/connectionpool.py", line 845, in urlopen
    retries = retries.increment(
  File "/opt/python/urllib3/util/retry.py", line 515, in increment
    raise MaxRetryError(_pool, url, reason) from reason  # type: ignore[arg-type]
urllib3.exceptions.MaxRetryError: HTTPConnectionPool(host='democracy.canterbury.gov.uk', port=80): Max retries exceeded with url: /mgWebService.asmx/GetCouncillorsByWard (Caused by ConnectTimeoutError(<urllib3.connection.HTTPConnection object at 0x7f4db9eebee0>, 'Connection to democracy.canterbury.gov.uk timed out. (connect timeout=None)'))

During handling of the above exception, another exception occurred:

Traceback (most recent call last):
  File "/var/task/lgsf/aws_lambda/handlers.py", line 32, in scraper_worker_handler
    scraper.run(run_log)
  File "/var/task/lgsf/councillors/scrapers.py", line 200, in run
    wards = self.get_councillors()
  File "/var/task/lgsf/councillors/scrapers.py", line 219, in get_councillors
    req = self.get(
  File "/var/task/lgsf/scrapers/base.py", line 47, in get
    response = self.requests_session.get(
  File "/opt/python/requests/sessions.py", line 602, in get
    return self.request("GET", url, **kwargs)
  File "/opt/python/requests/sessions.py", line 589, in request
    resp = self.send(prep, **send_kwargs)
  File "/opt/python/requests/sessions.py", line 703, in send
    r = adapter.send(request, **kwargs)
  File "/opt/python/requests/adapters.py", line 507, in send
    raise ConnectTimeout(e, request=request)
requests.exceptions.ConnectTimeout: HTTPConnectionPool(host='democracy.canterbury.gov.uk', port=80): Max retries exceeded with url: /mgWebService.asmx/GetCouncillorsByWard (Caused by ConnectTimeoutError(<urllib3.connection.HTTPConnection object at 0x7f4db9eebee0>, 'Connection to democracy.canterbury.gov.uk timed out. (connect timeout=None)'))
</dd>
      </div>
    </dl>
  </div>
  </div>

  <h3>Run log</h3>
  <pre>[10:30:22] Fetching Scraper for: CAT                              handlers.py:23
[10:30:23] Begin attempting to scrape: CAT                        handlers.py:27
           Deleting existing data...                                 base.py:251
           Getting all files in Councillors...                       base.py:203
           ...found 1 files in Councillors                           base.py:219
           Deleting batch no. 1 consisting of 1 files                base.py:230
[10:30:24] ...data deleted.                                          base.py:258
           Scraping from                                              base.py:41
           http://democracy.canterbury.gov.uk/mgWebService.asmx/GetCo           
           uncillorsByWard                                                      
[10:32:34] HTTPConnectionPool(host='democracy.canterbury.gov.uk', handlers.py:36
           port=80): Max retries exceeded with url:                             
           /mgWebService.asmx/GetCouncillorsByWard (Caused by                   
           ConnectTimeoutError(<urllib3.connection.HTTPConnection               
           object at 0x7f4db9eebee0>, 'Connection to                            
           democracy.canterbury.gov.uk timed out. (connect                      
           timeout=None)'))                                                     
[10:32:35] Finished attempting to scrape: CAT                        base.py:339
</pre>
  

  


  <h2 id="2024-03-12-09-40">2024-03-12</h2>
  <div class="ds-card">
  <div class="ds-card-body">
    <dl class="ds-descriptions">
      <div>
        <dt>Duration</dt>
        <dd>132 seconds</dd>
      </div>
      <div>
        <dt>Start</dt>
        <dd>2024-03-12 09:40:15.744087</dd>
      </div>
      <div>
        <dt>End</dt>
        <dd>2024-03-12 09:42:28.376839</dd>
      </div>
      <div>
        <dt>Status code</dt>
        <dd>1</dd>
      </div>
      <div>
        <dt>Error</dt>
        <dd>Traceback (most recent call last):
  File "/opt/python/urllib3/connection.py", line 203, in _new_conn
    sock = connection.create_connection(
  File "/opt/python/urllib3/util/connection.py", line 85, in create_connection
    raise err
  File "/opt/python/urllib3/util/connection.py", line 73, in create_connection
    sock.connect(sa)
TimeoutError: [Errno 110] Connection timed out

The above exception was the direct cause of the following exception:

Traceback (most recent call last):
  File "/opt/python/urllib3/connectionpool.py", line 791, in urlopen
    response = self._make_request(
  File "/opt/python/urllib3/connectionpool.py", line 497, in _make_request
    conn.request(
  File "/opt/python/urllib3/connection.py", line 395, in request
    self.endheaders()
  File "/var/lang/lib/python3.10/http/client.py", line 1278, in endheaders
    self._send_output(message_body, encode_chunked=encode_chunked)
  File "/var/lang/lib/python3.10/http/client.py", line 1038, in _send_output
    self.send(msg)
  File "/var/lang/lib/python3.10/http/client.py", line 976, in send
    self.connect()
  File "/opt/python/urllib3/connection.py", line 243, in connect
    self.sock = self._new_conn()
  File "/opt/python/urllib3/connection.py", line 212, in _new_conn
    raise ConnectTimeoutError(
urllib3.exceptions.ConnectTimeoutError: (<urllib3.connection.HTTPConnection object at 0x7f62876aae30>, 'Connection to democracy.canterbury.gov.uk timed out. (connect timeout=None)')

The above exception was the direct cause of the following exception:

Traceback (most recent call last):
  File "/opt/python/requests/adapters.py", line 486, in send
    resp = conn.urlopen(
  File "/opt/python/urllib3/connectionpool.py", line 845, in urlopen
    retries = retries.increment(
  File "/opt/python/urllib3/util/retry.py", line 515, in increment
    raise MaxRetryError(_pool, url, reason) from reason  # type: ignore[arg-type]
urllib3.exceptions.MaxRetryError: HTTPConnectionPool(host='democracy.canterbury.gov.uk', port=80): Max retries exceeded with url: /mgWebService.asmx/GetCouncillorsByWard (Caused by ConnectTimeoutError(<urllib3.connection.HTTPConnection object at 0x7f62876aae30>, 'Connection to democracy.canterbury.gov.uk timed out. (connect timeout=None)'))

During handling of the above exception, another exception occurred:

Traceback (most recent call last):
  File "/var/task/lgsf/aws_lambda/handlers.py", line 32, in scraper_worker_handler
    scraper.run(run_log)
  File "/var/task/lgsf/councillors/scrapers.py", line 200, in run
    wards = self.get_councillors()
  File "/var/task/lgsf/councillors/scrapers.py", line 219, in get_councillors
    req = self.get(
  File "/var/task/lgsf/scrapers/base.py", line 47, in get
    response = self.requests_session.get(
  File "/opt/python/requests/sessions.py", line 602, in get
    return self.request("GET", url, **kwargs)
  File "/opt/python/requests/sessions.py", line 589, in request
    resp = self.send(prep, **send_kwargs)
  File "/opt/python/requests/sessions.py", line 703, in send
    r = adapter.send(request, **kwargs)
  File "/opt/python/requests/adapters.py", line 507, in send
    raise ConnectTimeout(e, request=request)
requests.exceptions.ConnectTimeout: HTTPConnectionPool(host='democracy.canterbury.gov.uk', port=80): Max retries exceeded with url: /mgWebService.asmx/GetCouncillorsByWard (Caused by ConnectTimeoutError(<urllib3.connection.HTTPConnection object at 0x7f62876aae30>, 'Connection to democracy.canterbury.gov.uk timed out. (connect timeout=None)'))
</dd>
      </div>
    </dl>
  </div>
  </div>

  <h3>Run log</h3>
  <pre>[09:40:15] Fetching Scraper for: CAT                              handlers.py:23
           Begin attempting to scrape: CAT                        handlers.py:27
[09:40:16] Deleting existing data...                                 base.py:251
           Getting all files in Councillors...                       base.py:203
           ...found 1 files in Councillors                           base.py:219
           Deleting batch no. 1 consisting of 1 files                base.py:230
[09:40:17] ...data deleted.                                          base.py:258
           Scraping from                                              base.py:41
           http://democracy.canterbury.gov.uk/mgWebService.asmx/GetCo           
           uncillorsByWard                                                      
[09:42:27] HTTPConnectionPool(host='democracy.canterbury.gov.uk', handlers.py:36
           port=80): Max retries exceeded with url:                             
           /mgWebService.asmx/GetCouncillorsByWard (Caused by                   
           ConnectTimeoutError(<urllib3.connection.HTTPConnection               
           object at 0x7f62876aae30>, 'Connection to                            
           democracy.canterbury.gov.uk timed out. (connect                      
           timeout=None)'))                                                     
[09:42:28] Finished attempting to scrape: CAT                        base.py:339
</pre>
  

  


  <h2 id="2024-03-11-10-44">2024-03-11</h2>
  <div class="ds-card">
  <div class="ds-card-body">
    <dl class="ds-descriptions">
      <div>
        <dt>Duration</dt>
        <dd>132 seconds</dd>
      </div>
      <div>
        <dt>Start</dt>
        <dd>2024-03-11 10:44:10.044537</dd>
      </div>
      <div>
        <dt>End</dt>
        <dd>2024-03-11 10:46:22.493780</dd>
      </div>
      <div>
        <dt>Status code</dt>
        <dd>1</dd>
      </div>
      <div>
        <dt>Error</dt>
        <dd>Traceback (most recent call last):
  File "/opt/python/urllib3/connection.py", line 203, in _new_conn
    sock = connection.create_connection(
  File "/opt/python/urllib3/util/connection.py", line 85, in create_connection
    raise err
  File "/opt/python/urllib3/util/connection.py", line 73, in create_connection
    sock.connect(sa)
TimeoutError: [Errno 110] Connection timed out

The above exception was the direct cause of the following exception:

Traceback (most recent call last):
  File "/opt/python/urllib3/connectionpool.py", line 791, in urlopen
    response = self._make_request(
  File "/opt/python/urllib3/connectionpool.py", line 497, in _make_request
    conn.request(
  File "/opt/python/urllib3/connection.py", line 395, in request
    self.endheaders()
  File "/var/lang/lib/python3.10/http/client.py", line 1278, in endheaders
    self._send_output(message_body, encode_chunked=encode_chunked)
  File "/var/lang/lib/python3.10/http/client.py", line 1038, in _send_output
    self.send(msg)
  File "/var/lang/lib/python3.10/http/client.py", line 976, in send
    self.connect()
  File "/opt/python/urllib3/connection.py", line 243, in connect
    self.sock = self._new_conn()
  File "/opt/python/urllib3/connection.py", line 212, in _new_conn
    raise ConnectTimeoutError(
urllib3.exceptions.ConnectTimeoutError: (<urllib3.connection.HTTPConnection object at 0x7f2048699f60>, 'Connection to democracy.canterbury.gov.uk timed out. (connect timeout=None)')

The above exception was the direct cause of the following exception:

Traceback (most recent call last):
  File "/opt/python/requests/adapters.py", line 486, in send
    resp = conn.urlopen(
  File "/opt/python/urllib3/connectionpool.py", line 845, in urlopen
    retries = retries.increment(
  File "/opt/python/urllib3/util/retry.py", line 515, in increment
    raise MaxRetryError(_pool, url, reason) from reason  # type: ignore[arg-type]
urllib3.exceptions.MaxRetryError: HTTPConnectionPool(host='democracy.canterbury.gov.uk', port=80): Max retries exceeded with url: /mgWebService.asmx/GetCouncillorsByWard (Caused by ConnectTimeoutError(<urllib3.connection.HTTPConnection object at 0x7f2048699f60>, 'Connection to democracy.canterbury.gov.uk timed out. (connect timeout=None)'))

During handling of the above exception, another exception occurred:

Traceback (most recent call last):
  File "/var/task/lgsf/aws_lambda/handlers.py", line 32, in scraper_worker_handler
    scraper.run(run_log)
  File "/var/task/lgsf/councillors/scrapers.py", line 200, in run
    wards = self.get_councillors()
  File "/var/task/lgsf/councillors/scrapers.py", line 219, in get_councillors
    req = self.get(
  File "/var/task/lgsf/scrapers/base.py", line 47, in get
    response = self.requests_session.get(
  File "/opt/python/requests/sessions.py", line 602, in get
    return self.request("GET", url, **kwargs)
  File "/opt/python/requests/sessions.py", line 589, in request
    resp = self.send(prep, **send_kwargs)
  File "/opt/python/requests/sessions.py", line 703, in send
    r = adapter.send(request, **kwargs)
  File "/opt/python/requests/adapters.py", line 507, in send
    raise ConnectTimeout(e, request=request)
requests.exceptions.ConnectTimeout: HTTPConnectionPool(host='democracy.canterbury.gov.uk', port=80): Max retries exceeded with url: /mgWebService.asmx/GetCouncillorsByWard (Caused by ConnectTimeoutError(<urllib3.connection.HTTPConnection object at 0x7f2048699f60>, 'Connection to democracy.canterbury.gov.uk timed out. (connect timeout=None)'))
</dd>
      </div>
    </dl>
  </div>
  </div>

  <h3>Run log</h3>
  <pre>[10:44:10] Fetching Scraper for: CAT                              handlers.py:23
           Begin attempting to scrape: CAT                        handlers.py:27
           Deleting existing data...                                 base.py:251
           Getting all files in Councillors...                       base.py:203
[10:44:11] ...found 1 files in Councillors                           base.py:219
           Deleting batch no. 1 consisting of 1 files                base.py:230
           ...data deleted.                                          base.py:258
           Scraping from                                              base.py:41
           http://democracy.canterbury.gov.uk/mgWebService.asmx/GetCo           
           uncillorsByWard                                                      
[10:46:22] HTTPConnectionPool(host='democracy.canterbury.gov.uk', handlers.py:36
           port=80): Max retries exceeded with url:                             
           /mgWebService.asmx/GetCouncillorsByWard (Caused by                   
           ConnectTimeoutError(<urllib3.connection.HTTPConnection               
           object at 0x7f2048699f60>, 'Connection to                            
           democracy.canterbury.gov.uk timed out. (connect                      
           timeout=None)'))                                                     
           Finished attempting to scrape: CAT                        base.py:339
</pre>
  

  


  <h2 id="2024-03-10-09-45">2024-03-10</h2>
  <div class="ds-card">
  <div class="ds-card-body">
    <dl class="ds-descriptions">
      <div>
        <dt>Duration</dt>
        <dd>132 seconds</dd>
      </div>
      <div>
        <dt>Start</dt>
        <dd>2024-03-10 09:45:01.200543</dd>
      </div>
      <div>
        <dt>End</dt>
        <dd>2024-03-10 09:47:13.462093</dd>
      </div>
      <div>
        <dt>Status code</dt>
        <dd>1</dd>
      </div>
      <div>
        <dt>Error</dt>
        <dd>Traceback (most recent call last):
  File "/opt/python/urllib3/connection.py", line 203, in _new_conn
    sock = connection.create_connection(
  File "/opt/python/urllib3/util/connection.py", line 85, in create_connection
    raise err
  File "/opt/python/urllib3/util/connection.py", line 73, in create_connection
    sock.connect(sa)
TimeoutError: [Errno 110] Connection timed out

The above exception was the direct cause of the following exception:

Traceback (most recent call last):
  File "/opt/python/urllib3/connectionpool.py", line 791, in urlopen
    response = self._make_request(
  File "/opt/python/urllib3/connectionpool.py", line 497, in _make_request
    conn.request(
  File "/opt/python/urllib3/connection.py", line 395, in request
    self.endheaders()
  File "/var/lang/lib/python3.10/http/client.py", line 1278, in endheaders
    self._send_output(message_body, encode_chunked=encode_chunked)
  File "/var/lang/lib/python3.10/http/client.py", line 1038, in _send_output
    self.send(msg)
  File "/var/lang/lib/python3.10/http/client.py", line 976, in send
    self.connect()
  File "/opt/python/urllib3/connection.py", line 243, in connect
    self.sock = self._new_conn()
  File "/opt/python/urllib3/connection.py", line 212, in _new_conn
    raise ConnectTimeoutError(
urllib3.exceptions.ConnectTimeoutError: (<urllib3.connection.HTTPConnection object at 0x7f50d5803910>, 'Connection to democracy.canterbury.gov.uk timed out. (connect timeout=None)')

The above exception was the direct cause of the following exception:

Traceback (most recent call last):
  File "/opt/python/requests/adapters.py", line 486, in send
    resp = conn.urlopen(
  File "/opt/python/urllib3/connectionpool.py", line 845, in urlopen
    retries = retries.increment(
  File "/opt/python/urllib3/util/retry.py", line 515, in increment
    raise MaxRetryError(_pool, url, reason) from reason  # type: ignore[arg-type]
urllib3.exceptions.MaxRetryError: HTTPConnectionPool(host='democracy.canterbury.gov.uk', port=80): Max retries exceeded with url: /mgWebService.asmx/GetCouncillorsByWard (Caused by ConnectTimeoutError(<urllib3.connection.HTTPConnection object at 0x7f50d5803910>, 'Connection to democracy.canterbury.gov.uk timed out. (connect timeout=None)'))

During handling of the above exception, another exception occurred:

Traceback (most recent call last):
  File "/var/task/lgsf/aws_lambda/handlers.py", line 32, in scraper_worker_handler
    scraper.run(run_log)
  File "/var/task/lgsf/councillors/scrapers.py", line 200, in run
    wards = self.get_councillors()
  File "/var/task/lgsf/councillors/scrapers.py", line 219, in get_councillors
    req = self.get(
  File "/var/task/lgsf/scrapers/base.py", line 47, in get
    response = self.requests_session.get(
  File "/opt/python/requests/sessions.py", line 602, in get
    return self.request("GET", url, **kwargs)
  File "/opt/python/requests/sessions.py", line 589, in request
    resp = self.send(prep, **send_kwargs)
  File "/opt/python/requests/sessions.py", line 703, in send
    r = adapter.send(request, **kwargs)
  File "/opt/python/requests/adapters.py", line 507, in send
    raise ConnectTimeout(e, request=request)
requests.exceptions.ConnectTimeout: HTTPConnectionPool(host='democracy.canterbury.gov.uk', port=80): Max retries exceeded with url: /mgWebService.asmx/GetCouncillorsByWard (Caused by ConnectTimeoutError(<urllib3.connection.HTTPConnection object at 0x7f50d5803910>, 'Connection to democracy.canterbury.gov.uk timed out. (connect timeout=None)'))
</dd>
      </div>
    </dl>
  </div>
  </div>

  <h3>Run log</h3>
  <pre>[09:45:01] Fetching Scraper for: CAT                              handlers.py:23
           Begin attempting to scrape: CAT                        handlers.py:27
           Deleting existing data...                                 base.py:251
[09:45:02] Getting all files in Councillors...                       base.py:203
           ...found 1 files in Councillors                           base.py:219
           Deleting batch no. 1 consisting of 1 files                base.py:230
           ...data deleted.                                          base.py:258
           Scraping from                                              base.py:41
           http://democracy.canterbury.gov.uk/mgWebService.asmx/GetCo           
           uncillorsByWard                                                      
[09:47:13] HTTPConnectionPool(host='democracy.canterbury.gov.uk', handlers.py:36
           port=80): Max retries exceeded with url:                             
           /mgWebService.asmx/GetCouncillorsByWard (Caused by                   
           ConnectTimeoutError(<urllib3.connection.HTTPConnection               
           object at 0x7f50d5803910>, 'Connection to                            
           democracy.canterbury.gov.uk timed out. (connect                      
           timeout=None)'))                                                     
           Finished attempting to scrape: CAT                        base.py:339
</pre>
  


      </main>
      <footer class="ds-footer">
        <div class="ds-block-centered ds-text-centered ds-stack">
          <div class="ds-cluster-center">
            <ul>
              <li><a href="/lgsf-dashboard/api/failing.json">Failing JSON</a></li>
            </ul>
          </div>
          <div class="ds-copyright">
            <a href="https://democracyclub.org.uk/">
              <img src="https://DemocracyClub.github.io/design-system/images/logo_white_text.svg" alt="Democracy Club Home" />
            </a>
            <p>Copyright © 2021 Democracy Club</p>
            <p>Community Interest Company</p>
            <p>Company No: <a href="https://beta.companieshouse.gov.uk/company/09461226">09461226</a></p>
          </div>
        </div>
      </footer>
    </div>
  </body>
