<!doctype html>
<html>
  <head>
    <title>LGSF Dashboard</title>
    <link rel="stylesheet"  href="/lgsf-dashboard/assets/css/styles.css">
    <link rel="shortcut icon" href="https://democracyclub.org.uk/static/images/logo_icon.png">
  </head>
  <body>
    <div class="ds-page">
      <a class="ds-skip-link" href="#main">skip to content</a>

      <header class="ds-header">
        <a class="ds-skip-link" href="#main">skip to content</a>
        <a class="ds-logo" href="/lgsf-dashboard/">
          <img src="https://DemocracyClub.github.io/design-system/images/logo_icon.svg" alt="" />
          <span>LGSF Logbooks</span>
        </a>

      </header>


      <main id="main" tabindex="-1" class="ds-stack">

        
<style>

    pre {
        height:400px;
        overflow-x: scroll;
        width:100%
    }
</style>




  


  <h2 id="2024-03-16-08-52">2024-03-16</h2>
  <div class="ds-card">
  <div class="ds-card-body">
    <dl class="ds-descriptions">
      <div>
        <dt>Duration</dt>
        <dd>132 seconds</dd>
      </div>
      <div>
        <dt>Start</dt>
        <dd>2024-03-16 08:52:07.309104</dd>
      </div>
      <div>
        <dt>End</dt>
        <dd>2024-03-16 08:54:20.111886</dd>
      </div>
      <div>
        <dt>Status code</dt>
        <dd>1</dd>
      </div>
      <div>
        <dt>Error</dt>
        <dd>Traceback (most recent call last):
  File "/opt/python/urllib3/connection.py", line 203, in _new_conn
    sock = connection.create_connection(
  File "/opt/python/urllib3/util/connection.py", line 85, in create_connection
    raise err
  File "/opt/python/urllib3/util/connection.py", line 73, in create_connection
    sock.connect(sa)
TimeoutError: [Errno 110] Connection timed out

The above exception was the direct cause of the following exception:

Traceback (most recent call last):
  File "/opt/python/urllib3/connectionpool.py", line 791, in urlopen
    response = self._make_request(
  File "/opt/python/urllib3/connectionpool.py", line 497, in _make_request
    conn.request(
  File "/opt/python/urllib3/connection.py", line 395, in request
    self.endheaders()
  File "/var/lang/lib/python3.10/http/client.py", line 1278, in endheaders
    self._send_output(message_body, encode_chunked=encode_chunked)
  File "/var/lang/lib/python3.10/http/client.py", line 1038, in _send_output
    self.send(msg)
  File "/var/lang/lib/python3.10/http/client.py", line 976, in send
    self.connect()
  File "/opt/python/urllib3/connection.py", line 243, in connect
    self.sock = self._new_conn()
  File "/opt/python/urllib3/connection.py", line 212, in _new_conn
    raise ConnectTimeoutError(
urllib3.exceptions.ConnectTimeoutError: (<urllib3.connection.HTTPConnection object at 0x7fe27ed8f3d0>, 'Connection to democracy.canterbury.gov.uk timed out. (connect timeout=None)')

The above exception was the direct cause of the following exception:

Traceback (most recent call last):
  File "/opt/python/requests/adapters.py", line 486, in send
    resp = conn.urlopen(
  File "/opt/python/urllib3/connectionpool.py", line 845, in urlopen
    retries = retries.increment(
  File "/opt/python/urllib3/util/retry.py", line 515, in increment
    raise MaxRetryError(_pool, url, reason) from reason  # type: ignore[arg-type]
urllib3.exceptions.MaxRetryError: HTTPConnectionPool(host='democracy.canterbury.gov.uk', port=80): Max retries exceeded with url: /mgWebService.asmx/GetCouncillorsByWard (Caused by ConnectTimeoutError(<urllib3.connection.HTTPConnection object at 0x7fe27ed8f3d0>, 'Connection to democracy.canterbury.gov.uk timed out. (connect timeout=None)'))

During handling of the above exception, another exception occurred:

Traceback (most recent call last):
  File "/var/task/lgsf/aws_lambda/handlers.py", line 32, in scraper_worker_handler
    scraper.run(run_log)
  File "/var/task/lgsf/councillors/scrapers.py", line 200, in run
    wards = self.get_councillors()
  File "/var/task/lgsf/councillors/scrapers.py", line 219, in get_councillors
    req = self.get(
  File "/var/task/lgsf/scrapers/base.py", line 47, in get
    response = self.requests_session.get(
  File "/opt/python/requests/sessions.py", line 602, in get
    return self.request("GET", url, **kwargs)
  File "/opt/python/requests/sessions.py", line 589, in request
    resp = self.send(prep, **send_kwargs)
  File "/opt/python/requests/sessions.py", line 703, in send
    r = adapter.send(request, **kwargs)
  File "/opt/python/requests/adapters.py", line 507, in send
    raise ConnectTimeout(e, request=request)
requests.exceptions.ConnectTimeout: HTTPConnectionPool(host='democracy.canterbury.gov.uk', port=80): Max retries exceeded with url: /mgWebService.asmx/GetCouncillorsByWard (Caused by ConnectTimeoutError(<urllib3.connection.HTTPConnection object at 0x7fe27ed8f3d0>, 'Connection to democracy.canterbury.gov.uk timed out. (connect timeout=None)'))
</dd>
      </div>
    </dl>
  </div>
  </div>

  <h3>Run log</h3>
  <pre>[08:52:07] Fetching Scraper for: CAT                              handlers.py:23
           Begin attempting to scrape: CAT                        handlers.py:27
           Deleting existing data...                                 base.py:251
[08:52:08] Getting all files in Councillors...                       base.py:203
           ...found 1 files in Councillors                           base.py:219
           Deleting batch no. 1 consisting of 1 files                base.py:230
[08:52:09] ...data deleted.                                          base.py:258
           Scraping from                                              base.py:41
           http://democracy.canterbury.gov.uk/mgWebService.asmx/GetCo           
           uncillorsByWard                                                      
[08:54:19] HTTPConnectionPool(host='democracy.canterbury.gov.uk', handlers.py:36
           port=80): Max retries exceeded with url:                             
           /mgWebService.asmx/GetCouncillorsByWard (Caused by                   
           ConnectTimeoutError(<urllib3.connection.HTTPConnection               
           object at 0x7fe27ed8f3d0>, 'Connection to                            
           democracy.canterbury.gov.uk timed out. (connect                      
           timeout=None)'))                                                     
[08:54:20] Finished attempting to scrape: CAT                        base.py:339
</pre>
  

  


  <h2 id="2024-03-15-09-33">2024-03-15</h2>
  <div class="ds-card">
  <div class="ds-card-body">
    <dl class="ds-descriptions">
      <div>
        <dt>Duration</dt>
        <dd>132 seconds</dd>
      </div>
      <div>
        <dt>Start</dt>
        <dd>2024-03-15 09:33:53.062165</dd>
      </div>
      <div>
        <dt>End</dt>
        <dd>2024-03-15 09:36:05.471357</dd>
      </div>
      <div>
        <dt>Status code</dt>
        <dd>1</dd>
      </div>
      <div>
        <dt>Error</dt>
        <dd>Traceback (most recent call last):
  File "/opt/python/urllib3/connection.py", line 203, in _new_conn
    sock = connection.create_connection(
  File "/opt/python/urllib3/util/connection.py", line 85, in create_connection
    raise err
  File "/opt/python/urllib3/util/connection.py", line 73, in create_connection
    sock.connect(sa)
TimeoutError: [Errno 110] Connection timed out

The above exception was the direct cause of the following exception:

Traceback (most recent call last):
  File "/opt/python/urllib3/connectionpool.py", line 791, in urlopen
    response = self._make_request(
  File "/opt/python/urllib3/connectionpool.py", line 497, in _make_request
    conn.request(
  File "/opt/python/urllib3/connection.py", line 395, in request
    self.endheaders()
  File "/var/lang/lib/python3.10/http/client.py", line 1278, in endheaders
    self._send_output(message_body, encode_chunked=encode_chunked)
  File "/var/lang/lib/python3.10/http/client.py", line 1038, in _send_output
    self.send(msg)
  File "/var/lang/lib/python3.10/http/client.py", line 976, in send
    self.connect()
  File "/opt/python/urllib3/connection.py", line 243, in connect
    self.sock = self._new_conn()
  File "/opt/python/urllib3/connection.py", line 212, in _new_conn
    raise ConnectTimeoutError(
urllib3.exceptions.ConnectTimeoutError: (<urllib3.connection.HTTPConnection object at 0x7fc897404280>, 'Connection to democracy.canterbury.gov.uk timed out. (connect timeout=None)')

The above exception was the direct cause of the following exception:

Traceback (most recent call last):
  File "/opt/python/requests/adapters.py", line 486, in send
    resp = conn.urlopen(
  File "/opt/python/urllib3/connectionpool.py", line 845, in urlopen
    retries = retries.increment(
  File "/opt/python/urllib3/util/retry.py", line 515, in increment
    raise MaxRetryError(_pool, url, reason) from reason  # type: ignore[arg-type]
urllib3.exceptions.MaxRetryError: HTTPConnectionPool(host='democracy.canterbury.gov.uk', port=80): Max retries exceeded with url: /mgWebService.asmx/GetCouncillorsByWard (Caused by ConnectTimeoutError(<urllib3.connection.HTTPConnection object at 0x7fc897404280>, 'Connection to democracy.canterbury.gov.uk timed out. (connect timeout=None)'))

During handling of the above exception, another exception occurred:

Traceback (most recent call last):
  File "/var/task/lgsf/aws_lambda/handlers.py", line 32, in scraper_worker_handler
    scraper.run(run_log)
  File "/var/task/lgsf/councillors/scrapers.py", line 200, in run
    wards = self.get_councillors()
  File "/var/task/lgsf/councillors/scrapers.py", line 219, in get_councillors
    req = self.get(
  File "/var/task/lgsf/scrapers/base.py", line 47, in get
    response = self.requests_session.get(
  File "/opt/python/requests/sessions.py", line 602, in get
    return self.request("GET", url, **kwargs)
  File "/opt/python/requests/sessions.py", line 589, in request
    resp = self.send(prep, **send_kwargs)
  File "/opt/python/requests/sessions.py", line 703, in send
    r = adapter.send(request, **kwargs)
  File "/opt/python/requests/adapters.py", line 507, in send
    raise ConnectTimeout(e, request=request)
requests.exceptions.ConnectTimeout: HTTPConnectionPool(host='democracy.canterbury.gov.uk', port=80): Max retries exceeded with url: /mgWebService.asmx/GetCouncillorsByWard (Caused by ConnectTimeoutError(<urllib3.connection.HTTPConnection object at 0x7fc897404280>, 'Connection to democracy.canterbury.gov.uk timed out. (connect timeout=None)'))
</dd>
      </div>
    </dl>
  </div>
  </div>

  <h3>Run log</h3>
  <pre>[09:33:53] Fetching Scraper for: CAT                              handlers.py:23
           Begin attempting to scrape: CAT                        handlers.py:27
           Deleting existing data...                                 base.py:251
           Getting all files in Councillors...                       base.py:203
[09:33:54] ...found 1 files in Councillors                           base.py:219
           Deleting batch no. 1 consisting of 1 files                base.py:230
           ...data deleted.                                          base.py:258
           Scraping from                                              base.py:41
           http://democracy.canterbury.gov.uk/mgWebService.asmx/GetCo           
           uncillorsByWard                                                      
[09:36:05] HTTPConnectionPool(host='democracy.canterbury.gov.uk', handlers.py:36
           port=80): Max retries exceeded with url:                             
           /mgWebService.asmx/GetCouncillorsByWard (Caused by                   
           ConnectTimeoutError(<urllib3.connection.HTTPConnection               
           object at 0x7fc897404280>, 'Connection to                            
           democracy.canterbury.gov.uk timed out. (connect                      
           timeout=None)'))                                                     
           Finished attempting to scrape: CAT                        base.py:339
</pre>
  

  


  <h2 id="2024-03-14-08-29">2024-03-14</h2>
  <div class="ds-card">
  <div class="ds-card-body">
    <dl class="ds-descriptions">
      <div>
        <dt>Duration</dt>
        <dd>132 seconds</dd>
      </div>
      <div>
        <dt>Start</dt>
        <dd>2024-03-14 08:29:50.795187</dd>
      </div>
      <div>
        <dt>End</dt>
        <dd>2024-03-14 08:32:03.230580</dd>
      </div>
      <div>
        <dt>Status code</dt>
        <dd>1</dd>
      </div>
      <div>
        <dt>Error</dt>
        <dd>Traceback (most recent call last):
  File "/opt/python/urllib3/connection.py", line 203, in _new_conn
    sock = connection.create_connection(
  File "/opt/python/urllib3/util/connection.py", line 85, in create_connection
    raise err
  File "/opt/python/urllib3/util/connection.py", line 73, in create_connection
    sock.connect(sa)
TimeoutError: [Errno 110] Connection timed out

The above exception was the direct cause of the following exception:

Traceback (most recent call last):
  File "/opt/python/urllib3/connectionpool.py", line 791, in urlopen
    response = self._make_request(
  File "/opt/python/urllib3/connectionpool.py", line 497, in _make_request
    conn.request(
  File "/opt/python/urllib3/connection.py", line 395, in request
    self.endheaders()
  File "/var/lang/lib/python3.10/http/client.py", line 1278, in endheaders
    self._send_output(message_body, encode_chunked=encode_chunked)
  File "/var/lang/lib/python3.10/http/client.py", line 1038, in _send_output
    self.send(msg)
  File "/var/lang/lib/python3.10/http/client.py", line 976, in send
    self.connect()
  File "/opt/python/urllib3/connection.py", line 243, in connect
    self.sock = self._new_conn()
  File "/opt/python/urllib3/connection.py", line 212, in _new_conn
    raise ConnectTimeoutError(
urllib3.exceptions.ConnectTimeoutError: (<urllib3.connection.HTTPConnection object at 0x7f12f453d6f0>, 'Connection to democracy.canterbury.gov.uk timed out. (connect timeout=None)')

The above exception was the direct cause of the following exception:

Traceback (most recent call last):
  File "/opt/python/requests/adapters.py", line 486, in send
    resp = conn.urlopen(
  File "/opt/python/urllib3/connectionpool.py", line 845, in urlopen
    retries = retries.increment(
  File "/opt/python/urllib3/util/retry.py", line 515, in increment
    raise MaxRetryError(_pool, url, reason) from reason  # type: ignore[arg-type]
urllib3.exceptions.MaxRetryError: HTTPConnectionPool(host='democracy.canterbury.gov.uk', port=80): Max retries exceeded with url: /mgWebService.asmx/GetCouncillorsByWard (Caused by ConnectTimeoutError(<urllib3.connection.HTTPConnection object at 0x7f12f453d6f0>, 'Connection to democracy.canterbury.gov.uk timed out. (connect timeout=None)'))

During handling of the above exception, another exception occurred:

Traceback (most recent call last):
  File "/var/task/lgsf/aws_lambda/handlers.py", line 32, in scraper_worker_handler
    scraper.run(run_log)
  File "/var/task/lgsf/councillors/scrapers.py", line 200, in run
    wards = self.get_councillors()
  File "/var/task/lgsf/councillors/scrapers.py", line 219, in get_councillors
    req = self.get(
  File "/var/task/lgsf/scrapers/base.py", line 47, in get
    response = self.requests_session.get(
  File "/opt/python/requests/sessions.py", line 602, in get
    return self.request("GET", url, **kwargs)
  File "/opt/python/requests/sessions.py", line 589, in request
    resp = self.send(prep, **send_kwargs)
  File "/opt/python/requests/sessions.py", line 703, in send
    r = adapter.send(request, **kwargs)
  File "/opt/python/requests/adapters.py", line 507, in send
    raise ConnectTimeout(e, request=request)
requests.exceptions.ConnectTimeout: HTTPConnectionPool(host='democracy.canterbury.gov.uk', port=80): Max retries exceeded with url: /mgWebService.asmx/GetCouncillorsByWard (Caused by ConnectTimeoutError(<urllib3.connection.HTTPConnection object at 0x7f12f453d6f0>, 'Connection to democracy.canterbury.gov.uk timed out. (connect timeout=None)'))
</dd>
      </div>
    </dl>
  </div>
  </div>

  <h3>Run log</h3>
  <pre>[08:29:50] Fetching Scraper for: CAT                              handlers.py:23
           Begin attempting to scrape: CAT                        handlers.py:27
[08:29:51] Deleting existing data...                                 base.py:251
           Getting all files in Councillors...                       base.py:203
           ...found 1 files in Councillors                           base.py:219
           Deleting batch no. 1 consisting of 1 files                base.py:230
[08:29:52] ...data deleted.                                          base.py:258
           Scraping from                                              base.py:41
           http://democracy.canterbury.gov.uk/mgWebService.asmx/GetCo           
           uncillorsByWard                                                      
[08:32:02] HTTPConnectionPool(host='democracy.canterbury.gov.uk', handlers.py:36
           port=80): Max retries exceeded with url:                             
           /mgWebService.asmx/GetCouncillorsByWard (Caused by                   
           ConnectTimeoutError(<urllib3.connection.HTTPConnection               
           object at 0x7f12f453d6f0>, 'Connection to                            
           democracy.canterbury.gov.uk timed out. (connect                      
           timeout=None)'))                                                     
[08:32:03] Finished attempting to scrape: CAT                        base.py:339
</pre>
  

  


  <h2 id="2024-03-13-10-30">2024-03-13</h2>
  <div class="ds-card">
  <div class="ds-card-body">
    <dl class="ds-descriptions">
      <div>
        <dt>Duration</dt>
        <dd>132 seconds</dd>
      </div>
      <div>
        <dt>Start</dt>
        <dd>2024-03-13 10:30:22.975354</dd>
      </div>
      <div>
        <dt>End</dt>
        <dd>2024-03-13 10:32:35.348165</dd>
      </div>
      <div>
        <dt>Status code</dt>
        <dd>1</dd>
      </div>
      <div>
        <dt>Error</dt>
        <dd>Traceback (most recent call last):
  File "/opt/python/urllib3/connection.py", line 203, in _new_conn
    sock = connection.create_connection(
  File "/opt/python/urllib3/util/connection.py", line 85, in create_connection
    raise err
  File "/opt/python/urllib3/util/connection.py", line 73, in create_connection
    sock.connect(sa)
TimeoutError: [Errno 110] Connection timed out

The above exception was the direct cause of the following exception:

Traceback (most recent call last):
  File "/opt/python/urllib3/connectionpool.py", line 791, in urlopen
    response = self._make_request(
  File "/opt/python/urllib3/connectionpool.py", line 497, in _make_request
    conn.request(
  File "/opt/python/urllib3/connection.py", line 395, in request
    self.endheaders()
  File "/var/lang/lib/python3.10/http/client.py", line 1278, in endheaders
    self._send_output(message_body, encode_chunked=encode_chunked)
  File "/var/lang/lib/python3.10/http/client.py", line 1038, in _send_output
    self.send(msg)
  File "/var/lang/lib/python3.10/http/client.py", line 976, in send
    self.connect()
  File "/opt/python/urllib3/connection.py", line 243, in connect
    self.sock = self._new_conn()
  File "/opt/python/urllib3/connection.py", line 212, in _new_conn
    raise ConnectTimeoutError(
urllib3.exceptions.ConnectTimeoutError: (<urllib3.connection.HTTPConnection object at 0x7f4db9eebee0>, 'Connection to democracy.canterbury.gov.uk timed out. (connect timeout=None)')

The above exception was the direct cause of the following exception:

Traceback (most recent call last):
  File "/opt/python/requests/adapters.py", line 486, in send
    resp = conn.urlopen(
  File "/opt/python/urllib3/connectionpool.py", line 845, in urlopen
    retries = retries.increment(
  File "/opt/python/urllib3/util/retry.py", line 515, in increment
    raise MaxRetryError(_pool, url, reason) from reason  # type: ignore[arg-type]
urllib3.exceptions.MaxRetryError: HTTPConnectionPool(host='democracy.canterbury.gov.uk', port=80): Max retries exceeded with url: /mgWebService.asmx/GetCouncillorsByWard (Caused by ConnectTimeoutError(<urllib3.connection.HTTPConnection object at 0x7f4db9eebee0>, 'Connection to democracy.canterbury.gov.uk timed out. (connect timeout=None)'))

During handling of the above exception, another exception occurred:

Traceback (most recent call last):
  File "/var/task/lgsf/aws_lambda/handlers.py", line 32, in scraper_worker_handler
    scraper.run(run_log)
  File "/var/task/lgsf/councillors/scrapers.py", line 200, in run
    wards = self.get_councillors()
  File "/var/task/lgsf/councillors/scrapers.py", line 219, in get_councillors
    req = self.get(
  File "/var/task/lgsf/scrapers/base.py", line 47, in get
    response = self.requests_session.get(
  File "/opt/python/requests/sessions.py", line 602, in get
    return self.request("GET", url, **kwargs)
  File "/opt/python/requests/sessions.py", line 589, in request
    resp = self.send(prep, **send_kwargs)
  File "/opt/python/requests/sessions.py", line 703, in send
    r = adapter.send(request, **kwargs)
  File "/opt/python/requests/adapters.py", line 507, in send
    raise ConnectTimeout(e, request=request)
requests.exceptions.ConnectTimeout: HTTPConnectionPool(host='democracy.canterbury.gov.uk', port=80): Max retries exceeded with url: /mgWebService.asmx/GetCouncillorsByWard (Caused by ConnectTimeoutError(<urllib3.connection.HTTPConnection object at 0x7f4db9eebee0>, 'Connection to democracy.canterbury.gov.uk timed out. (connect timeout=None)'))
</dd>
      </div>
    </dl>
  </div>
  </div>

  <h3>Run log</h3>
  <pre>[10:30:22] Fetching Scraper for: CAT                              handlers.py:23
[10:30:23] Begin attempting to scrape: CAT                        handlers.py:27
           Deleting existing data...                                 base.py:251
           Getting all files in Councillors...                       base.py:203
           ...found 1 files in Councillors                           base.py:219
           Deleting batch no. 1 consisting of 1 files                base.py:230
[10:30:24] ...data deleted.                                          base.py:258
           Scraping from                                              base.py:41
           http://democracy.canterbury.gov.uk/mgWebService.asmx/GetCo           
           uncillorsByWard                                                      
[10:32:34] HTTPConnectionPool(host='democracy.canterbury.gov.uk', handlers.py:36
           port=80): Max retries exceeded with url:                             
           /mgWebService.asmx/GetCouncillorsByWard (Caused by                   
           ConnectTimeoutError(<urllib3.connection.HTTPConnection               
           object at 0x7f4db9eebee0>, 'Connection to                            
           democracy.canterbury.gov.uk timed out. (connect                      
           timeout=None)'))                                                     
[10:32:35] Finished attempting to scrape: CAT                        base.py:339
</pre>
  

  


  <h2 id="2024-03-12-09-40">2024-03-12</h2>
  <div class="ds-card">
  <div class="ds-card-body">
    <dl class="ds-descriptions">
      <div>
        <dt>Duration</dt>
        <dd>132 seconds</dd>
      </div>
      <div>
        <dt>Start</dt>
        <dd>2024-03-12 09:40:15.744087</dd>
      </div>
      <div>
        <dt>End</dt>
        <dd>2024-03-12 09:42:28.376839</dd>
      </div>
      <div>
        <dt>Status code</dt>
        <dd>1</dd>
      </div>
      <div>
        <dt>Error</dt>
        <dd>Traceback (most recent call last):
  File "/opt/python/urllib3/connection.py", line 203, in _new_conn
    sock = connection.create_connection(
  File "/opt/python/urllib3/util/connection.py", line 85, in create_connection
    raise err
  File "/opt/python/urllib3/util/connection.py", line 73, in create_connection
    sock.connect(sa)
TimeoutError: [Errno 110] Connection timed out

The above exception was the direct cause of the following exception:

Traceback (most recent call last):
  File "/opt/python/urllib3/connectionpool.py", line 791, in urlopen
    response = self._make_request(
  File "/opt/python/urllib3/connectionpool.py", line 497, in _make_request
    conn.request(
  File "/opt/python/urllib3/connection.py", line 395, in request
    self.endheaders()
  File "/var/lang/lib/python3.10/http/client.py", line 1278, in endheaders
    self._send_output(message_body, encode_chunked=encode_chunked)
  File "/var/lang/lib/python3.10/http/client.py", line 1038, in _send_output
    self.send(msg)
  File "/var/lang/lib/python3.10/http/client.py", line 976, in send
    self.connect()
  File "/opt/python/urllib3/connection.py", line 243, in connect
    self.sock = self._new_conn()
  File "/opt/python/urllib3/connection.py", line 212, in _new_conn
    raise ConnectTimeoutError(
urllib3.exceptions.ConnectTimeoutError: (<urllib3.connection.HTTPConnection object at 0x7f62876aae30>, 'Connection to democracy.canterbury.gov.uk timed out. (connect timeout=None)')

The above exception was the direct cause of the following exception:

Traceback (most recent call last):
  File "/opt/python/requests/adapters.py", line 486, in send
    resp = conn.urlopen(
  File "/opt/python/urllib3/connectionpool.py", line 845, in urlopen
    retries = retries.increment(
  File "/opt/python/urllib3/util/retry.py", line 515, in increment
    raise MaxRetryError(_pool, url, reason) from reason  # type: ignore[arg-type]
urllib3.exceptions.MaxRetryError: HTTPConnectionPool(host='democracy.canterbury.gov.uk', port=80): Max retries exceeded with url: /mgWebService.asmx/GetCouncillorsByWard (Caused by ConnectTimeoutError(<urllib3.connection.HTTPConnection object at 0x7f62876aae30>, 'Connection to democracy.canterbury.gov.uk timed out. (connect timeout=None)'))

During handling of the above exception, another exception occurred:

Traceback (most recent call last):
  File "/var/task/lgsf/aws_lambda/handlers.py", line 32, in scraper_worker_handler
    scraper.run(run_log)
  File "/var/task/lgsf/councillors/scrapers.py", line 200, in run
    wards = self.get_councillors()
  File "/var/task/lgsf/councillors/scrapers.py", line 219, in get_councillors
    req = self.get(
  File "/var/task/lgsf/scrapers/base.py", line 47, in get
    response = self.requests_session.get(
  File "/opt/python/requests/sessions.py", line 602, in get
    return self.request("GET", url, **kwargs)
  File "/opt/python/requests/sessions.py", line 589, in request
    resp = self.send(prep, **send_kwargs)
  File "/opt/python/requests/sessions.py", line 703, in send
    r = adapter.send(request, **kwargs)
  File "/opt/python/requests/adapters.py", line 507, in send
    raise ConnectTimeout(e, request=request)
requests.exceptions.ConnectTimeout: HTTPConnectionPool(host='democracy.canterbury.gov.uk', port=80): Max retries exceeded with url: /mgWebService.asmx/GetCouncillorsByWard (Caused by ConnectTimeoutError(<urllib3.connection.HTTPConnection object at 0x7f62876aae30>, 'Connection to democracy.canterbury.gov.uk timed out. (connect timeout=None)'))
</dd>
      </div>
    </dl>
  </div>
  </div>

  <h3>Run log</h3>
  <pre>[09:40:15] Fetching Scraper for: CAT                              handlers.py:23
           Begin attempting to scrape: CAT                        handlers.py:27
[09:40:16] Deleting existing data...                                 base.py:251
           Getting all files in Councillors...                       base.py:203
           ...found 1 files in Councillors                           base.py:219
           Deleting batch no. 1 consisting of 1 files                base.py:230
[09:40:17] ...data deleted.                                          base.py:258
           Scraping from                                              base.py:41
           http://democracy.canterbury.gov.uk/mgWebService.asmx/GetCo           
           uncillorsByWard                                                      
[09:42:27] HTTPConnectionPool(host='democracy.canterbury.gov.uk', handlers.py:36
           port=80): Max retries exceeded with url:                             
           /mgWebService.asmx/GetCouncillorsByWard (Caused by                   
           ConnectTimeoutError(<urllib3.connection.HTTPConnection               
           object at 0x7f62876aae30>, 'Connection to                            
           democracy.canterbury.gov.uk timed out. (connect                      
           timeout=None)'))                                                     
[09:42:28] Finished attempting to scrape: CAT                        base.py:339
</pre>
  

  


  <h2 id="2024-03-11-10-44">2024-03-11</h2>
  <div class="ds-card">
  <div class="ds-card-body">
    <dl class="ds-descriptions">
      <div>
        <dt>Duration</dt>
        <dd>132 seconds</dd>
      </div>
      <div>
        <dt>Start</dt>
        <dd>2024-03-11 10:44:10.044537</dd>
      </div>
      <div>
        <dt>End</dt>
        <dd>2024-03-11 10:46:22.493780</dd>
      </div>
      <div>
        <dt>Status code</dt>
        <dd>1</dd>
      </div>
      <div>
        <dt>Error</dt>
        <dd>Traceback (most recent call last):
  File "/opt/python/urllib3/connection.py", line 203, in _new_conn
    sock = connection.create_connection(
  File "/opt/python/urllib3/util/connection.py", line 85, in create_connection
    raise err
  File "/opt/python/urllib3/util/connection.py", line 73, in create_connection
    sock.connect(sa)
TimeoutError: [Errno 110] Connection timed out

The above exception was the direct cause of the following exception:

Traceback (most recent call last):
  File "/opt/python/urllib3/connectionpool.py", line 791, in urlopen
    response = self._make_request(
  File "/opt/python/urllib3/connectionpool.py", line 497, in _make_request
    conn.request(
  File "/opt/python/urllib3/connection.py", line 395, in request
    self.endheaders()
  File "/var/lang/lib/python3.10/http/client.py", line 1278, in endheaders
    self._send_output(message_body, encode_chunked=encode_chunked)
  File "/var/lang/lib/python3.10/http/client.py", line 1038, in _send_output
    self.send(msg)
  File "/var/lang/lib/python3.10/http/client.py", line 976, in send
    self.connect()
  File "/opt/python/urllib3/connection.py", line 243, in connect
    self.sock = self._new_conn()
  File "/opt/python/urllib3/connection.py", line 212, in _new_conn
    raise ConnectTimeoutError(
urllib3.exceptions.ConnectTimeoutError: (<urllib3.connection.HTTPConnection object at 0x7f2048699f60>, 'Connection to democracy.canterbury.gov.uk timed out. (connect timeout=None)')

The above exception was the direct cause of the following exception:

Traceback (most recent call last):
  File "/opt/python/requests/adapters.py", line 486, in send
    resp = conn.urlopen(
  File "/opt/python/urllib3/connectionpool.py", line 845, in urlopen
    retries = retries.increment(
  File "/opt/python/urllib3/util/retry.py", line 515, in increment
    raise MaxRetryError(_pool, url, reason) from reason  # type: ignore[arg-type]
urllib3.exceptions.MaxRetryError: HTTPConnectionPool(host='democracy.canterbury.gov.uk', port=80): Max retries exceeded with url: /mgWebService.asmx/GetCouncillorsByWard (Caused by ConnectTimeoutError(<urllib3.connection.HTTPConnection object at 0x7f2048699f60>, 'Connection to democracy.canterbury.gov.uk timed out. (connect timeout=None)'))

During handling of the above exception, another exception occurred:

Traceback (most recent call last):
  File "/var/task/lgsf/aws_lambda/handlers.py", line 32, in scraper_worker_handler
    scraper.run(run_log)
  File "/var/task/lgsf/councillors/scrapers.py", line 200, in run
    wards = self.get_councillors()
  File "/var/task/lgsf/councillors/scrapers.py", line 219, in get_councillors
    req = self.get(
  File "/var/task/lgsf/scrapers/base.py", line 47, in get
    response = self.requests_session.get(
  File "/opt/python/requests/sessions.py", line 602, in get
    return self.request("GET", url, **kwargs)
  File "/opt/python/requests/sessions.py", line 589, in request
    resp = self.send(prep, **send_kwargs)
  File "/opt/python/requests/sessions.py", line 703, in send
    r = adapter.send(request, **kwargs)
  File "/opt/python/requests/adapters.py", line 507, in send
    raise ConnectTimeout(e, request=request)
requests.exceptions.ConnectTimeout: HTTPConnectionPool(host='democracy.canterbury.gov.uk', port=80): Max retries exceeded with url: /mgWebService.asmx/GetCouncillorsByWard (Caused by ConnectTimeoutError(<urllib3.connection.HTTPConnection object at 0x7f2048699f60>, 'Connection to democracy.canterbury.gov.uk timed out. (connect timeout=None)'))
</dd>
      </div>
    </dl>
  </div>
  </div>

  <h3>Run log</h3>
  <pre>[10:44:10] Fetching Scraper for: CAT                              handlers.py:23
           Begin attempting to scrape: CAT                        handlers.py:27
           Deleting existing data...                                 base.py:251
           Getting all files in Councillors...                       base.py:203
[10:44:11] ...found 1 files in Councillors                           base.py:219
           Deleting batch no. 1 consisting of 1 files                base.py:230
           ...data deleted.                                          base.py:258
           Scraping from                                              base.py:41
           http://democracy.canterbury.gov.uk/mgWebService.asmx/GetCo           
           uncillorsByWard                                                      
[10:46:22] HTTPConnectionPool(host='democracy.canterbury.gov.uk', handlers.py:36
           port=80): Max retries exceeded with url:                             
           /mgWebService.asmx/GetCouncillorsByWard (Caused by                   
           ConnectTimeoutError(<urllib3.connection.HTTPConnection               
           object at 0x7f2048699f60>, 'Connection to                            
           democracy.canterbury.gov.uk timed out. (connect                      
           timeout=None)'))                                                     
           Finished attempting to scrape: CAT                        base.py:339
</pre>
  

  


  <h2 id="2024-03-10-09-45">2024-03-10</h2>
  <div class="ds-card">
  <div class="ds-card-body">
    <dl class="ds-descriptions">
      <div>
        <dt>Duration</dt>
        <dd>132 seconds</dd>
      </div>
      <div>
        <dt>Start</dt>
        <dd>2024-03-10 09:45:01.200543</dd>
      </div>
      <div>
        <dt>End</dt>
        <dd>2024-03-10 09:47:13.462093</dd>
      </div>
      <div>
        <dt>Status code</dt>
        <dd>1</dd>
      </div>
      <div>
        <dt>Error</dt>
        <dd>Traceback (most recent call last):
  File "/opt/python/urllib3/connection.py", line 203, in _new_conn
    sock = connection.create_connection(
  File "/opt/python/urllib3/util/connection.py", line 85, in create_connection
    raise err
  File "/opt/python/urllib3/util/connection.py", line 73, in create_connection
    sock.connect(sa)
TimeoutError: [Errno 110] Connection timed out

The above exception was the direct cause of the following exception:

Traceback (most recent call last):
  File "/opt/python/urllib3/connectionpool.py", line 791, in urlopen
    response = self._make_request(
  File "/opt/python/urllib3/connectionpool.py", line 497, in _make_request
    conn.request(
  File "/opt/python/urllib3/connection.py", line 395, in request
    self.endheaders()
  File "/var/lang/lib/python3.10/http/client.py", line 1278, in endheaders
    self._send_output(message_body, encode_chunked=encode_chunked)
  File "/var/lang/lib/python3.10/http/client.py", line 1038, in _send_output
    self.send(msg)
  File "/var/lang/lib/python3.10/http/client.py", line 976, in send
    self.connect()
  File "/opt/python/urllib3/connection.py", line 243, in connect
    self.sock = self._new_conn()
  File "/opt/python/urllib3/connection.py", line 212, in _new_conn
    raise ConnectTimeoutError(
urllib3.exceptions.ConnectTimeoutError: (<urllib3.connection.HTTPConnection object at 0x7f50d5803910>, 'Connection to democracy.canterbury.gov.uk timed out. (connect timeout=None)')

The above exception was the direct cause of the following exception:

Traceback (most recent call last):
  File "/opt/python/requests/adapters.py", line 486, in send
    resp = conn.urlopen(
  File "/opt/python/urllib3/connectionpool.py", line 845, in urlopen
    retries = retries.increment(
  File "/opt/python/urllib3/util/retry.py", line 515, in increment
    raise MaxRetryError(_pool, url, reason) from reason  # type: ignore[arg-type]
urllib3.exceptions.MaxRetryError: HTTPConnectionPool(host='democracy.canterbury.gov.uk', port=80): Max retries exceeded with url: /mgWebService.asmx/GetCouncillorsByWard (Caused by ConnectTimeoutError(<urllib3.connection.HTTPConnection object at 0x7f50d5803910>, 'Connection to democracy.canterbury.gov.uk timed out. (connect timeout=None)'))

During handling of the above exception, another exception occurred:

Traceback (most recent call last):
  File "/var/task/lgsf/aws_lambda/handlers.py", line 32, in scraper_worker_handler
    scraper.run(run_log)
  File "/var/task/lgsf/councillors/scrapers.py", line 200, in run
    wards = self.get_councillors()
  File "/var/task/lgsf/councillors/scrapers.py", line 219, in get_councillors
    req = self.get(
  File "/var/task/lgsf/scrapers/base.py", line 47, in get
    response = self.requests_session.get(
  File "/opt/python/requests/sessions.py", line 602, in get
    return self.request("GET", url, **kwargs)
  File "/opt/python/requests/sessions.py", line 589, in request
    resp = self.send(prep, **send_kwargs)
  File "/opt/python/requests/sessions.py", line 703, in send
    r = adapter.send(request, **kwargs)
  File "/opt/python/requests/adapters.py", line 507, in send
    raise ConnectTimeout(e, request=request)
requests.exceptions.ConnectTimeout: HTTPConnectionPool(host='democracy.canterbury.gov.uk', port=80): Max retries exceeded with url: /mgWebService.asmx/GetCouncillorsByWard (Caused by ConnectTimeoutError(<urllib3.connection.HTTPConnection object at 0x7f50d5803910>, 'Connection to democracy.canterbury.gov.uk timed out. (connect timeout=None)'))
</dd>
      </div>
    </dl>
  </div>
  </div>

  <h3>Run log</h3>
  <pre>[09:45:01] Fetching Scraper for: CAT                              handlers.py:23
           Begin attempting to scrape: CAT                        handlers.py:27
           Deleting existing data...                                 base.py:251
[09:45:02] Getting all files in Councillors...                       base.py:203
           ...found 1 files in Councillors                           base.py:219
           Deleting batch no. 1 consisting of 1 files                base.py:230
           ...data deleted.                                          base.py:258
           Scraping from                                              base.py:41
           http://democracy.canterbury.gov.uk/mgWebService.asmx/GetCo           
           uncillorsByWard                                                      
[09:47:13] HTTPConnectionPool(host='democracy.canterbury.gov.uk', handlers.py:36
           port=80): Max retries exceeded with url:                             
           /mgWebService.asmx/GetCouncillorsByWard (Caused by                   
           ConnectTimeoutError(<urllib3.connection.HTTPConnection               
           object at 0x7f50d5803910>, 'Connection to                            
           democracy.canterbury.gov.uk timed out. (connect                      
           timeout=None)'))                                                     
           Finished attempting to scrape: CAT                        base.py:339
</pre>
  

  


  <h2 id="2024-03-09-08-29">2024-03-09</h2>
  <div class="ds-card">
  <div class="ds-card-body">
    <dl class="ds-descriptions">
      <div>
        <dt>Duration</dt>
        <dd>133 seconds</dd>
      </div>
      <div>
        <dt>Start</dt>
        <dd>2024-03-09 08:29:32.430441</dd>
      </div>
      <div>
        <dt>End</dt>
        <dd>2024-03-09 08:31:45.504559</dd>
      </div>
      <div>
        <dt>Status code</dt>
        <dd>1</dd>
      </div>
      <div>
        <dt>Error</dt>
        <dd>Traceback (most recent call last):
  File "/opt/python/urllib3/connection.py", line 203, in _new_conn
    sock = connection.create_connection(
  File "/opt/python/urllib3/util/connection.py", line 85, in create_connection
    raise err
  File "/opt/python/urllib3/util/connection.py", line 73, in create_connection
    sock.connect(sa)
TimeoutError: [Errno 110] Connection timed out

The above exception was the direct cause of the following exception:

Traceback (most recent call last):
  File "/opt/python/urllib3/connectionpool.py", line 791, in urlopen
    response = self._make_request(
  File "/opt/python/urllib3/connectionpool.py", line 497, in _make_request
    conn.request(
  File "/opt/python/urllib3/connection.py", line 395, in request
    self.endheaders()
  File "/var/lang/lib/python3.10/http/client.py", line 1278, in endheaders
    self._send_output(message_body, encode_chunked=encode_chunked)
  File "/var/lang/lib/python3.10/http/client.py", line 1038, in _send_output
    self.send(msg)
  File "/var/lang/lib/python3.10/http/client.py", line 976, in send
    self.connect()
  File "/opt/python/urllib3/connection.py", line 243, in connect
    self.sock = self._new_conn()
  File "/opt/python/urllib3/connection.py", line 212, in _new_conn
    raise ConnectTimeoutError(
urllib3.exceptions.ConnectTimeoutError: (<urllib3.connection.HTTPConnection object at 0x7f09d27fbca0>, 'Connection to democracy.canterbury.gov.uk timed out. (connect timeout=None)')

The above exception was the direct cause of the following exception:

Traceback (most recent call last):
  File "/opt/python/requests/adapters.py", line 486, in send
    resp = conn.urlopen(
  File "/opt/python/urllib3/connectionpool.py", line 845, in urlopen
    retries = retries.increment(
  File "/opt/python/urllib3/util/retry.py", line 515, in increment
    raise MaxRetryError(_pool, url, reason) from reason  # type: ignore[arg-type]
urllib3.exceptions.MaxRetryError: HTTPConnectionPool(host='democracy.canterbury.gov.uk', port=80): Max retries exceeded with url: /mgWebService.asmx/GetCouncillorsByWard (Caused by ConnectTimeoutError(<urllib3.connection.HTTPConnection object at 0x7f09d27fbca0>, 'Connection to democracy.canterbury.gov.uk timed out. (connect timeout=None)'))

During handling of the above exception, another exception occurred:

Traceback (most recent call last):
  File "/var/task/lgsf/aws_lambda/handlers.py", line 32, in scraper_worker_handler
    scraper.run(run_log)
  File "/var/task/lgsf/councillors/scrapers.py", line 200, in run
    wards = self.get_councillors()
  File "/var/task/lgsf/councillors/scrapers.py", line 219, in get_councillors
    req = self.get(
  File "/var/task/lgsf/scrapers/base.py", line 47, in get
    response = self.requests_session.get(
  File "/opt/python/requests/sessions.py", line 602, in get
    return self.request("GET", url, **kwargs)
  File "/opt/python/requests/sessions.py", line 589, in request
    resp = self.send(prep, **send_kwargs)
  File "/opt/python/requests/sessions.py", line 703, in send
    r = adapter.send(request, **kwargs)
  File "/opt/python/requests/adapters.py", line 507, in send
    raise ConnectTimeout(e, request=request)
requests.exceptions.ConnectTimeout: HTTPConnectionPool(host='democracy.canterbury.gov.uk', port=80): Max retries exceeded with url: /mgWebService.asmx/GetCouncillorsByWard (Caused by ConnectTimeoutError(<urllib3.connection.HTTPConnection object at 0x7f09d27fbca0>, 'Connection to democracy.canterbury.gov.uk timed out. (connect timeout=None)'))
</dd>
      </div>
    </dl>
  </div>
  </div>

  <h3>Run log</h3>
  <pre>[08:29:32] Fetching Scraper for: CAT                              handlers.py:23
           Begin attempting to scrape: CAT                        handlers.py:27
           Deleting existing data...                                 base.py:251
[08:29:33] Getting all files in Councillors...                       base.py:203
           ...found 1 files in Councillors                           base.py:219
           Deleting batch no. 1 consisting of 1 files                base.py:230
           ...data deleted.                                          base.py:258
           Scraping from                                              base.py:41
           http://democracy.canterbury.gov.uk/mgWebService.asmx/GetCo           
           uncillorsByWard                                                      
[08:31:45] HTTPConnectionPool(host='democracy.canterbury.gov.uk', handlers.py:36
           port=80): Max retries exceeded with url:                             
           /mgWebService.asmx/GetCouncillorsByWard (Caused by                   
           ConnectTimeoutError(<urllib3.connection.HTTPConnection               
           object at 0x7f09d27fbca0>, 'Connection to                            
           democracy.canterbury.gov.uk timed out. (connect                      
           timeout=None)'))                                                     
           Finished attempting to scrape: CAT                        base.py:339
</pre>
  

  


  <h2 id="2024-03-08-10-05">2024-03-08</h2>
  <div class="ds-card">
  <div class="ds-card-body">
    <dl class="ds-descriptions">
      <div>
        <dt>Duration</dt>
        <dd>132 seconds</dd>
      </div>
      <div>
        <dt>Start</dt>
        <dd>2024-03-08 10:05:51.926388</dd>
      </div>
      <div>
        <dt>End</dt>
        <dd>2024-03-08 10:08:04.357402</dd>
      </div>
      <div>
        <dt>Status code</dt>
        <dd>1</dd>
      </div>
      <div>
        <dt>Error</dt>
        <dd>Traceback (most recent call last):
  File "/opt/python/urllib3/connection.py", line 203, in _new_conn
    sock = connection.create_connection(
  File "/opt/python/urllib3/util/connection.py", line 85, in create_connection
    raise err
  File "/opt/python/urllib3/util/connection.py", line 73, in create_connection
    sock.connect(sa)
TimeoutError: [Errno 110] Connection timed out

The above exception was the direct cause of the following exception:

Traceback (most recent call last):
  File "/opt/python/urllib3/connectionpool.py", line 791, in urlopen
    response = self._make_request(
  File "/opt/python/urllib3/connectionpool.py", line 497, in _make_request
    conn.request(
  File "/opt/python/urllib3/connection.py", line 395, in request
    self.endheaders()
  File "/var/lang/lib/python3.10/http/client.py", line 1278, in endheaders
    self._send_output(message_body, encode_chunked=encode_chunked)
  File "/var/lang/lib/python3.10/http/client.py", line 1038, in _send_output
    self.send(msg)
  File "/var/lang/lib/python3.10/http/client.py", line 976, in send
    self.connect()
  File "/opt/python/urllib3/connection.py", line 243, in connect
    self.sock = self._new_conn()
  File "/opt/python/urllib3/connection.py", line 212, in _new_conn
    raise ConnectTimeoutError(
urllib3.exceptions.ConnectTimeoutError: (<urllib3.connection.HTTPConnection object at 0x7fc24079b280>, 'Connection to democracy.canterbury.gov.uk timed out. (connect timeout=None)')

The above exception was the direct cause of the following exception:

Traceback (most recent call last):
  File "/opt/python/requests/adapters.py", line 486, in send
    resp = conn.urlopen(
  File "/opt/python/urllib3/connectionpool.py", line 845, in urlopen
    retries = retries.increment(
  File "/opt/python/urllib3/util/retry.py", line 515, in increment
    raise MaxRetryError(_pool, url, reason) from reason  # type: ignore[arg-type]
urllib3.exceptions.MaxRetryError: HTTPConnectionPool(host='democracy.canterbury.gov.uk', port=80): Max retries exceeded with url: /mgWebService.asmx/GetCouncillorsByWard (Caused by ConnectTimeoutError(<urllib3.connection.HTTPConnection object at 0x7fc24079b280>, 'Connection to democracy.canterbury.gov.uk timed out. (connect timeout=None)'))

During handling of the above exception, another exception occurred:

Traceback (most recent call last):
  File "/var/task/lgsf/aws_lambda/handlers.py", line 32, in scraper_worker_handler
    scraper.run(run_log)
  File "/var/task/lgsf/councillors/scrapers.py", line 200, in run
    wards = self.get_councillors()
  File "/var/task/lgsf/councillors/scrapers.py", line 219, in get_councillors
    req = self.get(
  File "/var/task/lgsf/scrapers/base.py", line 47, in get
    response = self.requests_session.get(
  File "/opt/python/requests/sessions.py", line 602, in get
    return self.request("GET", url, **kwargs)
  File "/opt/python/requests/sessions.py", line 589, in request
    resp = self.send(prep, **send_kwargs)
  File "/opt/python/requests/sessions.py", line 703, in send
    r = adapter.send(request, **kwargs)
  File "/opt/python/requests/adapters.py", line 507, in send
    raise ConnectTimeout(e, request=request)
requests.exceptions.ConnectTimeout: HTTPConnectionPool(host='democracy.canterbury.gov.uk', port=80): Max retries exceeded with url: /mgWebService.asmx/GetCouncillorsByWard (Caused by ConnectTimeoutError(<urllib3.connection.HTTPConnection object at 0x7fc24079b280>, 'Connection to democracy.canterbury.gov.uk timed out. (connect timeout=None)'))
</dd>
      </div>
    </dl>
  </div>
  </div>

  <h3>Run log</h3>
  <pre>[10:05:51] Fetching Scraper for: CAT                              handlers.py:23
           Begin attempting to scrape: CAT                        handlers.py:27
[10:05:52] Deleting existing data...                                 base.py:251
           Getting all files in Councillors...                       base.py:203
           ...found 1 files in Councillors                           base.py:219
           Deleting batch no. 1 consisting of 1 files                base.py:230
[10:05:53] ...data deleted.                                          base.py:258
           Scraping from                                              base.py:41
           http://democracy.canterbury.gov.uk/mgWebService.asmx/GetCo           
           uncillorsByWard                                                      
[10:08:03] HTTPConnectionPool(host='democracy.canterbury.gov.uk', handlers.py:36
           port=80): Max retries exceeded with url:                             
           /mgWebService.asmx/GetCouncillorsByWard (Caused by                   
           ConnectTimeoutError(<urllib3.connection.HTTPConnection               
           object at 0x7fc24079b280>, 'Connection to                            
           democracy.canterbury.gov.uk timed out. (connect                      
           timeout=None)'))                                                     
[10:08:04] Finished attempting to scrape: CAT                        base.py:339
</pre>
  

  


  <h2 id="2024-03-07-09-17">2024-03-07</h2>
  <div class="ds-card">
  <div class="ds-card-body">
    <dl class="ds-descriptions">
      <div>
        <dt>Duration</dt>
        <dd>132 seconds</dd>
      </div>
      <div>
        <dt>Start</dt>
        <dd>2024-03-07 09:17:49.443054</dd>
      </div>
      <div>
        <dt>End</dt>
        <dd>2024-03-07 09:20:01.478782</dd>
      </div>
      <div>
        <dt>Status code</dt>
        <dd>1</dd>
      </div>
      <div>
        <dt>Error</dt>
        <dd>Traceback (most recent call last):
  File "/opt/python/urllib3/connection.py", line 203, in _new_conn
    sock = connection.create_connection(
  File "/opt/python/urllib3/util/connection.py", line 85, in create_connection
    raise err
  File "/opt/python/urllib3/util/connection.py", line 73, in create_connection
    sock.connect(sa)
TimeoutError: [Errno 110] Connection timed out

The above exception was the direct cause of the following exception:

Traceback (most recent call last):
  File "/opt/python/urllib3/connectionpool.py", line 791, in urlopen
    response = self._make_request(
  File "/opt/python/urllib3/connectionpool.py", line 497, in _make_request
    conn.request(
  File "/opt/python/urllib3/connection.py", line 395, in request
    self.endheaders()
  File "/var/lang/lib/python3.10/http/client.py", line 1278, in endheaders
    self._send_output(message_body, encode_chunked=encode_chunked)
  File "/var/lang/lib/python3.10/http/client.py", line 1038, in _send_output
    self.send(msg)
  File "/var/lang/lib/python3.10/http/client.py", line 976, in send
    self.connect()
  File "/opt/python/urllib3/connection.py", line 243, in connect
    self.sock = self._new_conn()
  File "/opt/python/urllib3/connection.py", line 212, in _new_conn
    raise ConnectTimeoutError(
urllib3.exceptions.ConnectTimeoutError: (<urllib3.connection.HTTPConnection object at 0x7f95c2226ad0>, 'Connection to democracy.canterbury.gov.uk timed out. (connect timeout=None)')

The above exception was the direct cause of the following exception:

Traceback (most recent call last):
  File "/opt/python/requests/adapters.py", line 486, in send
    resp = conn.urlopen(
  File "/opt/python/urllib3/connectionpool.py", line 845, in urlopen
    retries = retries.increment(
  File "/opt/python/urllib3/util/retry.py", line 515, in increment
    raise MaxRetryError(_pool, url, reason) from reason  # type: ignore[arg-type]
urllib3.exceptions.MaxRetryError: HTTPConnectionPool(host='democracy.canterbury.gov.uk', port=80): Max retries exceeded with url: /mgWebService.asmx/GetCouncillorsByWard (Caused by ConnectTimeoutError(<urllib3.connection.HTTPConnection object at 0x7f95c2226ad0>, 'Connection to democracy.canterbury.gov.uk timed out. (connect timeout=None)'))

During handling of the above exception, another exception occurred:

Traceback (most recent call last):
  File "/var/task/lgsf/aws_lambda/handlers.py", line 32, in scraper_worker_handler
    scraper.run(run_log)
  File "/var/task/lgsf/councillors/scrapers.py", line 200, in run
    wards = self.get_councillors()
  File "/var/task/lgsf/councillors/scrapers.py", line 219, in get_councillors
    req = self.get(
  File "/var/task/lgsf/scrapers/base.py", line 47, in get
    response = self.requests_session.get(
  File "/opt/python/requests/sessions.py", line 602, in get
    return self.request("GET", url, **kwargs)
  File "/opt/python/requests/sessions.py", line 589, in request
    resp = self.send(prep, **send_kwargs)
  File "/opt/python/requests/sessions.py", line 703, in send
    r = adapter.send(request, **kwargs)
  File "/opt/python/requests/adapters.py", line 507, in send
    raise ConnectTimeout(e, request=request)
requests.exceptions.ConnectTimeout: HTTPConnectionPool(host='democracy.canterbury.gov.uk', port=80): Max retries exceeded with url: /mgWebService.asmx/GetCouncillorsByWard (Caused by ConnectTimeoutError(<urllib3.connection.HTTPConnection object at 0x7f95c2226ad0>, 'Connection to democracy.canterbury.gov.uk timed out. (connect timeout=None)'))
</dd>
      </div>
    </dl>
  </div>
  </div>

  <h3>Run log</h3>
  <pre>[09:17:49] Fetching Scraper for: CAT                              handlers.py:23
           Begin attempting to scrape: CAT                        handlers.py:27
           Deleting existing data...                                 base.py:251
[09:17:50] Getting all files in Councillors...                       base.py:203
           ...found 1 files in Councillors                           base.py:219
           Deleting batch no. 1 consisting of 1 files                base.py:230
[09:17:51] ...data deleted.                                          base.py:258
           Scraping from                                              base.py:41
           http://democracy.canterbury.gov.uk/mgWebService.asmx/GetCo           
           uncillorsByWard                                                      
[09:20:01] HTTPConnectionPool(host='democracy.canterbury.gov.uk', handlers.py:36
           port=80): Max retries exceeded with url:                             
           /mgWebService.asmx/GetCouncillorsByWard (Caused by                   
           ConnectTimeoutError(<urllib3.connection.HTTPConnection               
           object at 0x7f95c2226ad0>, 'Connection to                            
           democracy.canterbury.gov.uk timed out. (connect                      
           timeout=None)'))                                                     
           Finished attempting to scrape: CAT                        base.py:339
</pre>
  

  


  <h2 id="2024-03-06-09-51">2024-03-06</h2>
  <div class="ds-card">
  <div class="ds-card-body">
    <dl class="ds-descriptions">
      <div>
        <dt>Duration</dt>
        <dd>132 seconds</dd>
      </div>
      <div>
        <dt>Start</dt>
        <dd>2024-03-06 09:51:44.217230</dd>
      </div>
      <div>
        <dt>End</dt>
        <dd>2024-03-06 09:53:56.340325</dd>
      </div>
      <div>
        <dt>Status code</dt>
        <dd>1</dd>
      </div>
      <div>
        <dt>Error</dt>
        <dd>Traceback (most recent call last):
  File "/opt/python/urllib3/connection.py", line 203, in _new_conn
    sock = connection.create_connection(
  File "/opt/python/urllib3/util/connection.py", line 85, in create_connection
    raise err
  File "/opt/python/urllib3/util/connection.py", line 73, in create_connection
    sock.connect(sa)
TimeoutError: [Errno 110] Connection timed out

The above exception was the direct cause of the following exception:

Traceback (most recent call last):
  File "/opt/python/urllib3/connectionpool.py", line 791, in urlopen
    response = self._make_request(
  File "/opt/python/urllib3/connectionpool.py", line 497, in _make_request
    conn.request(
  File "/opt/python/urllib3/connection.py", line 395, in request
    self.endheaders()
  File "/var/lang/lib/python3.10/http/client.py", line 1278, in endheaders
    self._send_output(message_body, encode_chunked=encode_chunked)
  File "/var/lang/lib/python3.10/http/client.py", line 1038, in _send_output
    self.send(msg)
  File "/var/lang/lib/python3.10/http/client.py", line 976, in send
    self.connect()
  File "/opt/python/urllib3/connection.py", line 243, in connect
    self.sock = self._new_conn()
  File "/opt/python/urllib3/connection.py", line 212, in _new_conn
    raise ConnectTimeoutError(
urllib3.exceptions.ConnectTimeoutError: (<urllib3.connection.HTTPConnection object at 0x7fcd19907af0>, 'Connection to democracy.canterbury.gov.uk timed out. (connect timeout=None)')

The above exception was the direct cause of the following exception:

Traceback (most recent call last):
  File "/opt/python/requests/adapters.py", line 486, in send
    resp = conn.urlopen(
  File "/opt/python/urllib3/connectionpool.py", line 845, in urlopen
    retries = retries.increment(
  File "/opt/python/urllib3/util/retry.py", line 515, in increment
    raise MaxRetryError(_pool, url, reason) from reason  # type: ignore[arg-type]
urllib3.exceptions.MaxRetryError: HTTPConnectionPool(host='democracy.canterbury.gov.uk', port=80): Max retries exceeded with url: /mgWebService.asmx/GetCouncillorsByWard (Caused by ConnectTimeoutError(<urllib3.connection.HTTPConnection object at 0x7fcd19907af0>, 'Connection to democracy.canterbury.gov.uk timed out. (connect timeout=None)'))

During handling of the above exception, another exception occurred:

Traceback (most recent call last):
  File "/var/task/lgsf/aws_lambda/handlers.py", line 32, in scraper_worker_handler
    scraper.run(run_log)
  File "/var/task/lgsf/councillors/scrapers.py", line 200, in run
    wards = self.get_councillors()
  File "/var/task/lgsf/councillors/scrapers.py", line 219, in get_councillors
    req = self.get(
  File "/var/task/lgsf/scrapers/base.py", line 47, in get
    response = self.requests_session.get(
  File "/opt/python/requests/sessions.py", line 602, in get
    return self.request("GET", url, **kwargs)
  File "/opt/python/requests/sessions.py", line 589, in request
    resp = self.send(prep, **send_kwargs)
  File "/opt/python/requests/sessions.py", line 703, in send
    r = adapter.send(request, **kwargs)
  File "/opt/python/requests/adapters.py", line 507, in send
    raise ConnectTimeout(e, request=request)
requests.exceptions.ConnectTimeout: HTTPConnectionPool(host='democracy.canterbury.gov.uk', port=80): Max retries exceeded with url: /mgWebService.asmx/GetCouncillorsByWard (Caused by ConnectTimeoutError(<urllib3.connection.HTTPConnection object at 0x7fcd19907af0>, 'Connection to democracy.canterbury.gov.uk timed out. (connect timeout=None)'))
</dd>
      </div>
    </dl>
  </div>
  </div>

  <h3>Run log</h3>
  <pre>[09:51:44] Fetching Scraper for: CAT                              handlers.py:23
           Begin attempting to scrape: CAT                        handlers.py:27
           Deleting existing data...                                 base.py:251
[09:51:45] Getting all files in Councillors...                       base.py:203
           ...found 1 files in Councillors                           base.py:219
           Deleting batch no. 1 consisting of 1 files                base.py:230
           ...data deleted.                                          base.py:258
           Scraping from                                              base.py:41
           http://democracy.canterbury.gov.uk/mgWebService.asmx/GetCo           
           uncillorsByWard                                                      
[09:53:56] HTTPConnectionPool(host='democracy.canterbury.gov.uk', handlers.py:36
           port=80): Max retries exceeded with url:                             
           /mgWebService.asmx/GetCouncillorsByWard (Caused by                   
           ConnectTimeoutError(<urllib3.connection.HTTPConnection               
           object at 0x7fcd19907af0>, 'Connection to                            
           democracy.canterbury.gov.uk timed out. (connect                      
           timeout=None)'))                                                     
           Finished attempting to scrape: CAT                        base.py:339
</pre>
  

  


  <h2 id="2024-03-05-09-21">2024-03-05</h2>
  <div class="ds-card">
  <div class="ds-card-body">
    <dl class="ds-descriptions">
      <div>
        <dt>Duration</dt>
        <dd>131 seconds</dd>
      </div>
      <div>
        <dt>Start</dt>
        <dd>2024-03-05 09:21:24.369376</dd>
      </div>
      <div>
        <dt>End</dt>
        <dd>2024-03-05 09:23:36.092850</dd>
      </div>
      <div>
        <dt>Status code</dt>
        <dd>1</dd>
      </div>
      <div>
        <dt>Error</dt>
        <dd>Traceback (most recent call last):
  File "/opt/python/urllib3/connection.py", line 203, in _new_conn
    sock = connection.create_connection(
  File "/opt/python/urllib3/util/connection.py", line 85, in create_connection
    raise err
  File "/opt/python/urllib3/util/connection.py", line 73, in create_connection
    sock.connect(sa)
TimeoutError: [Errno 110] Connection timed out

The above exception was the direct cause of the following exception:

Traceback (most recent call last):
  File "/opt/python/urllib3/connectionpool.py", line 791, in urlopen
    response = self._make_request(
  File "/opt/python/urllib3/connectionpool.py", line 497, in _make_request
    conn.request(
  File "/opt/python/urllib3/connection.py", line 395, in request
    self.endheaders()
  File "/var/lang/lib/python3.10/http/client.py", line 1278, in endheaders
    self._send_output(message_body, encode_chunked=encode_chunked)
  File "/var/lang/lib/python3.10/http/client.py", line 1038, in _send_output
    self.send(msg)
  File "/var/lang/lib/python3.10/http/client.py", line 976, in send
    self.connect()
  File "/opt/python/urllib3/connection.py", line 243, in connect
    self.sock = self._new_conn()
  File "/opt/python/urllib3/connection.py", line 212, in _new_conn
    raise ConnectTimeoutError(
urllib3.exceptions.ConnectTimeoutError: (<urllib3.connection.HTTPConnection object at 0x7f1871dc1000>, 'Connection to democracy.canterbury.gov.uk timed out. (connect timeout=None)')

The above exception was the direct cause of the following exception:

Traceback (most recent call last):
  File "/opt/python/requests/adapters.py", line 486, in send
    resp = conn.urlopen(
  File "/opt/python/urllib3/connectionpool.py", line 845, in urlopen
    retries = retries.increment(
  File "/opt/python/urllib3/util/retry.py", line 515, in increment
    raise MaxRetryError(_pool, url, reason) from reason  # type: ignore[arg-type]
urllib3.exceptions.MaxRetryError: HTTPConnectionPool(host='democracy.canterbury.gov.uk', port=80): Max retries exceeded with url: /mgWebService.asmx/GetCouncillorsByWard (Caused by ConnectTimeoutError(<urllib3.connection.HTTPConnection object at 0x7f1871dc1000>, 'Connection to democracy.canterbury.gov.uk timed out. (connect timeout=None)'))

During handling of the above exception, another exception occurred:

Traceback (most recent call last):
  File "/var/task/lgsf/aws_lambda/handlers.py", line 32, in scraper_worker_handler
    scraper.run(run_log)
  File "/var/task/lgsf/councillors/scrapers.py", line 200, in run
    wards = self.get_councillors()
  File "/var/task/lgsf/councillors/scrapers.py", line 219, in get_councillors
    req = self.get(
  File "/var/task/lgsf/scrapers/base.py", line 47, in get
    response = self.requests_session.get(
  File "/opt/python/requests/sessions.py", line 602, in get
    return self.request("GET", url, **kwargs)
  File "/opt/python/requests/sessions.py", line 589, in request
    resp = self.send(prep, **send_kwargs)
  File "/opt/python/requests/sessions.py", line 703, in send
    r = adapter.send(request, **kwargs)
  File "/opt/python/requests/adapters.py", line 507, in send
    raise ConnectTimeout(e, request=request)
requests.exceptions.ConnectTimeout: HTTPConnectionPool(host='democracy.canterbury.gov.uk', port=80): Max retries exceeded with url: /mgWebService.asmx/GetCouncillorsByWard (Caused by ConnectTimeoutError(<urllib3.connection.HTTPConnection object at 0x7f1871dc1000>, 'Connection to democracy.canterbury.gov.uk timed out. (connect timeout=None)'))
</dd>
      </div>
    </dl>
  </div>
  </div>

  <h3>Run log</h3>
  <pre>[09:21:24] Fetching Scraper for: CAT                              handlers.py:23
           Begin attempting to scrape: CAT                        handlers.py:27
           Deleting existing data...                                 base.py:251
[09:21:25] Getting all files in Councillors...                       base.py:203
           ...found 1 files in Councillors                           base.py:219
           Deleting batch no. 1 consisting of 1 files                base.py:230
           ...data deleted.                                          base.py:258
           Scraping from                                              base.py:41
           http://democracy.canterbury.gov.uk/mgWebService.asmx/GetCo           
           uncillorsByWard                                                      
[09:23:35] HTTPConnectionPool(host='democracy.canterbury.gov.uk', handlers.py:36
           port=80): Max retries exceeded with url:                             
           /mgWebService.asmx/GetCouncillorsByWard (Caused by                   
           ConnectTimeoutError(<urllib3.connection.HTTPConnection               
           object at 0x7f1871dc1000>, 'Connection to                            
           democracy.canterbury.gov.uk timed out. (connect                      
           timeout=None)'))                                                     
[09:23:36] Finished attempting to scrape: CAT                        base.py:339
</pre>
  

  


  <h2 id="2024-03-04-09-41">2024-03-04</h2>
  <div class="ds-card">
  <div class="ds-card-body">
    <dl class="ds-descriptions">
      <div>
        <dt>Duration</dt>
        <dd>132 seconds</dd>
      </div>
      <div>
        <dt>Start</dt>
        <dd>2024-03-04 09:41:56.342269</dd>
      </div>
      <div>
        <dt>End</dt>
        <dd>2024-03-04 09:44:08.992136</dd>
      </div>
      <div>
        <dt>Status code</dt>
        <dd>1</dd>
      </div>
      <div>
        <dt>Error</dt>
        <dd>Traceback (most recent call last):
  File "/opt/python/urllib3/connection.py", line 203, in _new_conn
    sock = connection.create_connection(
  File "/opt/python/urllib3/util/connection.py", line 85, in create_connection
    raise err
  File "/opt/python/urllib3/util/connection.py", line 73, in create_connection
    sock.connect(sa)
TimeoutError: [Errno 110] Connection timed out

The above exception was the direct cause of the following exception:

Traceback (most recent call last):
  File "/opt/python/urllib3/connectionpool.py", line 791, in urlopen
    response = self._make_request(
  File "/opt/python/urllib3/connectionpool.py", line 497, in _make_request
    conn.request(
  File "/opt/python/urllib3/connection.py", line 395, in request
    self.endheaders()
  File "/var/lang/lib/python3.10/http/client.py", line 1278, in endheaders
    self._send_output(message_body, encode_chunked=encode_chunked)
  File "/var/lang/lib/python3.10/http/client.py", line 1038, in _send_output
    self.send(msg)
  File "/var/lang/lib/python3.10/http/client.py", line 976, in send
    self.connect()
  File "/opt/python/urllib3/connection.py", line 243, in connect
    self.sock = self._new_conn()
  File "/opt/python/urllib3/connection.py", line 212, in _new_conn
    raise ConnectTimeoutError(
urllib3.exceptions.ConnectTimeoutError: (<urllib3.connection.HTTPConnection object at 0x7fce5fd7c6d0>, 'Connection to democracy.canterbury.gov.uk timed out. (connect timeout=None)')

The above exception was the direct cause of the following exception:

Traceback (most recent call last):
  File "/opt/python/requests/adapters.py", line 486, in send
    resp = conn.urlopen(
  File "/opt/python/urllib3/connectionpool.py", line 845, in urlopen
    retries = retries.increment(
  File "/opt/python/urllib3/util/retry.py", line 515, in increment
    raise MaxRetryError(_pool, url, reason) from reason  # type: ignore[arg-type]
urllib3.exceptions.MaxRetryError: HTTPConnectionPool(host='democracy.canterbury.gov.uk', port=80): Max retries exceeded with url: /mgWebService.asmx/GetCouncillorsByWard (Caused by ConnectTimeoutError(<urllib3.connection.HTTPConnection object at 0x7fce5fd7c6d0>, 'Connection to democracy.canterbury.gov.uk timed out. (connect timeout=None)'))

During handling of the above exception, another exception occurred:

Traceback (most recent call last):
  File "/var/task/lgsf/aws_lambda/handlers.py", line 32, in scraper_worker_handler
    scraper.run(run_log)
  File "/var/task/lgsf/councillors/scrapers.py", line 200, in run
    wards = self.get_councillors()
  File "/var/task/lgsf/councillors/scrapers.py", line 219, in get_councillors
    req = self.get(
  File "/var/task/lgsf/scrapers/base.py", line 47, in get
    response = self.requests_session.get(
  File "/opt/python/requests/sessions.py", line 602, in get
    return self.request("GET", url, **kwargs)
  File "/opt/python/requests/sessions.py", line 589, in request
    resp = self.send(prep, **send_kwargs)
  File "/opt/python/requests/sessions.py", line 703, in send
    r = adapter.send(request, **kwargs)
  File "/opt/python/requests/adapters.py", line 507, in send
    raise ConnectTimeout(e, request=request)
requests.exceptions.ConnectTimeout: HTTPConnectionPool(host='democracy.canterbury.gov.uk', port=80): Max retries exceeded with url: /mgWebService.asmx/GetCouncillorsByWard (Caused by ConnectTimeoutError(<urllib3.connection.HTTPConnection object at 0x7fce5fd7c6d0>, 'Connection to democracy.canterbury.gov.uk timed out. (connect timeout=None)'))
</dd>
      </div>
    </dl>
  </div>
  </div>

  <h3>Run log</h3>
  <pre>[09:41:56] Fetching Scraper for: CAT                              handlers.py:23
           Begin attempting to scrape: CAT                        handlers.py:27
           Deleting existing data...                                 base.py:251
[09:41:57] Getting all files in Councillors...                       base.py:203
           ...found 1 files in Councillors                           base.py:219
           Deleting batch no. 1 consisting of 1 files                base.py:230
           ...data deleted.                                          base.py:258
           Scraping from                                              base.py:41
           http://democracy.canterbury.gov.uk/mgWebService.asmx/GetCo           
           uncillorsByWard                                                      
[09:44:08] HTTPConnectionPool(host='democracy.canterbury.gov.uk', handlers.py:36
           port=80): Max retries exceeded with url:                             
           /mgWebService.asmx/GetCouncillorsByWard (Caused by                   
           ConnectTimeoutError(<urllib3.connection.HTTPConnection               
           object at 0x7fce5fd7c6d0>, 'Connection to                            
           democracy.canterbury.gov.uk timed out. (connect                      
           timeout=None)'))                                                     
           Finished attempting to scrape: CAT                        base.py:339
</pre>
  

  


  <h2 id="2024-03-03-09-39">2024-03-03</h2>
  <div class="ds-card">
  <div class="ds-card-body">
    <dl class="ds-descriptions">
      <div>
        <dt>Duration</dt>
        <dd>132 seconds</dd>
      </div>
      <div>
        <dt>Start</dt>
        <dd>2024-03-03 09:39:03.899030</dd>
      </div>
      <div>
        <dt>End</dt>
        <dd>2024-03-03 09:41:15.925976</dd>
      </div>
      <div>
        <dt>Status code</dt>
        <dd>1</dd>
      </div>
      <div>
        <dt>Error</dt>
        <dd>Traceback (most recent call last):
  File "/opt/python/urllib3/connection.py", line 203, in _new_conn
    sock = connection.create_connection(
  File "/opt/python/urllib3/util/connection.py", line 85, in create_connection
    raise err
  File "/opt/python/urllib3/util/connection.py", line 73, in create_connection
    sock.connect(sa)
TimeoutError: [Errno 110] Connection timed out

The above exception was the direct cause of the following exception:

Traceback (most recent call last):
  File "/opt/python/urllib3/connectionpool.py", line 791, in urlopen
    response = self._make_request(
  File "/opt/python/urllib3/connectionpool.py", line 497, in _make_request
    conn.request(
  File "/opt/python/urllib3/connection.py", line 395, in request
    self.endheaders()
  File "/var/lang/lib/python3.10/http/client.py", line 1278, in endheaders
    self._send_output(message_body, encode_chunked=encode_chunked)
  File "/var/lang/lib/python3.10/http/client.py", line 1038, in _send_output
    self.send(msg)
  File "/var/lang/lib/python3.10/http/client.py", line 976, in send
    self.connect()
  File "/opt/python/urllib3/connection.py", line 243, in connect
    self.sock = self._new_conn()
  File "/opt/python/urllib3/connection.py", line 212, in _new_conn
    raise ConnectTimeoutError(
urllib3.exceptions.ConnectTimeoutError: (<urllib3.connection.HTTPConnection object at 0x7fc97f0941c0>, 'Connection to democracy.canterbury.gov.uk timed out. (connect timeout=None)')

The above exception was the direct cause of the following exception:

Traceback (most recent call last):
  File "/opt/python/requests/adapters.py", line 486, in send
    resp = conn.urlopen(
  File "/opt/python/urllib3/connectionpool.py", line 845, in urlopen
    retries = retries.increment(
  File "/opt/python/urllib3/util/retry.py", line 515, in increment
    raise MaxRetryError(_pool, url, reason) from reason  # type: ignore[arg-type]
urllib3.exceptions.MaxRetryError: HTTPConnectionPool(host='democracy.canterbury.gov.uk', port=80): Max retries exceeded with url: /mgWebService.asmx/GetCouncillorsByWard (Caused by ConnectTimeoutError(<urllib3.connection.HTTPConnection object at 0x7fc97f0941c0>, 'Connection to democracy.canterbury.gov.uk timed out. (connect timeout=None)'))

During handling of the above exception, another exception occurred:

Traceback (most recent call last):
  File "/var/task/lgsf/aws_lambda/handlers.py", line 32, in scraper_worker_handler
    scraper.run(run_log)
  File "/var/task/lgsf/councillors/scrapers.py", line 200, in run
    wards = self.get_councillors()
  File "/var/task/lgsf/councillors/scrapers.py", line 219, in get_councillors
    req = self.get(
  File "/var/task/lgsf/scrapers/base.py", line 47, in get
    response = self.requests_session.get(
  File "/opt/python/requests/sessions.py", line 602, in get
    return self.request("GET", url, **kwargs)
  File "/opt/python/requests/sessions.py", line 589, in request
    resp = self.send(prep, **send_kwargs)
  File "/opt/python/requests/sessions.py", line 703, in send
    r = adapter.send(request, **kwargs)
  File "/opt/python/requests/adapters.py", line 507, in send
    raise ConnectTimeout(e, request=request)
requests.exceptions.ConnectTimeout: HTTPConnectionPool(host='democracy.canterbury.gov.uk', port=80): Max retries exceeded with url: /mgWebService.asmx/GetCouncillorsByWard (Caused by ConnectTimeoutError(<urllib3.connection.HTTPConnection object at 0x7fc97f0941c0>, 'Connection to democracy.canterbury.gov.uk timed out. (connect timeout=None)'))
</dd>
      </div>
    </dl>
  </div>
  </div>

  <h3>Run log</h3>
  <pre>[09:39:03] Fetching Scraper for: CAT                              handlers.py:23
           Begin attempting to scrape: CAT                        handlers.py:27
[09:39:04] Deleting existing data...                                 base.py:251
           Getting all files in Councillors...                       base.py:203
[09:39:05] ...found 1 files in Councillors                           base.py:219
           Deleting batch no. 1 consisting of 1 files                base.py:230
           ...data deleted.                                          base.py:258
           Scraping from                                              base.py:41
           http://democracy.canterbury.gov.uk/mgWebService.asmx/GetCo           
           uncillorsByWard                                                      
[09:41:15] HTTPConnectionPool(host='democracy.canterbury.gov.uk', handlers.py:36
           port=80): Max retries exceeded with url:                             
           /mgWebService.asmx/GetCouncillorsByWard (Caused by                   
           ConnectTimeoutError(<urllib3.connection.HTTPConnection               
           object at 0x7fc97f0941c0>, 'Connection to                            
           democracy.canterbury.gov.uk timed out. (connect                      
           timeout=None)'))                                                     
           Finished attempting to scrape: CAT                        base.py:339
</pre>
  

  


  <h2 id="2024-03-02-09-27">2024-03-02</h2>
  <div class="ds-card">
  <div class="ds-card-body">
    <dl class="ds-descriptions">
      <div>
        <dt>Duration</dt>
        <dd>131 seconds</dd>
      </div>
      <div>
        <dt>Start</dt>
        <dd>2024-03-02 09:27:58.964391</dd>
      </div>
      <div>
        <dt>End</dt>
        <dd>2024-03-02 09:30:10.796009</dd>
      </div>
      <div>
        <dt>Status code</dt>
        <dd>1</dd>
      </div>
      <div>
        <dt>Error</dt>
        <dd>Traceback (most recent call last):
  File "/opt/python/urllib3/connection.py", line 203, in _new_conn
    sock = connection.create_connection(
  File "/opt/python/urllib3/util/connection.py", line 85, in create_connection
    raise err
  File "/opt/python/urllib3/util/connection.py", line 73, in create_connection
    sock.connect(sa)
TimeoutError: [Errno 110] Connection timed out

The above exception was the direct cause of the following exception:

Traceback (most recent call last):
  File "/opt/python/urllib3/connectionpool.py", line 791, in urlopen
    response = self._make_request(
  File "/opt/python/urllib3/connectionpool.py", line 497, in _make_request
    conn.request(
  File "/opt/python/urllib3/connection.py", line 395, in request
    self.endheaders()
  File "/var/lang/lib/python3.10/http/client.py", line 1278, in endheaders
    self._send_output(message_body, encode_chunked=encode_chunked)
  File "/var/lang/lib/python3.10/http/client.py", line 1038, in _send_output
    self.send(msg)
  File "/var/lang/lib/python3.10/http/client.py", line 976, in send
    self.connect()
  File "/opt/python/urllib3/connection.py", line 243, in connect
    self.sock = self._new_conn()
  File "/opt/python/urllib3/connection.py", line 212, in _new_conn
    raise ConnectTimeoutError(
urllib3.exceptions.ConnectTimeoutError: (<urllib3.connection.HTTPConnection object at 0x7ff4a836d240>, 'Connection to democracy.canterbury.gov.uk timed out. (connect timeout=None)')

The above exception was the direct cause of the following exception:

Traceback (most recent call last):
  File "/opt/python/requests/adapters.py", line 486, in send
    resp = conn.urlopen(
  File "/opt/python/urllib3/connectionpool.py", line 845, in urlopen
    retries = retries.increment(
  File "/opt/python/urllib3/util/retry.py", line 515, in increment
    raise MaxRetryError(_pool, url, reason) from reason  # type: ignore[arg-type]
urllib3.exceptions.MaxRetryError: HTTPConnectionPool(host='democracy.canterbury.gov.uk', port=80): Max retries exceeded with url: /mgWebService.asmx/GetCouncillorsByWard (Caused by ConnectTimeoutError(<urllib3.connection.HTTPConnection object at 0x7ff4a836d240>, 'Connection to democracy.canterbury.gov.uk timed out. (connect timeout=None)'))

During handling of the above exception, another exception occurred:

Traceback (most recent call last):
  File "/var/task/lgsf/aws_lambda/handlers.py", line 32, in scraper_worker_handler
    scraper.run(run_log)
  File "/var/task/lgsf/councillors/scrapers.py", line 200, in run
    wards = self.get_councillors()
  File "/var/task/lgsf/councillors/scrapers.py", line 219, in get_councillors
    req = self.get(
  File "/var/task/lgsf/scrapers/base.py", line 47, in get
    response = self.requests_session.get(
  File "/opt/python/requests/sessions.py", line 602, in get
    return self.request("GET", url, **kwargs)
  File "/opt/python/requests/sessions.py", line 589, in request
    resp = self.send(prep, **send_kwargs)
  File "/opt/python/requests/sessions.py", line 703, in send
    r = adapter.send(request, **kwargs)
  File "/opt/python/requests/adapters.py", line 507, in send
    raise ConnectTimeout(e, request=request)
requests.exceptions.ConnectTimeout: HTTPConnectionPool(host='democracy.canterbury.gov.uk', port=80): Max retries exceeded with url: /mgWebService.asmx/GetCouncillorsByWard (Caused by ConnectTimeoutError(<urllib3.connection.HTTPConnection object at 0x7ff4a836d240>, 'Connection to democracy.canterbury.gov.uk timed out. (connect timeout=None)'))
</dd>
      </div>
    </dl>
  </div>
  </div>

  <h3>Run log</h3>
  <pre>[09:27:58] Fetching Scraper for: CAT                              handlers.py:23
           Begin attempting to scrape: CAT                        handlers.py:27
[09:27:59] Deleting existing data...                                 base.py:251
           Getting all files in Councillors...                       base.py:203
           ...found 1 files in Councillors                           base.py:219
           Deleting batch no. 1 consisting of 1 files                base.py:230
[09:28:00] ...data deleted.                                          base.py:258
           Scraping from                                              base.py:41
           http://democracy.canterbury.gov.uk/mgWebService.asmx/GetCo           
           uncillorsByWard                                                      
[09:30:10] HTTPConnectionPool(host='democracy.canterbury.gov.uk', handlers.py:36
           port=80): Max retries exceeded with url:                             
           /mgWebService.asmx/GetCouncillorsByWard (Caused by                   
           ConnectTimeoutError(<urllib3.connection.HTTPConnection               
           object at 0x7ff4a836d240>, 'Connection to                            
           democracy.canterbury.gov.uk timed out. (connect                      
           timeout=None)'))                                                     
           Finished attempting to scrape: CAT                        base.py:339
</pre>
  

  


  <h2 id="2024-03-01-08-39">2024-03-01</h2>
  <div class="ds-card">
  <div class="ds-card-body">
    <dl class="ds-descriptions">
      <div>
        <dt>Duration</dt>
        <dd>131 seconds</dd>
      </div>
      <div>
        <dt>Start</dt>
        <dd>2024-03-01 08:39:40.587917</dd>
      </div>
      <div>
        <dt>End</dt>
        <dd>2024-03-01 08:41:52.081394</dd>
      </div>
      <div>
        <dt>Status code</dt>
        <dd>1</dd>
      </div>
      <div>
        <dt>Error</dt>
        <dd>Traceback (most recent call last):
  File "/opt/python/urllib3/connection.py", line 203, in _new_conn
    sock = connection.create_connection(
  File "/opt/python/urllib3/util/connection.py", line 85, in create_connection
    raise err
  File "/opt/python/urllib3/util/connection.py", line 73, in create_connection
    sock.connect(sa)
TimeoutError: [Errno 110] Connection timed out

The above exception was the direct cause of the following exception:

Traceback (most recent call last):
  File "/opt/python/urllib3/connectionpool.py", line 791, in urlopen
    response = self._make_request(
  File "/opt/python/urllib3/connectionpool.py", line 497, in _make_request
    conn.request(
  File "/opt/python/urllib3/connection.py", line 395, in request
    self.endheaders()
  File "/var/lang/lib/python3.10/http/client.py", line 1278, in endheaders
    self._send_output(message_body, encode_chunked=encode_chunked)
  File "/var/lang/lib/python3.10/http/client.py", line 1038, in _send_output
    self.send(msg)
  File "/var/lang/lib/python3.10/http/client.py", line 976, in send
    self.connect()
  File "/opt/python/urllib3/connection.py", line 243, in connect
    self.sock = self._new_conn()
  File "/opt/python/urllib3/connection.py", line 212, in _new_conn
    raise ConnectTimeoutError(
urllib3.exceptions.ConnectTimeoutError: (<urllib3.connection.HTTPConnection object at 0x7f6b9aac6260>, 'Connection to democracy.canterbury.gov.uk timed out. (connect timeout=None)')

The above exception was the direct cause of the following exception:

Traceback (most recent call last):
  File "/opt/python/requests/adapters.py", line 486, in send
    resp = conn.urlopen(
  File "/opt/python/urllib3/connectionpool.py", line 845, in urlopen
    retries = retries.increment(
  File "/opt/python/urllib3/util/retry.py", line 515, in increment
    raise MaxRetryError(_pool, url, reason) from reason  # type: ignore[arg-type]
urllib3.exceptions.MaxRetryError: HTTPConnectionPool(host='democracy.canterbury.gov.uk', port=80): Max retries exceeded with url: /mgWebService.asmx/GetCouncillorsByWard (Caused by ConnectTimeoutError(<urllib3.connection.HTTPConnection object at 0x7f6b9aac6260>, 'Connection to democracy.canterbury.gov.uk timed out. (connect timeout=None)'))

During handling of the above exception, another exception occurred:

Traceback (most recent call last):
  File "/var/task/lgsf/aws_lambda/handlers.py", line 32, in scraper_worker_handler
    scraper.run(run_log)
  File "/var/task/lgsf/councillors/scrapers.py", line 200, in run
    wards = self.get_councillors()
  File "/var/task/lgsf/councillors/scrapers.py", line 219, in get_councillors
    req = self.get(
  File "/var/task/lgsf/scrapers/base.py", line 47, in get
    response = self.requests_session.get(
  File "/opt/python/requests/sessions.py", line 602, in get
    return self.request("GET", url, **kwargs)
  File "/opt/python/requests/sessions.py", line 589, in request
    resp = self.send(prep, **send_kwargs)
  File "/opt/python/requests/sessions.py", line 703, in send
    r = adapter.send(request, **kwargs)
  File "/opt/python/requests/adapters.py", line 507, in send
    raise ConnectTimeout(e, request=request)
requests.exceptions.ConnectTimeout: HTTPConnectionPool(host='democracy.canterbury.gov.uk', port=80): Max retries exceeded with url: /mgWebService.asmx/GetCouncillorsByWard (Caused by ConnectTimeoutError(<urllib3.connection.HTTPConnection object at 0x7f6b9aac6260>, 'Connection to democracy.canterbury.gov.uk timed out. (connect timeout=None)'))
</dd>
      </div>
    </dl>
  </div>
  </div>

  <h3>Run log</h3>
  <pre>[08:39:40] Fetching Scraper for: CAT                              handlers.py:23
           Begin attempting to scrape: CAT                        handlers.py:27
           Deleting existing data...                                 base.py:251
[08:39:41] Getting all files in Councillors...                       base.py:203
           ...found 1 files in Councillors                           base.py:219
           Deleting batch no. 1 consisting of 1 files                base.py:230
[08:39:42] ...data deleted.                                          base.py:258
           Scraping from                                              base.py:41
           http://democracy.canterbury.gov.uk/mgWebService.asmx/GetCo           
           uncillorsByWard                                                      
[08:41:51] HTTPConnectionPool(host='democracy.canterbury.gov.uk', handlers.py:36
           port=80): Max retries exceeded with url:                             
           /mgWebService.asmx/GetCouncillorsByWard (Caused by                   
           ConnectTimeoutError(<urllib3.connection.HTTPConnection               
           object at 0x7f6b9aac6260>, 'Connection to                            
           democracy.canterbury.gov.uk timed out. (connect                      
           timeout=None)'))                                                     
[08:41:52] Finished attempting to scrape: CAT                        base.py:339
</pre>
  

  


  <h2 id="2024-02-29-09-40">2024-02-29</h2>
  <div class="ds-card">
  <div class="ds-card-body">
    <dl class="ds-descriptions">
      <div>
        <dt>Duration</dt>
        <dd>132 seconds</dd>
      </div>
      <div>
        <dt>Start</dt>
        <dd>2024-02-29 09:40:51.836329</dd>
      </div>
      <div>
        <dt>End</dt>
        <dd>2024-02-29 09:43:04.539972</dd>
      </div>
      <div>
        <dt>Status code</dt>
        <dd>1</dd>
      </div>
      <div>
        <dt>Error</dt>
        <dd>Traceback (most recent call last):
  File "/opt/python/urllib3/connection.py", line 203, in _new_conn
    sock = connection.create_connection(
  File "/opt/python/urllib3/util/connection.py", line 85, in create_connection
    raise err
  File "/opt/python/urllib3/util/connection.py", line 73, in create_connection
    sock.connect(sa)
TimeoutError: [Errno 110] Connection timed out

The above exception was the direct cause of the following exception:

Traceback (most recent call last):
  File "/opt/python/urllib3/connectionpool.py", line 791, in urlopen
    response = self._make_request(
  File "/opt/python/urllib3/connectionpool.py", line 497, in _make_request
    conn.request(
  File "/opt/python/urllib3/connection.py", line 395, in request
    self.endheaders()
  File "/var/lang/lib/python3.10/http/client.py", line 1278, in endheaders
    self._send_output(message_body, encode_chunked=encode_chunked)
  File "/var/lang/lib/python3.10/http/client.py", line 1038, in _send_output
    self.send(msg)
  File "/var/lang/lib/python3.10/http/client.py", line 976, in send
    self.connect()
  File "/opt/python/urllib3/connection.py", line 243, in connect
    self.sock = self._new_conn()
  File "/opt/python/urllib3/connection.py", line 212, in _new_conn
    raise ConnectTimeoutError(
urllib3.exceptions.ConnectTimeoutError: (<urllib3.connection.HTTPConnection object at 0x7f5bbdc6e410>, 'Connection to democracy.canterbury.gov.uk timed out. (connect timeout=None)')

The above exception was the direct cause of the following exception:

Traceback (most recent call last):
  File "/opt/python/requests/adapters.py", line 486, in send
    resp = conn.urlopen(
  File "/opt/python/urllib3/connectionpool.py", line 845, in urlopen
    retries = retries.increment(
  File "/opt/python/urllib3/util/retry.py", line 515, in increment
    raise MaxRetryError(_pool, url, reason) from reason  # type: ignore[arg-type]
urllib3.exceptions.MaxRetryError: HTTPConnectionPool(host='democracy.canterbury.gov.uk', port=80): Max retries exceeded with url: /mgWebService.asmx/GetCouncillorsByWard (Caused by ConnectTimeoutError(<urllib3.connection.HTTPConnection object at 0x7f5bbdc6e410>, 'Connection to democracy.canterbury.gov.uk timed out. (connect timeout=None)'))

During handling of the above exception, another exception occurred:

Traceback (most recent call last):
  File "/var/task/lgsf/aws_lambda/handlers.py", line 32, in scraper_worker_handler
    scraper.run(run_log)
  File "/var/task/lgsf/councillors/scrapers.py", line 200, in run
    wards = self.get_councillors()
  File "/var/task/lgsf/councillors/scrapers.py", line 219, in get_councillors
    req = self.get(
  File "/var/task/lgsf/scrapers/base.py", line 47, in get
    response = self.requests_session.get(
  File "/opt/python/requests/sessions.py", line 602, in get
    return self.request("GET", url, **kwargs)
  File "/opt/python/requests/sessions.py", line 589, in request
    resp = self.send(prep, **send_kwargs)
  File "/opt/python/requests/sessions.py", line 703, in send
    r = adapter.send(request, **kwargs)
  File "/opt/python/requests/adapters.py", line 507, in send
    raise ConnectTimeout(e, request=request)
requests.exceptions.ConnectTimeout: HTTPConnectionPool(host='democracy.canterbury.gov.uk', port=80): Max retries exceeded with url: /mgWebService.asmx/GetCouncillorsByWard (Caused by ConnectTimeoutError(<urllib3.connection.HTTPConnection object at 0x7f5bbdc6e410>, 'Connection to democracy.canterbury.gov.uk timed out. (connect timeout=None)'))
</dd>
      </div>
    </dl>
  </div>
  </div>

  <h3>Run log</h3>
  <pre>[09:40:51] Fetching Scraper for: CAT                              handlers.py:23
           Begin attempting to scrape: CAT                        handlers.py:27
[09:40:52] Deleting existing data...                                 base.py:251
           Getting all files in Councillors...                       base.py:203
           ...found 1 files in Councillors                           base.py:219
           Deleting batch no. 1 consisting of 1 files                base.py:230
[09:40:53] ...data deleted.                                          base.py:258
           Scraping from                                              base.py:41
           http://democracy.canterbury.gov.uk/mgWebService.asmx/GetCo           
           uncillorsByWard                                                      
[09:43:04] HTTPConnectionPool(host='democracy.canterbury.gov.uk', handlers.py:36
           port=80): Max retries exceeded with url:                             
           /mgWebService.asmx/GetCouncillorsByWard (Caused by                   
           ConnectTimeoutError(<urllib3.connection.HTTPConnection               
           object at 0x7f5bbdc6e410>, 'Connection to                            
           democracy.canterbury.gov.uk timed out. (connect                      
           timeout=None)'))                                                     
           Finished attempting to scrape: CAT                        base.py:339
</pre>
  

  


  <h2 id="2024-02-28-10-36">2024-02-28</h2>
  <div class="ds-card">
  <div class="ds-card-body">
    <dl class="ds-descriptions">
      <div>
        <dt>Duration</dt>
        <dd>133 seconds</dd>
      </div>
      <div>
        <dt>Start</dt>
        <dd>2024-02-28 10:36:23.512034</dd>
      </div>
      <div>
        <dt>End</dt>
        <dd>2024-02-28 10:38:36.981822</dd>
      </div>
      <div>
        <dt>Status code</dt>
        <dd>1</dd>
      </div>
      <div>
        <dt>Error</dt>
        <dd>Traceback (most recent call last):
  File "/opt/python/urllib3/connection.py", line 203, in _new_conn
    sock = connection.create_connection(
  File "/opt/python/urllib3/util/connection.py", line 85, in create_connection
    raise err
  File "/opt/python/urllib3/util/connection.py", line 73, in create_connection
    sock.connect(sa)
TimeoutError: [Errno 110] Connection timed out

The above exception was the direct cause of the following exception:

Traceback (most recent call last):
  File "/opt/python/urllib3/connectionpool.py", line 791, in urlopen
    response = self._make_request(
  File "/opt/python/urllib3/connectionpool.py", line 497, in _make_request
    conn.request(
  File "/opt/python/urllib3/connection.py", line 395, in request
    self.endheaders()
  File "/var/lang/lib/python3.10/http/client.py", line 1278, in endheaders
    self._send_output(message_body, encode_chunked=encode_chunked)
  File "/var/lang/lib/python3.10/http/client.py", line 1038, in _send_output
    self.send(msg)
  File "/var/lang/lib/python3.10/http/client.py", line 976, in send
    self.connect()
  File "/opt/python/urllib3/connection.py", line 243, in connect
    self.sock = self._new_conn()
  File "/opt/python/urllib3/connection.py", line 212, in _new_conn
    raise ConnectTimeoutError(
urllib3.exceptions.ConnectTimeoutError: (<urllib3.connection.HTTPConnection object at 0x7ff6266df5e0>, 'Connection to democracy.canterbury.gov.uk timed out. (connect timeout=None)')

The above exception was the direct cause of the following exception:

Traceback (most recent call last):
  File "/opt/python/requests/adapters.py", line 486, in send
    resp = conn.urlopen(
  File "/opt/python/urllib3/connectionpool.py", line 845, in urlopen
    retries = retries.increment(
  File "/opt/python/urllib3/util/retry.py", line 515, in increment
    raise MaxRetryError(_pool, url, reason) from reason  # type: ignore[arg-type]
urllib3.exceptions.MaxRetryError: HTTPConnectionPool(host='democracy.canterbury.gov.uk', port=80): Max retries exceeded with url: /mgWebService.asmx/GetCouncillorsByWard (Caused by ConnectTimeoutError(<urllib3.connection.HTTPConnection object at 0x7ff6266df5e0>, 'Connection to democracy.canterbury.gov.uk timed out. (connect timeout=None)'))

During handling of the above exception, another exception occurred:

Traceback (most recent call last):
  File "/var/task/lgsf/aws_lambda/handlers.py", line 32, in scraper_worker_handler
    scraper.run(run_log)
  File "/var/task/lgsf/councillors/scrapers.py", line 200, in run
    wards = self.get_councillors()
  File "/var/task/lgsf/councillors/scrapers.py", line 219, in get_councillors
    req = self.get(
  File "/var/task/lgsf/scrapers/base.py", line 47, in get
    response = self.requests_session.get(
  File "/opt/python/requests/sessions.py", line 602, in get
    return self.request("GET", url, **kwargs)
  File "/opt/python/requests/sessions.py", line 589, in request
    resp = self.send(prep, **send_kwargs)
  File "/opt/python/requests/sessions.py", line 703, in send
    r = adapter.send(request, **kwargs)
  File "/opt/python/requests/adapters.py", line 507, in send
    raise ConnectTimeout(e, request=request)
requests.exceptions.ConnectTimeout: HTTPConnectionPool(host='democracy.canterbury.gov.uk', port=80): Max retries exceeded with url: /mgWebService.asmx/GetCouncillorsByWard (Caused by ConnectTimeoutError(<urllib3.connection.HTTPConnection object at 0x7ff6266df5e0>, 'Connection to democracy.canterbury.gov.uk timed out. (connect timeout=None)'))
</dd>
      </div>
    </dl>
  </div>
  </div>

  <h3>Run log</h3>
  <pre>[10:36:23] Fetching Scraper for: CAT                              handlers.py:23
           Begin attempting to scrape: CAT                        handlers.py:27
           Deleting existing data...                                 base.py:251
[10:36:24] Getting all files in Councillors...                       base.py:203
           ...found 1 files in Councillors                           base.py:219
           Deleting batch no. 1 consisting of 1 files                base.py:230
[10:36:25] ...data deleted.                                          base.py:258
           Scraping from                                              base.py:41
           http://democracy.canterbury.gov.uk/mgWebService.asmx/GetCo           
           uncillorsByWard                                                      
[10:38:36] HTTPConnectionPool(host='democracy.canterbury.gov.uk', handlers.py:36
           port=80): Max retries exceeded with url:                             
           /mgWebService.asmx/GetCouncillorsByWard (Caused by                   
           ConnectTimeoutError(<urllib3.connection.HTTPConnection               
           object at 0x7ff6266df5e0>, 'Connection to                            
           democracy.canterbury.gov.uk timed out. (connect                      
           timeout=None)'))                                                     
           Finished attempting to scrape: CAT                        base.py:339
</pre>
  

  


  <h2 id="2024-02-27-08-35">2024-02-27</h2>
  <div class="ds-card">
  <div class="ds-card-body">
    <dl class="ds-descriptions">
      <div>
        <dt>Duration</dt>
        <dd>131 seconds</dd>
      </div>
      <div>
        <dt>Start</dt>
        <dd>2024-02-27 08:35:35.533676</dd>
      </div>
      <div>
        <dt>End</dt>
        <dd>2024-02-27 08:37:47.059717</dd>
      </div>
      <div>
        <dt>Status code</dt>
        <dd>1</dd>
      </div>
      <div>
        <dt>Error</dt>
        <dd>Traceback (most recent call last):
  File "/opt/python/urllib3/connection.py", line 203, in _new_conn
    sock = connection.create_connection(
  File "/opt/python/urllib3/util/connection.py", line 85, in create_connection
    raise err
  File "/opt/python/urllib3/util/connection.py", line 73, in create_connection
    sock.connect(sa)
TimeoutError: [Errno 110] Connection timed out

The above exception was the direct cause of the following exception:

Traceback (most recent call last):
  File "/opt/python/urllib3/connectionpool.py", line 791, in urlopen
    response = self._make_request(
  File "/opt/python/urllib3/connectionpool.py", line 497, in _make_request
    conn.request(
  File "/opt/python/urllib3/connection.py", line 395, in request
    self.endheaders()
  File "/var/lang/lib/python3.10/http/client.py", line 1278, in endheaders
    self._send_output(message_body, encode_chunked=encode_chunked)
  File "/var/lang/lib/python3.10/http/client.py", line 1038, in _send_output
    self.send(msg)
  File "/var/lang/lib/python3.10/http/client.py", line 976, in send
    self.connect()
  File "/opt/python/urllib3/connection.py", line 243, in connect
    self.sock = self._new_conn()
  File "/opt/python/urllib3/connection.py", line 212, in _new_conn
    raise ConnectTimeoutError(
urllib3.exceptions.ConnectTimeoutError: (<urllib3.connection.HTTPConnection object at 0x7fa92006af20>, 'Connection to democracy.canterbury.gov.uk timed out. (connect timeout=None)')

The above exception was the direct cause of the following exception:

Traceback (most recent call last):
  File "/opt/python/requests/adapters.py", line 486, in send
    resp = conn.urlopen(
  File "/opt/python/urllib3/connectionpool.py", line 845, in urlopen
    retries = retries.increment(
  File "/opt/python/urllib3/util/retry.py", line 515, in increment
    raise MaxRetryError(_pool, url, reason) from reason  # type: ignore[arg-type]
urllib3.exceptions.MaxRetryError: HTTPConnectionPool(host='democracy.canterbury.gov.uk', port=80): Max retries exceeded with url: /mgWebService.asmx/GetCouncillorsByWard (Caused by ConnectTimeoutError(<urllib3.connection.HTTPConnection object at 0x7fa92006af20>, 'Connection to democracy.canterbury.gov.uk timed out. (connect timeout=None)'))

During handling of the above exception, another exception occurred:

Traceback (most recent call last):
  File "/var/task/lgsf/aws_lambda/handlers.py", line 32, in scraper_worker_handler
    scraper.run(run_log)
  File "/var/task/lgsf/councillors/scrapers.py", line 200, in run
    wards = self.get_councillors()
  File "/var/task/lgsf/councillors/scrapers.py", line 219, in get_councillors
    req = self.get(
  File "/var/task/lgsf/scrapers/base.py", line 47, in get
    response = self.requests_session.get(
  File "/opt/python/requests/sessions.py", line 602, in get
    return self.request("GET", url, **kwargs)
  File "/opt/python/requests/sessions.py", line 589, in request
    resp = self.send(prep, **send_kwargs)
  File "/opt/python/requests/sessions.py", line 703, in send
    r = adapter.send(request, **kwargs)
  File "/opt/python/requests/adapters.py", line 507, in send
    raise ConnectTimeout(e, request=request)
requests.exceptions.ConnectTimeout: HTTPConnectionPool(host='democracy.canterbury.gov.uk', port=80): Max retries exceeded with url: /mgWebService.asmx/GetCouncillorsByWard (Caused by ConnectTimeoutError(<urllib3.connection.HTTPConnection object at 0x7fa92006af20>, 'Connection to democracy.canterbury.gov.uk timed out. (connect timeout=None)'))
</dd>
      </div>
    </dl>
  </div>
  </div>

  <h3>Run log</h3>
  <pre>[08:35:35] Fetching Scraper for: CAT                              handlers.py:23
           Begin attempting to scrape: CAT                        handlers.py:27
           Deleting existing data...                                 base.py:251
[08:35:36] Getting all files in Councillors...                       base.py:203
           ...found 1 files in Councillors                           base.py:219
           Deleting batch no. 1 consisting of 1 files                base.py:230
[08:35:37] ...data deleted.                                          base.py:258
           Scraping from                                              base.py:41
           http://democracy.canterbury.gov.uk/mgWebService.asmx/GetCo           
           uncillorsByWard                                                      
[08:37:46] HTTPConnectionPool(host='democracy.canterbury.gov.uk', handlers.py:36
           port=80): Max retries exceeded with url:                             
           /mgWebService.asmx/GetCouncillorsByWard (Caused by                   
           ConnectTimeoutError(<urllib3.connection.HTTPConnection               
           object at 0x7fa92006af20>, 'Connection to                            
           democracy.canterbury.gov.uk timed out. (connect                      
           timeout=None)'))                                                     
[08:37:47] Finished attempting to scrape: CAT                        base.py:339
</pre>
  

  


  <h2 id="2024-02-26-09-08">2024-02-26</h2>
  <div class="ds-card">
  <div class="ds-card-body">
    <dl class="ds-descriptions">
      <div>
        <dt>Duration</dt>
        <dd>132 seconds</dd>
      </div>
      <div>
        <dt>Start</dt>
        <dd>2024-02-26 09:08:32.521898</dd>
      </div>
      <div>
        <dt>End</dt>
        <dd>2024-02-26 09:10:44.995699</dd>
      </div>
      <div>
        <dt>Status code</dt>
        <dd>1</dd>
      </div>
      <div>
        <dt>Error</dt>
        <dd>Traceback (most recent call last):
  File "/opt/python/urllib3/connection.py", line 203, in _new_conn
    sock = connection.create_connection(
  File "/opt/python/urllib3/util/connection.py", line 85, in create_connection
    raise err
  File "/opt/python/urllib3/util/connection.py", line 73, in create_connection
    sock.connect(sa)
TimeoutError: [Errno 110] Connection timed out

The above exception was the direct cause of the following exception:

Traceback (most recent call last):
  File "/opt/python/urllib3/connectionpool.py", line 791, in urlopen
    response = self._make_request(
  File "/opt/python/urllib3/connectionpool.py", line 497, in _make_request
    conn.request(
  File "/opt/python/urllib3/connection.py", line 395, in request
    self.endheaders()
  File "/var/lang/lib/python3.10/http/client.py", line 1278, in endheaders
    self._send_output(message_body, encode_chunked=encode_chunked)
  File "/var/lang/lib/python3.10/http/client.py", line 1038, in _send_output
    self.send(msg)
  File "/var/lang/lib/python3.10/http/client.py", line 976, in send
    self.connect()
  File "/opt/python/urllib3/connection.py", line 243, in connect
    self.sock = self._new_conn()
  File "/opt/python/urllib3/connection.py", line 212, in _new_conn
    raise ConnectTimeoutError(
urllib3.exceptions.ConnectTimeoutError: (<urllib3.connection.HTTPConnection object at 0x7efc4304c1c0>, 'Connection to democracy.canterbury.gov.uk timed out. (connect timeout=None)')

The above exception was the direct cause of the following exception:

Traceback (most recent call last):
  File "/opt/python/requests/adapters.py", line 486, in send
    resp = conn.urlopen(
  File "/opt/python/urllib3/connectionpool.py", line 845, in urlopen
    retries = retries.increment(
  File "/opt/python/urllib3/util/retry.py", line 515, in increment
    raise MaxRetryError(_pool, url, reason) from reason  # type: ignore[arg-type]
urllib3.exceptions.MaxRetryError: HTTPConnectionPool(host='democracy.canterbury.gov.uk', port=80): Max retries exceeded with url: /mgWebService.asmx/GetCouncillorsByWard (Caused by ConnectTimeoutError(<urllib3.connection.HTTPConnection object at 0x7efc4304c1c0>, 'Connection to democracy.canterbury.gov.uk timed out. (connect timeout=None)'))

During handling of the above exception, another exception occurred:

Traceback (most recent call last):
  File "/var/task/lgsf/aws_lambda/handlers.py", line 32, in scraper_worker_handler
    scraper.run(run_log)
  File "/var/task/lgsf/councillors/scrapers.py", line 200, in run
    wards = self.get_councillors()
  File "/var/task/lgsf/councillors/scrapers.py", line 219, in get_councillors
    req = self.get(
  File "/var/task/lgsf/scrapers/base.py", line 47, in get
    response = self.requests_session.get(
  File "/opt/python/requests/sessions.py", line 602, in get
    return self.request("GET", url, **kwargs)
  File "/opt/python/requests/sessions.py", line 589, in request
    resp = self.send(prep, **send_kwargs)
  File "/opt/python/requests/sessions.py", line 703, in send
    r = adapter.send(request, **kwargs)
  File "/opt/python/requests/adapters.py", line 507, in send
    raise ConnectTimeout(e, request=request)
requests.exceptions.ConnectTimeout: HTTPConnectionPool(host='democracy.canterbury.gov.uk', port=80): Max retries exceeded with url: /mgWebService.asmx/GetCouncillorsByWard (Caused by ConnectTimeoutError(<urllib3.connection.HTTPConnection object at 0x7efc4304c1c0>, 'Connection to democracy.canterbury.gov.uk timed out. (connect timeout=None)'))
</dd>
      </div>
    </dl>
  </div>
  </div>

  <h3>Run log</h3>
  <pre>[09:08:32] Fetching Scraper for: CAT                              handlers.py:23
           Begin attempting to scrape: CAT                        handlers.py:27
           Deleting existing data...                                 base.py:251
[09:08:33] Getting all files in Councillors...                       base.py:203
           ...found 1 files in Councillors                           base.py:219
           Deleting batch no. 1 consisting of 1 files                base.py:230
[09:08:34] ...data deleted.                                          base.py:258
           Scraping from                                              base.py:41
           http://democracy.canterbury.gov.uk/mgWebService.asmx/GetCo           
           uncillorsByWard                                                      
[09:10:44] HTTPConnectionPool(host='democracy.canterbury.gov.uk', handlers.py:36
           port=80): Max retries exceeded with url:                             
           /mgWebService.asmx/GetCouncillorsByWard (Caused by                   
           ConnectTimeoutError(<urllib3.connection.HTTPConnection               
           object at 0x7efc4304c1c0>, 'Connection to                            
           democracy.canterbury.gov.uk timed out. (connect                      
           timeout=None)'))                                                     
           Finished attempting to scrape: CAT                        base.py:339
</pre>
  


      </main>
      <footer class="ds-footer">
        <div class="ds-block-centered ds-text-centered ds-stack">
          <div class="ds-cluster-center">
            <ul>
              <li><a href="/lgsf-dashboard/api/failing.json">Failing JSON</a></li>
            </ul>
          </div>
          <div class="ds-copyright">
            <a href="https://democracyclub.org.uk/">
              <img src="https://DemocracyClub.github.io/design-system/images/logo_white_text.svg" alt="Democracy Club Home" />
            </a>
            <p>Copyright © 2021 Democracy Club</p>
            <p>Community Interest Company</p>
            <p>Company No: <a href="https://beta.companieshouse.gov.uk/company/09461226">09461226</a></p>
          </div>
        </div>
      </footer>
    </div>
  </body>
