<!doctype html>
<html>
  <head>
    <title>LGSF Dashboard</title>
    <link rel="stylesheet"  href="/lgsf-dashboard/assets/css/styles.css">
    <link rel="shortcut icon" href="https://democracyclub.org.uk/static/images/logo_icon.png">
  </head>
  <body>
    <div class="ds-page">
      <a class="ds-skip-link" href="#main">skip to content</a>

      <header class="ds-header">
        <a class="ds-skip-link" href="#main">skip to content</a>
        <a class="ds-logo" href="/lgsf-dashboard/">
          <img src="https://DemocracyClub.github.io/design-system/images/logo_icon.svg" alt="" />
          <span>LGSF Logbooks</span>
        </a>

      </header>


      <main id="main" tabindex="-1" class="ds-stack">

        
<style>

    pre {
        height:400px;
        overflow-x: scroll;
        width:100%
    }
</style>




  


  <h2 id="2024-04-23-08-49">2024-04-23</h2>
  <div class="ds-card">
  <div class="ds-card-body">
    <dl class="ds-descriptions">
      <div>
        <dt>Duration</dt>
        <dd>133 seconds</dd>
      </div>
      <div>
        <dt>Start</dt>
        <dd>2024-04-23 08:49:29.617588</dd>
      </div>
      <div>
        <dt>End</dt>
        <dd>2024-04-23 08:51:42.671713</dd>
      </div>
      <div>
        <dt>Status code</dt>
        <dd>1</dd>
      </div>
      <div>
        <dt>Error</dt>
        <dd>Traceback (most recent call last):
  File "/opt/python/urllib3/connection.py", line 203, in _new_conn
    sock = connection.create_connection(
  File "/opt/python/urllib3/util/connection.py", line 85, in create_connection
    raise err
  File "/opt/python/urllib3/util/connection.py", line 73, in create_connection
    sock.connect(sa)
TimeoutError: [Errno 110] Connection timed out

The above exception was the direct cause of the following exception:

Traceback (most recent call last):
  File "/opt/python/urllib3/connectionpool.py", line 791, in urlopen
    response = self._make_request(
  File "/opt/python/urllib3/connectionpool.py", line 497, in _make_request
    conn.request(
  File "/opt/python/urllib3/connection.py", line 395, in request
    self.endheaders()
  File "/var/lang/lib/python3.10/http/client.py", line 1278, in endheaders
    self._send_output(message_body, encode_chunked=encode_chunked)
  File "/var/lang/lib/python3.10/http/client.py", line 1038, in _send_output
    self.send(msg)
  File "/var/lang/lib/python3.10/http/client.py", line 976, in send
    self.connect()
  File "/opt/python/urllib3/connection.py", line 243, in connect
    self.sock = self._new_conn()
  File "/opt/python/urllib3/connection.py", line 212, in _new_conn
    raise ConnectTimeoutError(
urllib3.exceptions.ConnectTimeoutError: (<urllib3.connection.HTTPConnection object at 0x7f0b5eaf7d00>, 'Connection to democracy.canterbury.gov.uk timed out. (connect timeout=None)')

The above exception was the direct cause of the following exception:

Traceback (most recent call last):
  File "/opt/python/requests/adapters.py", line 486, in send
    resp = conn.urlopen(
  File "/opt/python/urllib3/connectionpool.py", line 845, in urlopen
    retries = retries.increment(
  File "/opt/python/urllib3/util/retry.py", line 515, in increment
    raise MaxRetryError(_pool, url, reason) from reason  # type: ignore[arg-type]
urllib3.exceptions.MaxRetryError: HTTPConnectionPool(host='democracy.canterbury.gov.uk', port=80): Max retries exceeded with url: /mgWebService.asmx/GetCouncillorsByWard (Caused by ConnectTimeoutError(<urllib3.connection.HTTPConnection object at 0x7f0b5eaf7d00>, 'Connection to democracy.canterbury.gov.uk timed out. (connect timeout=None)'))

During handling of the above exception, another exception occurred:

Traceback (most recent call last):
  File "/var/task/lgsf/aws_lambda/handlers.py", line 32, in scraper_worker_handler
    scraper.run(run_log)
  File "/var/task/lgsf/councillors/scrapers.py", line 200, in run
    wards = self.get_councillors()
  File "/var/task/lgsf/councillors/scrapers.py", line 219, in get_councillors
    req = self.get(
  File "/var/task/lgsf/scrapers/base.py", line 47, in get
    response = self.requests_session.get(
  File "/opt/python/requests/sessions.py", line 602, in get
    return self.request("GET", url, **kwargs)
  File "/opt/python/requests/sessions.py", line 589, in request
    resp = self.send(prep, **send_kwargs)
  File "/opt/python/requests/sessions.py", line 703, in send
    r = adapter.send(request, **kwargs)
  File "/opt/python/requests/adapters.py", line 507, in send
    raise ConnectTimeout(e, request=request)
requests.exceptions.ConnectTimeout: HTTPConnectionPool(host='democracy.canterbury.gov.uk', port=80): Max retries exceeded with url: /mgWebService.asmx/GetCouncillorsByWard (Caused by ConnectTimeoutError(<urllib3.connection.HTTPConnection object at 0x7f0b5eaf7d00>, 'Connection to democracy.canterbury.gov.uk timed out. (connect timeout=None)'))
</dd>
      </div>
    </dl>
  </div>
  </div>

  <h3>Run log</h3>
  <pre>[08:49:29] Fetching Scraper for: CAT                              handlers.py:23
           Begin attempting to scrape: CAT                        handlers.py:27
           Deleting existing data...                                 base.py:251
[08:49:30] Getting all files in Councillors...                       base.py:203
           ...found 1 files in Councillors                           base.py:219
           Deleting batch no. 1 consisting of 1 files                base.py:230
[08:49:31] ...data deleted.                                          base.py:258
           Scraping from                                              base.py:41
           http://democracy.canterbury.gov.uk/mgWebService.asmx/GetCo           
           uncillorsByWard                                                      
[08:51:42] HTTPConnectionPool(host='democracy.canterbury.gov.uk', handlers.py:36
           port=80): Max retries exceeded with url:                             
           /mgWebService.asmx/GetCouncillorsByWard (Caused by                   
           ConnectTimeoutError(<urllib3.connection.HTTPConnection               
           object at 0x7f0b5eaf7d00>, 'Connection to                            
           democracy.canterbury.gov.uk timed out. (connect                      
           timeout=None)'))                                                     
           Finished attempting to scrape: CAT                        base.py:339
</pre>
  

  


  <h2 id="2024-04-22-08-59">2024-04-22</h2>
  <div class="ds-card">
  <div class="ds-card-body">
    <dl class="ds-descriptions">
      <div>
        <dt>Duration</dt>
        <dd>132 seconds</dd>
      </div>
      <div>
        <dt>Start</dt>
        <dd>2024-04-22 08:59:03.895172</dd>
      </div>
      <div>
        <dt>End</dt>
        <dd>2024-04-22 09:01:16.023489</dd>
      </div>
      <div>
        <dt>Status code</dt>
        <dd>1</dd>
      </div>
      <div>
        <dt>Error</dt>
        <dd>Traceback (most recent call last):
  File "/opt/python/urllib3/connection.py", line 203, in _new_conn
    sock = connection.create_connection(
  File "/opt/python/urllib3/util/connection.py", line 85, in create_connection
    raise err
  File "/opt/python/urllib3/util/connection.py", line 73, in create_connection
    sock.connect(sa)
TimeoutError: [Errno 110] Connection timed out

The above exception was the direct cause of the following exception:

Traceback (most recent call last):
  File "/opt/python/urllib3/connectionpool.py", line 791, in urlopen
    response = self._make_request(
  File "/opt/python/urllib3/connectionpool.py", line 497, in _make_request
    conn.request(
  File "/opt/python/urllib3/connection.py", line 395, in request
    self.endheaders()
  File "/var/lang/lib/python3.10/http/client.py", line 1278, in endheaders
    self._send_output(message_body, encode_chunked=encode_chunked)
  File "/var/lang/lib/python3.10/http/client.py", line 1038, in _send_output
    self.send(msg)
  File "/var/lang/lib/python3.10/http/client.py", line 976, in send
    self.connect()
  File "/opt/python/urllib3/connection.py", line 243, in connect
    self.sock = self._new_conn()
  File "/opt/python/urllib3/connection.py", line 212, in _new_conn
    raise ConnectTimeoutError(
urllib3.exceptions.ConnectTimeoutError: (<urllib3.connection.HTTPConnection object at 0x7f5cab546f80>, 'Connection to democracy.canterbury.gov.uk timed out. (connect timeout=None)')

The above exception was the direct cause of the following exception:

Traceback (most recent call last):
  File "/opt/python/requests/adapters.py", line 486, in send
    resp = conn.urlopen(
  File "/opt/python/urllib3/connectionpool.py", line 845, in urlopen
    retries = retries.increment(
  File "/opt/python/urllib3/util/retry.py", line 515, in increment
    raise MaxRetryError(_pool, url, reason) from reason  # type: ignore[arg-type]
urllib3.exceptions.MaxRetryError: HTTPConnectionPool(host='democracy.canterbury.gov.uk', port=80): Max retries exceeded with url: /mgWebService.asmx/GetCouncillorsByWard (Caused by ConnectTimeoutError(<urllib3.connection.HTTPConnection object at 0x7f5cab546f80>, 'Connection to democracy.canterbury.gov.uk timed out. (connect timeout=None)'))

During handling of the above exception, another exception occurred:

Traceback (most recent call last):
  File "/var/task/lgsf/aws_lambda/handlers.py", line 32, in scraper_worker_handler
    scraper.run(run_log)
  File "/var/task/lgsf/councillors/scrapers.py", line 200, in run
    wards = self.get_councillors()
  File "/var/task/lgsf/councillors/scrapers.py", line 219, in get_councillors
    req = self.get(
  File "/var/task/lgsf/scrapers/base.py", line 47, in get
    response = self.requests_session.get(
  File "/opt/python/requests/sessions.py", line 602, in get
    return self.request("GET", url, **kwargs)
  File "/opt/python/requests/sessions.py", line 589, in request
    resp = self.send(prep, **send_kwargs)
  File "/opt/python/requests/sessions.py", line 703, in send
    r = adapter.send(request, **kwargs)
  File "/opt/python/requests/adapters.py", line 507, in send
    raise ConnectTimeout(e, request=request)
requests.exceptions.ConnectTimeout: HTTPConnectionPool(host='democracy.canterbury.gov.uk', port=80): Max retries exceeded with url: /mgWebService.asmx/GetCouncillorsByWard (Caused by ConnectTimeoutError(<urllib3.connection.HTTPConnection object at 0x7f5cab546f80>, 'Connection to democracy.canterbury.gov.uk timed out. (connect timeout=None)'))
</dd>
      </div>
    </dl>
  </div>
  </div>

  <h3>Run log</h3>
  <pre>[08:59:03] Fetching Scraper for: CAT                              handlers.py:23
           Begin attempting to scrape: CAT                        handlers.py:27
[08:59:04] Deleting existing data...                                 base.py:251
           Getting all files in Councillors...                       base.py:203
           ...found 1 files in Councillors                           base.py:219
           Deleting batch no. 1 consisting of 1 files                base.py:230
[08:59:05] ...data deleted.                                          base.py:258
           Scraping from                                              base.py:41
           http://democracy.canterbury.gov.uk/mgWebService.asmx/GetCo           
           uncillorsByWard                                                      
[09:01:15] HTTPConnectionPool(host='democracy.canterbury.gov.uk', handlers.py:36
           port=80): Max retries exceeded with url:                             
           /mgWebService.asmx/GetCouncillorsByWard (Caused by                   
           ConnectTimeoutError(<urllib3.connection.HTTPConnection               
           object at 0x7f5cab546f80>, 'Connection to                            
           democracy.canterbury.gov.uk timed out. (connect                      
           timeout=None)'))                                                     
[09:01:16] Finished attempting to scrape: CAT                        base.py:339
</pre>
  

  


  <h2 id="2024-04-21-09-53">2024-04-21</h2>
  <div class="ds-card">
  <div class="ds-card-body">
    <dl class="ds-descriptions">
      <div>
        <dt>Duration</dt>
        <dd>132 seconds</dd>
      </div>
      <div>
        <dt>Start</dt>
        <dd>2024-04-21 09:53:03.937932</dd>
      </div>
      <div>
        <dt>End</dt>
        <dd>2024-04-21 09:55:16.606146</dd>
      </div>
      <div>
        <dt>Status code</dt>
        <dd>1</dd>
      </div>
      <div>
        <dt>Error</dt>
        <dd>Traceback (most recent call last):
  File "/opt/python/urllib3/connection.py", line 203, in _new_conn
    sock = connection.create_connection(
  File "/opt/python/urllib3/util/connection.py", line 85, in create_connection
    raise err
  File "/opt/python/urllib3/util/connection.py", line 73, in create_connection
    sock.connect(sa)
TimeoutError: [Errno 110] Connection timed out

The above exception was the direct cause of the following exception:

Traceback (most recent call last):
  File "/opt/python/urllib3/connectionpool.py", line 791, in urlopen
    response = self._make_request(
  File "/opt/python/urllib3/connectionpool.py", line 497, in _make_request
    conn.request(
  File "/opt/python/urllib3/connection.py", line 395, in request
    self.endheaders()
  File "/var/lang/lib/python3.10/http/client.py", line 1278, in endheaders
    self._send_output(message_body, encode_chunked=encode_chunked)
  File "/var/lang/lib/python3.10/http/client.py", line 1038, in _send_output
    self.send(msg)
  File "/var/lang/lib/python3.10/http/client.py", line 976, in send
    self.connect()
  File "/opt/python/urllib3/connection.py", line 243, in connect
    self.sock = self._new_conn()
  File "/opt/python/urllib3/connection.py", line 212, in _new_conn
    raise ConnectTimeoutError(
urllib3.exceptions.ConnectTimeoutError: (<urllib3.connection.HTTPConnection object at 0x7ffa7a8b5c60>, 'Connection to democracy.canterbury.gov.uk timed out. (connect timeout=None)')

The above exception was the direct cause of the following exception:

Traceback (most recent call last):
  File "/opt/python/requests/adapters.py", line 486, in send
    resp = conn.urlopen(
  File "/opt/python/urllib3/connectionpool.py", line 845, in urlopen
    retries = retries.increment(
  File "/opt/python/urllib3/util/retry.py", line 515, in increment
    raise MaxRetryError(_pool, url, reason) from reason  # type: ignore[arg-type]
urllib3.exceptions.MaxRetryError: HTTPConnectionPool(host='democracy.canterbury.gov.uk', port=80): Max retries exceeded with url: /mgWebService.asmx/GetCouncillorsByWard (Caused by ConnectTimeoutError(<urllib3.connection.HTTPConnection object at 0x7ffa7a8b5c60>, 'Connection to democracy.canterbury.gov.uk timed out. (connect timeout=None)'))

During handling of the above exception, another exception occurred:

Traceback (most recent call last):
  File "/var/task/lgsf/aws_lambda/handlers.py", line 32, in scraper_worker_handler
    scraper.run(run_log)
  File "/var/task/lgsf/councillors/scrapers.py", line 200, in run
    wards = self.get_councillors()
  File "/var/task/lgsf/councillors/scrapers.py", line 219, in get_councillors
    req = self.get(
  File "/var/task/lgsf/scrapers/base.py", line 47, in get
    response = self.requests_session.get(
  File "/opt/python/requests/sessions.py", line 602, in get
    return self.request("GET", url, **kwargs)
  File "/opt/python/requests/sessions.py", line 589, in request
    resp = self.send(prep, **send_kwargs)
  File "/opt/python/requests/sessions.py", line 703, in send
    r = adapter.send(request, **kwargs)
  File "/opt/python/requests/adapters.py", line 507, in send
    raise ConnectTimeout(e, request=request)
requests.exceptions.ConnectTimeout: HTTPConnectionPool(host='democracy.canterbury.gov.uk', port=80): Max retries exceeded with url: /mgWebService.asmx/GetCouncillorsByWard (Caused by ConnectTimeoutError(<urllib3.connection.HTTPConnection object at 0x7ffa7a8b5c60>, 'Connection to democracy.canterbury.gov.uk timed out. (connect timeout=None)'))
</dd>
      </div>
    </dl>
  </div>
  </div>

  <h3>Run log</h3>
  <pre>[09:53:03] Fetching Scraper for: CAT                              handlers.py:23
           Begin attempting to scrape: CAT                        handlers.py:27
[09:53:04] Deleting existing data...                                 base.py:251
           Getting all files in Councillors...                       base.py:203
           ...found 1 files in Councillors                           base.py:219
           Deleting batch no. 1 consisting of 1 files                base.py:230
[09:53:05] ...data deleted.                                          base.py:258
           Scraping from                                              base.py:41
           http://democracy.canterbury.gov.uk/mgWebService.asmx/GetCo           
           uncillorsByWard                                                      
[09:55:16] HTTPConnectionPool(host='democracy.canterbury.gov.uk', handlers.py:36
           port=80): Max retries exceeded with url:                             
           /mgWebService.asmx/GetCouncillorsByWard (Caused by                   
           ConnectTimeoutError(<urllib3.connection.HTTPConnection               
           object at 0x7ffa7a8b5c60>, 'Connection to                            
           democracy.canterbury.gov.uk timed out. (connect                      
           timeout=None)'))                                                     
           Finished attempting to scrape: CAT                        base.py:339
</pre>
  

  


  <h2 id="2024-04-20-10-00">2024-04-20</h2>
  <div class="ds-card">
  <div class="ds-card-body">
    <dl class="ds-descriptions">
      <div>
        <dt>Duration</dt>
        <dd>132 seconds</dd>
      </div>
      <div>
        <dt>Start</dt>
        <dd>2024-04-20 10:00:39.751071</dd>
      </div>
      <div>
        <dt>End</dt>
        <dd>2024-04-20 10:02:52.657413</dd>
      </div>
      <div>
        <dt>Status code</dt>
        <dd>1</dd>
      </div>
      <div>
        <dt>Error</dt>
        <dd>Traceback (most recent call last):
  File "/opt/python/urllib3/connection.py", line 203, in _new_conn
    sock = connection.create_connection(
  File "/opt/python/urllib3/util/connection.py", line 85, in create_connection
    raise err
  File "/opt/python/urllib3/util/connection.py", line 73, in create_connection
    sock.connect(sa)
TimeoutError: [Errno 110] Connection timed out

The above exception was the direct cause of the following exception:

Traceback (most recent call last):
  File "/opt/python/urllib3/connectionpool.py", line 791, in urlopen
    response = self._make_request(
  File "/opt/python/urllib3/connectionpool.py", line 497, in _make_request
    conn.request(
  File "/opt/python/urllib3/connection.py", line 395, in request
    self.endheaders()
  File "/var/lang/lib/python3.10/http/client.py", line 1278, in endheaders
    self._send_output(message_body, encode_chunked=encode_chunked)
  File "/var/lang/lib/python3.10/http/client.py", line 1038, in _send_output
    self.send(msg)
  File "/var/lang/lib/python3.10/http/client.py", line 976, in send
    self.connect()
  File "/opt/python/urllib3/connection.py", line 243, in connect
    self.sock = self._new_conn()
  File "/opt/python/urllib3/connection.py", line 212, in _new_conn
    raise ConnectTimeoutError(
urllib3.exceptions.ConnectTimeoutError: (<urllib3.connection.HTTPConnection object at 0x7f93ff811930>, 'Connection to democracy.canterbury.gov.uk timed out. (connect timeout=None)')

The above exception was the direct cause of the following exception:

Traceback (most recent call last):
  File "/opt/python/requests/adapters.py", line 486, in send
    resp = conn.urlopen(
  File "/opt/python/urllib3/connectionpool.py", line 845, in urlopen
    retries = retries.increment(
  File "/opt/python/urllib3/util/retry.py", line 515, in increment
    raise MaxRetryError(_pool, url, reason) from reason  # type: ignore[arg-type]
urllib3.exceptions.MaxRetryError: HTTPConnectionPool(host='democracy.canterbury.gov.uk', port=80): Max retries exceeded with url: /mgWebService.asmx/GetCouncillorsByWard (Caused by ConnectTimeoutError(<urllib3.connection.HTTPConnection object at 0x7f93ff811930>, 'Connection to democracy.canterbury.gov.uk timed out. (connect timeout=None)'))

During handling of the above exception, another exception occurred:

Traceback (most recent call last):
  File "/var/task/lgsf/aws_lambda/handlers.py", line 32, in scraper_worker_handler
    scraper.run(run_log)
  File "/var/task/lgsf/councillors/scrapers.py", line 200, in run
    wards = self.get_councillors()
  File "/var/task/lgsf/councillors/scrapers.py", line 219, in get_councillors
    req = self.get(
  File "/var/task/lgsf/scrapers/base.py", line 47, in get
    response = self.requests_session.get(
  File "/opt/python/requests/sessions.py", line 602, in get
    return self.request("GET", url, **kwargs)
  File "/opt/python/requests/sessions.py", line 589, in request
    resp = self.send(prep, **send_kwargs)
  File "/opt/python/requests/sessions.py", line 703, in send
    r = adapter.send(request, **kwargs)
  File "/opt/python/requests/adapters.py", line 507, in send
    raise ConnectTimeout(e, request=request)
requests.exceptions.ConnectTimeout: HTTPConnectionPool(host='democracy.canterbury.gov.uk', port=80): Max retries exceeded with url: /mgWebService.asmx/GetCouncillorsByWard (Caused by ConnectTimeoutError(<urllib3.connection.HTTPConnection object at 0x7f93ff811930>, 'Connection to democracy.canterbury.gov.uk timed out. (connect timeout=None)'))
</dd>
      </div>
    </dl>
  </div>
  </div>

  <h3>Run log</h3>
  <pre>[10:00:39] Fetching Scraper for: CAT                              handlers.py:23
           Begin attempting to scrape: CAT                        handlers.py:27
[10:00:40] Deleting existing data...                                 base.py:251
           Getting all files in Councillors...                       base.py:203
           ...found 1 files in Councillors                           base.py:219
           Deleting batch no. 1 consisting of 1 files                base.py:230
[10:00:41] ...data deleted.                                          base.py:258
           Scraping from                                              base.py:41
           http://democracy.canterbury.gov.uk/mgWebService.asmx/GetCo           
           uncillorsByWard                                                      
[10:02:50] HTTPConnectionPool(host='democracy.canterbury.gov.uk', handlers.py:36
           port=80): Max retries exceeded with url:                             
           /mgWebService.asmx/GetCouncillorsByWard (Caused by                   
           ConnectTimeoutError(<urllib3.connection.HTTPConnection               
           object at 0x7f93ff811930>, 'Connection to                            
           democracy.canterbury.gov.uk timed out. (connect                      
           timeout=None)'))                                                     
[10:02:52] Finished attempting to scrape: CAT                        base.py:339
</pre>
  

  


  <h2 id="2024-04-19-10-29">2024-04-19</h2>
  <div class="ds-card">
  <div class="ds-card-body">
    <dl class="ds-descriptions">
      <div>
        <dt>Duration</dt>
        <dd>132 seconds</dd>
      </div>
      <div>
        <dt>Start</dt>
        <dd>2024-04-19 10:29:07.785152</dd>
      </div>
      <div>
        <dt>End</dt>
        <dd>2024-04-19 10:31:20.353317</dd>
      </div>
      <div>
        <dt>Status code</dt>
        <dd>1</dd>
      </div>
      <div>
        <dt>Error</dt>
        <dd>Traceback (most recent call last):
  File "/opt/python/urllib3/connection.py", line 203, in _new_conn
    sock = connection.create_connection(
  File "/opt/python/urllib3/util/connection.py", line 85, in create_connection
    raise err
  File "/opt/python/urllib3/util/connection.py", line 73, in create_connection
    sock.connect(sa)
TimeoutError: [Errno 110] Connection timed out

The above exception was the direct cause of the following exception:

Traceback (most recent call last):
  File "/opt/python/urllib3/connectionpool.py", line 791, in urlopen
    response = self._make_request(
  File "/opt/python/urllib3/connectionpool.py", line 497, in _make_request
    conn.request(
  File "/opt/python/urllib3/connection.py", line 395, in request
    self.endheaders()
  File "/var/lang/lib/python3.10/http/client.py", line 1278, in endheaders
    self._send_output(message_body, encode_chunked=encode_chunked)
  File "/var/lang/lib/python3.10/http/client.py", line 1038, in _send_output
    self.send(msg)
  File "/var/lang/lib/python3.10/http/client.py", line 976, in send
    self.connect()
  File "/opt/python/urllib3/connection.py", line 243, in connect
    self.sock = self._new_conn()
  File "/opt/python/urllib3/connection.py", line 212, in _new_conn
    raise ConnectTimeoutError(
urllib3.exceptions.ConnectTimeoutError: (<urllib3.connection.HTTPConnection object at 0x7f2abd56ad40>, 'Connection to democracy.canterbury.gov.uk timed out. (connect timeout=None)')

The above exception was the direct cause of the following exception:

Traceback (most recent call last):
  File "/opt/python/requests/adapters.py", line 486, in send
    resp = conn.urlopen(
  File "/opt/python/urllib3/connectionpool.py", line 845, in urlopen
    retries = retries.increment(
  File "/opt/python/urllib3/util/retry.py", line 515, in increment
    raise MaxRetryError(_pool, url, reason) from reason  # type: ignore[arg-type]
urllib3.exceptions.MaxRetryError: HTTPConnectionPool(host='democracy.canterbury.gov.uk', port=80): Max retries exceeded with url: /mgWebService.asmx/GetCouncillorsByWard (Caused by ConnectTimeoutError(<urllib3.connection.HTTPConnection object at 0x7f2abd56ad40>, 'Connection to democracy.canterbury.gov.uk timed out. (connect timeout=None)'))

During handling of the above exception, another exception occurred:

Traceback (most recent call last):
  File "/var/task/lgsf/aws_lambda/handlers.py", line 32, in scraper_worker_handler
    scraper.run(run_log)
  File "/var/task/lgsf/councillors/scrapers.py", line 200, in run
    wards = self.get_councillors()
  File "/var/task/lgsf/councillors/scrapers.py", line 219, in get_councillors
    req = self.get(
  File "/var/task/lgsf/scrapers/base.py", line 47, in get
    response = self.requests_session.get(
  File "/opt/python/requests/sessions.py", line 602, in get
    return self.request("GET", url, **kwargs)
  File "/opt/python/requests/sessions.py", line 589, in request
    resp = self.send(prep, **send_kwargs)
  File "/opt/python/requests/sessions.py", line 703, in send
    r = adapter.send(request, **kwargs)
  File "/opt/python/requests/adapters.py", line 507, in send
    raise ConnectTimeout(e, request=request)
requests.exceptions.ConnectTimeout: HTTPConnectionPool(host='democracy.canterbury.gov.uk', port=80): Max retries exceeded with url: /mgWebService.asmx/GetCouncillorsByWard (Caused by ConnectTimeoutError(<urllib3.connection.HTTPConnection object at 0x7f2abd56ad40>, 'Connection to democracy.canterbury.gov.uk timed out. (connect timeout=None)'))
</dd>
      </div>
    </dl>
  </div>
  </div>

  <h3>Run log</h3>
  <pre>[10:29:07] Fetching Scraper for: CAT                              handlers.py:23
           Begin attempting to scrape: CAT                        handlers.py:27
[10:29:08] Deleting existing data...                                 base.py:251
           Getting all files in Councillors...                       base.py:203
           ...found 1 files in Councillors                           base.py:219
           Deleting batch no. 1 consisting of 1 files                base.py:230
[10:29:09] ...data deleted.                                          base.py:258
           Scraping from                                              base.py:41
           http://democracy.canterbury.gov.uk/mgWebService.asmx/GetCo           
           uncillorsByWard                                                      
[10:31:19] HTTPConnectionPool(host='democracy.canterbury.gov.uk', handlers.py:36
           port=80): Max retries exceeded with url:                             
           /mgWebService.asmx/GetCouncillorsByWard (Caused by                   
           ConnectTimeoutError(<urllib3.connection.HTTPConnection               
           object at 0x7f2abd56ad40>, 'Connection to                            
           democracy.canterbury.gov.uk timed out. (connect                      
           timeout=None)'))                                                     
[10:31:20] Finished attempting to scrape: CAT                        base.py:339
</pre>
  

  


  <h2 id="2024-04-18-08-48">2024-04-18</h2>
  <div class="ds-card">
  <div class="ds-card-body">
    <dl class="ds-descriptions">
      <div>
        <dt>Duration</dt>
        <dd>132 seconds</dd>
      </div>
      <div>
        <dt>Start</dt>
        <dd>2024-04-18 08:48:23.699148</dd>
      </div>
      <div>
        <dt>End</dt>
        <dd>2024-04-18 08:50:36.021201</dd>
      </div>
      <div>
        <dt>Status code</dt>
        <dd>1</dd>
      </div>
      <div>
        <dt>Error</dt>
        <dd>Traceback (most recent call last):
  File "/opt/python/urllib3/connection.py", line 203, in _new_conn
    sock = connection.create_connection(
  File "/opt/python/urllib3/util/connection.py", line 85, in create_connection
    raise err
  File "/opt/python/urllib3/util/connection.py", line 73, in create_connection
    sock.connect(sa)
TimeoutError: [Errno 110] Connection timed out

The above exception was the direct cause of the following exception:

Traceback (most recent call last):
  File "/opt/python/urllib3/connectionpool.py", line 791, in urlopen
    response = self._make_request(
  File "/opt/python/urllib3/connectionpool.py", line 497, in _make_request
    conn.request(
  File "/opt/python/urllib3/connection.py", line 395, in request
    self.endheaders()
  File "/var/lang/lib/python3.10/http/client.py", line 1278, in endheaders
    self._send_output(message_body, encode_chunked=encode_chunked)
  File "/var/lang/lib/python3.10/http/client.py", line 1038, in _send_output
    self.send(msg)
  File "/var/lang/lib/python3.10/http/client.py", line 976, in send
    self.connect()
  File "/opt/python/urllib3/connection.py", line 243, in connect
    self.sock = self._new_conn()
  File "/opt/python/urllib3/connection.py", line 212, in _new_conn
    raise ConnectTimeoutError(
urllib3.exceptions.ConnectTimeoutError: (<urllib3.connection.HTTPConnection object at 0x7f03ca2f1e10>, 'Connection to democracy.canterbury.gov.uk timed out. (connect timeout=None)')

The above exception was the direct cause of the following exception:

Traceback (most recent call last):
  File "/opt/python/requests/adapters.py", line 486, in send
    resp = conn.urlopen(
  File "/opt/python/urllib3/connectionpool.py", line 845, in urlopen
    retries = retries.increment(
  File "/opt/python/urllib3/util/retry.py", line 515, in increment
    raise MaxRetryError(_pool, url, reason) from reason  # type: ignore[arg-type]
urllib3.exceptions.MaxRetryError: HTTPConnectionPool(host='democracy.canterbury.gov.uk', port=80): Max retries exceeded with url: /mgWebService.asmx/GetCouncillorsByWard (Caused by ConnectTimeoutError(<urllib3.connection.HTTPConnection object at 0x7f03ca2f1e10>, 'Connection to democracy.canterbury.gov.uk timed out. (connect timeout=None)'))

During handling of the above exception, another exception occurred:

Traceback (most recent call last):
  File "/var/task/lgsf/aws_lambda/handlers.py", line 32, in scraper_worker_handler
    scraper.run(run_log)
  File "/var/task/lgsf/councillors/scrapers.py", line 200, in run
    wards = self.get_councillors()
  File "/var/task/lgsf/councillors/scrapers.py", line 219, in get_councillors
    req = self.get(
  File "/var/task/lgsf/scrapers/base.py", line 47, in get
    response = self.requests_session.get(
  File "/opt/python/requests/sessions.py", line 602, in get
    return self.request("GET", url, **kwargs)
  File "/opt/python/requests/sessions.py", line 589, in request
    resp = self.send(prep, **send_kwargs)
  File "/opt/python/requests/sessions.py", line 703, in send
    r = adapter.send(request, **kwargs)
  File "/opt/python/requests/adapters.py", line 507, in send
    raise ConnectTimeout(e, request=request)
requests.exceptions.ConnectTimeout: HTTPConnectionPool(host='democracy.canterbury.gov.uk', port=80): Max retries exceeded with url: /mgWebService.asmx/GetCouncillorsByWard (Caused by ConnectTimeoutError(<urllib3.connection.HTTPConnection object at 0x7f03ca2f1e10>, 'Connection to democracy.canterbury.gov.uk timed out. (connect timeout=None)'))
</dd>
      </div>
    </dl>
  </div>
  </div>

  <h3>Run log</h3>
  <pre>[08:48:23] Fetching Scraper for: CAT                              handlers.py:23
           Begin attempting to scrape: CAT                        handlers.py:27
[08:48:24] Deleting existing data...                                 base.py:251
           Getting all files in Councillors...                       base.py:203
           ...found 1 files in Councillors                           base.py:219
           Deleting batch no. 1 consisting of 1 files                base.py:230
[08:48:25] ...data deleted.                                          base.py:258
           Scraping from                                              base.py:41
           http://democracy.canterbury.gov.uk/mgWebService.asmx/GetCo           
           uncillorsByWard                                                      
[08:50:35] HTTPConnectionPool(host='democracy.canterbury.gov.uk', handlers.py:36
           port=80): Max retries exceeded with url:                             
           /mgWebService.asmx/GetCouncillorsByWard (Caused by                   
           ConnectTimeoutError(<urllib3.connection.HTTPConnection               
           object at 0x7f03ca2f1e10>, 'Connection to                            
           democracy.canterbury.gov.uk timed out. (connect                      
           timeout=None)'))                                                     
[08:50:36] Finished attempting to scrape: CAT                        base.py:339
</pre>
  

  


  <h2 id="2024-04-17-10-25">2024-04-17</h2>
  <div class="ds-card">
  <div class="ds-card-body">
    <dl class="ds-descriptions">
      <div>
        <dt>Duration</dt>
        <dd>131 seconds</dd>
      </div>
      <div>
        <dt>Start</dt>
        <dd>2024-04-17 10:25:53.302423</dd>
      </div>
      <div>
        <dt>End</dt>
        <dd>2024-04-17 10:28:05.247134</dd>
      </div>
      <div>
        <dt>Status code</dt>
        <dd>1</dd>
      </div>
      <div>
        <dt>Error</dt>
        <dd>Traceback (most recent call last):
  File "/opt/python/urllib3/connection.py", line 203, in _new_conn
    sock = connection.create_connection(
  File "/opt/python/urllib3/util/connection.py", line 85, in create_connection
    raise err
  File "/opt/python/urllib3/util/connection.py", line 73, in create_connection
    sock.connect(sa)
TimeoutError: [Errno 110] Connection timed out

The above exception was the direct cause of the following exception:

Traceback (most recent call last):
  File "/opt/python/urllib3/connectionpool.py", line 791, in urlopen
    response = self._make_request(
  File "/opt/python/urllib3/connectionpool.py", line 497, in _make_request
    conn.request(
  File "/opt/python/urllib3/connection.py", line 395, in request
    self.endheaders()
  File "/var/lang/lib/python3.10/http/client.py", line 1278, in endheaders
    self._send_output(message_body, encode_chunked=encode_chunked)
  File "/var/lang/lib/python3.10/http/client.py", line 1038, in _send_output
    self.send(msg)
  File "/var/lang/lib/python3.10/http/client.py", line 976, in send
    self.connect()
  File "/opt/python/urllib3/connection.py", line 243, in connect
    self.sock = self._new_conn()
  File "/opt/python/urllib3/connection.py", line 212, in _new_conn
    raise ConnectTimeoutError(
urllib3.exceptions.ConnectTimeoutError: (<urllib3.connection.HTTPConnection object at 0x7fe22718ded0>, 'Connection to democracy.canterbury.gov.uk timed out. (connect timeout=None)')

The above exception was the direct cause of the following exception:

Traceback (most recent call last):
  File "/opt/python/requests/adapters.py", line 486, in send
    resp = conn.urlopen(
  File "/opt/python/urllib3/connectionpool.py", line 845, in urlopen
    retries = retries.increment(
  File "/opt/python/urllib3/util/retry.py", line 515, in increment
    raise MaxRetryError(_pool, url, reason) from reason  # type: ignore[arg-type]
urllib3.exceptions.MaxRetryError: HTTPConnectionPool(host='democracy.canterbury.gov.uk', port=80): Max retries exceeded with url: /mgWebService.asmx/GetCouncillorsByWard (Caused by ConnectTimeoutError(<urllib3.connection.HTTPConnection object at 0x7fe22718ded0>, 'Connection to democracy.canterbury.gov.uk timed out. (connect timeout=None)'))

During handling of the above exception, another exception occurred:

Traceback (most recent call last):
  File "/var/task/lgsf/aws_lambda/handlers.py", line 32, in scraper_worker_handler
    scraper.run(run_log)
  File "/var/task/lgsf/councillors/scrapers.py", line 200, in run
    wards = self.get_councillors()
  File "/var/task/lgsf/councillors/scrapers.py", line 219, in get_councillors
    req = self.get(
  File "/var/task/lgsf/scrapers/base.py", line 47, in get
    response = self.requests_session.get(
  File "/opt/python/requests/sessions.py", line 602, in get
    return self.request("GET", url, **kwargs)
  File "/opt/python/requests/sessions.py", line 589, in request
    resp = self.send(prep, **send_kwargs)
  File "/opt/python/requests/sessions.py", line 703, in send
    r = adapter.send(request, **kwargs)
  File "/opt/python/requests/adapters.py", line 507, in send
    raise ConnectTimeout(e, request=request)
requests.exceptions.ConnectTimeout: HTTPConnectionPool(host='democracy.canterbury.gov.uk', port=80): Max retries exceeded with url: /mgWebService.asmx/GetCouncillorsByWard (Caused by ConnectTimeoutError(<urllib3.connection.HTTPConnection object at 0x7fe22718ded0>, 'Connection to democracy.canterbury.gov.uk timed out. (connect timeout=None)'))
</dd>
      </div>
    </dl>
  </div>
  </div>

  <h3>Run log</h3>
  <pre>[10:25:53] Fetching Scraper for: CAT                              handlers.py:23
           Begin attempting to scrape: CAT                        handlers.py:27
           Deleting existing data...                                 base.py:251
[10:25:54] Getting all files in Councillors...                       base.py:203
           ...found 1 files in Councillors                           base.py:219
           Deleting batch no. 1 consisting of 1 files                base.py:230
           ...data deleted.                                          base.py:258
           Scraping from                                              base.py:41
           http://democracy.canterbury.gov.uk/mgWebService.asmx/GetCo           
           uncillorsByWard                                                      
[10:28:04] HTTPConnectionPool(host='democracy.canterbury.gov.uk', handlers.py:36
           port=80): Max retries exceeded with url:                             
           /mgWebService.asmx/GetCouncillorsByWard (Caused by                   
           ConnectTimeoutError(<urllib3.connection.HTTPConnection               
           object at 0x7fe22718ded0>, 'Connection to                            
           democracy.canterbury.gov.uk timed out. (connect                      
           timeout=None)'))                                                     
[10:28:05] Finished attempting to scrape: CAT                        base.py:339
</pre>
  

  


  <h2 id="2024-04-16-08-38">2024-04-16</h2>
  <div class="ds-card">
  <div class="ds-card-body">
    <dl class="ds-descriptions">
      <div>
        <dt>Duration</dt>
        <dd>131 seconds</dd>
      </div>
      <div>
        <dt>Start</dt>
        <dd>2024-04-16 08:38:37.923573</dd>
      </div>
      <div>
        <dt>End</dt>
        <dd>2024-04-16 08:40:49.658215</dd>
      </div>
      <div>
        <dt>Status code</dt>
        <dd>1</dd>
      </div>
      <div>
        <dt>Error</dt>
        <dd>Traceback (most recent call last):
  File "/opt/python/urllib3/connection.py", line 203, in _new_conn
    sock = connection.create_connection(
  File "/opt/python/urllib3/util/connection.py", line 85, in create_connection
    raise err
  File "/opt/python/urllib3/util/connection.py", line 73, in create_connection
    sock.connect(sa)
TimeoutError: [Errno 110] Connection timed out

The above exception was the direct cause of the following exception:

Traceback (most recent call last):
  File "/opt/python/urllib3/connectionpool.py", line 791, in urlopen
    response = self._make_request(
  File "/opt/python/urllib3/connectionpool.py", line 497, in _make_request
    conn.request(
  File "/opt/python/urllib3/connection.py", line 395, in request
    self.endheaders()
  File "/var/lang/lib/python3.10/http/client.py", line 1278, in endheaders
    self._send_output(message_body, encode_chunked=encode_chunked)
  File "/var/lang/lib/python3.10/http/client.py", line 1038, in _send_output
    self.send(msg)
  File "/var/lang/lib/python3.10/http/client.py", line 976, in send
    self.connect()
  File "/opt/python/urllib3/connection.py", line 243, in connect
    self.sock = self._new_conn()
  File "/opt/python/urllib3/connection.py", line 212, in _new_conn
    raise ConnectTimeoutError(
urllib3.exceptions.ConnectTimeoutError: (<urllib3.connection.HTTPConnection object at 0x7f7451b0e830>, 'Connection to democracy.canterbury.gov.uk timed out. (connect timeout=None)')

The above exception was the direct cause of the following exception:

Traceback (most recent call last):
  File "/opt/python/requests/adapters.py", line 486, in send
    resp = conn.urlopen(
  File "/opt/python/urllib3/connectionpool.py", line 845, in urlopen
    retries = retries.increment(
  File "/opt/python/urllib3/util/retry.py", line 515, in increment
    raise MaxRetryError(_pool, url, reason) from reason  # type: ignore[arg-type]
urllib3.exceptions.MaxRetryError: HTTPConnectionPool(host='democracy.canterbury.gov.uk', port=80): Max retries exceeded with url: /mgWebService.asmx/GetCouncillorsByWard (Caused by ConnectTimeoutError(<urllib3.connection.HTTPConnection object at 0x7f7451b0e830>, 'Connection to democracy.canterbury.gov.uk timed out. (connect timeout=None)'))

During handling of the above exception, another exception occurred:

Traceback (most recent call last):
  File "/var/task/lgsf/aws_lambda/handlers.py", line 32, in scraper_worker_handler
    scraper.run(run_log)
  File "/var/task/lgsf/councillors/scrapers.py", line 200, in run
    wards = self.get_councillors()
  File "/var/task/lgsf/councillors/scrapers.py", line 219, in get_councillors
    req = self.get(
  File "/var/task/lgsf/scrapers/base.py", line 47, in get
    response = self.requests_session.get(
  File "/opt/python/requests/sessions.py", line 602, in get
    return self.request("GET", url, **kwargs)
  File "/opt/python/requests/sessions.py", line 589, in request
    resp = self.send(prep, **send_kwargs)
  File "/opt/python/requests/sessions.py", line 703, in send
    r = adapter.send(request, **kwargs)
  File "/opt/python/requests/adapters.py", line 507, in send
    raise ConnectTimeout(e, request=request)
requests.exceptions.ConnectTimeout: HTTPConnectionPool(host='democracy.canterbury.gov.uk', port=80): Max retries exceeded with url: /mgWebService.asmx/GetCouncillorsByWard (Caused by ConnectTimeoutError(<urllib3.connection.HTTPConnection object at 0x7f7451b0e830>, 'Connection to democracy.canterbury.gov.uk timed out. (connect timeout=None)'))
</dd>
      </div>
    </dl>
  </div>
  </div>

  <h3>Run log</h3>
  <pre>[08:38:37] Fetching Scraper for: CAT                              handlers.py:23
           Begin attempting to scrape: CAT                        handlers.py:27
[08:38:38] Deleting existing data...                                 base.py:251
           Getting all files in Councillors...                       base.py:203
           ...found 1 files in Councillors                           base.py:219
           Deleting batch no. 1 consisting of 1 files                base.py:230
[08:38:39] ...data deleted.                                          base.py:258
           Scraping from                                              base.py:41
           http://democracy.canterbury.gov.uk/mgWebService.asmx/GetCo           
           uncillorsByWard                                                      
[08:40:49] HTTPConnectionPool(host='democracy.canterbury.gov.uk', handlers.py:36
           port=80): Max retries exceeded with url:                             
           /mgWebService.asmx/GetCouncillorsByWard (Caused by                   
           ConnectTimeoutError(<urllib3.connection.HTTPConnection               
           object at 0x7f7451b0e830>, 'Connection to                            
           democracy.canterbury.gov.uk timed out. (connect                      
           timeout=None)'))                                                     
           Finished attempting to scrape: CAT                        base.py:339
</pre>
  

  


  <h2 id="2024-04-15-09-24">2024-04-15</h2>
  <div class="ds-card">
  <div class="ds-card-body">
    <dl class="ds-descriptions">
      <div>
        <dt>Duration</dt>
        <dd>131 seconds</dd>
      </div>
      <div>
        <dt>Start</dt>
        <dd>2024-04-15 09:24:57.265733</dd>
      </div>
      <div>
        <dt>End</dt>
        <dd>2024-04-15 09:27:09.256561</dd>
      </div>
      <div>
        <dt>Status code</dt>
        <dd>1</dd>
      </div>
      <div>
        <dt>Error</dt>
        <dd>Traceback (most recent call last):
  File "/opt/python/urllib3/connection.py", line 203, in _new_conn
    sock = connection.create_connection(
  File "/opt/python/urllib3/util/connection.py", line 85, in create_connection
    raise err
  File "/opt/python/urllib3/util/connection.py", line 73, in create_connection
    sock.connect(sa)
TimeoutError: [Errno 110] Connection timed out

The above exception was the direct cause of the following exception:

Traceback (most recent call last):
  File "/opt/python/urllib3/connectionpool.py", line 791, in urlopen
    response = self._make_request(
  File "/opt/python/urllib3/connectionpool.py", line 497, in _make_request
    conn.request(
  File "/opt/python/urllib3/connection.py", line 395, in request
    self.endheaders()
  File "/var/lang/lib/python3.10/http/client.py", line 1278, in endheaders
    self._send_output(message_body, encode_chunked=encode_chunked)
  File "/var/lang/lib/python3.10/http/client.py", line 1038, in _send_output
    self.send(msg)
  File "/var/lang/lib/python3.10/http/client.py", line 976, in send
    self.connect()
  File "/opt/python/urllib3/connection.py", line 243, in connect
    self.sock = self._new_conn()
  File "/opt/python/urllib3/connection.py", line 212, in _new_conn
    raise ConnectTimeoutError(
urllib3.exceptions.ConnectTimeoutError: (<urllib3.connection.HTTPConnection object at 0x7f88900280d0>, 'Connection to democracy.canterbury.gov.uk timed out. (connect timeout=None)')

The above exception was the direct cause of the following exception:

Traceback (most recent call last):
  File "/opt/python/requests/adapters.py", line 486, in send
    resp = conn.urlopen(
  File "/opt/python/urllib3/connectionpool.py", line 845, in urlopen
    retries = retries.increment(
  File "/opt/python/urllib3/util/retry.py", line 515, in increment
    raise MaxRetryError(_pool, url, reason) from reason  # type: ignore[arg-type]
urllib3.exceptions.MaxRetryError: HTTPConnectionPool(host='democracy.canterbury.gov.uk', port=80): Max retries exceeded with url: /mgWebService.asmx/GetCouncillorsByWard (Caused by ConnectTimeoutError(<urllib3.connection.HTTPConnection object at 0x7f88900280d0>, 'Connection to democracy.canterbury.gov.uk timed out. (connect timeout=None)'))

During handling of the above exception, another exception occurred:

Traceback (most recent call last):
  File "/var/task/lgsf/aws_lambda/handlers.py", line 32, in scraper_worker_handler
    scraper.run(run_log)
  File "/var/task/lgsf/councillors/scrapers.py", line 200, in run
    wards = self.get_councillors()
  File "/var/task/lgsf/councillors/scrapers.py", line 219, in get_councillors
    req = self.get(
  File "/var/task/lgsf/scrapers/base.py", line 47, in get
    response = self.requests_session.get(
  File "/opt/python/requests/sessions.py", line 602, in get
    return self.request("GET", url, **kwargs)
  File "/opt/python/requests/sessions.py", line 589, in request
    resp = self.send(prep, **send_kwargs)
  File "/opt/python/requests/sessions.py", line 703, in send
    r = adapter.send(request, **kwargs)
  File "/opt/python/requests/adapters.py", line 507, in send
    raise ConnectTimeout(e, request=request)
requests.exceptions.ConnectTimeout: HTTPConnectionPool(host='democracy.canterbury.gov.uk', port=80): Max retries exceeded with url: /mgWebService.asmx/GetCouncillorsByWard (Caused by ConnectTimeoutError(<urllib3.connection.HTTPConnection object at 0x7f88900280d0>, 'Connection to democracy.canterbury.gov.uk timed out. (connect timeout=None)'))
</dd>
      </div>
    </dl>
  </div>
  </div>

  <h3>Run log</h3>
  <pre>[09:24:57] Fetching Scraper for: CAT                              handlers.py:23
           Begin attempting to scrape: CAT                        handlers.py:27
           Deleting existing data...                                 base.py:251
[09:24:58] Getting all files in Councillors...                       base.py:203
           ...found 1 files in Councillors                           base.py:219
           Deleting batch no. 1 consisting of 1 files                base.py:230
[09:24:59] ...data deleted.                                          base.py:258
           Scraping from                                              base.py:41
           http://democracy.canterbury.gov.uk/mgWebService.asmx/GetCo           
           uncillorsByWard                                                      
[09:27:08] HTTPConnectionPool(host='democracy.canterbury.gov.uk', handlers.py:36
           port=80): Max retries exceeded with url:                             
           /mgWebService.asmx/GetCouncillorsByWard (Caused by                   
           ConnectTimeoutError(<urllib3.connection.HTTPConnection               
           object at 0x7f88900280d0>, 'Connection to                            
           democracy.canterbury.gov.uk timed out. (connect                      
           timeout=None)'))                                                     
[09:27:09] Finished attempting to scrape: CAT                        base.py:339
</pre>
  

  


  <h2 id="2024-04-14-08-59">2024-04-14</h2>
  <div class="ds-card">
  <div class="ds-card-body">
    <dl class="ds-descriptions">
      <div>
        <dt>Duration</dt>
        <dd>132 seconds</dd>
      </div>
      <div>
        <dt>Start</dt>
        <dd>2024-04-14 08:59:56.241501</dd>
      </div>
      <div>
        <dt>End</dt>
        <dd>2024-04-14 09:02:09.126338</dd>
      </div>
      <div>
        <dt>Status code</dt>
        <dd>1</dd>
      </div>
      <div>
        <dt>Error</dt>
        <dd>Traceback (most recent call last):
  File "/opt/python/urllib3/connection.py", line 203, in _new_conn
    sock = connection.create_connection(
  File "/opt/python/urllib3/util/connection.py", line 85, in create_connection
    raise err
  File "/opt/python/urllib3/util/connection.py", line 73, in create_connection
    sock.connect(sa)
TimeoutError: [Errno 110] Connection timed out

The above exception was the direct cause of the following exception:

Traceback (most recent call last):
  File "/opt/python/urllib3/connectionpool.py", line 791, in urlopen
    response = self._make_request(
  File "/opt/python/urllib3/connectionpool.py", line 497, in _make_request
    conn.request(
  File "/opt/python/urllib3/connection.py", line 395, in request
    self.endheaders()
  File "/var/lang/lib/python3.10/http/client.py", line 1278, in endheaders
    self._send_output(message_body, encode_chunked=encode_chunked)
  File "/var/lang/lib/python3.10/http/client.py", line 1038, in _send_output
    self.send(msg)
  File "/var/lang/lib/python3.10/http/client.py", line 976, in send
    self.connect()
  File "/opt/python/urllib3/connection.py", line 243, in connect
    self.sock = self._new_conn()
  File "/opt/python/urllib3/connection.py", line 212, in _new_conn
    raise ConnectTimeoutError(
urllib3.exceptions.ConnectTimeoutError: (<urllib3.connection.HTTPConnection object at 0x7f3ba49587f0>, 'Connection to democracy.canterbury.gov.uk timed out. (connect timeout=None)')

The above exception was the direct cause of the following exception:

Traceback (most recent call last):
  File "/opt/python/requests/adapters.py", line 486, in send
    resp = conn.urlopen(
  File "/opt/python/urllib3/connectionpool.py", line 845, in urlopen
    retries = retries.increment(
  File "/opt/python/urllib3/util/retry.py", line 515, in increment
    raise MaxRetryError(_pool, url, reason) from reason  # type: ignore[arg-type]
urllib3.exceptions.MaxRetryError: HTTPConnectionPool(host='democracy.canterbury.gov.uk', port=80): Max retries exceeded with url: /mgWebService.asmx/GetCouncillorsByWard (Caused by ConnectTimeoutError(<urllib3.connection.HTTPConnection object at 0x7f3ba49587f0>, 'Connection to democracy.canterbury.gov.uk timed out. (connect timeout=None)'))

During handling of the above exception, another exception occurred:

Traceback (most recent call last):
  File "/var/task/lgsf/aws_lambda/handlers.py", line 32, in scraper_worker_handler
    scraper.run(run_log)
  File "/var/task/lgsf/councillors/scrapers.py", line 200, in run
    wards = self.get_councillors()
  File "/var/task/lgsf/councillors/scrapers.py", line 219, in get_councillors
    req = self.get(
  File "/var/task/lgsf/scrapers/base.py", line 47, in get
    response = self.requests_session.get(
  File "/opt/python/requests/sessions.py", line 602, in get
    return self.request("GET", url, **kwargs)
  File "/opt/python/requests/sessions.py", line 589, in request
    resp = self.send(prep, **send_kwargs)
  File "/opt/python/requests/sessions.py", line 703, in send
    r = adapter.send(request, **kwargs)
  File "/opt/python/requests/adapters.py", line 507, in send
    raise ConnectTimeout(e, request=request)
requests.exceptions.ConnectTimeout: HTTPConnectionPool(host='democracy.canterbury.gov.uk', port=80): Max retries exceeded with url: /mgWebService.asmx/GetCouncillorsByWard (Caused by ConnectTimeoutError(<urllib3.connection.HTTPConnection object at 0x7f3ba49587f0>, 'Connection to democracy.canterbury.gov.uk timed out. (connect timeout=None)'))
</dd>
      </div>
    </dl>
  </div>
  </div>

  <h3>Run log</h3>
  <pre>[08:59:56] Fetching Scraper for: CAT                              handlers.py:23
           Begin attempting to scrape: CAT                        handlers.py:27
           Deleting existing data...                                 base.py:251
[08:59:57] Getting all files in Councillors...                       base.py:203
           ...found 1 files in Councillors                           base.py:219
           Deleting batch no. 1 consisting of 1 files                base.py:230
[08:59:58] ...data deleted.                                          base.py:258
           Scraping from                                              base.py:41
           http://democracy.canterbury.gov.uk/mgWebService.asmx/GetCo           
           uncillorsByWard                                                      
[09:02:08] HTTPConnectionPool(host='democracy.canterbury.gov.uk', handlers.py:36
           port=80): Max retries exceeded with url:                             
           /mgWebService.asmx/GetCouncillorsByWard (Caused by                   
           ConnectTimeoutError(<urllib3.connection.HTTPConnection               
           object at 0x7f3ba49587f0>, 'Connection to                            
           democracy.canterbury.gov.uk timed out. (connect                      
           timeout=None)'))                                                     
[09:02:09] Finished attempting to scrape: CAT                        base.py:339
</pre>
  

  


  <h2 id="2024-04-13-09-38">2024-04-13</h2>
  <div class="ds-card">
  <div class="ds-card-body">
    <dl class="ds-descriptions">
      <div>
        <dt>Duration</dt>
        <dd>132 seconds</dd>
      </div>
      <div>
        <dt>Start</dt>
        <dd>2024-04-13 09:38:42.405422</dd>
      </div>
      <div>
        <dt>End</dt>
        <dd>2024-04-13 09:40:54.861014</dd>
      </div>
      <div>
        <dt>Status code</dt>
        <dd>1</dd>
      </div>
      <div>
        <dt>Error</dt>
        <dd>Traceback (most recent call last):
  File "/opt/python/urllib3/connection.py", line 203, in _new_conn
    sock = connection.create_connection(
  File "/opt/python/urllib3/util/connection.py", line 85, in create_connection
    raise err
  File "/opt/python/urllib3/util/connection.py", line 73, in create_connection
    sock.connect(sa)
TimeoutError: [Errno 110] Connection timed out

The above exception was the direct cause of the following exception:

Traceback (most recent call last):
  File "/opt/python/urllib3/connectionpool.py", line 791, in urlopen
    response = self._make_request(
  File "/opt/python/urllib3/connectionpool.py", line 497, in _make_request
    conn.request(
  File "/opt/python/urllib3/connection.py", line 395, in request
    self.endheaders()
  File "/var/lang/lib/python3.10/http/client.py", line 1278, in endheaders
    self._send_output(message_body, encode_chunked=encode_chunked)
  File "/var/lang/lib/python3.10/http/client.py", line 1038, in _send_output
    self.send(msg)
  File "/var/lang/lib/python3.10/http/client.py", line 976, in send
    self.connect()
  File "/opt/python/urllib3/connection.py", line 243, in connect
    self.sock = self._new_conn()
  File "/opt/python/urllib3/connection.py", line 212, in _new_conn
    raise ConnectTimeoutError(
urllib3.exceptions.ConnectTimeoutError: (<urllib3.connection.HTTPConnection object at 0x7f18ef938580>, 'Connection to democracy.canterbury.gov.uk timed out. (connect timeout=None)')

The above exception was the direct cause of the following exception:

Traceback (most recent call last):
  File "/opt/python/requests/adapters.py", line 486, in send
    resp = conn.urlopen(
  File "/opt/python/urllib3/connectionpool.py", line 845, in urlopen
    retries = retries.increment(
  File "/opt/python/urllib3/util/retry.py", line 515, in increment
    raise MaxRetryError(_pool, url, reason) from reason  # type: ignore[arg-type]
urllib3.exceptions.MaxRetryError: HTTPConnectionPool(host='democracy.canterbury.gov.uk', port=80): Max retries exceeded with url: /mgWebService.asmx/GetCouncillorsByWard (Caused by ConnectTimeoutError(<urllib3.connection.HTTPConnection object at 0x7f18ef938580>, 'Connection to democracy.canterbury.gov.uk timed out. (connect timeout=None)'))

During handling of the above exception, another exception occurred:

Traceback (most recent call last):
  File "/var/task/lgsf/aws_lambda/handlers.py", line 32, in scraper_worker_handler
    scraper.run(run_log)
  File "/var/task/lgsf/councillors/scrapers.py", line 200, in run
    wards = self.get_councillors()
  File "/var/task/lgsf/councillors/scrapers.py", line 219, in get_councillors
    req = self.get(
  File "/var/task/lgsf/scrapers/base.py", line 47, in get
    response = self.requests_session.get(
  File "/opt/python/requests/sessions.py", line 602, in get
    return self.request("GET", url, **kwargs)
  File "/opt/python/requests/sessions.py", line 589, in request
    resp = self.send(prep, **send_kwargs)
  File "/opt/python/requests/sessions.py", line 703, in send
    r = adapter.send(request, **kwargs)
  File "/opt/python/requests/adapters.py", line 507, in send
    raise ConnectTimeout(e, request=request)
requests.exceptions.ConnectTimeout: HTTPConnectionPool(host='democracy.canterbury.gov.uk', port=80): Max retries exceeded with url: /mgWebService.asmx/GetCouncillorsByWard (Caused by ConnectTimeoutError(<urllib3.connection.HTTPConnection object at 0x7f18ef938580>, 'Connection to democracy.canterbury.gov.uk timed out. (connect timeout=None)'))
</dd>
      </div>
    </dl>
  </div>
  </div>

  <h3>Run log</h3>
  <pre>[09:38:42] Fetching Scraper for: CAT                              handlers.py:23
           Begin attempting to scrape: CAT                        handlers.py:27
           Deleting existing data...                                 base.py:251
[09:38:43] Getting all files in Councillors...                       base.py:203
           ...found 1 files in Councillors                           base.py:219
           Deleting batch no. 1 consisting of 1 files                base.py:230
[09:38:44] ...data deleted.                                          base.py:258
           Scraping from                                              base.py:41
           http://democracy.canterbury.gov.uk/mgWebService.asmx/GetCo           
           uncillorsByWard                                                      
[09:40:54] HTTPConnectionPool(host='democracy.canterbury.gov.uk', handlers.py:36
           port=80): Max retries exceeded with url:                             
           /mgWebService.asmx/GetCouncillorsByWard (Caused by                   
           ConnectTimeoutError(<urllib3.connection.HTTPConnection               
           object at 0x7f18ef938580>, 'Connection to                            
           democracy.canterbury.gov.uk timed out. (connect                      
           timeout=None)'))                                                     
           Finished attempting to scrape: CAT                        base.py:339
</pre>
  

  


  <h2 id="2024-04-12-08-18">2024-04-12</h2>
  <div class="ds-card">
  <div class="ds-card-body">
    <dl class="ds-descriptions">
      <div>
        <dt>Duration</dt>
        <dd>131 seconds</dd>
      </div>
      <div>
        <dt>Start</dt>
        <dd>2024-04-12 08:18:14.215624</dd>
      </div>
      <div>
        <dt>End</dt>
        <dd>2024-04-12 08:20:25.995345</dd>
      </div>
      <div>
        <dt>Status code</dt>
        <dd>1</dd>
      </div>
      <div>
        <dt>Error</dt>
        <dd>Traceback (most recent call last):
  File "/opt/python/urllib3/connection.py", line 203, in _new_conn
    sock = connection.create_connection(
  File "/opt/python/urllib3/util/connection.py", line 85, in create_connection
    raise err
  File "/opt/python/urllib3/util/connection.py", line 73, in create_connection
    sock.connect(sa)
TimeoutError: [Errno 110] Connection timed out

The above exception was the direct cause of the following exception:

Traceback (most recent call last):
  File "/opt/python/urllib3/connectionpool.py", line 791, in urlopen
    response = self._make_request(
  File "/opt/python/urllib3/connectionpool.py", line 497, in _make_request
    conn.request(
  File "/opt/python/urllib3/connection.py", line 395, in request
    self.endheaders()
  File "/var/lang/lib/python3.10/http/client.py", line 1278, in endheaders
    self._send_output(message_body, encode_chunked=encode_chunked)
  File "/var/lang/lib/python3.10/http/client.py", line 1038, in _send_output
    self.send(msg)
  File "/var/lang/lib/python3.10/http/client.py", line 976, in send
    self.connect()
  File "/opt/python/urllib3/connection.py", line 243, in connect
    self.sock = self._new_conn()
  File "/opt/python/urllib3/connection.py", line 212, in _new_conn
    raise ConnectTimeoutError(
urllib3.exceptions.ConnectTimeoutError: (<urllib3.connection.HTTPConnection object at 0x7f92a21d3f70>, 'Connection to democracy.canterbury.gov.uk timed out. (connect timeout=None)')

The above exception was the direct cause of the following exception:

Traceback (most recent call last):
  File "/opt/python/requests/adapters.py", line 486, in send
    resp = conn.urlopen(
  File "/opt/python/urllib3/connectionpool.py", line 845, in urlopen
    retries = retries.increment(
  File "/opt/python/urllib3/util/retry.py", line 515, in increment
    raise MaxRetryError(_pool, url, reason) from reason  # type: ignore[arg-type]
urllib3.exceptions.MaxRetryError: HTTPConnectionPool(host='democracy.canterbury.gov.uk', port=80): Max retries exceeded with url: /mgWebService.asmx/GetCouncillorsByWard (Caused by ConnectTimeoutError(<urllib3.connection.HTTPConnection object at 0x7f92a21d3f70>, 'Connection to democracy.canterbury.gov.uk timed out. (connect timeout=None)'))

During handling of the above exception, another exception occurred:

Traceback (most recent call last):
  File "/var/task/lgsf/aws_lambda/handlers.py", line 32, in scraper_worker_handler
    scraper.run(run_log)
  File "/var/task/lgsf/councillors/scrapers.py", line 200, in run
    wards = self.get_councillors()
  File "/var/task/lgsf/councillors/scrapers.py", line 219, in get_councillors
    req = self.get(
  File "/var/task/lgsf/scrapers/base.py", line 47, in get
    response = self.requests_session.get(
  File "/opt/python/requests/sessions.py", line 602, in get
    return self.request("GET", url, **kwargs)
  File "/opt/python/requests/sessions.py", line 589, in request
    resp = self.send(prep, **send_kwargs)
  File "/opt/python/requests/sessions.py", line 703, in send
    r = adapter.send(request, **kwargs)
  File "/opt/python/requests/adapters.py", line 507, in send
    raise ConnectTimeout(e, request=request)
requests.exceptions.ConnectTimeout: HTTPConnectionPool(host='democracy.canterbury.gov.uk', port=80): Max retries exceeded with url: /mgWebService.asmx/GetCouncillorsByWard (Caused by ConnectTimeoutError(<urllib3.connection.HTTPConnection object at 0x7f92a21d3f70>, 'Connection to democracy.canterbury.gov.uk timed out. (connect timeout=None)'))
</dd>
      </div>
    </dl>
  </div>
  </div>

  <h3>Run log</h3>
  <pre>[08:18:14] Fetching Scraper for: CAT                              handlers.py:23
           Begin attempting to scrape: CAT                        handlers.py:27
           Deleting existing data...                                 base.py:251
[08:18:15] Getting all files in Councillors...                       base.py:203
           ...found 1 files in Councillors                           base.py:219
           Deleting batch no. 1 consisting of 1 files                base.py:230
           ...data deleted.                                          base.py:258
           Scraping from                                              base.py:41
           http://democracy.canterbury.gov.uk/mgWebService.asmx/GetCo           
           uncillorsByWard                                                      
[08:20:25] HTTPConnectionPool(host='democracy.canterbury.gov.uk', handlers.py:36
           port=80): Max retries exceeded with url:                             
           /mgWebService.asmx/GetCouncillorsByWard (Caused by                   
           ConnectTimeoutError(<urllib3.connection.HTTPConnection               
           object at 0x7f92a21d3f70>, 'Connection to                            
           democracy.canterbury.gov.uk timed out. (connect                      
           timeout=None)'))                                                     
           Finished attempting to scrape: CAT                        base.py:339
</pre>
  

  


  <h2 id="2024-04-11-10-16">2024-04-11</h2>
  <div class="ds-card">
  <div class="ds-card-body">
    <dl class="ds-descriptions">
      <div>
        <dt>Duration</dt>
        <dd>132 seconds</dd>
      </div>
      <div>
        <dt>Start</dt>
        <dd>2024-04-11 10:16:28.914765</dd>
      </div>
      <div>
        <dt>End</dt>
        <dd>2024-04-11 10:18:41.491376</dd>
      </div>
      <div>
        <dt>Status code</dt>
        <dd>1</dd>
      </div>
      <div>
        <dt>Error</dt>
        <dd>Traceback (most recent call last):
  File "/opt/python/urllib3/connection.py", line 203, in _new_conn
    sock = connection.create_connection(
  File "/opt/python/urllib3/util/connection.py", line 85, in create_connection
    raise err
  File "/opt/python/urllib3/util/connection.py", line 73, in create_connection
    sock.connect(sa)
TimeoutError: [Errno 110] Connection timed out

The above exception was the direct cause of the following exception:

Traceback (most recent call last):
  File "/opt/python/urllib3/connectionpool.py", line 791, in urlopen
    response = self._make_request(
  File "/opt/python/urllib3/connectionpool.py", line 497, in _make_request
    conn.request(
  File "/opt/python/urllib3/connection.py", line 395, in request
    self.endheaders()
  File "/var/lang/lib/python3.10/http/client.py", line 1278, in endheaders
    self._send_output(message_body, encode_chunked=encode_chunked)
  File "/var/lang/lib/python3.10/http/client.py", line 1038, in _send_output
    self.send(msg)
  File "/var/lang/lib/python3.10/http/client.py", line 976, in send
    self.connect()
  File "/opt/python/urllib3/connection.py", line 243, in connect
    self.sock = self._new_conn()
  File "/opt/python/urllib3/connection.py", line 212, in _new_conn
    raise ConnectTimeoutError(
urllib3.exceptions.ConnectTimeoutError: (<urllib3.connection.HTTPConnection object at 0x7fde405c8df0>, 'Connection to democracy.canterbury.gov.uk timed out. (connect timeout=None)')

The above exception was the direct cause of the following exception:

Traceback (most recent call last):
  File "/opt/python/requests/adapters.py", line 486, in send
    resp = conn.urlopen(
  File "/opt/python/urllib3/connectionpool.py", line 845, in urlopen
    retries = retries.increment(
  File "/opt/python/urllib3/util/retry.py", line 515, in increment
    raise MaxRetryError(_pool, url, reason) from reason  # type: ignore[arg-type]
urllib3.exceptions.MaxRetryError: HTTPConnectionPool(host='democracy.canterbury.gov.uk', port=80): Max retries exceeded with url: /mgWebService.asmx/GetCouncillorsByWard (Caused by ConnectTimeoutError(<urllib3.connection.HTTPConnection object at 0x7fde405c8df0>, 'Connection to democracy.canterbury.gov.uk timed out. (connect timeout=None)'))

During handling of the above exception, another exception occurred:

Traceback (most recent call last):
  File "/var/task/lgsf/aws_lambda/handlers.py", line 32, in scraper_worker_handler
    scraper.run(run_log)
  File "/var/task/lgsf/councillors/scrapers.py", line 200, in run
    wards = self.get_councillors()
  File "/var/task/lgsf/councillors/scrapers.py", line 219, in get_councillors
    req = self.get(
  File "/var/task/lgsf/scrapers/base.py", line 47, in get
    response = self.requests_session.get(
  File "/opt/python/requests/sessions.py", line 602, in get
    return self.request("GET", url, **kwargs)
  File "/opt/python/requests/sessions.py", line 589, in request
    resp = self.send(prep, **send_kwargs)
  File "/opt/python/requests/sessions.py", line 703, in send
    r = adapter.send(request, **kwargs)
  File "/opt/python/requests/adapters.py", line 507, in send
    raise ConnectTimeout(e, request=request)
requests.exceptions.ConnectTimeout: HTTPConnectionPool(host='democracy.canterbury.gov.uk', port=80): Max retries exceeded with url: /mgWebService.asmx/GetCouncillorsByWard (Caused by ConnectTimeoutError(<urllib3.connection.HTTPConnection object at 0x7fde405c8df0>, 'Connection to democracy.canterbury.gov.uk timed out. (connect timeout=None)'))
</dd>
      </div>
    </dl>
  </div>
  </div>

  <h3>Run log</h3>
  <pre>[10:16:28] Fetching Scraper for: CAT                              handlers.py:23
           Begin attempting to scrape: CAT                        handlers.py:27
[10:16:29] Deleting existing data...                                 base.py:251
           Getting all files in Councillors...                       base.py:203
[10:16:30] ...found 1 files in Councillors                           base.py:219
           Deleting batch no. 1 consisting of 1 files                base.py:230
           ...data deleted.                                          base.py:258
           Scraping from                                              base.py:41
           http://democracy.canterbury.gov.uk/mgWebService.asmx/GetCo           
           uncillorsByWard                                                      
[10:18:41] HTTPConnectionPool(host='democracy.canterbury.gov.uk', handlers.py:36
           port=80): Max retries exceeded with url:                             
           /mgWebService.asmx/GetCouncillorsByWard (Caused by                   
           ConnectTimeoutError(<urllib3.connection.HTTPConnection               
           object at 0x7fde405c8df0>, 'Connection to                            
           democracy.canterbury.gov.uk timed out. (connect                      
           timeout=None)'))                                                     
           Finished attempting to scrape: CAT                        base.py:339
</pre>
  

  


  <h2 id="2024-04-10-10-35">2024-04-10</h2>
  <div class="ds-card">
  <div class="ds-card-body">
    <dl class="ds-descriptions">
      <div>
        <dt>Duration</dt>
        <dd>131 seconds</dd>
      </div>
      <div>
        <dt>Start</dt>
        <dd>2024-04-10 10:35:58.650011</dd>
      </div>
      <div>
        <dt>End</dt>
        <dd>2024-04-10 10:38:10.074321</dd>
      </div>
      <div>
        <dt>Status code</dt>
        <dd>1</dd>
      </div>
      <div>
        <dt>Error</dt>
        <dd>Traceback (most recent call last):
  File "/opt/python/urllib3/connection.py", line 203, in _new_conn
    sock = connection.create_connection(
  File "/opt/python/urllib3/util/connection.py", line 85, in create_connection
    raise err
  File "/opt/python/urllib3/util/connection.py", line 73, in create_connection
    sock.connect(sa)
TimeoutError: [Errno 110] Connection timed out

The above exception was the direct cause of the following exception:

Traceback (most recent call last):
  File "/opt/python/urllib3/connectionpool.py", line 791, in urlopen
    response = self._make_request(
  File "/opt/python/urllib3/connectionpool.py", line 497, in _make_request
    conn.request(
  File "/opt/python/urllib3/connection.py", line 395, in request
    self.endheaders()
  File "/var/lang/lib/python3.10/http/client.py", line 1278, in endheaders
    self._send_output(message_body, encode_chunked=encode_chunked)
  File "/var/lang/lib/python3.10/http/client.py", line 1038, in _send_output
    self.send(msg)
  File "/var/lang/lib/python3.10/http/client.py", line 976, in send
    self.connect()
  File "/opt/python/urllib3/connection.py", line 243, in connect
    self.sock = self._new_conn()
  File "/opt/python/urllib3/connection.py", line 212, in _new_conn
    raise ConnectTimeoutError(
urllib3.exceptions.ConnectTimeoutError: (<urllib3.connection.HTTPConnection object at 0x7f4c679de4d0>, 'Connection to democracy.canterbury.gov.uk timed out. (connect timeout=None)')

The above exception was the direct cause of the following exception:

Traceback (most recent call last):
  File "/opt/python/requests/adapters.py", line 486, in send
    resp = conn.urlopen(
  File "/opt/python/urllib3/connectionpool.py", line 845, in urlopen
    retries = retries.increment(
  File "/opt/python/urllib3/util/retry.py", line 515, in increment
    raise MaxRetryError(_pool, url, reason) from reason  # type: ignore[arg-type]
urllib3.exceptions.MaxRetryError: HTTPConnectionPool(host='democracy.canterbury.gov.uk', port=80): Max retries exceeded with url: /mgWebService.asmx/GetCouncillorsByWard (Caused by ConnectTimeoutError(<urllib3.connection.HTTPConnection object at 0x7f4c679de4d0>, 'Connection to democracy.canterbury.gov.uk timed out. (connect timeout=None)'))

During handling of the above exception, another exception occurred:

Traceback (most recent call last):
  File "/var/task/lgsf/aws_lambda/handlers.py", line 32, in scraper_worker_handler
    scraper.run(run_log)
  File "/var/task/lgsf/councillors/scrapers.py", line 200, in run
    wards = self.get_councillors()
  File "/var/task/lgsf/councillors/scrapers.py", line 219, in get_councillors
    req = self.get(
  File "/var/task/lgsf/scrapers/base.py", line 47, in get
    response = self.requests_session.get(
  File "/opt/python/requests/sessions.py", line 602, in get
    return self.request("GET", url, **kwargs)
  File "/opt/python/requests/sessions.py", line 589, in request
    resp = self.send(prep, **send_kwargs)
  File "/opt/python/requests/sessions.py", line 703, in send
    r = adapter.send(request, **kwargs)
  File "/opt/python/requests/adapters.py", line 507, in send
    raise ConnectTimeout(e, request=request)
requests.exceptions.ConnectTimeout: HTTPConnectionPool(host='democracy.canterbury.gov.uk', port=80): Max retries exceeded with url: /mgWebService.asmx/GetCouncillorsByWard (Caused by ConnectTimeoutError(<urllib3.connection.HTTPConnection object at 0x7f4c679de4d0>, 'Connection to democracy.canterbury.gov.uk timed out. (connect timeout=None)'))
</dd>
      </div>
    </dl>
  </div>
  </div>

  <h3>Run log</h3>
  <pre>[10:35:58] Fetching Scraper for: CAT                              handlers.py:23
           Begin attempting to scrape: CAT                        handlers.py:27
           Deleting existing data...                                 base.py:251
[10:35:59] Getting all files in Councillors...                       base.py:203
           ...found 1 files in Councillors                           base.py:219
           Deleting batch no. 1 consisting of 1 files                base.py:230
[10:36:00] ...data deleted.                                          base.py:258
           Scraping from                                              base.py:41
           http://democracy.canterbury.gov.uk/mgWebService.asmx/GetCo           
           uncillorsByWard                                                      
[10:38:09] HTTPConnectionPool(host='democracy.canterbury.gov.uk', handlers.py:36
           port=80): Max retries exceeded with url:                             
           /mgWebService.asmx/GetCouncillorsByWard (Caused by                   
           ConnectTimeoutError(<urllib3.connection.HTTPConnection               
           object at 0x7f4c679de4d0>, 'Connection to                            
           democracy.canterbury.gov.uk timed out. (connect                      
           timeout=None)'))                                                     
[10:38:10] Finished attempting to scrape: CAT                        base.py:339
</pre>
  

  


  <h2 id="2024-04-09-09-13">2024-04-09</h2>
  <div class="ds-card">
  <div class="ds-card-body">
    <dl class="ds-descriptions">
      <div>
        <dt>Duration</dt>
        <dd>131 seconds</dd>
      </div>
      <div>
        <dt>Start</dt>
        <dd>2024-04-09 09:13:59.012491</dd>
      </div>
      <div>
        <dt>End</dt>
        <dd>2024-04-09 09:16:10.725973</dd>
      </div>
      <div>
        <dt>Status code</dt>
        <dd>1</dd>
      </div>
      <div>
        <dt>Error</dt>
        <dd>Traceback (most recent call last):
  File "/opt/python/urllib3/connection.py", line 203, in _new_conn
    sock = connection.create_connection(
  File "/opt/python/urllib3/util/connection.py", line 85, in create_connection
    raise err
  File "/opt/python/urllib3/util/connection.py", line 73, in create_connection
    sock.connect(sa)
TimeoutError: [Errno 110] Connection timed out

The above exception was the direct cause of the following exception:

Traceback (most recent call last):
  File "/opt/python/urllib3/connectionpool.py", line 791, in urlopen
    response = self._make_request(
  File "/opt/python/urllib3/connectionpool.py", line 497, in _make_request
    conn.request(
  File "/opt/python/urllib3/connection.py", line 395, in request
    self.endheaders()
  File "/var/lang/lib/python3.10/http/client.py", line 1278, in endheaders
    self._send_output(message_body, encode_chunked=encode_chunked)
  File "/var/lang/lib/python3.10/http/client.py", line 1038, in _send_output
    self.send(msg)
  File "/var/lang/lib/python3.10/http/client.py", line 976, in send
    self.connect()
  File "/opt/python/urllib3/connection.py", line 243, in connect
    self.sock = self._new_conn()
  File "/opt/python/urllib3/connection.py", line 212, in _new_conn
    raise ConnectTimeoutError(
urllib3.exceptions.ConnectTimeoutError: (<urllib3.connection.HTTPConnection object at 0x7f2c07db7160>, 'Connection to democracy.canterbury.gov.uk timed out. (connect timeout=None)')

The above exception was the direct cause of the following exception:

Traceback (most recent call last):
  File "/opt/python/requests/adapters.py", line 486, in send
    resp = conn.urlopen(
  File "/opt/python/urllib3/connectionpool.py", line 845, in urlopen
    retries = retries.increment(
  File "/opt/python/urllib3/util/retry.py", line 515, in increment
    raise MaxRetryError(_pool, url, reason) from reason  # type: ignore[arg-type]
urllib3.exceptions.MaxRetryError: HTTPConnectionPool(host='democracy.canterbury.gov.uk', port=80): Max retries exceeded with url: /mgWebService.asmx/GetCouncillorsByWard (Caused by ConnectTimeoutError(<urllib3.connection.HTTPConnection object at 0x7f2c07db7160>, 'Connection to democracy.canterbury.gov.uk timed out. (connect timeout=None)'))

During handling of the above exception, another exception occurred:

Traceback (most recent call last):
  File "/var/task/lgsf/aws_lambda/handlers.py", line 32, in scraper_worker_handler
    scraper.run(run_log)
  File "/var/task/lgsf/councillors/scrapers.py", line 200, in run
    wards = self.get_councillors()
  File "/var/task/lgsf/councillors/scrapers.py", line 219, in get_councillors
    req = self.get(
  File "/var/task/lgsf/scrapers/base.py", line 47, in get
    response = self.requests_session.get(
  File "/opt/python/requests/sessions.py", line 602, in get
    return self.request("GET", url, **kwargs)
  File "/opt/python/requests/sessions.py", line 589, in request
    resp = self.send(prep, **send_kwargs)
  File "/opt/python/requests/sessions.py", line 703, in send
    r = adapter.send(request, **kwargs)
  File "/opt/python/requests/adapters.py", line 507, in send
    raise ConnectTimeout(e, request=request)
requests.exceptions.ConnectTimeout: HTTPConnectionPool(host='democracy.canterbury.gov.uk', port=80): Max retries exceeded with url: /mgWebService.asmx/GetCouncillorsByWard (Caused by ConnectTimeoutError(<urllib3.connection.HTTPConnection object at 0x7f2c07db7160>, 'Connection to democracy.canterbury.gov.uk timed out. (connect timeout=None)'))
</dd>
      </div>
    </dl>
  </div>
  </div>

  <h3>Run log</h3>
  <pre>[09:13:59] Fetching Scraper for: CAT                              handlers.py:23
           Begin attempting to scrape: CAT                        handlers.py:27
           Deleting existing data...                                 base.py:251
           Getting all files in Councillors...                       base.py:203
[09:14:00] ...found 1 files in Councillors                           base.py:219
           Deleting batch no. 1 consisting of 1 files                base.py:230
           ...data deleted.                                          base.py:258
           Scraping from                                              base.py:41
           http://democracy.canterbury.gov.uk/mgWebService.asmx/GetCo           
           uncillorsByWard                                                      
[09:16:10] HTTPConnectionPool(host='democracy.canterbury.gov.uk', handlers.py:36
           port=80): Max retries exceeded with url:                             
           /mgWebService.asmx/GetCouncillorsByWard (Caused by                   
           ConnectTimeoutError(<urllib3.connection.HTTPConnection               
           object at 0x7f2c07db7160>, 'Connection to                            
           democracy.canterbury.gov.uk timed out. (connect                      
           timeout=None)'))                                                     
           Finished attempting to scrape: CAT                        base.py:339
</pre>
  

  


  <h2 id="2024-04-08-10-46">2024-04-08</h2>
  <div class="ds-card">
  <div class="ds-card-body">
    <dl class="ds-descriptions">
      <div>
        <dt>Duration</dt>
        <dd>132 seconds</dd>
      </div>
      <div>
        <dt>Start</dt>
        <dd>2024-04-08 10:46:43.830107</dd>
      </div>
      <div>
        <dt>End</dt>
        <dd>2024-04-08 10:48:56.661903</dd>
      </div>
      <div>
        <dt>Status code</dt>
        <dd>1</dd>
      </div>
      <div>
        <dt>Error</dt>
        <dd>Traceback (most recent call last):
  File "/opt/python/urllib3/connection.py", line 203, in _new_conn
    sock = connection.create_connection(
  File "/opt/python/urllib3/util/connection.py", line 85, in create_connection
    raise err
  File "/opt/python/urllib3/util/connection.py", line 73, in create_connection
    sock.connect(sa)
TimeoutError: [Errno 110] Connection timed out

The above exception was the direct cause of the following exception:

Traceback (most recent call last):
  File "/opt/python/urllib3/connectionpool.py", line 791, in urlopen
    response = self._make_request(
  File "/opt/python/urllib3/connectionpool.py", line 497, in _make_request
    conn.request(
  File "/opt/python/urllib3/connection.py", line 395, in request
    self.endheaders()
  File "/var/lang/lib/python3.10/http/client.py", line 1278, in endheaders
    self._send_output(message_body, encode_chunked=encode_chunked)
  File "/var/lang/lib/python3.10/http/client.py", line 1038, in _send_output
    self.send(msg)
  File "/var/lang/lib/python3.10/http/client.py", line 976, in send
    self.connect()
  File "/opt/python/urllib3/connection.py", line 243, in connect
    self.sock = self._new_conn()
  File "/opt/python/urllib3/connection.py", line 212, in _new_conn
    raise ConnectTimeoutError(
urllib3.exceptions.ConnectTimeoutError: (<urllib3.connection.HTTPConnection object at 0x7fb8468b89d0>, 'Connection to democracy.canterbury.gov.uk timed out. (connect timeout=None)')

The above exception was the direct cause of the following exception:

Traceback (most recent call last):
  File "/opt/python/requests/adapters.py", line 486, in send
    resp = conn.urlopen(
  File "/opt/python/urllib3/connectionpool.py", line 845, in urlopen
    retries = retries.increment(
  File "/opt/python/urllib3/util/retry.py", line 515, in increment
    raise MaxRetryError(_pool, url, reason) from reason  # type: ignore[arg-type]
urllib3.exceptions.MaxRetryError: HTTPConnectionPool(host='democracy.canterbury.gov.uk', port=80): Max retries exceeded with url: /mgWebService.asmx/GetCouncillorsByWard (Caused by ConnectTimeoutError(<urllib3.connection.HTTPConnection object at 0x7fb8468b89d0>, 'Connection to democracy.canterbury.gov.uk timed out. (connect timeout=None)'))

During handling of the above exception, another exception occurred:

Traceback (most recent call last):
  File "/var/task/lgsf/aws_lambda/handlers.py", line 32, in scraper_worker_handler
    scraper.run(run_log)
  File "/var/task/lgsf/councillors/scrapers.py", line 200, in run
    wards = self.get_councillors()
  File "/var/task/lgsf/councillors/scrapers.py", line 219, in get_councillors
    req = self.get(
  File "/var/task/lgsf/scrapers/base.py", line 47, in get
    response = self.requests_session.get(
  File "/opt/python/requests/sessions.py", line 602, in get
    return self.request("GET", url, **kwargs)
  File "/opt/python/requests/sessions.py", line 589, in request
    resp = self.send(prep, **send_kwargs)
  File "/opt/python/requests/sessions.py", line 703, in send
    r = adapter.send(request, **kwargs)
  File "/opt/python/requests/adapters.py", line 507, in send
    raise ConnectTimeout(e, request=request)
requests.exceptions.ConnectTimeout: HTTPConnectionPool(host='democracy.canterbury.gov.uk', port=80): Max retries exceeded with url: /mgWebService.asmx/GetCouncillorsByWard (Caused by ConnectTimeoutError(<urllib3.connection.HTTPConnection object at 0x7fb8468b89d0>, 'Connection to democracy.canterbury.gov.uk timed out. (connect timeout=None)'))
</dd>
      </div>
    </dl>
  </div>
  </div>

  <h3>Run log</h3>
  <pre>[10:46:43] Fetching Scraper for: CAT                              handlers.py:23
           Begin attempting to scrape: CAT                        handlers.py:27
[10:46:44] Deleting existing data...                                 base.py:251
           Getting all files in Councillors...                       base.py:203
           ...found 1 files in Councillors                           base.py:219
           Deleting batch no. 1 consisting of 1 files                base.py:230
[10:46:45] ...data deleted.                                          base.py:258
           Scraping from                                              base.py:41
           http://democracy.canterbury.gov.uk/mgWebService.asmx/GetCo           
           uncillorsByWard                                                      
[10:48:56] HTTPConnectionPool(host='democracy.canterbury.gov.uk', handlers.py:36
           port=80): Max retries exceeded with url:                             
           /mgWebService.asmx/GetCouncillorsByWard (Caused by                   
           ConnectTimeoutError(<urllib3.connection.HTTPConnection               
           object at 0x7fb8468b89d0>, 'Connection to                            
           democracy.canterbury.gov.uk timed out. (connect                      
           timeout=None)'))                                                     
           Finished attempting to scrape: CAT                        base.py:339
</pre>
  

  


  <h2 id="2024-04-07-08-41">2024-04-07</h2>
  <div class="ds-card">
  <div class="ds-card-body">
    <dl class="ds-descriptions">
      <div>
        <dt>Duration</dt>
        <dd>131 seconds</dd>
      </div>
      <div>
        <dt>Start</dt>
        <dd>2024-04-07 08:41:09.417013</dd>
      </div>
      <div>
        <dt>End</dt>
        <dd>2024-04-07 08:43:21.029381</dd>
      </div>
      <div>
        <dt>Status code</dt>
        <dd>1</dd>
      </div>
      <div>
        <dt>Error</dt>
        <dd>Traceback (most recent call last):
  File "/opt/python/urllib3/connection.py", line 203, in _new_conn
    sock = connection.create_connection(
  File "/opt/python/urllib3/util/connection.py", line 85, in create_connection
    raise err
  File "/opt/python/urllib3/util/connection.py", line 73, in create_connection
    sock.connect(sa)
TimeoutError: [Errno 110] Connection timed out

The above exception was the direct cause of the following exception:

Traceback (most recent call last):
  File "/opt/python/urllib3/connectionpool.py", line 791, in urlopen
    response = self._make_request(
  File "/opt/python/urllib3/connectionpool.py", line 497, in _make_request
    conn.request(
  File "/opt/python/urllib3/connection.py", line 395, in request
    self.endheaders()
  File "/var/lang/lib/python3.10/http/client.py", line 1278, in endheaders
    self._send_output(message_body, encode_chunked=encode_chunked)
  File "/var/lang/lib/python3.10/http/client.py", line 1038, in _send_output
    self.send(msg)
  File "/var/lang/lib/python3.10/http/client.py", line 976, in send
    self.connect()
  File "/opt/python/urllib3/connection.py", line 243, in connect
    self.sock = self._new_conn()
  File "/opt/python/urllib3/connection.py", line 212, in _new_conn
    raise ConnectTimeoutError(
urllib3.exceptions.ConnectTimeoutError: (<urllib3.connection.HTTPConnection object at 0x7f931ff91f60>, 'Connection to democracy.canterbury.gov.uk timed out. (connect timeout=None)')

The above exception was the direct cause of the following exception:

Traceback (most recent call last):
  File "/opt/python/requests/adapters.py", line 486, in send
    resp = conn.urlopen(
  File "/opt/python/urllib3/connectionpool.py", line 845, in urlopen
    retries = retries.increment(
  File "/opt/python/urllib3/util/retry.py", line 515, in increment
    raise MaxRetryError(_pool, url, reason) from reason  # type: ignore[arg-type]
urllib3.exceptions.MaxRetryError: HTTPConnectionPool(host='democracy.canterbury.gov.uk', port=80): Max retries exceeded with url: /mgWebService.asmx/GetCouncillorsByWard (Caused by ConnectTimeoutError(<urllib3.connection.HTTPConnection object at 0x7f931ff91f60>, 'Connection to democracy.canterbury.gov.uk timed out. (connect timeout=None)'))

During handling of the above exception, another exception occurred:

Traceback (most recent call last):
  File "/var/task/lgsf/aws_lambda/handlers.py", line 32, in scraper_worker_handler
    scraper.run(run_log)
  File "/var/task/lgsf/councillors/scrapers.py", line 200, in run
    wards = self.get_councillors()
  File "/var/task/lgsf/councillors/scrapers.py", line 219, in get_councillors
    req = self.get(
  File "/var/task/lgsf/scrapers/base.py", line 47, in get
    response = self.requests_session.get(
  File "/opt/python/requests/sessions.py", line 602, in get
    return self.request("GET", url, **kwargs)
  File "/opt/python/requests/sessions.py", line 589, in request
    resp = self.send(prep, **send_kwargs)
  File "/opt/python/requests/sessions.py", line 703, in send
    r = adapter.send(request, **kwargs)
  File "/opt/python/requests/adapters.py", line 507, in send
    raise ConnectTimeout(e, request=request)
requests.exceptions.ConnectTimeout: HTTPConnectionPool(host='democracy.canterbury.gov.uk', port=80): Max retries exceeded with url: /mgWebService.asmx/GetCouncillorsByWard (Caused by ConnectTimeoutError(<urllib3.connection.HTTPConnection object at 0x7f931ff91f60>, 'Connection to democracy.canterbury.gov.uk timed out. (connect timeout=None)'))
</dd>
      </div>
    </dl>
  </div>
  </div>

  <h3>Run log</h3>
  <pre>[08:41:09] Fetching Scraper for: CAT                              handlers.py:23
           Begin attempting to scrape: CAT                        handlers.py:27
           Deleting existing data...                                 base.py:251
[08:41:10] Getting all files in Councillors...                       base.py:203
           ...found 1 files in Councillors                           base.py:219
           Deleting batch no. 1 consisting of 1 files                base.py:230
[08:41:11] ...data deleted.                                          base.py:258
           Scraping from                                              base.py:41
           http://democracy.canterbury.gov.uk/mgWebService.asmx/GetCo           
           uncillorsByWard                                                      
[08:43:20] HTTPConnectionPool(host='democracy.canterbury.gov.uk', handlers.py:36
           port=80): Max retries exceeded with url:                             
           /mgWebService.asmx/GetCouncillorsByWard (Caused by                   
           ConnectTimeoutError(<urllib3.connection.HTTPConnection               
           object at 0x7f931ff91f60>, 'Connection to                            
           democracy.canterbury.gov.uk timed out. (connect                      
           timeout=None)'))                                                     
[08:43:21] Finished attempting to scrape: CAT                        base.py:339
</pre>
  

  


  <h2 id="2024-04-06-10-08">2024-04-06</h2>
  <div class="ds-card">
  <div class="ds-card-body">
    <dl class="ds-descriptions">
      <div>
        <dt>Duration</dt>
        <dd>131 seconds</dd>
      </div>
      <div>
        <dt>Start</dt>
        <dd>2024-04-06 10:08:27.936628</dd>
      </div>
      <div>
        <dt>End</dt>
        <dd>2024-04-06 10:10:39.634537</dd>
      </div>
      <div>
        <dt>Status code</dt>
        <dd>1</dd>
      </div>
      <div>
        <dt>Error</dt>
        <dd>Traceback (most recent call last):
  File "/opt/python/urllib3/connection.py", line 203, in _new_conn
    sock = connection.create_connection(
  File "/opt/python/urllib3/util/connection.py", line 85, in create_connection
    raise err
  File "/opt/python/urllib3/util/connection.py", line 73, in create_connection
    sock.connect(sa)
TimeoutError: [Errno 110] Connection timed out

The above exception was the direct cause of the following exception:

Traceback (most recent call last):
  File "/opt/python/urllib3/connectionpool.py", line 791, in urlopen
    response = self._make_request(
  File "/opt/python/urllib3/connectionpool.py", line 497, in _make_request
    conn.request(
  File "/opt/python/urllib3/connection.py", line 395, in request
    self.endheaders()
  File "/var/lang/lib/python3.10/http/client.py", line 1278, in endheaders
    self._send_output(message_body, encode_chunked=encode_chunked)
  File "/var/lang/lib/python3.10/http/client.py", line 1038, in _send_output
    self.send(msg)
  File "/var/lang/lib/python3.10/http/client.py", line 976, in send
    self.connect()
  File "/opt/python/urllib3/connection.py", line 243, in connect
    self.sock = self._new_conn()
  File "/opt/python/urllib3/connection.py", line 212, in _new_conn
    raise ConnectTimeoutError(
urllib3.exceptions.ConnectTimeoutError: (<urllib3.connection.HTTPConnection object at 0x7f4ef4a02380>, 'Connection to democracy.canterbury.gov.uk timed out. (connect timeout=None)')

The above exception was the direct cause of the following exception:

Traceback (most recent call last):
  File "/opt/python/requests/adapters.py", line 486, in send
    resp = conn.urlopen(
  File "/opt/python/urllib3/connectionpool.py", line 845, in urlopen
    retries = retries.increment(
  File "/opt/python/urllib3/util/retry.py", line 515, in increment
    raise MaxRetryError(_pool, url, reason) from reason  # type: ignore[arg-type]
urllib3.exceptions.MaxRetryError: HTTPConnectionPool(host='democracy.canterbury.gov.uk', port=80): Max retries exceeded with url: /mgWebService.asmx/GetCouncillorsByWard (Caused by ConnectTimeoutError(<urllib3.connection.HTTPConnection object at 0x7f4ef4a02380>, 'Connection to democracy.canterbury.gov.uk timed out. (connect timeout=None)'))

During handling of the above exception, another exception occurred:

Traceback (most recent call last):
  File "/var/task/lgsf/aws_lambda/handlers.py", line 32, in scraper_worker_handler
    scraper.run(run_log)
  File "/var/task/lgsf/councillors/scrapers.py", line 200, in run
    wards = self.get_councillors()
  File "/var/task/lgsf/councillors/scrapers.py", line 219, in get_councillors
    req = self.get(
  File "/var/task/lgsf/scrapers/base.py", line 47, in get
    response = self.requests_session.get(
  File "/opt/python/requests/sessions.py", line 602, in get
    return self.request("GET", url, **kwargs)
  File "/opt/python/requests/sessions.py", line 589, in request
    resp = self.send(prep, **send_kwargs)
  File "/opt/python/requests/sessions.py", line 703, in send
    r = adapter.send(request, **kwargs)
  File "/opt/python/requests/adapters.py", line 507, in send
    raise ConnectTimeout(e, request=request)
requests.exceptions.ConnectTimeout: HTTPConnectionPool(host='democracy.canterbury.gov.uk', port=80): Max retries exceeded with url: /mgWebService.asmx/GetCouncillorsByWard (Caused by ConnectTimeoutError(<urllib3.connection.HTTPConnection object at 0x7f4ef4a02380>, 'Connection to democracy.canterbury.gov.uk timed out. (connect timeout=None)'))
</dd>
      </div>
    </dl>
  </div>
  </div>

  <h3>Run log</h3>
  <pre>[10:08:27] Fetching Scraper for: CAT                              handlers.py:23
           Begin attempting to scrape: CAT                        handlers.py:27
[10:08:28] Deleting existing data...                                 base.py:251
           Getting all files in Councillors...                       base.py:203
           ...found 1 files in Councillors                           base.py:219
           Deleting batch no. 1 consisting of 1 files                base.py:230
[10:08:29] ...data deleted.                                          base.py:258
           Scraping from                                              base.py:41
           http://democracy.canterbury.gov.uk/mgWebService.asmx/GetCo           
           uncillorsByWard                                                      
[10:10:39] HTTPConnectionPool(host='democracy.canterbury.gov.uk', handlers.py:36
           port=80): Max retries exceeded with url:                             
           /mgWebService.asmx/GetCouncillorsByWard (Caused by                   
           ConnectTimeoutError(<urllib3.connection.HTTPConnection               
           object at 0x7f4ef4a02380>, 'Connection to                            
           democracy.canterbury.gov.uk timed out. (connect                      
           timeout=None)'))                                                     
           Finished attempting to scrape: CAT                        base.py:339
</pre>
  

  


  <h2 id="2024-04-05-09-07">2024-04-05</h2>
  <div class="ds-card">
  <div class="ds-card-body">
    <dl class="ds-descriptions">
      <div>
        <dt>Duration</dt>
        <dd>131 seconds</dd>
      </div>
      <div>
        <dt>Start</dt>
        <dd>2024-04-05 09:07:07.452507</dd>
      </div>
      <div>
        <dt>End</dt>
        <dd>2024-04-05 09:09:19.298579</dd>
      </div>
      <div>
        <dt>Status code</dt>
        <dd>1</dd>
      </div>
      <div>
        <dt>Error</dt>
        <dd>Traceback (most recent call last):
  File "/opt/python/urllib3/connection.py", line 203, in _new_conn
    sock = connection.create_connection(
  File "/opt/python/urllib3/util/connection.py", line 85, in create_connection
    raise err
  File "/opt/python/urllib3/util/connection.py", line 73, in create_connection
    sock.connect(sa)
TimeoutError: [Errno 110] Connection timed out

The above exception was the direct cause of the following exception:

Traceback (most recent call last):
  File "/opt/python/urllib3/connectionpool.py", line 791, in urlopen
    response = self._make_request(
  File "/opt/python/urllib3/connectionpool.py", line 497, in _make_request
    conn.request(
  File "/opt/python/urllib3/connection.py", line 395, in request
    self.endheaders()
  File "/var/lang/lib/python3.10/http/client.py", line 1278, in endheaders
    self._send_output(message_body, encode_chunked=encode_chunked)
  File "/var/lang/lib/python3.10/http/client.py", line 1038, in _send_output
    self.send(msg)
  File "/var/lang/lib/python3.10/http/client.py", line 976, in send
    self.connect()
  File "/opt/python/urllib3/connection.py", line 243, in connect
    self.sock = self._new_conn()
  File "/opt/python/urllib3/connection.py", line 212, in _new_conn
    raise ConnectTimeoutError(
urllib3.exceptions.ConnectTimeoutError: (<urllib3.connection.HTTPConnection object at 0x7fedf0a84520>, 'Connection to democracy.canterbury.gov.uk timed out. (connect timeout=None)')

The above exception was the direct cause of the following exception:

Traceback (most recent call last):
  File "/opt/python/requests/adapters.py", line 486, in send
    resp = conn.urlopen(
  File "/opt/python/urllib3/connectionpool.py", line 845, in urlopen
    retries = retries.increment(
  File "/opt/python/urllib3/util/retry.py", line 515, in increment
    raise MaxRetryError(_pool, url, reason) from reason  # type: ignore[arg-type]
urllib3.exceptions.MaxRetryError: HTTPConnectionPool(host='democracy.canterbury.gov.uk', port=80): Max retries exceeded with url: /mgWebService.asmx/GetCouncillorsByWard (Caused by ConnectTimeoutError(<urllib3.connection.HTTPConnection object at 0x7fedf0a84520>, 'Connection to democracy.canterbury.gov.uk timed out. (connect timeout=None)'))

During handling of the above exception, another exception occurred:

Traceback (most recent call last):
  File "/var/task/lgsf/aws_lambda/handlers.py", line 32, in scraper_worker_handler
    scraper.run(run_log)
  File "/var/task/lgsf/councillors/scrapers.py", line 200, in run
    wards = self.get_councillors()
  File "/var/task/lgsf/councillors/scrapers.py", line 219, in get_councillors
    req = self.get(
  File "/var/task/lgsf/scrapers/base.py", line 47, in get
    response = self.requests_session.get(
  File "/opt/python/requests/sessions.py", line 602, in get
    return self.request("GET", url, **kwargs)
  File "/opt/python/requests/sessions.py", line 589, in request
    resp = self.send(prep, **send_kwargs)
  File "/opt/python/requests/sessions.py", line 703, in send
    r = adapter.send(request, **kwargs)
  File "/opt/python/requests/adapters.py", line 507, in send
    raise ConnectTimeout(e, request=request)
requests.exceptions.ConnectTimeout: HTTPConnectionPool(host='democracy.canterbury.gov.uk', port=80): Max retries exceeded with url: /mgWebService.asmx/GetCouncillorsByWard (Caused by ConnectTimeoutError(<urllib3.connection.HTTPConnection object at 0x7fedf0a84520>, 'Connection to democracy.canterbury.gov.uk timed out. (connect timeout=None)'))
</dd>
      </div>
    </dl>
  </div>
  </div>

  <h3>Run log</h3>
  <pre>[09:07:07] Fetching Scraper for: CAT                              handlers.py:23
           Begin attempting to scrape: CAT                        handlers.py:27
           Deleting existing data...                                 base.py:251
[09:07:08] Getting all files in Councillors...                       base.py:203
           ...found 1 files in Councillors                           base.py:219
           Deleting batch no. 1 consisting of 1 files                base.py:230
[09:07:09] ...data deleted.                                          base.py:258
           Scraping from                                              base.py:41
           http://democracy.canterbury.gov.uk/mgWebService.asmx/GetCo           
           uncillorsByWard                                                      
[09:09:18] HTTPConnectionPool(host='democracy.canterbury.gov.uk', handlers.py:36
           port=80): Max retries exceeded with url:                             
           /mgWebService.asmx/GetCouncillorsByWard (Caused by                   
           ConnectTimeoutError(<urllib3.connection.HTTPConnection               
           object at 0x7fedf0a84520>, 'Connection to                            
           democracy.canterbury.gov.uk timed out. (connect                      
           timeout=None)'))                                                     
[09:09:19] Finished attempting to scrape: CAT                        base.py:339
</pre>
  

  


  <h2 id="2024-04-04-08-54">2024-04-04</h2>
  <div class="ds-card">
  <div class="ds-card-body">
    <dl class="ds-descriptions">
      <div>
        <dt>Duration</dt>
        <dd>133 seconds</dd>
      </div>
      <div>
        <dt>Start</dt>
        <dd>2024-04-04 08:54:39.243511</dd>
      </div>
      <div>
        <dt>End</dt>
        <dd>2024-04-04 08:56:52.378203</dd>
      </div>
      <div>
        <dt>Status code</dt>
        <dd>1</dd>
      </div>
      <div>
        <dt>Error</dt>
        <dd>Traceback (most recent call last):
  File "/opt/python/urllib3/connection.py", line 203, in _new_conn
    sock = connection.create_connection(
  File "/opt/python/urllib3/util/connection.py", line 85, in create_connection
    raise err
  File "/opt/python/urllib3/util/connection.py", line 73, in create_connection
    sock.connect(sa)
TimeoutError: [Errno 110] Connection timed out

The above exception was the direct cause of the following exception:

Traceback (most recent call last):
  File "/opt/python/urllib3/connectionpool.py", line 791, in urlopen
    response = self._make_request(
  File "/opt/python/urllib3/connectionpool.py", line 497, in _make_request
    conn.request(
  File "/opt/python/urllib3/connection.py", line 395, in request
    self.endheaders()
  File "/var/lang/lib/python3.10/http/client.py", line 1278, in endheaders
    self._send_output(message_body, encode_chunked=encode_chunked)
  File "/var/lang/lib/python3.10/http/client.py", line 1038, in _send_output
    self.send(msg)
  File "/var/lang/lib/python3.10/http/client.py", line 976, in send
    self.connect()
  File "/opt/python/urllib3/connection.py", line 243, in connect
    self.sock = self._new_conn()
  File "/opt/python/urllib3/connection.py", line 212, in _new_conn
    raise ConnectTimeoutError(
urllib3.exceptions.ConnectTimeoutError: (<urllib3.connection.HTTPConnection object at 0x7f4a95e23070>, 'Connection to democracy.canterbury.gov.uk timed out. (connect timeout=None)')

The above exception was the direct cause of the following exception:

Traceback (most recent call last):
  File "/opt/python/requests/adapters.py", line 486, in send
    resp = conn.urlopen(
  File "/opt/python/urllib3/connectionpool.py", line 845, in urlopen
    retries = retries.increment(
  File "/opt/python/urllib3/util/retry.py", line 515, in increment
    raise MaxRetryError(_pool, url, reason) from reason  # type: ignore[arg-type]
urllib3.exceptions.MaxRetryError: HTTPConnectionPool(host='democracy.canterbury.gov.uk', port=80): Max retries exceeded with url: /mgWebService.asmx/GetCouncillorsByWard (Caused by ConnectTimeoutError(<urllib3.connection.HTTPConnection object at 0x7f4a95e23070>, 'Connection to democracy.canterbury.gov.uk timed out. (connect timeout=None)'))

During handling of the above exception, another exception occurred:

Traceback (most recent call last):
  File "/var/task/lgsf/aws_lambda/handlers.py", line 32, in scraper_worker_handler
    scraper.run(run_log)
  File "/var/task/lgsf/councillors/scrapers.py", line 200, in run
    wards = self.get_councillors()
  File "/var/task/lgsf/councillors/scrapers.py", line 219, in get_councillors
    req = self.get(
  File "/var/task/lgsf/scrapers/base.py", line 47, in get
    response = self.requests_session.get(
  File "/opt/python/requests/sessions.py", line 602, in get
    return self.request("GET", url, **kwargs)
  File "/opt/python/requests/sessions.py", line 589, in request
    resp = self.send(prep, **send_kwargs)
  File "/opt/python/requests/sessions.py", line 703, in send
    r = adapter.send(request, **kwargs)
  File "/opt/python/requests/adapters.py", line 507, in send
    raise ConnectTimeout(e, request=request)
requests.exceptions.ConnectTimeout: HTTPConnectionPool(host='democracy.canterbury.gov.uk', port=80): Max retries exceeded with url: /mgWebService.asmx/GetCouncillorsByWard (Caused by ConnectTimeoutError(<urllib3.connection.HTTPConnection object at 0x7f4a95e23070>, 'Connection to democracy.canterbury.gov.uk timed out. (connect timeout=None)'))
</dd>
      </div>
    </dl>
  </div>
  </div>

  <h3>Run log</h3>
  <pre>[08:54:39] Fetching Scraper for: CAT                              handlers.py:23
           Begin attempting to scrape: CAT                        handlers.py:27
           Deleting existing data...                                 base.py:251
[08:54:40] Getting all files in Councillors...                       base.py:203
           ...found 1 files in Councillors                           base.py:219
           Deleting batch no. 1 consisting of 1 files                base.py:230
[08:54:41] ...data deleted.                                          base.py:258
           Scraping from                                              base.py:41
           http://democracy.canterbury.gov.uk/mgWebService.asmx/GetCo           
           uncillorsByWard                                                      
[08:56:52] HTTPConnectionPool(host='democracy.canterbury.gov.uk', handlers.py:36
           port=80): Max retries exceeded with url:                             
           /mgWebService.asmx/GetCouncillorsByWard (Caused by                   
           ConnectTimeoutError(<urllib3.connection.HTTPConnection               
           object at 0x7f4a95e23070>, 'Connection to                            
           democracy.canterbury.gov.uk timed out. (connect                      
           timeout=None)'))                                                     
           Finished attempting to scrape: CAT                        base.py:339
</pre>
  


      </main>
      <footer class="ds-footer">
        <div class="ds-block-centered ds-text-centered ds-stack">
          <div class="ds-cluster-center">
            <ul>
              <li><a href="/lgsf-dashboard/api/failing.json">Failing JSON</a></li>
            </ul>
          </div>
          <div class="ds-copyright">
            <a href="https://democracyclub.org.uk/">
              <img src="https://DemocracyClub.github.io/design-system/images/logo_white_text.svg" alt="Democracy Club Home" />
            </a>
            <p>Copyright © 2021 Democracy Club</p>
            <p>Community Interest Company</p>
            <p>Company No: <a href="https://beta.companieshouse.gov.uk/company/09461226">09461226</a></p>
          </div>
        </div>
      </footer>
    </div>
  </body>
