<!doctype html>
<html>
  <head>
    <title>LGSF Dashboard</title>
    <link rel="stylesheet"  href="/lgsf-dashboard/assets/css/styles.css">
    <link rel="shortcut icon" href="https://democracyclub.org.uk/static/images/logo_icon.png">
  </head>
  <body>
    <div class="ds-page">
      <a class="ds-skip-link" href="#main">skip to content</a>

      <header class="ds-header">
        <a class="ds-skip-link" href="#main">skip to content</a>
        <a class="ds-logo" href="/lgsf-dashboard/">
          <img src="https://DemocracyClub.github.io/design-system/images/logo_icon.svg" alt="" />
          <span>LGSF Logbooks</span>
        </a>

      </header>


      <main id="main" tabindex="-1" class="ds-stack">

        
<style>

    pre {
        height:400px;
        overflow-x: scroll;
        width:100%
    }
</style>




  


  <h2 id="2023-04-10-15-15">2023-04-10</h2>
  <div class="ds-card">
  <div class="ds-card-body">
    <dl class="ds-descriptions">
      <div>
        <dt>Duration</dt>
        <dd>2 seconds</dd>
      </div>
      <div>
        <dt>Start</dt>
        <dd>2023-04-10 15:15:58.843119</dd>
      </div>
      <div>
        <dt>End</dt>
        <dd>2023-04-10 15:16:00.945975</dd>
      </div>
      <div>
        <dt>Status code</dt>
        <dd>1</dd>
      </div>
      <div>
        <dt>Error</dt>
        <dd>Traceback (most recent call last):
  File "/opt/python/urllib3/connection.py", line 174, in _new_conn
    conn = connection.create_connection(
  File "/opt/python/urllib3/util/connection.py", line 72, in create_connection
    for res in socket.getaddrinfo(host, port, family, socket.SOCK_STREAM):
  File "/var/lang/lib/python3.8/socket.py", line 918, in getaddrinfo
    for res in _socket.getaddrinfo(host, port, family, type, proto, flags):
socket.gaierror: [Errno -5] No address associated with hostname

During handling of the above exception, another exception occurred:

Traceback (most recent call last):
  File "/opt/python/urllib3/connectionpool.py", line 703, in urlopen
    httplib_response = self._make_request(
  File "/opt/python/urllib3/connectionpool.py", line 386, in _make_request
    self._validate_conn(conn)
  File "/opt/python/urllib3/connectionpool.py", line 1042, in _validate_conn
    conn.connect()
  File "/opt/python/urllib3/connection.py", line 358, in connect
    self.sock = conn = self._new_conn()
  File "/opt/python/urllib3/connection.py", line 186, in _new_conn
    raise NewConnectionError(
urllib3.exceptions.NewConnectionError: <urllib3.connection.HTTPSConnection object at 0x7f18306b75b0>: Failed to establish a new connection: [Errno -5] No address associated with hostname

During handling of the above exception, another exception occurred:

Traceback (most recent call last):
  File "/opt/python/requests/adapters.py", line 489, in send
    resp = conn.urlopen(
  File "/opt/python/urllib3/connectionpool.py", line 787, in urlopen
    retries = retries.increment(
  File "/opt/python/urllib3/util/retry.py", line 592, in increment
    raise MaxRetryError(_pool, url, error or ResponseError(cause))
urllib3.exceptions.MaxRetryError: HTTPSConnectionPool(host='estates4.warwickdc.gov.uk', port=443): Max retries exceeded with url: /cmis/CouncillorsAtoZ/tabid/39/ScreenMode/Ward/Default.aspx (Caused by NewConnectionError('<urllib3.connection.HTTPSConnection object at 0x7f18306b75b0>: Failed to establish a new connection: [Errno -5] No address associated with hostname'))

During handling of the above exception, another exception occurred:

Traceback (most recent call last):
  File "/var/task/lgsf/aws_lambda/handlers.py", line 32, in scraper_worker_handler
    scraper.run(run_log)
  File "/var/task/lgsf/councillors/scrapers.py", line 46, in run
    for councillor_html in self.get_councillors():
  File "/var/task/lgsf/councillors/scrapers.py", line 242, in get_councillors
    req = self.get(self.base_url, extra_headers=self.extra_headers)
  File "/var/task/lgsf/scrapers/base.py", line 48, in get
    response = self.requests_session.get(url, headers=headers, verify=verify)
  File "/opt/python/requests/sessions.py", line 600, in get
    return self.request("GET", url, **kwargs)
  File "/opt/python/requests/sessions.py", line 587, in request
    resp = self.send(prep, **send_kwargs)
  File "/opt/python/requests/sessions.py", line 701, in send
    r = adapter.send(request, **kwargs)
  File "/opt/python/requests/adapters.py", line 565, in send
    raise ConnectionError(e, request=request)
requests.exceptions.ConnectionError: HTTPSConnectionPool(host='estates4.warwickdc.gov.uk', port=443): Max retries exceeded with url: /cmis/CouncillorsAtoZ/tabid/39/ScreenMode/Ward/Default.aspx (Caused by NewConnectionError('<urllib3.connection.HTTPSConnection object at 0x7f18306b75b0>: Failed to establish a new connection: [Errno -5] No address associated with hostname'))
</dd>
      </div>
    </dl>
  </div>
  </div>

  <h3>Run log</h3>
  <pre>[15:15:58] Fetching Scraper for: WAW                              handlers.py:23
           Begin attempting to scrape: WAW                        handlers.py:27
[15:15:59] Deleting existing data...                                 base.py:239
           Getting all files in Councillors...                       base.py:191
           ...found 1 files in Councillors                           base.py:207
           Deleting batch no. 1 consisting of 1 files                base.py:216
[15:16:00] ...data deleted.                                          base.py:246
           Scraping from                                              base.py:42
           https://estates4.warwickdc.gov.uk/cmis/CouncillorsAtoZ/tab           
           id/39/ScreenMode/Ward/Default.aspx                                   
           HTTPSConnectionPool(host='estates4.warwickdc.gov.uk',  handlers.py:36
           port=443): Max retries exceeded with url:                            
           /cmis/CouncillorsAtoZ/tabid/39/ScreenMode/Ward/Default               
           .aspx (Caused by                                                     
           NewConnectionError('<urllib3.connection.HTTPSConnectio               
           n object at 0x7f18306b75b0>: Failed to establish a new               
           connection: [Errno -5] No address associated with                    
           hostname'))                                                          
           Finished attempting to scrape: WAW                        base.py:324
</pre>
  

  


  <h2 id="2023-04-03-13-45">2023-04-03</h2>
  <div class="ds-card">
  <div class="ds-card-body">
    <dl class="ds-descriptions">
      <div>
        <dt>Duration</dt>
        <dd>2 seconds</dd>
      </div>
      <div>
        <dt>Start</dt>
        <dd>2023-04-03 13:45:32.539724</dd>
      </div>
      <div>
        <dt>End</dt>
        <dd>2023-04-03 13:45:34.768321</dd>
      </div>
      <div>
        <dt>Status code</dt>
        <dd>1</dd>
      </div>
      <div>
        <dt>Error</dt>
        <dd>Traceback (most recent call last):
  File "/opt/python/urllib3/connection.py", line 174, in _new_conn
    conn = connection.create_connection(
  File "/opt/python/urllib3/util/connection.py", line 72, in create_connection
    for res in socket.getaddrinfo(host, port, family, socket.SOCK_STREAM):
  File "/var/lang/lib/python3.8/socket.py", line 918, in getaddrinfo
    for res in _socket.getaddrinfo(host, port, family, type, proto, flags):
socket.gaierror: [Errno -5] No address associated with hostname

During handling of the above exception, another exception occurred:

Traceback (most recent call last):
  File "/opt/python/urllib3/connectionpool.py", line 703, in urlopen
    httplib_response = self._make_request(
  File "/opt/python/urllib3/connectionpool.py", line 386, in _make_request
    self._validate_conn(conn)
  File "/opt/python/urllib3/connectionpool.py", line 1042, in _validate_conn
    conn.connect()
  File "/opt/python/urllib3/connection.py", line 358, in connect
    self.sock = conn = self._new_conn()
  File "/opt/python/urllib3/connection.py", line 186, in _new_conn
    raise NewConnectionError(
urllib3.exceptions.NewConnectionError: <urllib3.connection.HTTPSConnection object at 0x7fac34778040>: Failed to establish a new connection: [Errno -5] No address associated with hostname

During handling of the above exception, another exception occurred:

Traceback (most recent call last):
  File "/opt/python/requests/adapters.py", line 489, in send
    resp = conn.urlopen(
  File "/opt/python/urllib3/connectionpool.py", line 787, in urlopen
    retries = retries.increment(
  File "/opt/python/urllib3/util/retry.py", line 592, in increment
    raise MaxRetryError(_pool, url, error or ResponseError(cause))
urllib3.exceptions.MaxRetryError: HTTPSConnectionPool(host='estates4.warwickdc.gov.uk', port=443): Max retries exceeded with url: /cmis/CouncillorsAtoZ/tabid/39/ScreenMode/Ward/Default.aspx (Caused by NewConnectionError('<urllib3.connection.HTTPSConnection object at 0x7fac34778040>: Failed to establish a new connection: [Errno -5] No address associated with hostname'))

During handling of the above exception, another exception occurred:

Traceback (most recent call last):
  File "/var/task/lgsf/aws_lambda/handlers.py", line 32, in scraper_worker_handler
    scraper.run(run_log)
  File "/var/task/lgsf/councillors/scrapers.py", line 46, in run
    for councillor_html in self.get_councillors():
  File "/var/task/lgsf/councillors/scrapers.py", line 242, in get_councillors
    req = self.get(self.base_url, extra_headers=self.extra_headers)
  File "/var/task/lgsf/scrapers/base.py", line 48, in get
    response = self.requests_session.get(url, headers=headers, verify=verify)
  File "/opt/python/requests/sessions.py", line 600, in get
    return self.request("GET", url, **kwargs)
  File "/opt/python/requests/sessions.py", line 587, in request
    resp = self.send(prep, **send_kwargs)
  File "/opt/python/requests/sessions.py", line 701, in send
    r = adapter.send(request, **kwargs)
  File "/opt/python/requests/adapters.py", line 565, in send
    raise ConnectionError(e, request=request)
requests.exceptions.ConnectionError: HTTPSConnectionPool(host='estates4.warwickdc.gov.uk', port=443): Max retries exceeded with url: /cmis/CouncillorsAtoZ/tabid/39/ScreenMode/Ward/Default.aspx (Caused by NewConnectionError('<urllib3.connection.HTTPSConnection object at 0x7fac34778040>: Failed to establish a new connection: [Errno -5] No address associated with hostname'))
</dd>
      </div>
    </dl>
  </div>
  </div>

  <h3>Run log</h3>
  <pre>[13:45:32] Fetching Scraper for: WAW                              handlers.py:23
           Begin attempting to scrape: WAW                        handlers.py:27
           Deleting existing data...                                 base.py:239
[13:45:33] Getting all files in Councillors...                       base.py:191
           ...found 1 files in Councillors                           base.py:207
           Deleting batch no. 1 consisting of 1 files                base.py:216
[13:45:34] ...data deleted.                                          base.py:246
           Scraping from                                              base.py:42
           https://estates4.warwickdc.gov.uk/cmis/CouncillorsAtoZ/tab           
           id/39/ScreenMode/Ward/Default.aspx                                   
           HTTPSConnectionPool(host='estates4.warwickdc.gov.uk',  handlers.py:36
           port=443): Max retries exceeded with url:                            
           /cmis/CouncillorsAtoZ/tabid/39/ScreenMode/Ward/Default               
           .aspx (Caused by                                                     
           NewConnectionError('<urllib3.connection.HTTPSConnectio               
           n object at 0x7fac34778040>: Failed to establish a new               
           connection: [Errno -5] No address associated with                    
           hostname'))                                                          
           Finished attempting to scrape: WAW                        base.py:324
</pre>
  

  


  <h2 id="2023-03-27-14-43">2023-03-27</h2>
  <div class="ds-card">
  <div class="ds-card-body">
    <dl class="ds-descriptions">
      <div>
        <dt>Duration</dt>
        <dd>2 seconds</dd>
      </div>
      <div>
        <dt>Start</dt>
        <dd>2023-03-27 14:43:54.856159</dd>
      </div>
      <div>
        <dt>End</dt>
        <dd>2023-03-27 14:43:56.952331</dd>
      </div>
      <div>
        <dt>Status code</dt>
        <dd>1</dd>
      </div>
      <div>
        <dt>Error</dt>
        <dd>Traceback (most recent call last):
  File "/opt/python/urllib3/connection.py", line 174, in _new_conn
    conn = connection.create_connection(
  File "/opt/python/urllib3/util/connection.py", line 72, in create_connection
    for res in socket.getaddrinfo(host, port, family, socket.SOCK_STREAM):
  File "/var/lang/lib/python3.8/socket.py", line 918, in getaddrinfo
    for res in _socket.getaddrinfo(host, port, family, type, proto, flags):
socket.gaierror: [Errno -5] No address associated with hostname

During handling of the above exception, another exception occurred:

Traceback (most recent call last):
  File "/opt/python/urllib3/connectionpool.py", line 703, in urlopen
    httplib_response = self._make_request(
  File "/opt/python/urllib3/connectionpool.py", line 386, in _make_request
    self._validate_conn(conn)
  File "/opt/python/urllib3/connectionpool.py", line 1042, in _validate_conn
    conn.connect()
  File "/opt/python/urllib3/connection.py", line 358, in connect
    self.sock = conn = self._new_conn()
  File "/opt/python/urllib3/connection.py", line 186, in _new_conn
    raise NewConnectionError(
urllib3.exceptions.NewConnectionError: <urllib3.connection.HTTPSConnection object at 0x7fe7f572b790>: Failed to establish a new connection: [Errno -5] No address associated with hostname

During handling of the above exception, another exception occurred:

Traceback (most recent call last):
  File "/opt/python/requests/adapters.py", line 489, in send
    resp = conn.urlopen(
  File "/opt/python/urllib3/connectionpool.py", line 787, in urlopen
    retries = retries.increment(
  File "/opt/python/urllib3/util/retry.py", line 592, in increment
    raise MaxRetryError(_pool, url, error or ResponseError(cause))
urllib3.exceptions.MaxRetryError: HTTPSConnectionPool(host='estates4.warwickdc.gov.uk', port=443): Max retries exceeded with url: /cmis/CouncillorsAtoZ/tabid/39/ScreenMode/Ward/Default.aspx (Caused by NewConnectionError('<urllib3.connection.HTTPSConnection object at 0x7fe7f572b790>: Failed to establish a new connection: [Errno -5] No address associated with hostname'))

During handling of the above exception, another exception occurred:

Traceback (most recent call last):
  File "/var/task/lgsf/aws_lambda/handlers.py", line 32, in scraper_worker_handler
    scraper.run(run_log)
  File "/var/task/lgsf/councillors/scrapers.py", line 46, in run
    for councillor_html in self.get_councillors():
  File "/var/task/lgsf/councillors/scrapers.py", line 242, in get_councillors
    req = self.get(self.base_url, extra_headers=self.extra_headers)
  File "/var/task/lgsf/scrapers/base.py", line 48, in get
    response = self.requests_session.get(url, headers=headers, verify=verify)
  File "/opt/python/requests/sessions.py", line 600, in get
    return self.request("GET", url, **kwargs)
  File "/opt/python/requests/sessions.py", line 587, in request
    resp = self.send(prep, **send_kwargs)
  File "/opt/python/requests/sessions.py", line 701, in send
    r = adapter.send(request, **kwargs)
  File "/opt/python/requests/adapters.py", line 565, in send
    raise ConnectionError(e, request=request)
requests.exceptions.ConnectionError: HTTPSConnectionPool(host='estates4.warwickdc.gov.uk', port=443): Max retries exceeded with url: /cmis/CouncillorsAtoZ/tabid/39/ScreenMode/Ward/Default.aspx (Caused by NewConnectionError('<urllib3.connection.HTTPSConnection object at 0x7fe7f572b790>: Failed to establish a new connection: [Errno -5] No address associated with hostname'))
</dd>
      </div>
    </dl>
  </div>
  </div>

  <h3>Run log</h3>
  <pre>[14:43:54] Fetching Scraper for: WAW                              handlers.py:23
           Begin attempting to scrape: WAW                        handlers.py:27
[14:43:55] Deleting existing data...                                 base.py:239
           Getting all files in Councillors...                       base.py:191
           ...found 1 files in Councillors                           base.py:207
           Deleting batch no. 1 consisting of 1 files                base.py:216
[14:43:56] ...data deleted.                                          base.py:246
           Scraping from                                              base.py:42
           https://estates4.warwickdc.gov.uk/cmis/CouncillorsAtoZ/tab           
           id/39/ScreenMode/Ward/Default.aspx                                   
           HTTPSConnectionPool(host='estates4.warwickdc.gov.uk',  handlers.py:36
           port=443): Max retries exceeded with url:                            
           /cmis/CouncillorsAtoZ/tabid/39/ScreenMode/Ward/Default               
           .aspx (Caused by                                                     
           NewConnectionError('<urllib3.connection.HTTPSConnectio               
           n object at 0x7fe7f572b790>: Failed to establish a new               
           connection: [Errno -5] No address associated with                    
           hostname'))                                                          
           Finished attempting to scrape: WAW                        base.py:324
</pre>
  

  


  <h2 id="2023-03-20-15-10">2023-03-20</h2>
  <div class="ds-card">
  <div class="ds-card-body">
    <dl class="ds-descriptions">
      <div>
        <dt>Duration</dt>
        <dd>2 seconds</dd>
      </div>
      <div>
        <dt>Start</dt>
        <dd>2023-03-20 15:10:01.054752</dd>
      </div>
      <div>
        <dt>End</dt>
        <dd>2023-03-20 15:10:04.036123</dd>
      </div>
      <div>
        <dt>Status code</dt>
        <dd>1</dd>
      </div>
      <div>
        <dt>Error</dt>
        <dd>Traceback (most recent call last):
  File "/opt/python/urllib3/connection.py", line 174, in _new_conn
    conn = connection.create_connection(
  File "/opt/python/urllib3/util/connection.py", line 72, in create_connection
    for res in socket.getaddrinfo(host, port, family, socket.SOCK_STREAM):
  File "/var/lang/lib/python3.8/socket.py", line 918, in getaddrinfo
    for res in _socket.getaddrinfo(host, port, family, type, proto, flags):
socket.gaierror: [Errno -5] No address associated with hostname

During handling of the above exception, another exception occurred:

Traceback (most recent call last):
  File "/opt/python/urllib3/connectionpool.py", line 703, in urlopen
    httplib_response = self._make_request(
  File "/opt/python/urllib3/connectionpool.py", line 386, in _make_request
    self._validate_conn(conn)
  File "/opt/python/urllib3/connectionpool.py", line 1042, in _validate_conn
    conn.connect()
  File "/opt/python/urllib3/connection.py", line 358, in connect
    self.sock = conn = self._new_conn()
  File "/opt/python/urllib3/connection.py", line 186, in _new_conn
    raise NewConnectionError(
urllib3.exceptions.NewConnectionError: <urllib3.connection.HTTPSConnection object at 0x7ff18bcca160>: Failed to establish a new connection: [Errno -5] No address associated with hostname

During handling of the above exception, another exception occurred:

Traceback (most recent call last):
  File "/opt/python/requests/adapters.py", line 489, in send
    resp = conn.urlopen(
  File "/opt/python/urllib3/connectionpool.py", line 787, in urlopen
    retries = retries.increment(
  File "/opt/python/urllib3/util/retry.py", line 592, in increment
    raise MaxRetryError(_pool, url, error or ResponseError(cause))
urllib3.exceptions.MaxRetryError: HTTPSConnectionPool(host='estates4.warwickdc.gov.uk', port=443): Max retries exceeded with url: /cmis/CouncillorsAtoZ/tabid/39/ScreenMode/Ward/Default.aspx (Caused by NewConnectionError('<urllib3.connection.HTTPSConnection object at 0x7ff18bcca160>: Failed to establish a new connection: [Errno -5] No address associated with hostname'))

During handling of the above exception, another exception occurred:

Traceback (most recent call last):
  File "/var/task/lgsf/aws_lambda/handlers.py", line 32, in scraper_worker_handler
    scraper.run(run_log)
  File "/var/task/lgsf/councillors/scrapers.py", line 46, in run
    for councillor_html in self.get_councillors():
  File "/var/task/lgsf/councillors/scrapers.py", line 242, in get_councillors
    req = self.get(self.base_url, extra_headers=self.extra_headers)
  File "/var/task/lgsf/scrapers/base.py", line 48, in get
    response = self.requests_session.get(url, headers=headers, verify=verify)
  File "/opt/python/requests/sessions.py", line 600, in get
    return self.request("GET", url, **kwargs)
  File "/opt/python/requests/sessions.py", line 587, in request
    resp = self.send(prep, **send_kwargs)
  File "/opt/python/requests/sessions.py", line 701, in send
    r = adapter.send(request, **kwargs)
  File "/opt/python/requests/adapters.py", line 565, in send
    raise ConnectionError(e, request=request)
requests.exceptions.ConnectionError: HTTPSConnectionPool(host='estates4.warwickdc.gov.uk', port=443): Max retries exceeded with url: /cmis/CouncillorsAtoZ/tabid/39/ScreenMode/Ward/Default.aspx (Caused by NewConnectionError('<urllib3.connection.HTTPSConnection object at 0x7ff18bcca160>: Failed to establish a new connection: [Errno -5] No address associated with hostname'))
</dd>
      </div>
    </dl>
  </div>
  </div>

  <h3>Run log</h3>
  <pre>[15:10:01] Fetching Scraper for: WAW                              handlers.py:23
           Begin attempting to scrape: WAW                        handlers.py:27
           Deleting existing data...                                 base.py:239
           Getting all files in Councillors...                       base.py:191
[15:10:02] ...found 1 files in Councillors                           base.py:207
           Deleting batch no. 1 consisting of 1 files                base.py:216
[15:10:03] ...data deleted.                                          base.py:246
           Scraping from                                              base.py:42
           https://estates4.warwickdc.gov.uk/cmis/CouncillorsAtoZ/tab           
           id/39/ScreenMode/Ward/Default.aspx                                   
           HTTPSConnectionPool(host='estates4.warwickdc.gov.uk',  handlers.py:36
           port=443): Max retries exceeded with url:                            
           /cmis/CouncillorsAtoZ/tabid/39/ScreenMode/Ward/Default               
           .aspx (Caused by                                                     
           NewConnectionError('<urllib3.connection.HTTPSConnectio               
           n object at 0x7ff18bcca160>: Failed to establish a new               
           connection: [Errno -5] No address associated with                    
           hostname'))                                                          
[15:10:04] Finished attempting to scrape: WAW                        base.py:324
</pre>
  

  


  <h2 id="2023-03-13-13-55">2023-03-13</h2>
  <div class="ds-card">
  <div class="ds-card-body">
    <dl class="ds-descriptions">
      <div>
        <dt>Duration</dt>
        <dd>2 seconds</dd>
      </div>
      <div>
        <dt>Start</dt>
        <dd>2023-03-13 13:55:58.821675</dd>
      </div>
      <div>
        <dt>End</dt>
        <dd>2023-03-13 13:56:01.009205</dd>
      </div>
      <div>
        <dt>Status code</dt>
        <dd>1</dd>
      </div>
      <div>
        <dt>Error</dt>
        <dd>Traceback (most recent call last):
  File "/opt/python/urllib3/connection.py", line 174, in _new_conn
    conn = connection.create_connection(
  File "/opt/python/urllib3/util/connection.py", line 72, in create_connection
    for res in socket.getaddrinfo(host, port, family, socket.SOCK_STREAM):
  File "/var/lang/lib/python3.8/socket.py", line 918, in getaddrinfo
    for res in _socket.getaddrinfo(host, port, family, type, proto, flags):
socket.gaierror: [Errno -5] No address associated with hostname

During handling of the above exception, another exception occurred:

Traceback (most recent call last):
  File "/opt/python/urllib3/connectionpool.py", line 703, in urlopen
    httplib_response = self._make_request(
  File "/opt/python/urllib3/connectionpool.py", line 386, in _make_request
    self._validate_conn(conn)
  File "/opt/python/urllib3/connectionpool.py", line 1042, in _validate_conn
    conn.connect()
  File "/opt/python/urllib3/connection.py", line 358, in connect
    self.sock = conn = self._new_conn()
  File "/opt/python/urllib3/connection.py", line 186, in _new_conn
    raise NewConnectionError(
urllib3.exceptions.NewConnectionError: <urllib3.connection.HTTPSConnection object at 0x7fd4e85b8820>: Failed to establish a new connection: [Errno -5] No address associated with hostname

During handling of the above exception, another exception occurred:

Traceback (most recent call last):
  File "/opt/python/requests/adapters.py", line 489, in send
    resp = conn.urlopen(
  File "/opt/python/urllib3/connectionpool.py", line 787, in urlopen
    retries = retries.increment(
  File "/opt/python/urllib3/util/retry.py", line 592, in increment
    raise MaxRetryError(_pool, url, error or ResponseError(cause))
urllib3.exceptions.MaxRetryError: HTTPSConnectionPool(host='estates4.warwickdc.gov.uk', port=443): Max retries exceeded with url: /cmis/CouncillorsAtoZ/tabid/39/ScreenMode/Ward/Default.aspx (Caused by NewConnectionError('<urllib3.connection.HTTPSConnection object at 0x7fd4e85b8820>: Failed to establish a new connection: [Errno -5] No address associated with hostname'))

During handling of the above exception, another exception occurred:

Traceback (most recent call last):
  File "/var/task/lgsf/aws_lambda/handlers.py", line 32, in scraper_worker_handler
    scraper.run(run_log)
  File "/var/task/lgsf/councillors/scrapers.py", line 46, in run
    for councillor_html in self.get_councillors():
  File "/var/task/lgsf/councillors/scrapers.py", line 242, in get_councillors
    req = self.get(self.base_url, extra_headers=self.extra_headers)
  File "/var/task/lgsf/scrapers/base.py", line 48, in get
    response = self.requests_session.get(url, headers=headers, verify=verify)
  File "/opt/python/requests/sessions.py", line 600, in get
    return self.request("GET", url, **kwargs)
  File "/opt/python/requests/sessions.py", line 587, in request
    resp = self.send(prep, **send_kwargs)
  File "/opt/python/requests/sessions.py", line 701, in send
    r = adapter.send(request, **kwargs)
  File "/opt/python/requests/adapters.py", line 565, in send
    raise ConnectionError(e, request=request)
requests.exceptions.ConnectionError: HTTPSConnectionPool(host='estates4.warwickdc.gov.uk', port=443): Max retries exceeded with url: /cmis/CouncillorsAtoZ/tabid/39/ScreenMode/Ward/Default.aspx (Caused by NewConnectionError('<urllib3.connection.HTTPSConnection object at 0x7fd4e85b8820>: Failed to establish a new connection: [Errno -5] No address associated with hostname'))
</dd>
      </div>
    </dl>
  </div>
  </div>

  <h3>Run log</h3>
  <pre>[13:55:58] Fetching Scraper for: WAW                              handlers.py:23
           Begin attempting to scrape: WAW                        handlers.py:27
[13:55:59] Deleting existing data...                                 base.py:239
           Getting all files in Councillors...                       base.py:191
           ...found 1 files in Councillors                           base.py:207
           Deleting batch no. 1 consisting of 1 files                base.py:216
[13:56:00] ...data deleted.                                          base.py:246
           Scraping from                                              base.py:42
           https://estates4.warwickdc.gov.uk/cmis/CouncillorsAtoZ/tab           
           id/39/ScreenMode/Ward/Default.aspx                                   
           HTTPSConnectionPool(host='estates4.warwickdc.gov.uk',  handlers.py:36
           port=443): Max retries exceeded with url:                            
           /cmis/CouncillorsAtoZ/tabid/39/ScreenMode/Ward/Default               
           .aspx (Caused by                                                     
           NewConnectionError('<urllib3.connection.HTTPSConnectio               
           n object at 0x7fd4e85b8820>: Failed to establish a new               
           connection: [Errno -5] No address associated with                    
           hostname'))                                                          
[13:56:01] Finished attempting to scrape: WAW                        base.py:324
</pre>
  

  


  <h2 id="2023-03-06-15-09">2023-03-06</h2>
  <div class="ds-card">
  <div class="ds-card-body">
    <dl class="ds-descriptions">
      <div>
        <dt>Duration</dt>
        <dd>1 seconds</dd>
      </div>
      <div>
        <dt>Start</dt>
        <dd>2023-03-06 15:09:25.066679</dd>
      </div>
      <div>
        <dt>End</dt>
        <dd>2023-03-06 15:09:26.980091</dd>
      </div>
      <div>
        <dt>Status code</dt>
        <dd>1</dd>
      </div>
      <div>
        <dt>Error</dt>
        <dd>Traceback (most recent call last):
  File "/opt/python/urllib3/connection.py", line 174, in _new_conn
    conn = connection.create_connection(
  File "/opt/python/urllib3/util/connection.py", line 72, in create_connection
    for res in socket.getaddrinfo(host, port, family, socket.SOCK_STREAM):
  File "/var/lang/lib/python3.8/socket.py", line 918, in getaddrinfo
    for res in _socket.getaddrinfo(host, port, family, type, proto, flags):
socket.gaierror: [Errno -5] No address associated with hostname

During handling of the above exception, another exception occurred:

Traceback (most recent call last):
  File "/opt/python/urllib3/connectionpool.py", line 703, in urlopen
    httplib_response = self._make_request(
  File "/opt/python/urllib3/connectionpool.py", line 386, in _make_request
    self._validate_conn(conn)
  File "/opt/python/urllib3/connectionpool.py", line 1042, in _validate_conn
    conn.connect()
  File "/opt/python/urllib3/connection.py", line 358, in connect
    self.sock = conn = self._new_conn()
  File "/opt/python/urllib3/connection.py", line 186, in _new_conn
    raise NewConnectionError(
urllib3.exceptions.NewConnectionError: <urllib3.connection.HTTPSConnection object at 0x7f063e59d3d0>: Failed to establish a new connection: [Errno -5] No address associated with hostname

During handling of the above exception, another exception occurred:

Traceback (most recent call last):
  File "/opt/python/requests/adapters.py", line 489, in send
    resp = conn.urlopen(
  File "/opt/python/urllib3/connectionpool.py", line 787, in urlopen
    retries = retries.increment(
  File "/opt/python/urllib3/util/retry.py", line 592, in increment
    raise MaxRetryError(_pool, url, error or ResponseError(cause))
urllib3.exceptions.MaxRetryError: HTTPSConnectionPool(host='estates4.warwickdc.gov.uk', port=443): Max retries exceeded with url: /cmis/CouncillorsAtoZ/tabid/39/ScreenMode/Ward/Default.aspx (Caused by NewConnectionError('<urllib3.connection.HTTPSConnection object at 0x7f063e59d3d0>: Failed to establish a new connection: [Errno -5] No address associated with hostname'))

During handling of the above exception, another exception occurred:

Traceback (most recent call last):
  File "/var/task/lgsf/aws_lambda/handlers.py", line 32, in scraper_worker_handler
    scraper.run(run_log)
  File "/var/task/lgsf/councillors/scrapers.py", line 46, in run
    for councillor_html in self.get_councillors():
  File "/var/task/lgsf/councillors/scrapers.py", line 242, in get_councillors
    req = self.get(self.base_url, extra_headers=self.extra_headers)
  File "/var/task/lgsf/scrapers/base.py", line 48, in get
    response = self.requests_session.get(url, headers=headers, verify=verify)
  File "/opt/python/requests/sessions.py", line 600, in get
    return self.request("GET", url, **kwargs)
  File "/opt/python/requests/sessions.py", line 587, in request
    resp = self.send(prep, **send_kwargs)
  File "/opt/python/requests/sessions.py", line 701, in send
    r = adapter.send(request, **kwargs)
  File "/opt/python/requests/adapters.py", line 565, in send
    raise ConnectionError(e, request=request)
requests.exceptions.ConnectionError: HTTPSConnectionPool(host='estates4.warwickdc.gov.uk', port=443): Max retries exceeded with url: /cmis/CouncillorsAtoZ/tabid/39/ScreenMode/Ward/Default.aspx (Caused by NewConnectionError('<urllib3.connection.HTTPSConnection object at 0x7f063e59d3d0>: Failed to establish a new connection: [Errno -5] No address associated with hostname'))
</dd>
      </div>
    </dl>
  </div>
  </div>

  <h3>Run log</h3>
  <pre>[15:09:25] Fetching Scraper for: WAW                              handlers.py:23
           Begin attempting to scrape: WAW                        handlers.py:27
           Deleting existing data...                                 base.py:239
           Getting all files in Councillors...                       base.py:191
           ...found 1 files in Councillors                           base.py:207
           Deleting batch no. 1 consisting of 1 files                base.py:216
[15:09:26] ...data deleted.                                          base.py:246
           Scraping from                                              base.py:42
           https://estates4.warwickdc.gov.uk/cmis/CouncillorsAtoZ/tab           
           id/39/ScreenMode/Ward/Default.aspx                                   
           HTTPSConnectionPool(host='estates4.warwickdc.gov.uk',  handlers.py:36
           port=443): Max retries exceeded with url:                            
           /cmis/CouncillorsAtoZ/tabid/39/ScreenMode/Ward/Default               
           .aspx (Caused by                                                     
           NewConnectionError('<urllib3.connection.HTTPSConnectio               
           n object at 0x7f063e59d3d0>: Failed to establish a new               
           connection: [Errno -5] No address associated with                    
           hostname'))                                                          
           Finished attempting to scrape: WAW                        base.py:324
</pre>
  

  


  <h2 id="2023-02-27-14-47">2023-02-27</h2>
  <div class="ds-card">
  <div class="ds-card-body">
    <dl class="ds-descriptions">
      <div>
        <dt>Duration</dt>
        <dd>1 seconds</dd>
      </div>
      <div>
        <dt>Start</dt>
        <dd>2023-02-27 14:47:13.980887</dd>
      </div>
      <div>
        <dt>End</dt>
        <dd>2023-02-27 14:47:15.961888</dd>
      </div>
      <div>
        <dt>Status code</dt>
        <dd>1</dd>
      </div>
      <div>
        <dt>Error</dt>
        <dd>Traceback (most recent call last):
  File "/opt/python/urllib3/connection.py", line 174, in _new_conn
    conn = connection.create_connection(
  File "/opt/python/urllib3/util/connection.py", line 72, in create_connection
    for res in socket.getaddrinfo(host, port, family, socket.SOCK_STREAM):
  File "/var/lang/lib/python3.8/socket.py", line 918, in getaddrinfo
    for res in _socket.getaddrinfo(host, port, family, type, proto, flags):
socket.gaierror: [Errno -5] No address associated with hostname

During handling of the above exception, another exception occurred:

Traceback (most recent call last):
  File "/opt/python/urllib3/connectionpool.py", line 703, in urlopen
    httplib_response = self._make_request(
  File "/opt/python/urllib3/connectionpool.py", line 386, in _make_request
    self._validate_conn(conn)
  File "/opt/python/urllib3/connectionpool.py", line 1042, in _validate_conn
    conn.connect()
  File "/opt/python/urllib3/connection.py", line 358, in connect
    self.sock = conn = self._new_conn()
  File "/opt/python/urllib3/connection.py", line 186, in _new_conn
    raise NewConnectionError(
urllib3.exceptions.NewConnectionError: <urllib3.connection.HTTPSConnection object at 0x7f56006c09a0>: Failed to establish a new connection: [Errno -5] No address associated with hostname

During handling of the above exception, another exception occurred:

Traceback (most recent call last):
  File "/opt/python/requests/adapters.py", line 489, in send
    resp = conn.urlopen(
  File "/opt/python/urllib3/connectionpool.py", line 787, in urlopen
    retries = retries.increment(
  File "/opt/python/urllib3/util/retry.py", line 592, in increment
    raise MaxRetryError(_pool, url, error or ResponseError(cause))
urllib3.exceptions.MaxRetryError: HTTPSConnectionPool(host='estates4.warwickdc.gov.uk', port=443): Max retries exceeded with url: /cmis/CouncillorsAtoZ/tabid/39/ScreenMode/Ward/Default.aspx (Caused by NewConnectionError('<urllib3.connection.HTTPSConnection object at 0x7f56006c09a0>: Failed to establish a new connection: [Errno -5] No address associated with hostname'))

During handling of the above exception, another exception occurred:

Traceback (most recent call last):
  File "/var/task/lgsf/aws_lambda/handlers.py", line 32, in scraper_worker_handler
    scraper.run(run_log)
  File "/var/task/lgsf/councillors/scrapers.py", line 46, in run
    for councillor_html in self.get_councillors():
  File "/var/task/lgsf/councillors/scrapers.py", line 242, in get_councillors
    req = self.get(self.base_url, extra_headers=self.extra_headers)
  File "/var/task/lgsf/scrapers/base.py", line 48, in get
    response = self.requests_session.get(url, headers=headers, verify=verify)
  File "/opt/python/requests/sessions.py", line 600, in get
    return self.request("GET", url, **kwargs)
  File "/opt/python/requests/sessions.py", line 587, in request
    resp = self.send(prep, **send_kwargs)
  File "/opt/python/requests/sessions.py", line 701, in send
    r = adapter.send(request, **kwargs)
  File "/opt/python/requests/adapters.py", line 565, in send
    raise ConnectionError(e, request=request)
requests.exceptions.ConnectionError: HTTPSConnectionPool(host='estates4.warwickdc.gov.uk', port=443): Max retries exceeded with url: /cmis/CouncillorsAtoZ/tabid/39/ScreenMode/Ward/Default.aspx (Caused by NewConnectionError('<urllib3.connection.HTTPSConnection object at 0x7f56006c09a0>: Failed to establish a new connection: [Errno -5] No address associated with hostname'))
</dd>
      </div>
    </dl>
  </div>
  </div>

  <h3>Run log</h3>
  <pre>[14:47:13] Fetching Scraper for: WAW                              handlers.py:23
[14:47:14] Begin attempting to scrape: WAW                        handlers.py:27
           Deleting existing data...                                 base.py:239
           Getting all files in Councillors...                       base.py:191
           ...found 1 files in Councillors                           base.py:207
           Deleting batch no. 1 consisting of 1 files                base.py:216
[14:47:15] ...data deleted.                                          base.py:246
           Scraping from                                              base.py:42
           https://estates4.warwickdc.gov.uk/cmis/CouncillorsAtoZ/tab           
           id/39/ScreenMode/Ward/Default.aspx                                   
           HTTPSConnectionPool(host='estates4.warwickdc.gov.uk',  handlers.py:36
           port=443): Max retries exceeded with url:                            
           /cmis/CouncillorsAtoZ/tabid/39/ScreenMode/Ward/Default               
           .aspx (Caused by                                                     
           NewConnectionError('<urllib3.connection.HTTPSConnectio               
           n object at 0x7f56006c09a0>: Failed to establish a new               
           connection: [Errno -5] No address associated with                    
           hostname'))                                                          
           Finished attempting to scrape: WAW                        base.py:324
</pre>
  

  


  <h2 id="2023-02-20-13-06">2023-02-20</h2>
  <div class="ds-card">
  <div class="ds-card-body">
    <dl class="ds-descriptions">
      <div>
        <dt>Duration</dt>
        <dd>2 seconds</dd>
      </div>
      <div>
        <dt>Start</dt>
        <dd>2023-02-20 13:06:08.071269</dd>
      </div>
      <div>
        <dt>End</dt>
        <dd>2023-02-20 13:06:10.544912</dd>
      </div>
      <div>
        <dt>Status code</dt>
        <dd>1</dd>
      </div>
      <div>
        <dt>Error</dt>
        <dd>Traceback (most recent call last):
  File "/opt/python/urllib3/connection.py", line 174, in _new_conn
    conn = connection.create_connection(
  File "/opt/python/urllib3/util/connection.py", line 72, in create_connection
    for res in socket.getaddrinfo(host, port, family, socket.SOCK_STREAM):
  File "/var/lang/lib/python3.8/socket.py", line 918, in getaddrinfo
    for res in _socket.getaddrinfo(host, port, family, type, proto, flags):
socket.gaierror: [Errno -5] No address associated with hostname

During handling of the above exception, another exception occurred:

Traceback (most recent call last):
  File "/opt/python/urllib3/connectionpool.py", line 703, in urlopen
    httplib_response = self._make_request(
  File "/opt/python/urllib3/connectionpool.py", line 386, in _make_request
    self._validate_conn(conn)
  File "/opt/python/urllib3/connectionpool.py", line 1042, in _validate_conn
    conn.connect()
  File "/opt/python/urllib3/connection.py", line 358, in connect
    self.sock = conn = self._new_conn()
  File "/opt/python/urllib3/connection.py", line 186, in _new_conn
    raise NewConnectionError(
urllib3.exceptions.NewConnectionError: <urllib3.connection.HTTPSConnection object at 0x7f72f0e473d0>: Failed to establish a new connection: [Errno -5] No address associated with hostname

During handling of the above exception, another exception occurred:

Traceback (most recent call last):
  File "/opt/python/requests/adapters.py", line 489, in send
    resp = conn.urlopen(
  File "/opt/python/urllib3/connectionpool.py", line 787, in urlopen
    retries = retries.increment(
  File "/opt/python/urllib3/util/retry.py", line 592, in increment
    raise MaxRetryError(_pool, url, error or ResponseError(cause))
urllib3.exceptions.MaxRetryError: HTTPSConnectionPool(host='estates4.warwickdc.gov.uk', port=443): Max retries exceeded with url: /cmis/CouncillorsAtoZ/tabid/39/ScreenMode/Ward/Default.aspx (Caused by NewConnectionError('<urllib3.connection.HTTPSConnection object at 0x7f72f0e473d0>: Failed to establish a new connection: [Errno -5] No address associated with hostname'))

During handling of the above exception, another exception occurred:

Traceback (most recent call last):
  File "/var/task/lgsf/aws_lambda/handlers.py", line 32, in scraper_worker_handler
    scraper.run(run_log)
  File "/var/task/lgsf/councillors/scrapers.py", line 46, in run
    for councillor_html in self.get_councillors():
  File "/var/task/lgsf/councillors/scrapers.py", line 242, in get_councillors
    req = self.get(self.base_url, extra_headers=self.extra_headers)
  File "/var/task/lgsf/scrapers/base.py", line 48, in get
    response = self.requests_session.get(url, headers=headers, verify=verify)
  File "/opt/python/requests/sessions.py", line 600, in get
    return self.request("GET", url, **kwargs)
  File "/opt/python/requests/sessions.py", line 587, in request
    resp = self.send(prep, **send_kwargs)
  File "/opt/python/requests/sessions.py", line 701, in send
    r = adapter.send(request, **kwargs)
  File "/opt/python/requests/adapters.py", line 565, in send
    raise ConnectionError(e, request=request)
requests.exceptions.ConnectionError: HTTPSConnectionPool(host='estates4.warwickdc.gov.uk', port=443): Max retries exceeded with url: /cmis/CouncillorsAtoZ/tabid/39/ScreenMode/Ward/Default.aspx (Caused by NewConnectionError('<urllib3.connection.HTTPSConnection object at 0x7f72f0e473d0>: Failed to establish a new connection: [Errno -5] No address associated with hostname'))
</dd>
      </div>
    </dl>
  </div>
  </div>

  <h3>Run log</h3>
  <pre>[13:06:08] Fetching Scraper for: WAW                              handlers.py:23
           Begin attempting to scrape: WAW                        handlers.py:27
           Deleting existing data...                                 base.py:239
           Getting all files in Councillors...                       base.py:191
[13:06:09] ...found 1 files in Councillors                           base.py:207
           Deleting batch no. 1 consisting of 1 files                base.py:216
[13:06:10] ...data deleted.                                          base.py:246
           Scraping from                                              base.py:42
           https://estates4.warwickdc.gov.uk/cmis/CouncillorsAtoZ/tab           
           id/39/ScreenMode/Ward/Default.aspx                                   
           HTTPSConnectionPool(host='estates4.warwickdc.gov.uk',  handlers.py:36
           port=443): Max retries exceeded with url:                            
           /cmis/CouncillorsAtoZ/tabid/39/ScreenMode/Ward/Default               
           .aspx (Caused by                                                     
           NewConnectionError('<urllib3.connection.HTTPSConnectio               
           n object at 0x7f72f0e473d0>: Failed to establish a new               
           connection: [Errno -5] No address associated with                    
           hostname'))                                                          
           Finished attempting to scrape: WAW                        base.py:324
</pre>
  

  


  <h2 id="2023-02-13-14-07">2023-02-13</h2>
  <div class="ds-card">
  <div class="ds-card-body">
    <dl class="ds-descriptions">
      <div>
        <dt>Duration</dt>
        <dd>2 seconds</dd>
      </div>
      <div>
        <dt>Start</dt>
        <dd>2023-02-13 14:07:06.615050</dd>
      </div>
      <div>
        <dt>End</dt>
        <dd>2023-02-13 14:07:08.795514</dd>
      </div>
      <div>
        <dt>Status code</dt>
        <dd>1</dd>
      </div>
      <div>
        <dt>Error</dt>
        <dd>Traceback (most recent call last):
  File "/opt/python/urllib3/connection.py", line 174, in _new_conn
    conn = connection.create_connection(
  File "/opt/python/urllib3/util/connection.py", line 72, in create_connection
    for res in socket.getaddrinfo(host, port, family, socket.SOCK_STREAM):
  File "/var/lang/lib/python3.8/socket.py", line 918, in getaddrinfo
    for res in _socket.getaddrinfo(host, port, family, type, proto, flags):
socket.gaierror: [Errno -5] No address associated with hostname

During handling of the above exception, another exception occurred:

Traceback (most recent call last):
  File "/opt/python/urllib3/connectionpool.py", line 703, in urlopen
    httplib_response = self._make_request(
  File "/opt/python/urllib3/connectionpool.py", line 386, in _make_request
    self._validate_conn(conn)
  File "/opt/python/urllib3/connectionpool.py", line 1042, in _validate_conn
    conn.connect()
  File "/opt/python/urllib3/connection.py", line 358, in connect
    self.sock = conn = self._new_conn()
  File "/opt/python/urllib3/connection.py", line 186, in _new_conn
    raise NewConnectionError(
urllib3.exceptions.NewConnectionError: <urllib3.connection.HTTPSConnection object at 0x7efd7b4dfbb0>: Failed to establish a new connection: [Errno -5] No address associated with hostname

During handling of the above exception, another exception occurred:

Traceback (most recent call last):
  File "/opt/python/requests/adapters.py", line 489, in send
    resp = conn.urlopen(
  File "/opt/python/urllib3/connectionpool.py", line 787, in urlopen
    retries = retries.increment(
  File "/opt/python/urllib3/util/retry.py", line 592, in increment
    raise MaxRetryError(_pool, url, error or ResponseError(cause))
urllib3.exceptions.MaxRetryError: HTTPSConnectionPool(host='estates4.warwickdc.gov.uk', port=443): Max retries exceeded with url: /cmis/CouncillorsAtoZ/tabid/39/ScreenMode/Ward/Default.aspx (Caused by NewConnectionError('<urllib3.connection.HTTPSConnection object at 0x7efd7b4dfbb0>: Failed to establish a new connection: [Errno -5] No address associated with hostname'))

During handling of the above exception, another exception occurred:

Traceback (most recent call last):
  File "/var/task/lgsf/aws_lambda/handlers.py", line 32, in scraper_worker_handler
    scraper.run(run_log)
  File "/var/task/lgsf/councillors/scrapers.py", line 46, in run
    for councillor_html in self.get_councillors():
  File "/var/task/lgsf/councillors/scrapers.py", line 242, in get_councillors
    req = self.get(self.base_url, extra_headers=self.extra_headers)
  File "/var/task/lgsf/scrapers/base.py", line 48, in get
    response = self.requests_session.get(url, headers=headers, verify=verify)
  File "/opt/python/requests/sessions.py", line 600, in get
    return self.request("GET", url, **kwargs)
  File "/opt/python/requests/sessions.py", line 587, in request
    resp = self.send(prep, **send_kwargs)
  File "/opt/python/requests/sessions.py", line 701, in send
    r = adapter.send(request, **kwargs)
  File "/opt/python/requests/adapters.py", line 565, in send
    raise ConnectionError(e, request=request)
requests.exceptions.ConnectionError: HTTPSConnectionPool(host='estates4.warwickdc.gov.uk', port=443): Max retries exceeded with url: /cmis/CouncillorsAtoZ/tabid/39/ScreenMode/Ward/Default.aspx (Caused by NewConnectionError('<urllib3.connection.HTTPSConnection object at 0x7efd7b4dfbb0>: Failed to establish a new connection: [Errno -5] No address associated with hostname'))
</dd>
      </div>
    </dl>
  </div>
  </div>

  <h3>Run log</h3>
  <pre>[14:07:06] Fetching Scraper for: WAW                              handlers.py:23
           Begin attempting to scrape: WAW                        handlers.py:27
           Deleting existing data...                                 base.py:239
[14:07:07] Getting all files in Councillors...                       base.py:191
           ...found 1 files in Councillors                           base.py:207
           Deleting batch no. 1 consisting of 1 files                base.py:216
[14:07:08] ...data deleted.                                          base.py:246
           Scraping from                                              base.py:42
           https://estates4.warwickdc.gov.uk/cmis/CouncillorsAtoZ/tab           
           id/39/ScreenMode/Ward/Default.aspx                                   
           HTTPSConnectionPool(host='estates4.warwickdc.gov.uk',  handlers.py:36
           port=443): Max retries exceeded with url:                            
           /cmis/CouncillorsAtoZ/tabid/39/ScreenMode/Ward/Default               
           .aspx (Caused by                                                     
           NewConnectionError('<urllib3.connection.HTTPSConnectio               
           n object at 0x7efd7b4dfbb0>: Failed to establish a new               
           connection: [Errno -5] No address associated with                    
           hostname'))                                                          
           Finished attempting to scrape: WAW                        base.py:324
</pre>
  

  


  <h2 id="2023-02-06-15-06">2023-02-06</h2>
  <div class="ds-card">
  <div class="ds-card-body">
    <dl class="ds-descriptions">
      <div>
        <dt>Duration</dt>
        <dd>2 seconds</dd>
      </div>
      <div>
        <dt>Start</dt>
        <dd>2023-02-06 15:06:05.618204</dd>
      </div>
      <div>
        <dt>End</dt>
        <dd>2023-02-06 15:06:07.994234</dd>
      </div>
      <div>
        <dt>Status code</dt>
        <dd>1</dd>
      </div>
      <div>
        <dt>Error</dt>
        <dd>Traceback (most recent call last):
  File "/opt/python/urllib3/connection.py", line 174, in _new_conn
    conn = connection.create_connection(
  File "/opt/python/urllib3/util/connection.py", line 72, in create_connection
    for res in socket.getaddrinfo(host, port, family, socket.SOCK_STREAM):
  File "/var/lang/lib/python3.8/socket.py", line 918, in getaddrinfo
    for res in _socket.getaddrinfo(host, port, family, type, proto, flags):
socket.gaierror: [Errno -5] No address associated with hostname

During handling of the above exception, another exception occurred:

Traceback (most recent call last):
  File "/opt/python/urllib3/connectionpool.py", line 703, in urlopen
    httplib_response = self._make_request(
  File "/opt/python/urllib3/connectionpool.py", line 386, in _make_request
    self._validate_conn(conn)
  File "/opt/python/urllib3/connectionpool.py", line 1042, in _validate_conn
    conn.connect()
  File "/opt/python/urllib3/connection.py", line 358, in connect
    self.sock = conn = self._new_conn()
  File "/opt/python/urllib3/connection.py", line 186, in _new_conn
    raise NewConnectionError(
urllib3.exceptions.NewConnectionError: <urllib3.connection.HTTPSConnection object at 0x7f7f11a23880>: Failed to establish a new connection: [Errno -5] No address associated with hostname

During handling of the above exception, another exception occurred:

Traceback (most recent call last):
  File "/opt/python/requests/adapters.py", line 489, in send
    resp = conn.urlopen(
  File "/opt/python/urllib3/connectionpool.py", line 787, in urlopen
    retries = retries.increment(
  File "/opt/python/urllib3/util/retry.py", line 592, in increment
    raise MaxRetryError(_pool, url, error or ResponseError(cause))
urllib3.exceptions.MaxRetryError: HTTPSConnectionPool(host='estates4.warwickdc.gov.uk', port=443): Max retries exceeded with url: /cmis/CouncillorsAtoZ/tabid/39/ScreenMode/Ward/Default.aspx (Caused by NewConnectionError('<urllib3.connection.HTTPSConnection object at 0x7f7f11a23880>: Failed to establish a new connection: [Errno -5] No address associated with hostname'))

During handling of the above exception, another exception occurred:

Traceback (most recent call last):
  File "/var/task/lgsf/aws_lambda/handlers.py", line 32, in scraper_worker_handler
    scraper.run(run_log)
  File "/var/task/lgsf/councillors/scrapers.py", line 46, in run
    for councillor_html in self.get_councillors():
  File "/var/task/lgsf/councillors/scrapers.py", line 242, in get_councillors
    req = self.get(self.base_url, extra_headers=self.extra_headers)
  File "/var/task/lgsf/scrapers/base.py", line 48, in get
    response = self.requests_session.get(url, headers=headers, verify=verify)
  File "/opt/python/requests/sessions.py", line 600, in get
    return self.request("GET", url, **kwargs)
  File "/opt/python/requests/sessions.py", line 587, in request
    resp = self.send(prep, **send_kwargs)
  File "/opt/python/requests/sessions.py", line 701, in send
    r = adapter.send(request, **kwargs)
  File "/opt/python/requests/adapters.py", line 565, in send
    raise ConnectionError(e, request=request)
requests.exceptions.ConnectionError: HTTPSConnectionPool(host='estates4.warwickdc.gov.uk', port=443): Max retries exceeded with url: /cmis/CouncillorsAtoZ/tabid/39/ScreenMode/Ward/Default.aspx (Caused by NewConnectionError('<urllib3.connection.HTTPSConnection object at 0x7f7f11a23880>: Failed to establish a new connection: [Errno -5] No address associated with hostname'))
</dd>
      </div>
    </dl>
  </div>
  </div>

  <h3>Run log</h3>
  <pre>[15:06:05] Fetching Scraper for: WAW                              handlers.py:23
           Begin attempting to scrape: WAW                        handlers.py:27
           Deleting existing data...                                 base.py:239
[15:06:06] Getting all files in Councillors...                       base.py:191
           ...found 1 files in Councillors                           base.py:207
           Deleting batch no. 1 consisting of 1 files                base.py:216
[15:06:07] ...data deleted.                                          base.py:246
           Scraping from                                              base.py:42
           https://estates4.warwickdc.gov.uk/cmis/CouncillorsAtoZ/tab           
           id/39/ScreenMode/Ward/Default.aspx                                   
           HTTPSConnectionPool(host='estates4.warwickdc.gov.uk',  handlers.py:36
           port=443): Max retries exceeded with url:                            
           /cmis/CouncillorsAtoZ/tabid/39/ScreenMode/Ward/Default               
           .aspx (Caused by                                                     
           NewConnectionError('<urllib3.connection.HTTPSConnectio               
           n object at 0x7f7f11a23880>: Failed to establish a new               
           connection: [Errno -5] No address associated with                    
           hostname'))                                                          
           Finished attempting to scrape: WAW                        base.py:324
</pre>
  

  


  <h2 id="2023-01-30-13-52">2023-01-30</h2>
  <div class="ds-card">
  <div class="ds-card-body">
    <dl class="ds-descriptions">
      <div>
        <dt>Duration</dt>
        <dd>2 seconds</dd>
      </div>
      <div>
        <dt>Start</dt>
        <dd>2023-01-30 13:52:53.955830</dd>
      </div>
      <div>
        <dt>End</dt>
        <dd>2023-01-30 13:52:56.353668</dd>
      </div>
      <div>
        <dt>Status code</dt>
        <dd>1</dd>
      </div>
      <div>
        <dt>Error</dt>
        <dd>Traceback (most recent call last):
  File "/opt/python/urllib3/connection.py", line 174, in _new_conn
    conn = connection.create_connection(
  File "/opt/python/urllib3/util/connection.py", line 72, in create_connection
    for res in socket.getaddrinfo(host, port, family, socket.SOCK_STREAM):
  File "/var/lang/lib/python3.8/socket.py", line 918, in getaddrinfo
    for res in _socket.getaddrinfo(host, port, family, type, proto, flags):
socket.gaierror: [Errno -5] No address associated with hostname

During handling of the above exception, another exception occurred:

Traceback (most recent call last):
  File "/opt/python/urllib3/connectionpool.py", line 703, in urlopen
    httplib_response = self._make_request(
  File "/opt/python/urllib3/connectionpool.py", line 386, in _make_request
    self._validate_conn(conn)
  File "/opt/python/urllib3/connectionpool.py", line 1042, in _validate_conn
    conn.connect()
  File "/opt/python/urllib3/connection.py", line 358, in connect
    self.sock = conn = self._new_conn()
  File "/opt/python/urllib3/connection.py", line 186, in _new_conn
    raise NewConnectionError(
urllib3.exceptions.NewConnectionError: <urllib3.connection.HTTPSConnection object at 0x7fb094505040>: Failed to establish a new connection: [Errno -5] No address associated with hostname

During handling of the above exception, another exception occurred:

Traceback (most recent call last):
  File "/opt/python/requests/adapters.py", line 489, in send
    resp = conn.urlopen(
  File "/opt/python/urllib3/connectionpool.py", line 787, in urlopen
    retries = retries.increment(
  File "/opt/python/urllib3/util/retry.py", line 592, in increment
    raise MaxRetryError(_pool, url, error or ResponseError(cause))
urllib3.exceptions.MaxRetryError: HTTPSConnectionPool(host='estates4.warwickdc.gov.uk', port=443): Max retries exceeded with url: /cmis/CouncillorsAtoZ/tabid/39/ScreenMode/Ward/Default.aspx (Caused by NewConnectionError('<urllib3.connection.HTTPSConnection object at 0x7fb094505040>: Failed to establish a new connection: [Errno -5] No address associated with hostname'))

During handling of the above exception, another exception occurred:

Traceback (most recent call last):
  File "/var/task/lgsf/aws_lambda/handlers.py", line 32, in scraper_worker_handler
    scraper.run(run_log)
  File "/var/task/lgsf/councillors/scrapers.py", line 46, in run
    for councillor_html in self.get_councillors():
  File "/var/task/lgsf/councillors/scrapers.py", line 242, in get_councillors
    req = self.get(self.base_url, extra_headers=self.extra_headers)
  File "/var/task/lgsf/scrapers/base.py", line 48, in get
    response = self.requests_session.get(url, headers=headers, verify=verify)
  File "/opt/python/requests/sessions.py", line 600, in get
    return self.request("GET", url, **kwargs)
  File "/opt/python/requests/sessions.py", line 587, in request
    resp = self.send(prep, **send_kwargs)
  File "/opt/python/requests/sessions.py", line 701, in send
    r = adapter.send(request, **kwargs)
  File "/opt/python/requests/adapters.py", line 565, in send
    raise ConnectionError(e, request=request)
requests.exceptions.ConnectionError: HTTPSConnectionPool(host='estates4.warwickdc.gov.uk', port=443): Max retries exceeded with url: /cmis/CouncillorsAtoZ/tabid/39/ScreenMode/Ward/Default.aspx (Caused by NewConnectionError('<urllib3.connection.HTTPSConnection object at 0x7fb094505040>: Failed to establish a new connection: [Errno -5] No address associated with hostname'))
</dd>
      </div>
    </dl>
  </div>
  </div>

  <h3>Run log</h3>
  <pre>[13:52:53] Fetching Scraper for: WAW                              handlers.py:23
           Begin attempting to scrape: WAW                        handlers.py:27
[13:52:54] Deleting existing data...                                 base.py:239
           Getting all files in Councillors...                       base.py:191
[13:52:55] ...found 1 files in Councillors                           base.py:207
           Deleting batch no. 1 consisting of 1 files                base.py:216
           ...data deleted.                                          base.py:246
           Scraping from                                              base.py:42
           https://estates4.warwickdc.gov.uk/cmis/CouncillorsAtoZ/tab           
           id/39/ScreenMode/Ward/Default.aspx                                   
[13:52:56] HTTPSConnectionPool(host='estates4.warwickdc.gov.uk',  handlers.py:36
           port=443): Max retries exceeded with url:                            
           /cmis/CouncillorsAtoZ/tabid/39/ScreenMode/Ward/Default               
           .aspx (Caused by                                                     
           NewConnectionError('<urllib3.connection.HTTPSConnectio               
           n object at 0x7fb094505040>: Failed to establish a new               
           connection: [Errno -5] No address associated with                    
           hostname'))                                                          
           Finished attempting to scrape: WAW                        base.py:324
</pre>
  

  


  <h2 id="2023-01-23-13-36">2023-01-23</h2>
  <div class="ds-card">
  <div class="ds-card-body">
    <dl class="ds-descriptions">
      <div>
        <dt>Duration</dt>
        <dd>2 seconds</dd>
      </div>
      <div>
        <dt>Start</dt>
        <dd>2023-01-23 13:36:56.400363</dd>
      </div>
      <div>
        <dt>End</dt>
        <dd>2023-01-23 13:36:58.595220</dd>
      </div>
      <div>
        <dt>Status code</dt>
        <dd>1</dd>
      </div>
      <div>
        <dt>Error</dt>
        <dd>Traceback (most recent call last):
  File "/opt/python/urllib3/connection.py", line 174, in _new_conn
    conn = connection.create_connection(
  File "/opt/python/urllib3/util/connection.py", line 72, in create_connection
    for res in socket.getaddrinfo(host, port, family, socket.SOCK_STREAM):
  File "/var/lang/lib/python3.8/socket.py", line 918, in getaddrinfo
    for res in _socket.getaddrinfo(host, port, family, type, proto, flags):
socket.gaierror: [Errno -5] No address associated with hostname

During handling of the above exception, another exception occurred:

Traceback (most recent call last):
  File "/opt/python/urllib3/connectionpool.py", line 703, in urlopen
    httplib_response = self._make_request(
  File "/opt/python/urllib3/connectionpool.py", line 386, in _make_request
    self._validate_conn(conn)
  File "/opt/python/urllib3/connectionpool.py", line 1042, in _validate_conn
    conn.connect()
  File "/opt/python/urllib3/connection.py", line 358, in connect
    self.sock = conn = self._new_conn()
  File "/opt/python/urllib3/connection.py", line 186, in _new_conn
    raise NewConnectionError(
urllib3.exceptions.NewConnectionError: <urllib3.connection.HTTPSConnection object at 0x7f294e1f2640>: Failed to establish a new connection: [Errno -5] No address associated with hostname

During handling of the above exception, another exception occurred:

Traceback (most recent call last):
  File "/opt/python/requests/adapters.py", line 489, in send
    resp = conn.urlopen(
  File "/opt/python/urllib3/connectionpool.py", line 787, in urlopen
    retries = retries.increment(
  File "/opt/python/urllib3/util/retry.py", line 592, in increment
    raise MaxRetryError(_pool, url, error or ResponseError(cause))
urllib3.exceptions.MaxRetryError: HTTPSConnectionPool(host='estates4.warwickdc.gov.uk', port=443): Max retries exceeded with url: /cmis/CouncillorsAtoZ/tabid/39/ScreenMode/Ward/Default.aspx (Caused by NewConnectionError('<urllib3.connection.HTTPSConnection object at 0x7f294e1f2640>: Failed to establish a new connection: [Errno -5] No address associated with hostname'))

During handling of the above exception, another exception occurred:

Traceback (most recent call last):
  File "/var/task/lgsf/aws_lambda/handlers.py", line 32, in scraper_worker_handler
    scraper.run(run_log)
  File "/var/task/lgsf/councillors/scrapers.py", line 46, in run
    for councillor_html in self.get_councillors():
  File "/var/task/lgsf/councillors/scrapers.py", line 242, in get_councillors
    req = self.get(self.base_url, extra_headers=self.extra_headers)
  File "/var/task/lgsf/scrapers/base.py", line 48, in get
    response = self.requests_session.get(url, headers=headers, verify=verify)
  File "/opt/python/requests/sessions.py", line 600, in get
    return self.request("GET", url, **kwargs)
  File "/opt/python/requests/sessions.py", line 587, in request
    resp = self.send(prep, **send_kwargs)
  File "/opt/python/requests/sessions.py", line 701, in send
    r = adapter.send(request, **kwargs)
  File "/opt/python/requests/adapters.py", line 565, in send
    raise ConnectionError(e, request=request)
requests.exceptions.ConnectionError: HTTPSConnectionPool(host='estates4.warwickdc.gov.uk', port=443): Max retries exceeded with url: /cmis/CouncillorsAtoZ/tabid/39/ScreenMode/Ward/Default.aspx (Caused by NewConnectionError('<urllib3.connection.HTTPSConnection object at 0x7f294e1f2640>: Failed to establish a new connection: [Errno -5] No address associated with hostname'))
</dd>
      </div>
    </dl>
  </div>
  </div>

  <h3>Run log</h3>
  <pre>[13:36:56] Fetching Scraper for: WAW                              handlers.py:23
           Begin attempting to scrape: WAW                        handlers.py:27
           Deleting existing data...                                 base.py:239
[13:36:57] Getting all files in Councillors...                       base.py:191
           ...found 1 files in Councillors                           base.py:207
           Deleting batch no. 1 consisting of 1 files                base.py:216
[13:36:58] ...data deleted.                                          base.py:246
           Scraping from                                              base.py:42
           https://estates4.warwickdc.gov.uk/cmis/CouncillorsAtoZ/tab           
           id/39/ScreenMode/Ward/Default.aspx                                   
           HTTPSConnectionPool(host='estates4.warwickdc.gov.uk',  handlers.py:36
           port=443): Max retries exceeded with url:                            
           /cmis/CouncillorsAtoZ/tabid/39/ScreenMode/Ward/Default               
           .aspx (Caused by                                                     
           NewConnectionError('<urllib3.connection.HTTPSConnectio               
           n object at 0x7f294e1f2640>: Failed to establish a new               
           connection: [Errno -5] No address associated with                    
           hostname'))                                                          
           Finished attempting to scrape: WAW                        base.py:324
</pre>
  

  


  <h2 id="2023-01-16-13-09">2023-01-16</h2>
  <div class="ds-card">
  <div class="ds-card-body">
    <dl class="ds-descriptions">
      <div>
        <dt>Duration</dt>
        <dd>2 seconds</dd>
      </div>
      <div>
        <dt>Start</dt>
        <dd>2023-01-16 13:09:08.201794</dd>
      </div>
      <div>
        <dt>End</dt>
        <dd>2023-01-16 13:09:10.547910</dd>
      </div>
      <div>
        <dt>Status code</dt>
        <dd>1</dd>
      </div>
      <div>
        <dt>Error</dt>
        <dd>Traceback (most recent call last):
  File "/opt/python/urllib3/connection.py", line 174, in _new_conn
    conn = connection.create_connection(
  File "/opt/python/urllib3/util/connection.py", line 72, in create_connection
    for res in socket.getaddrinfo(host, port, family, socket.SOCK_STREAM):
  File "/var/lang/lib/python3.8/socket.py", line 918, in getaddrinfo
    for res in _socket.getaddrinfo(host, port, family, type, proto, flags):
socket.gaierror: [Errno -5] No address associated with hostname

During handling of the above exception, another exception occurred:

Traceback (most recent call last):
  File "/opt/python/urllib3/connectionpool.py", line 703, in urlopen
    httplib_response = self._make_request(
  File "/opt/python/urllib3/connectionpool.py", line 386, in _make_request
    self._validate_conn(conn)
  File "/opt/python/urllib3/connectionpool.py", line 1042, in _validate_conn
    conn.connect()
  File "/opt/python/urllib3/connection.py", line 358, in connect
    self.sock = conn = self._new_conn()
  File "/opt/python/urllib3/connection.py", line 186, in _new_conn
    raise NewConnectionError(
urllib3.exceptions.NewConnectionError: <urllib3.connection.HTTPSConnection object at 0x7f7e8e7dbb50>: Failed to establish a new connection: [Errno -5] No address associated with hostname

During handling of the above exception, another exception occurred:

Traceback (most recent call last):
  File "/opt/python/requests/adapters.py", line 489, in send
    resp = conn.urlopen(
  File "/opt/python/urllib3/connectionpool.py", line 787, in urlopen
    retries = retries.increment(
  File "/opt/python/urllib3/util/retry.py", line 592, in increment
    raise MaxRetryError(_pool, url, error or ResponseError(cause))
urllib3.exceptions.MaxRetryError: HTTPSConnectionPool(host='estates4.warwickdc.gov.uk', port=443): Max retries exceeded with url: /cmis/CouncillorsAtoZ/tabid/39/ScreenMode/Ward/Default.aspx (Caused by NewConnectionError('<urllib3.connection.HTTPSConnection object at 0x7f7e8e7dbb50>: Failed to establish a new connection: [Errno -5] No address associated with hostname'))

During handling of the above exception, another exception occurred:

Traceback (most recent call last):
  File "/var/task/lgsf/aws_lambda/handlers.py", line 32, in scraper_worker_handler
    scraper.run(run_log)
  File "/var/task/lgsf/councillors/scrapers.py", line 46, in run
    for councillor_html in self.get_councillors():
  File "/var/task/lgsf/councillors/scrapers.py", line 242, in get_councillors
    req = self.get(self.base_url, extra_headers=self.extra_headers)
  File "/var/task/lgsf/scrapers/base.py", line 48, in get
    response = self.requests_session.get(url, headers=headers, verify=verify)
  File "/opt/python/requests/sessions.py", line 600, in get
    return self.request("GET", url, **kwargs)
  File "/opt/python/requests/sessions.py", line 587, in request
    resp = self.send(prep, **send_kwargs)
  File "/opt/python/requests/sessions.py", line 701, in send
    r = adapter.send(request, **kwargs)
  File "/opt/python/requests/adapters.py", line 565, in send
    raise ConnectionError(e, request=request)
requests.exceptions.ConnectionError: HTTPSConnectionPool(host='estates4.warwickdc.gov.uk', port=443): Max retries exceeded with url: /cmis/CouncillorsAtoZ/tabid/39/ScreenMode/Ward/Default.aspx (Caused by NewConnectionError('<urllib3.connection.HTTPSConnection object at 0x7f7e8e7dbb50>: Failed to establish a new connection: [Errno -5] No address associated with hostname'))
</dd>
      </div>
    </dl>
  </div>
  </div>

  <h3>Run log</h3>
  <pre>[13:09:08] Fetching Scraper for: WAW                              handlers.py:23
           Begin attempting to scrape: WAW                        handlers.py:27
           Deleting existing data...                                 base.py:239
[13:09:09] Getting all files in Councillors...                       base.py:191
           ...found 1 files in Councillors                           base.py:207
           Deleting batch no. 1 consisting of 1 files                base.py:216
[13:09:10] ...data deleted.                                          base.py:246
           Scraping from                                              base.py:42
           https://estates4.warwickdc.gov.uk/cmis/CouncillorsAtoZ/tab           
           id/39/ScreenMode/Ward/Default.aspx                                   
           HTTPSConnectionPool(host='estates4.warwickdc.gov.uk',  handlers.py:36
           port=443): Max retries exceeded with url:                            
           /cmis/CouncillorsAtoZ/tabid/39/ScreenMode/Ward/Default               
           .aspx (Caused by                                                     
           NewConnectionError('<urllib3.connection.HTTPSConnectio               
           n object at 0x7f7e8e7dbb50>: Failed to establish a new               
           connection: [Errno -5] No address associated with                    
           hostname'))                                                          
           Finished attempting to scrape: WAW                        base.py:324
</pre>
  

  


  <h2 id="2023-01-09-14-04">2023-01-09</h2>
  <div class="ds-card">
  <div class="ds-card-body">
    <dl class="ds-descriptions">
      <div>
        <dt>Duration</dt>
        <dd>2 seconds</dd>
      </div>
      <div>
        <dt>Start</dt>
        <dd>2023-01-09 14:04:32.846228</dd>
      </div>
      <div>
        <dt>End</dt>
        <dd>2023-01-09 14:04:35.041010</dd>
      </div>
      <div>
        <dt>Status code</dt>
        <dd>1</dd>
      </div>
      <div>
        <dt>Error</dt>
        <dd>Traceback (most recent call last):
  File "/opt/python/urllib3/connection.py", line 174, in _new_conn
    conn = connection.create_connection(
  File "/opt/python/urllib3/util/connection.py", line 72, in create_connection
    for res in socket.getaddrinfo(host, port, family, socket.SOCK_STREAM):
  File "/var/lang/lib/python3.8/socket.py", line 918, in getaddrinfo
    for res in _socket.getaddrinfo(host, port, family, type, proto, flags):
socket.gaierror: [Errno -5] No address associated with hostname

During handling of the above exception, another exception occurred:

Traceback (most recent call last):
  File "/opt/python/urllib3/connectionpool.py", line 703, in urlopen
    httplib_response = self._make_request(
  File "/opt/python/urllib3/connectionpool.py", line 386, in _make_request
    self._validate_conn(conn)
  File "/opt/python/urllib3/connectionpool.py", line 1042, in _validate_conn
    conn.connect()
  File "/opt/python/urllib3/connection.py", line 358, in connect
    self.sock = conn = self._new_conn()
  File "/opt/python/urllib3/connection.py", line 186, in _new_conn
    raise NewConnectionError(
urllib3.exceptions.NewConnectionError: <urllib3.connection.HTTPSConnection object at 0x7f688ffe38b0>: Failed to establish a new connection: [Errno -5] No address associated with hostname

During handling of the above exception, another exception occurred:

Traceback (most recent call last):
  File "/opt/python/requests/adapters.py", line 489, in send
    resp = conn.urlopen(
  File "/opt/python/urllib3/connectionpool.py", line 787, in urlopen
    retries = retries.increment(
  File "/opt/python/urllib3/util/retry.py", line 592, in increment
    raise MaxRetryError(_pool, url, error or ResponseError(cause))
urllib3.exceptions.MaxRetryError: HTTPSConnectionPool(host='estates4.warwickdc.gov.uk', port=443): Max retries exceeded with url: /cmis/CouncillorsAtoZ/tabid/39/ScreenMode/Ward/Default.aspx (Caused by NewConnectionError('<urllib3.connection.HTTPSConnection object at 0x7f688ffe38b0>: Failed to establish a new connection: [Errno -5] No address associated with hostname'))

During handling of the above exception, another exception occurred:

Traceback (most recent call last):
  File "/var/task/lgsf/aws_lambda/handlers.py", line 32, in scraper_worker_handler
    scraper.run(run_log)
  File "/var/task/lgsf/councillors/scrapers.py", line 46, in run
    for councillor_html in self.get_councillors():
  File "/var/task/lgsf/councillors/scrapers.py", line 242, in get_councillors
    req = self.get(self.base_url, extra_headers=self.extra_headers)
  File "/var/task/lgsf/scrapers/base.py", line 48, in get
    response = self.requests_session.get(url, headers=headers, verify=verify)
  File "/opt/python/requests/sessions.py", line 600, in get
    return self.request("GET", url, **kwargs)
  File "/opt/python/requests/sessions.py", line 587, in request
    resp = self.send(prep, **send_kwargs)
  File "/opt/python/requests/sessions.py", line 701, in send
    r = adapter.send(request, **kwargs)
  File "/opt/python/requests/adapters.py", line 565, in send
    raise ConnectionError(e, request=request)
requests.exceptions.ConnectionError: HTTPSConnectionPool(host='estates4.warwickdc.gov.uk', port=443): Max retries exceeded with url: /cmis/CouncillorsAtoZ/tabid/39/ScreenMode/Ward/Default.aspx (Caused by NewConnectionError('<urllib3.connection.HTTPSConnection object at 0x7f688ffe38b0>: Failed to establish a new connection: [Errno -5] No address associated with hostname'))
</dd>
      </div>
    </dl>
  </div>
  </div>

  <h3>Run log</h3>
  <pre>[14:04:32] Fetching Scraper for: WAW                              handlers.py:23
           Begin attempting to scrape: WAW                        handlers.py:27
[14:04:33] Deleting existing data...                                 base.py:239
           Getting all files in Councillors...                       base.py:191
           ...found 1 files in Councillors                           base.py:207
           Deleting batch no. 1 consisting of 1 files                base.py:216
[14:04:34] ...data deleted.                                          base.py:246
           Scraping from                                              base.py:42
           https://estates4.warwickdc.gov.uk/cmis/CouncillorsAtoZ/tab           
           id/39/ScreenMode/Ward/Default.aspx                                   
           HTTPSConnectionPool(host='estates4.warwickdc.gov.uk',  handlers.py:36
           port=443): Max retries exceeded with url:                            
           /cmis/CouncillorsAtoZ/tabid/39/ScreenMode/Ward/Default               
           .aspx (Caused by                                                     
           NewConnectionError('<urllib3.connection.HTTPSConnectio               
           n object at 0x7f688ffe38b0>: Failed to establish a new               
           connection: [Errno -5] No address associated with                    
           hostname'))                                                          
[14:04:35] Finished attempting to scrape: WAW                        base.py:324
</pre>
  

  


  <h2 id="2023-01-02-13-34">2023-01-02</h2>
  <div class="ds-card">
  <div class="ds-card-body">
    <dl class="ds-descriptions">
      <div>
        <dt>Duration</dt>
        <dd>2 seconds</dd>
      </div>
      <div>
        <dt>Start</dt>
        <dd>2023-01-02 13:34:28.937904</dd>
      </div>
      <div>
        <dt>End</dt>
        <dd>2023-01-02 13:34:31.282896</dd>
      </div>
      <div>
        <dt>Status code</dt>
        <dd>1</dd>
      </div>
      <div>
        <dt>Error</dt>
        <dd>Traceback (most recent call last):
  File "/opt/python/urllib3/connection.py", line 174, in _new_conn
    conn = connection.create_connection(
  File "/opt/python/urllib3/util/connection.py", line 72, in create_connection
    for res in socket.getaddrinfo(host, port, family, socket.SOCK_STREAM):
  File "/var/lang/lib/python3.8/socket.py", line 918, in getaddrinfo
    for res in _socket.getaddrinfo(host, port, family, type, proto, flags):
socket.gaierror: [Errno -5] No address associated with hostname

During handling of the above exception, another exception occurred:

Traceback (most recent call last):
  File "/opt/python/urllib3/connectionpool.py", line 703, in urlopen
    httplib_response = self._make_request(
  File "/opt/python/urllib3/connectionpool.py", line 386, in _make_request
    self._validate_conn(conn)
  File "/opt/python/urllib3/connectionpool.py", line 1042, in _validate_conn
    conn.connect()
  File "/opt/python/urllib3/connection.py", line 358, in connect
    self.sock = conn = self._new_conn()
  File "/opt/python/urllib3/connection.py", line 186, in _new_conn
    raise NewConnectionError(
urllib3.exceptions.NewConnectionError: <urllib3.connection.HTTPSConnection object at 0x7fa91eac46a0>: Failed to establish a new connection: [Errno -5] No address associated with hostname

During handling of the above exception, another exception occurred:

Traceback (most recent call last):
  File "/opt/python/requests/adapters.py", line 489, in send
    resp = conn.urlopen(
  File "/opt/python/urllib3/connectionpool.py", line 787, in urlopen
    retries = retries.increment(
  File "/opt/python/urllib3/util/retry.py", line 592, in increment
    raise MaxRetryError(_pool, url, error or ResponseError(cause))
urllib3.exceptions.MaxRetryError: HTTPSConnectionPool(host='estates4.warwickdc.gov.uk', port=443): Max retries exceeded with url: /cmis/CouncillorsAtoZ/tabid/39/ScreenMode/Ward/Default.aspx (Caused by NewConnectionError('<urllib3.connection.HTTPSConnection object at 0x7fa91eac46a0>: Failed to establish a new connection: [Errno -5] No address associated with hostname'))

During handling of the above exception, another exception occurred:

Traceback (most recent call last):
  File "/var/task/lgsf/aws_lambda/handlers.py", line 32, in scraper_worker_handler
    scraper.run(run_log)
  File "/var/task/lgsf/councillors/scrapers.py", line 46, in run
    for councillor_html in self.get_councillors():
  File "/var/task/lgsf/councillors/scrapers.py", line 242, in get_councillors
    req = self.get(self.base_url, extra_headers=self.extra_headers)
  File "/var/task/lgsf/scrapers/base.py", line 48, in get
    response = self.requests_session.get(url, headers=headers, verify=verify)
  File "/opt/python/requests/sessions.py", line 600, in get
    return self.request("GET", url, **kwargs)
  File "/opt/python/requests/sessions.py", line 587, in request
    resp = self.send(prep, **send_kwargs)
  File "/opt/python/requests/sessions.py", line 701, in send
    r = adapter.send(request, **kwargs)
  File "/opt/python/requests/adapters.py", line 565, in send
    raise ConnectionError(e, request=request)
requests.exceptions.ConnectionError: HTTPSConnectionPool(host='estates4.warwickdc.gov.uk', port=443): Max retries exceeded with url: /cmis/CouncillorsAtoZ/tabid/39/ScreenMode/Ward/Default.aspx (Caused by NewConnectionError('<urllib3.connection.HTTPSConnection object at 0x7fa91eac46a0>: Failed to establish a new connection: [Errno -5] No address associated with hostname'))
</dd>
      </div>
    </dl>
  </div>
  </div>

  <h3>Run log</h3>
  <pre>[13:34:28] Fetching Scraper for: WAW                              handlers.py:23
           Begin attempting to scrape: WAW                        handlers.py:27
[13:34:29] Deleting existing data...                                 base.py:239
           Getting all files in Councillors...                       base.py:191
[13:34:30] ...found 1 files in Councillors                           base.py:207
           Deleting batch no. 1 consisting of 1 files                base.py:216
           ...data deleted.                                          base.py:246
           Scraping from                                              base.py:42
           https://estates4.warwickdc.gov.uk/cmis/CouncillorsAtoZ/tab           
           id/39/ScreenMode/Ward/Default.aspx                                   
[13:34:31] HTTPSConnectionPool(host='estates4.warwickdc.gov.uk',  handlers.py:36
           port=443): Max retries exceeded with url:                            
           /cmis/CouncillorsAtoZ/tabid/39/ScreenMode/Ward/Default               
           .aspx (Caused by                                                     
           NewConnectionError('<urllib3.connection.HTTPSConnectio               
           n object at 0x7fa91eac46a0>: Failed to establish a new               
           connection: [Errno -5] No address associated with                    
           hostname'))                                                          
           Finished attempting to scrape: WAW                        base.py:324
</pre>
  

  


  <h2 id="2022-12-26-14-49">2022-12-26</h2>
  <div class="ds-card">
  <div class="ds-card-body">
    <dl class="ds-descriptions">
      <div>
        <dt>Duration</dt>
        <dd>2 seconds</dd>
      </div>
      <div>
        <dt>Start</dt>
        <dd>2022-12-26 14:49:14.985701</dd>
      </div>
      <div>
        <dt>End</dt>
        <dd>2022-12-26 14:49:17.323258</dd>
      </div>
      <div>
        <dt>Status code</dt>
        <dd>1</dd>
      </div>
      <div>
        <dt>Error</dt>
        <dd>Traceback (most recent call last):
  File "/opt/python/urllib3/connection.py", line 174, in _new_conn
    conn = connection.create_connection(
  File "/opt/python/urllib3/util/connection.py", line 72, in create_connection
    for res in socket.getaddrinfo(host, port, family, socket.SOCK_STREAM):
  File "/var/lang/lib/python3.8/socket.py", line 918, in getaddrinfo
    for res in _socket.getaddrinfo(host, port, family, type, proto, flags):
socket.gaierror: [Errno -5] No address associated with hostname

During handling of the above exception, another exception occurred:

Traceback (most recent call last):
  File "/opt/python/urllib3/connectionpool.py", line 703, in urlopen
    httplib_response = self._make_request(
  File "/opt/python/urllib3/connectionpool.py", line 386, in _make_request
    self._validate_conn(conn)
  File "/opt/python/urllib3/connectionpool.py", line 1042, in _validate_conn
    conn.connect()
  File "/opt/python/urllib3/connection.py", line 358, in connect
    self.sock = conn = self._new_conn()
  File "/opt/python/urllib3/connection.py", line 186, in _new_conn
    raise NewConnectionError(
urllib3.exceptions.NewConnectionError: <urllib3.connection.HTTPSConnection object at 0x7f34e5527d00>: Failed to establish a new connection: [Errno -5] No address associated with hostname

During handling of the above exception, another exception occurred:

Traceback (most recent call last):
  File "/opt/python/requests/adapters.py", line 489, in send
    resp = conn.urlopen(
  File "/opt/python/urllib3/connectionpool.py", line 787, in urlopen
    retries = retries.increment(
  File "/opt/python/urllib3/util/retry.py", line 592, in increment
    raise MaxRetryError(_pool, url, error or ResponseError(cause))
urllib3.exceptions.MaxRetryError: HTTPSConnectionPool(host='estates4.warwickdc.gov.uk', port=443): Max retries exceeded with url: /cmis/CouncillorsAtoZ/tabid/39/ScreenMode/Ward/Default.aspx (Caused by NewConnectionError('<urllib3.connection.HTTPSConnection object at 0x7f34e5527d00>: Failed to establish a new connection: [Errno -5] No address associated with hostname'))

During handling of the above exception, another exception occurred:

Traceback (most recent call last):
  File "/var/task/lgsf/aws_lambda/handlers.py", line 32, in scraper_worker_handler
    scraper.run(run_log)
  File "/var/task/lgsf/councillors/scrapers.py", line 46, in run
    for councillor_html in self.get_councillors():
  File "/var/task/lgsf/councillors/scrapers.py", line 242, in get_councillors
    req = self.get(self.base_url, extra_headers=self.extra_headers)
  File "/var/task/lgsf/scrapers/base.py", line 48, in get
    response = self.requests_session.get(url, headers=headers, verify=verify)
  File "/opt/python/requests/sessions.py", line 600, in get
    return self.request("GET", url, **kwargs)
  File "/opt/python/requests/sessions.py", line 587, in request
    resp = self.send(prep, **send_kwargs)
  File "/opt/python/requests/sessions.py", line 701, in send
    r = adapter.send(request, **kwargs)
  File "/opt/python/requests/adapters.py", line 565, in send
    raise ConnectionError(e, request=request)
requests.exceptions.ConnectionError: HTTPSConnectionPool(host='estates4.warwickdc.gov.uk', port=443): Max retries exceeded with url: /cmis/CouncillorsAtoZ/tabid/39/ScreenMode/Ward/Default.aspx (Caused by NewConnectionError('<urllib3.connection.HTTPSConnection object at 0x7f34e5527d00>: Failed to establish a new connection: [Errno -5] No address associated with hostname'))
</dd>
      </div>
    </dl>
  </div>
  </div>

  <h3>Run log</h3>
  <pre>[14:49:14] Fetching Scraper for: WAW                              handlers.py:23
[14:49:15] Begin attempting to scrape: WAW                        handlers.py:27
           Deleting existing data...                                 base.py:239
           Getting all files in Councillors...                       base.py:191
[14:49:16] ...found 1 files in Councillors                           base.py:207
           Deleting batch no. 1 consisting of 1 files                base.py:216
           ...data deleted.                                          base.py:246
           Scraping from                                              base.py:42
           https://estates4.warwickdc.gov.uk/cmis/CouncillorsAtoZ/tab           
           id/39/ScreenMode/Ward/Default.aspx                                   
[14:49:17] HTTPSConnectionPool(host='estates4.warwickdc.gov.uk',  handlers.py:36
           port=443): Max retries exceeded with url:                            
           /cmis/CouncillorsAtoZ/tabid/39/ScreenMode/Ward/Default               
           .aspx (Caused by                                                     
           NewConnectionError('<urllib3.connection.HTTPSConnectio               
           n object at 0x7f34e5527d00>: Failed to establish a new               
           connection: [Errno -5] No address associated with                    
           hostname'))                                                          
           Finished attempting to scrape: WAW                        base.py:324
</pre>
  

  


  <h2 id="2022-12-19-15-06">2022-12-19</h2>
  <div class="ds-card">
  <div class="ds-card-body">
    <dl class="ds-descriptions">
      <div>
        <dt>Duration</dt>
        <dd>2 seconds</dd>
      </div>
      <div>
        <dt>Start</dt>
        <dd>2022-12-19 15:06:41.155275</dd>
      </div>
      <div>
        <dt>End</dt>
        <dd>2022-12-19 15:06:43.560833</dd>
      </div>
      <div>
        <dt>Status code</dt>
        <dd>1</dd>
      </div>
      <div>
        <dt>Error</dt>
        <dd>Traceback (most recent call last):
  File "/opt/python/urllib3/connection.py", line 174, in _new_conn
    conn = connection.create_connection(
  File "/opt/python/urllib3/util/connection.py", line 72, in create_connection
    for res in socket.getaddrinfo(host, port, family, socket.SOCK_STREAM):
  File "/var/lang/lib/python3.8/socket.py", line 918, in getaddrinfo
    for res in _socket.getaddrinfo(host, port, family, type, proto, flags):
socket.gaierror: [Errno -5] No address associated with hostname

During handling of the above exception, another exception occurred:

Traceback (most recent call last):
  File "/opt/python/urllib3/connectionpool.py", line 703, in urlopen
    httplib_response = self._make_request(
  File "/opt/python/urllib3/connectionpool.py", line 386, in _make_request
    self._validate_conn(conn)
  File "/opt/python/urllib3/connectionpool.py", line 1042, in _validate_conn
    conn.connect()
  File "/opt/python/urllib3/connection.py", line 358, in connect
    self.sock = conn = self._new_conn()
  File "/opt/python/urllib3/connection.py", line 186, in _new_conn
    raise NewConnectionError(
urllib3.exceptions.NewConnectionError: <urllib3.connection.HTTPSConnection object at 0x7f55f3708430>: Failed to establish a new connection: [Errno -5] No address associated with hostname

During handling of the above exception, another exception occurred:

Traceback (most recent call last):
  File "/opt/python/requests/adapters.py", line 489, in send
    resp = conn.urlopen(
  File "/opt/python/urllib3/connectionpool.py", line 787, in urlopen
    retries = retries.increment(
  File "/opt/python/urllib3/util/retry.py", line 592, in increment
    raise MaxRetryError(_pool, url, error or ResponseError(cause))
urllib3.exceptions.MaxRetryError: HTTPSConnectionPool(host='estates4.warwickdc.gov.uk', port=443): Max retries exceeded with url: /cmis/CouncillorsAtoZ/tabid/39/ScreenMode/Ward/Default.aspx (Caused by NewConnectionError('<urllib3.connection.HTTPSConnection object at 0x7f55f3708430>: Failed to establish a new connection: [Errno -5] No address associated with hostname'))

During handling of the above exception, another exception occurred:

Traceback (most recent call last):
  File "/var/task/lgsf/aws_lambda/handlers.py", line 32, in scraper_worker_handler
    scraper.run(run_log)
  File "/var/task/lgsf/councillors/scrapers.py", line 46, in run
    for councillor_html in self.get_councillors():
  File "/var/task/lgsf/councillors/scrapers.py", line 242, in get_councillors
    req = self.get(self.base_url, extra_headers=self.extra_headers)
  File "/var/task/lgsf/scrapers/base.py", line 48, in get
    response = self.requests_session.get(url, headers=headers, verify=verify)
  File "/opt/python/requests/sessions.py", line 600, in get
    return self.request("GET", url, **kwargs)
  File "/opt/python/requests/sessions.py", line 587, in request
    resp = self.send(prep, **send_kwargs)
  File "/opt/python/requests/sessions.py", line 701, in send
    r = adapter.send(request, **kwargs)
  File "/opt/python/requests/adapters.py", line 565, in send
    raise ConnectionError(e, request=request)
requests.exceptions.ConnectionError: HTTPSConnectionPool(host='estates4.warwickdc.gov.uk', port=443): Max retries exceeded with url: /cmis/CouncillorsAtoZ/tabid/39/ScreenMode/Ward/Default.aspx (Caused by NewConnectionError('<urllib3.connection.HTTPSConnection object at 0x7f55f3708430>: Failed to establish a new connection: [Errno -5] No address associated with hostname'))
</dd>
      </div>
    </dl>
  </div>
  </div>

  <h3>Run log</h3>
  <pre>[15:06:41] Fetching Scraper for: WAW                              handlers.py:23
           Begin attempting to scrape: WAW                        handlers.py:27
           Deleting existing data...                                 base.py:239
           Getting all files in Councillors...                       base.py:191
[15:06:42] ...found 1 files in Councillors                           base.py:207
           Deleting batch no. 1 consisting of 1 files                base.py:216
[15:06:43] ...data deleted.                                          base.py:246
           Scraping from                                              base.py:42
           https://estates4.warwickdc.gov.uk/cmis/CouncillorsAtoZ/tab           
           id/39/ScreenMode/Ward/Default.aspx                                   
           HTTPSConnectionPool(host='estates4.warwickdc.gov.uk',  handlers.py:36
           port=443): Max retries exceeded with url:                            
           /cmis/CouncillorsAtoZ/tabid/39/ScreenMode/Ward/Default               
           .aspx (Caused by                                                     
           NewConnectionError('<urllib3.connection.HTTPSConnectio               
           n object at 0x7f55f3708430>: Failed to establish a new               
           connection: [Errno -5] No address associated with                    
           hostname'))                                                          
           Finished attempting to scrape: WAW                        base.py:324
</pre>
  

  


  <h2 id="2022-12-12-14-45">2022-12-12</h2>
  <div class="ds-card">
  <div class="ds-card-body">
    <dl class="ds-descriptions">
      <div>
        <dt>Duration</dt>
        <dd>2 seconds</dd>
      </div>
      <div>
        <dt>Start</dt>
        <dd>2022-12-12 14:45:46.975049</dd>
      </div>
      <div>
        <dt>End</dt>
        <dd>2022-12-12 14:45:49.244822</dd>
      </div>
      <div>
        <dt>Status code</dt>
        <dd>1</dd>
      </div>
      <div>
        <dt>Error</dt>
        <dd>Traceback (most recent call last):
  File "/opt/python/urllib3/connection.py", line 174, in _new_conn
    conn = connection.create_connection(
  File "/opt/python/urllib3/util/connection.py", line 72, in create_connection
    for res in socket.getaddrinfo(host, port, family, socket.SOCK_STREAM):
  File "/var/lang/lib/python3.8/socket.py", line 918, in getaddrinfo
    for res in _socket.getaddrinfo(host, port, family, type, proto, flags):
socket.gaierror: [Errno -5] No address associated with hostname

During handling of the above exception, another exception occurred:

Traceback (most recent call last):
  File "/opt/python/urllib3/connectionpool.py", line 703, in urlopen
    httplib_response = self._make_request(
  File "/opt/python/urllib3/connectionpool.py", line 386, in _make_request
    self._validate_conn(conn)
  File "/opt/python/urllib3/connectionpool.py", line 1042, in _validate_conn
    conn.connect()
  File "/opt/python/urllib3/connection.py", line 358, in connect
    self.sock = conn = self._new_conn()
  File "/opt/python/urllib3/connection.py", line 186, in _new_conn
    raise NewConnectionError(
urllib3.exceptions.NewConnectionError: <urllib3.connection.HTTPSConnection object at 0x7f995add8f10>: Failed to establish a new connection: [Errno -5] No address associated with hostname

During handling of the above exception, another exception occurred:

Traceback (most recent call last):
  File "/opt/python/requests/adapters.py", line 489, in send
    resp = conn.urlopen(
  File "/opt/python/urllib3/connectionpool.py", line 787, in urlopen
    retries = retries.increment(
  File "/opt/python/urllib3/util/retry.py", line 592, in increment
    raise MaxRetryError(_pool, url, error or ResponseError(cause))
urllib3.exceptions.MaxRetryError: HTTPSConnectionPool(host='estates4.warwickdc.gov.uk', port=443): Max retries exceeded with url: /cmis/CouncillorsAtoZ/tabid/39/ScreenMode/Ward/Default.aspx (Caused by NewConnectionError('<urllib3.connection.HTTPSConnection object at 0x7f995add8f10>: Failed to establish a new connection: [Errno -5] No address associated with hostname'))

During handling of the above exception, another exception occurred:

Traceback (most recent call last):
  File "/var/task/lgsf/aws_lambda/handlers.py", line 32, in scraper_worker_handler
    scraper.run(run_log)
  File "/var/task/lgsf/councillors/scrapers.py", line 46, in run
    for councillor_html in self.get_councillors():
  File "/var/task/lgsf/councillors/scrapers.py", line 242, in get_councillors
    req = self.get(self.base_url, extra_headers=self.extra_headers)
  File "/var/task/lgsf/scrapers/base.py", line 48, in get
    response = self.requests_session.get(url, headers=headers, verify=verify)
  File "/opt/python/requests/sessions.py", line 600, in get
    return self.request("GET", url, **kwargs)
  File "/opt/python/requests/sessions.py", line 587, in request
    resp = self.send(prep, **send_kwargs)
  File "/opt/python/requests/sessions.py", line 701, in send
    r = adapter.send(request, **kwargs)
  File "/opt/python/requests/adapters.py", line 565, in send
    raise ConnectionError(e, request=request)
requests.exceptions.ConnectionError: HTTPSConnectionPool(host='estates4.warwickdc.gov.uk', port=443): Max retries exceeded with url: /cmis/CouncillorsAtoZ/tabid/39/ScreenMode/Ward/Default.aspx (Caused by NewConnectionError('<urllib3.connection.HTTPSConnection object at 0x7f995add8f10>: Failed to establish a new connection: [Errno -5] No address associated with hostname'))
</dd>
      </div>
    </dl>
  </div>
  </div>

  <h3>Run log</h3>
  <pre>[14:45:46] Fetching Scraper for: WAW                              handlers.py:23
           Begin attempting to scrape: WAW                        handlers.py:27
[14:45:47] Deleting existing data...                                 base.py:239
           Getting all files in Councillors...                       base.py:191
[14:45:48] ...found 1 files in Councillors                           base.py:207
           Deleting batch no. 1 consisting of 1 files                base.py:216
[14:45:49] ...data deleted.                                          base.py:246
           Scraping from                                              base.py:42
           https://estates4.warwickdc.gov.uk/cmis/CouncillorsAtoZ/tab           
           id/39/ScreenMode/Ward/Default.aspx                                   
           HTTPSConnectionPool(host='estates4.warwickdc.gov.uk',  handlers.py:36
           port=443): Max retries exceeded with url:                            
           /cmis/CouncillorsAtoZ/tabid/39/ScreenMode/Ward/Default               
           .aspx (Caused by                                                     
           NewConnectionError('<urllib3.connection.HTTPSConnectio               
           n object at 0x7f995add8f10>: Failed to establish a new               
           connection: [Errno -5] No address associated with                    
           hostname'))                                                          
           Finished attempting to scrape: WAW                        base.py:324
</pre>
  

  


  <h2 id="2022-12-05-15-24">2022-12-05</h2>
  <div class="ds-card">
  <div class="ds-card-body">
    <dl class="ds-descriptions">
      <div>
        <dt>Duration</dt>
        <dd>2 seconds</dd>
      </div>
      <div>
        <dt>Start</dt>
        <dd>2022-12-05 15:24:49.430897</dd>
      </div>
      <div>
        <dt>End</dt>
        <dd>2022-12-05 15:24:51.808279</dd>
      </div>
      <div>
        <dt>Status code</dt>
        <dd>1</dd>
      </div>
      <div>
        <dt>Error</dt>
        <dd>Traceback (most recent call last):
  File "/opt/python/urllib3/connection.py", line 174, in _new_conn
    conn = connection.create_connection(
  File "/opt/python/urllib3/util/connection.py", line 72, in create_connection
    for res in socket.getaddrinfo(host, port, family, socket.SOCK_STREAM):
  File "/var/lang/lib/python3.8/socket.py", line 918, in getaddrinfo
    for res in _socket.getaddrinfo(host, port, family, type, proto, flags):
socket.gaierror: [Errno -5] No address associated with hostname

During handling of the above exception, another exception occurred:

Traceback (most recent call last):
  File "/opt/python/urllib3/connectionpool.py", line 703, in urlopen
    httplib_response = self._make_request(
  File "/opt/python/urllib3/connectionpool.py", line 386, in _make_request
    self._validate_conn(conn)
  File "/opt/python/urllib3/connectionpool.py", line 1042, in _validate_conn
    conn.connect()
  File "/opt/python/urllib3/connection.py", line 358, in connect
    self.sock = conn = self._new_conn()
  File "/opt/python/urllib3/connection.py", line 186, in _new_conn
    raise NewConnectionError(
urllib3.exceptions.NewConnectionError: <urllib3.connection.HTTPSConnection object at 0x7f826a9294f0>: Failed to establish a new connection: [Errno -5] No address associated with hostname

During handling of the above exception, another exception occurred:

Traceback (most recent call last):
  File "/opt/python/requests/adapters.py", line 489, in send
    resp = conn.urlopen(
  File "/opt/python/urllib3/connectionpool.py", line 787, in urlopen
    retries = retries.increment(
  File "/opt/python/urllib3/util/retry.py", line 592, in increment
    raise MaxRetryError(_pool, url, error or ResponseError(cause))
urllib3.exceptions.MaxRetryError: HTTPSConnectionPool(host='estates4.warwickdc.gov.uk', port=443): Max retries exceeded with url: /cmis/CouncillorsAtoZ/tabid/39/ScreenMode/Ward/Default.aspx (Caused by NewConnectionError('<urllib3.connection.HTTPSConnection object at 0x7f826a9294f0>: Failed to establish a new connection: [Errno -5] No address associated with hostname'))

During handling of the above exception, another exception occurred:

Traceback (most recent call last):
  File "/var/task/lgsf/aws_lambda/handlers.py", line 32, in scraper_worker_handler
    scraper.run(run_log)
  File "/var/task/lgsf/councillors/scrapers.py", line 46, in run
    for councillor_html in self.get_councillors():
  File "/var/task/lgsf/councillors/scrapers.py", line 242, in get_councillors
    req = self.get(self.base_url, extra_headers=self.extra_headers)
  File "/var/task/lgsf/scrapers/base.py", line 48, in get
    response = self.requests_session.get(url, headers=headers, verify=verify)
  File "/opt/python/requests/sessions.py", line 600, in get
    return self.request("GET", url, **kwargs)
  File "/opt/python/requests/sessions.py", line 587, in request
    resp = self.send(prep, **send_kwargs)
  File "/opt/python/requests/sessions.py", line 701, in send
    r = adapter.send(request, **kwargs)
  File "/opt/python/requests/adapters.py", line 565, in send
    raise ConnectionError(e, request=request)
requests.exceptions.ConnectionError: HTTPSConnectionPool(host='estates4.warwickdc.gov.uk', port=443): Max retries exceeded with url: /cmis/CouncillorsAtoZ/tabid/39/ScreenMode/Ward/Default.aspx (Caused by NewConnectionError('<urllib3.connection.HTTPSConnection object at 0x7f826a9294f0>: Failed to establish a new connection: [Errno -5] No address associated with hostname'))
</dd>
      </div>
    </dl>
  </div>
  </div>

  <h3>Run log</h3>
  <pre>[15:24:49] Fetching Scraper for: WAW                              handlers.py:23
           Begin attempting to scrape: WAW                        handlers.py:27
           Deleting existing data...                                 base.py:239
[15:24:50] Getting all files in Councillors...                       base.py:191
           ...found 1 files in Councillors                           base.py:207
           Deleting batch no. 1 consisting of 1 files                base.py:216
[15:24:51] ...data deleted.                                          base.py:246
           Scraping from                                              base.py:42
           https://estates4.warwickdc.gov.uk/cmis/CouncillorsAtoZ/tab           
           id/39/ScreenMode/Ward/Default.aspx                                   
           HTTPSConnectionPool(host='estates4.warwickdc.gov.uk',  handlers.py:36
           port=443): Max retries exceeded with url:                            
           /cmis/CouncillorsAtoZ/tabid/39/ScreenMode/Ward/Default               
           .aspx (Caused by                                                     
           NewConnectionError('<urllib3.connection.HTTPSConnectio               
           n object at 0x7f826a9294f0>: Failed to establish a new               
           connection: [Errno -5] No address associated with                    
           hostname'))                                                          
           Finished attempting to scrape: WAW                        base.py:324
</pre>
  

  


  <h2 id="2022-11-28-13-47">2022-11-28</h2>
  <div class="ds-card">
  <div class="ds-card-body">
    <dl class="ds-descriptions">
      <div>
        <dt>Duration</dt>
        <dd>2 seconds</dd>
      </div>
      <div>
        <dt>Start</dt>
        <dd>2022-11-28 13:47:59.607009</dd>
      </div>
      <div>
        <dt>End</dt>
        <dd>2022-11-28 13:48:01.903926</dd>
      </div>
      <div>
        <dt>Status code</dt>
        <dd>1</dd>
      </div>
      <div>
        <dt>Error</dt>
        <dd>Traceback (most recent call last):
  File "/opt/python/urllib3/connection.py", line 174, in _new_conn
    conn = connection.create_connection(
  File "/opt/python/urllib3/util/connection.py", line 72, in create_connection
    for res in socket.getaddrinfo(host, port, family, socket.SOCK_STREAM):
  File "/var/lang/lib/python3.8/socket.py", line 918, in getaddrinfo
    for res in _socket.getaddrinfo(host, port, family, type, proto, flags):
socket.gaierror: [Errno -5] No address associated with hostname

During handling of the above exception, another exception occurred:

Traceback (most recent call last):
  File "/opt/python/urllib3/connectionpool.py", line 703, in urlopen
    httplib_response = self._make_request(
  File "/opt/python/urllib3/connectionpool.py", line 386, in _make_request
    self._validate_conn(conn)
  File "/opt/python/urllib3/connectionpool.py", line 1042, in _validate_conn
    conn.connect()
  File "/opt/python/urllib3/connection.py", line 358, in connect
    self.sock = conn = self._new_conn()
  File "/opt/python/urllib3/connection.py", line 186, in _new_conn
    raise NewConnectionError(
urllib3.exceptions.NewConnectionError: <urllib3.connection.HTTPSConnection object at 0x7f4159180070>: Failed to establish a new connection: [Errno -5] No address associated with hostname

During handling of the above exception, another exception occurred:

Traceback (most recent call last):
  File "/opt/python/requests/adapters.py", line 489, in send
    resp = conn.urlopen(
  File "/opt/python/urllib3/connectionpool.py", line 787, in urlopen
    retries = retries.increment(
  File "/opt/python/urllib3/util/retry.py", line 592, in increment
    raise MaxRetryError(_pool, url, error or ResponseError(cause))
urllib3.exceptions.MaxRetryError: HTTPSConnectionPool(host='estates4.warwickdc.gov.uk', port=443): Max retries exceeded with url: /cmis/CouncillorsAtoZ/tabid/39/ScreenMode/Ward/Default.aspx (Caused by NewConnectionError('<urllib3.connection.HTTPSConnection object at 0x7f4159180070>: Failed to establish a new connection: [Errno -5] No address associated with hostname'))

During handling of the above exception, another exception occurred:

Traceback (most recent call last):
  File "/var/task/lgsf/aws_lambda/handlers.py", line 32, in scraper_worker_handler
    scraper.run(run_log)
  File "/var/task/lgsf/councillors/scrapers.py", line 46, in run
    for councillor_html in self.get_councillors():
  File "/var/task/lgsf/councillors/scrapers.py", line 242, in get_councillors
    req = self.get(self.base_url, extra_headers=self.extra_headers)
  File "/var/task/lgsf/scrapers/base.py", line 48, in get
    response = self.requests_session.get(url, headers=headers, verify=verify)
  File "/opt/python/requests/sessions.py", line 600, in get
    return self.request("GET", url, **kwargs)
  File "/opt/python/requests/sessions.py", line 587, in request
    resp = self.send(prep, **send_kwargs)
  File "/opt/python/requests/sessions.py", line 701, in send
    r = adapter.send(request, **kwargs)
  File "/opt/python/requests/adapters.py", line 565, in send
    raise ConnectionError(e, request=request)
requests.exceptions.ConnectionError: HTTPSConnectionPool(host='estates4.warwickdc.gov.uk', port=443): Max retries exceeded with url: /cmis/CouncillorsAtoZ/tabid/39/ScreenMode/Ward/Default.aspx (Caused by NewConnectionError('<urllib3.connection.HTTPSConnection object at 0x7f4159180070>: Failed to establish a new connection: [Errno -5] No address associated with hostname'))
</dd>
      </div>
    </dl>
  </div>
  </div>

  <h3>Run log</h3>
  <pre>[13:47:59] Fetching Scraper for: WAW                              handlers.py:23
           Begin attempting to scrape: WAW                        handlers.py:27
           Deleting existing data...                                 base.py:239
[13:48:00] Getting all files in Councillors...                       base.py:191
           ...found 1 files in Councillors                           base.py:207
           Deleting batch no. 1 consisting of 1 files                base.py:216
[13:48:01] ...data deleted.                                          base.py:246
           Scraping from                                              base.py:42
           https://estates4.warwickdc.gov.uk/cmis/CouncillorsAtoZ/tab           
           id/39/ScreenMode/Ward/Default.aspx                                   
           HTTPSConnectionPool(host='estates4.warwickdc.gov.uk',  handlers.py:36
           port=443): Max retries exceeded with url:                            
           /cmis/CouncillorsAtoZ/tabid/39/ScreenMode/Ward/Default               
           .aspx (Caused by                                                     
           NewConnectionError('<urllib3.connection.HTTPSConnectio               
           n object at 0x7f4159180070>: Failed to establish a new               
           connection: [Errno -5] No address associated with                    
           hostname'))                                                          
           Finished attempting to scrape: WAW                        base.py:324
</pre>
  


      </main>
      <footer class="ds-footer">
        <div class="ds-block-centered ds-text-centered ds-stack">
          <div class="ds-cluster-center">
            <ul>
              <li><a href="/lgsf-dashboard/api/failing.json">Failing JSON</a></li>
            </ul>
          </div>
          <div class="ds-copyright">
            <a href="https://democracyclub.org.uk/">
              <img src="https://DemocracyClub.github.io/design-system/images/logo_white_text.svg" alt="Democracy Club Home" />
            </a>
            <p>Copyright © 2021 Democracy Club</p>
            <p>Community Interest Company</p>
            <p>Company No: <a href="https://beta.companieshouse.gov.uk/company/09461226">09461226</a></p>
          </div>
        </div>
      </footer>
    </div>
  </body>
