<!doctype html>
<html>
  <head>
    <title>LGSF Dashboard</title>
    <link rel="stylesheet"  href="/lgsf-dashboard/assets/css/styles.css">
    <link rel="shortcut icon" href="https://democracyclub.org.uk/static/images/logo_icon.png">
  </head>
  <body>
    <div class="ds-page">
      <a class="ds-skip-link" href="#main">skip to content</a>

      <header class="ds-header">
        <a class="ds-skip-link" href="#main">skip to content</a>
        <a class="ds-logo" href="/lgsf-dashboard/">
          <img src="https://DemocracyClub.github.io/design-system/images/logo_icon.svg" alt="" />
          <span>LGSF Logbooks</span>
        </a>

      </header>


      <main id="main" tabindex="-1" class="ds-stack">

        
<style>

    pre {
        height:400px;
        overflow-x: scroll;
        width:100%
    }
</style>




  


  <h2 id="2022-05-06-14-34">2022-05-06</h2>
  <div class="ds-card">
  <div class="ds-card-body">
    <dl class="ds-descriptions">
      <div>
        <dt>Duration</dt>
        <dd>2 seconds</dd>
      </div>
      <div>
        <dt>Start</dt>
        <dd>2022-05-06 14:34:13.659208</dd>
      </div>
      <div>
        <dt>End</dt>
        <dd>2022-05-06 14:34:15.825998</dd>
      </div>
      <div>
        <dt>Status code</dt>
        <dd>1</dd>
      </div>
      <div>
        <dt>Error</dt>
        <dd>Traceback (most recent call last):
  File "/opt/python/urllib3/connection.py", line 174, in _new_conn
    conn = connection.create_connection(
  File "/opt/python/urllib3/util/connection.py", line 72, in create_connection
    for res in socket.getaddrinfo(host, port, family, socket.SOCK_STREAM):
  File "/var/lang/lib/python3.8/socket.py", line 918, in getaddrinfo
    for res in _socket.getaddrinfo(host, port, family, type, proto, flags):
socket.gaierror: [Errno -5] No address associated with hostname

During handling of the above exception, another exception occurred:

Traceback (most recent call last):
  File "/opt/python/urllib3/connectionpool.py", line 703, in urlopen
    httplib_response = self._make_request(
  File "/opt/python/urllib3/connectionpool.py", line 386, in _make_request
    self._validate_conn(conn)
  File "/opt/python/urllib3/connectionpool.py", line 1040, in _validate_conn
    conn.connect()
  File "/opt/python/urllib3/connection.py", line 358, in connect
    conn = self._new_conn()
  File "/opt/python/urllib3/connection.py", line 186, in _new_conn
    raise NewConnectionError(
urllib3.exceptions.NewConnectionError: <urllib3.connection.HTTPSConnection object at 0x7f3ca14d3a30>: Failed to establish a new connection: [Errno -5] No address associated with hostname

During handling of the above exception, another exception occurred:

Traceback (most recent call last):
  File "/opt/python/requests/adapters.py", line 440, in send
    resp = conn.urlopen(
  File "/opt/python/urllib3/connectionpool.py", line 785, in urlopen
    retries = retries.increment(
  File "/opt/python/urllib3/util/retry.py", line 592, in increment
    raise MaxRetryError(_pool, url, error or ResponseError(cause))
urllib3.exceptions.MaxRetryError: HTTPSConnectionPool(host='estates4.warwickdc.gov.uk', port=443): Max retries exceeded with url: /cmis/CouncillorsAtoZ/tabid/39/ScreenMode/Ward/Default.aspx (Caused by NewConnectionError('<urllib3.connection.HTTPSConnection object at 0x7f3ca14d3a30>: Failed to establish a new connection: [Errno -5] No address associated with hostname'))

During handling of the above exception, another exception occurred:

Traceback (most recent call last):
  File "/var/task/lgsf/aws_lambda/handlers.py", line 32, in scraper_worker_handler
    scraper.run(run_log)
  File "/var/task/lgsf/councillors/scrapers.py", line 46, in run
    for councillor_html in self.get_councillors():
  File "/var/task/lgsf/councillors/scrapers.py", line 242, in get_councillors
    req = self.get(self.base_url, extra_headers=self.extra_headers)
  File "/var/task/lgsf/scrapers/base.py", line 48, in get
    response = self.requests_session.get(url, headers=headers, verify=verify)
  File "/opt/python/requests/sessions.py", line 542, in get
    return self.request('GET', url, **kwargs)
  File "/opt/python/requests/sessions.py", line 529, in request
    resp = self.send(prep, **send_kwargs)
  File "/opt/python/requests/sessions.py", line 645, in send
    r = adapter.send(request, **kwargs)
  File "/opt/python/requests/adapters.py", line 519, in send
    raise ConnectionError(e, request=request)
requests.exceptions.ConnectionError: HTTPSConnectionPool(host='estates4.warwickdc.gov.uk', port=443): Max retries exceeded with url: /cmis/CouncillorsAtoZ/tabid/39/ScreenMode/Ward/Default.aspx (Caused by NewConnectionError('<urllib3.connection.HTTPSConnection object at 0x7f3ca14d3a30>: Failed to establish a new connection: [Errno -5] No address associated with hostname'))
</dd>
      </div>
    </dl>
  </div>
  </div>

  <h3>Run log</h3>
  <pre>[14:34:13] Fetching Scraper for: WAW                              handlers.py:23
           Begin attempting to scrape: WAW                        handlers.py:27
           Deleting existing data...                                 base.py:230
[14:34:14] Getting all files in WAW...                               base.py:182
           ...found 1 files in WAW                                   base.py:198
           Deleting batch no. 1 consisting of 1 files                base.py:207
[14:34:15] ...data deleted.                                          base.py:237
           Scraping from https://estates4.warwickdc.gov.uk/cmis/Counc base.py:42
           illorsAtoZ/tabid/39/ScreenMode/Ward/Default.aspx                     
           HTTPSConnectionPool(host='estates4.warwickdc.gov.uk',  handlers.py:36
           port=443): Max retries exceeded with url: /cmis/Counci               
           llorsAtoZ/tabid/39/ScreenMode/Ward/Default.aspx                      
           (Caused by NewConnectionError('<urllib3.connection.HTT               
           PSConnection object at 0x7f3ca14d3a30>: Failed to                    
           establish a new connection: [Errno -5] No address                    
           associated with hostname'))                                          
           Finished attempting to scrape: WAW                        base.py:315
</pre>
  

  


  <h2 id="2022-05-05-12-03">2022-05-05</h2>
  <div class="ds-card">
  <div class="ds-card-body">
    <dl class="ds-descriptions">
      <div>
        <dt>Duration</dt>
        <dd>2 seconds</dd>
      </div>
      <div>
        <dt>Start</dt>
        <dd>2022-05-05 12:03:57.964738</dd>
      </div>
      <div>
        <dt>End</dt>
        <dd>2022-05-05 12:04:00.155306</dd>
      </div>
      <div>
        <dt>Status code</dt>
        <dd>1</dd>
      </div>
      <div>
        <dt>Error</dt>
        <dd>Traceback (most recent call last):
  File "/opt/python/urllib3/connection.py", line 174, in _new_conn
    conn = connection.create_connection(
  File "/opt/python/urllib3/util/connection.py", line 72, in create_connection
    for res in socket.getaddrinfo(host, port, family, socket.SOCK_STREAM):
  File "/var/lang/lib/python3.8/socket.py", line 918, in getaddrinfo
    for res in _socket.getaddrinfo(host, port, family, type, proto, flags):
socket.gaierror: [Errno -5] No address associated with hostname

During handling of the above exception, another exception occurred:

Traceback (most recent call last):
  File "/opt/python/urllib3/connectionpool.py", line 703, in urlopen
    httplib_response = self._make_request(
  File "/opt/python/urllib3/connectionpool.py", line 386, in _make_request
    self._validate_conn(conn)
  File "/opt/python/urllib3/connectionpool.py", line 1040, in _validate_conn
    conn.connect()
  File "/opt/python/urllib3/connection.py", line 358, in connect
    conn = self._new_conn()
  File "/opt/python/urllib3/connection.py", line 186, in _new_conn
    raise NewConnectionError(
urllib3.exceptions.NewConnectionError: <urllib3.connection.HTTPSConnection object at 0x7fc7c7a7efa0>: Failed to establish a new connection: [Errno -5] No address associated with hostname

During handling of the above exception, another exception occurred:

Traceback (most recent call last):
  File "/opt/python/requests/adapters.py", line 440, in send
    resp = conn.urlopen(
  File "/opt/python/urllib3/connectionpool.py", line 785, in urlopen
    retries = retries.increment(
  File "/opt/python/urllib3/util/retry.py", line 592, in increment
    raise MaxRetryError(_pool, url, error or ResponseError(cause))
urllib3.exceptions.MaxRetryError: HTTPSConnectionPool(host='estates4.warwickdc.gov.uk', port=443): Max retries exceeded with url: /cmis/CouncillorsAtoZ/tabid/39/ScreenMode/Ward/Default.aspx (Caused by NewConnectionError('<urllib3.connection.HTTPSConnection object at 0x7fc7c7a7efa0>: Failed to establish a new connection: [Errno -5] No address associated with hostname'))

During handling of the above exception, another exception occurred:

Traceback (most recent call last):
  File "/var/task/lgsf/aws_lambda/handlers.py", line 32, in scraper_worker_handler
    scraper.run(run_log)
  File "/var/task/lgsf/councillors/scrapers.py", line 46, in run
    for councillor_html in self.get_councillors():
  File "/var/task/lgsf/councillors/scrapers.py", line 242, in get_councillors
    req = self.get(self.base_url, extra_headers=self.extra_headers)
  File "/var/task/lgsf/scrapers/base.py", line 48, in get
    response = self.requests_session.get(url, headers=headers, verify=verify)
  File "/opt/python/requests/sessions.py", line 542, in get
    return self.request('GET', url, **kwargs)
  File "/opt/python/requests/sessions.py", line 529, in request
    resp = self.send(prep, **send_kwargs)
  File "/opt/python/requests/sessions.py", line 645, in send
    r = adapter.send(request, **kwargs)
  File "/opt/python/requests/adapters.py", line 519, in send
    raise ConnectionError(e, request=request)
requests.exceptions.ConnectionError: HTTPSConnectionPool(host='estates4.warwickdc.gov.uk', port=443): Max retries exceeded with url: /cmis/CouncillorsAtoZ/tabid/39/ScreenMode/Ward/Default.aspx (Caused by NewConnectionError('<urllib3.connection.HTTPSConnection object at 0x7fc7c7a7efa0>: Failed to establish a new connection: [Errno -5] No address associated with hostname'))
</dd>
      </div>
    </dl>
  </div>
  </div>

  <h3>Run log</h3>
  <pre>[12:03:57] Fetching Scraper for: WAW                              handlers.py:23
           Begin attempting to scrape: WAW                        handlers.py:27
[12:03:58] Deleting existing data...                                 base.py:230
           Getting all files in WAW...                               base.py:182
           ...found 1 files in WAW                                   base.py:198
           Deleting batch no. 1 consisting of 1 files                base.py:207
[12:03:59] ...data deleted.                                          base.py:237
           Scraping from https://estates4.warwickdc.gov.uk/cmis/Counc base.py:42
           illorsAtoZ/tabid/39/ScreenMode/Ward/Default.aspx                     
           HTTPSConnectionPool(host='estates4.warwickdc.gov.uk',  handlers.py:36
           port=443): Max retries exceeded with url: /cmis/Counci               
           llorsAtoZ/tabid/39/ScreenMode/Ward/Default.aspx                      
           (Caused by NewConnectionError('<urllib3.connection.HTT               
           PSConnection object at 0x7fc7c7a7efa0>: Failed to                    
           establish a new connection: [Errno -5] No address                    
           associated with hostname'))                                          
[12:04:00] Finished attempting to scrape: WAW                        base.py:315
</pre>
  

  


  <h2 id="2022-05-04-14-07">2022-05-04</h2>
  <div class="ds-card">
  <div class="ds-card-body">
    <dl class="ds-descriptions">
      <div>
        <dt>Duration</dt>
        <dd>2 seconds</dd>
      </div>
      <div>
        <dt>Start</dt>
        <dd>2022-05-04 14:07:03.677455</dd>
      </div>
      <div>
        <dt>End</dt>
        <dd>2022-05-04 14:07:05.871396</dd>
      </div>
      <div>
        <dt>Status code</dt>
        <dd>1</dd>
      </div>
      <div>
        <dt>Error</dt>
        <dd>Traceback (most recent call last):
  File "/opt/python/urllib3/connection.py", line 174, in _new_conn
    conn = connection.create_connection(
  File "/opt/python/urllib3/util/connection.py", line 72, in create_connection
    for res in socket.getaddrinfo(host, port, family, socket.SOCK_STREAM):
  File "/var/lang/lib/python3.8/socket.py", line 918, in getaddrinfo
    for res in _socket.getaddrinfo(host, port, family, type, proto, flags):
socket.gaierror: [Errno -5] No address associated with hostname

During handling of the above exception, another exception occurred:

Traceback (most recent call last):
  File "/opt/python/urllib3/connectionpool.py", line 703, in urlopen
    httplib_response = self._make_request(
  File "/opt/python/urllib3/connectionpool.py", line 386, in _make_request
    self._validate_conn(conn)
  File "/opt/python/urllib3/connectionpool.py", line 1040, in _validate_conn
    conn.connect()
  File "/opt/python/urllib3/connection.py", line 358, in connect
    conn = self._new_conn()
  File "/opt/python/urllib3/connection.py", line 186, in _new_conn
    raise NewConnectionError(
urllib3.exceptions.NewConnectionError: <urllib3.connection.HTTPSConnection object at 0x7fcd2f802220>: Failed to establish a new connection: [Errno -5] No address associated with hostname

During handling of the above exception, another exception occurred:

Traceback (most recent call last):
  File "/opt/python/requests/adapters.py", line 440, in send
    resp = conn.urlopen(
  File "/opt/python/urllib3/connectionpool.py", line 785, in urlopen
    retries = retries.increment(
  File "/opt/python/urllib3/util/retry.py", line 592, in increment
    raise MaxRetryError(_pool, url, error or ResponseError(cause))
urllib3.exceptions.MaxRetryError: HTTPSConnectionPool(host='estates4.warwickdc.gov.uk', port=443): Max retries exceeded with url: /cmis/CouncillorsAtoZ/tabid/39/ScreenMode/Ward/Default.aspx (Caused by NewConnectionError('<urllib3.connection.HTTPSConnection object at 0x7fcd2f802220>: Failed to establish a new connection: [Errno -5] No address associated with hostname'))

During handling of the above exception, another exception occurred:

Traceback (most recent call last):
  File "/var/task/lgsf/aws_lambda/handlers.py", line 32, in scraper_worker_handler
    scraper.run(run_log)
  File "/var/task/lgsf/councillors/scrapers.py", line 46, in run
    for councillor_html in self.get_councillors():
  File "/var/task/lgsf/councillors/scrapers.py", line 242, in get_councillors
    req = self.get(self.base_url, extra_headers=self.extra_headers)
  File "/var/task/lgsf/scrapers/base.py", line 48, in get
    response = self.requests_session.get(url, headers=headers, verify=verify)
  File "/opt/python/requests/sessions.py", line 542, in get
    return self.request('GET', url, **kwargs)
  File "/opt/python/requests/sessions.py", line 529, in request
    resp = self.send(prep, **send_kwargs)
  File "/opt/python/requests/sessions.py", line 645, in send
    r = adapter.send(request, **kwargs)
  File "/opt/python/requests/adapters.py", line 519, in send
    raise ConnectionError(e, request=request)
requests.exceptions.ConnectionError: HTTPSConnectionPool(host='estates4.warwickdc.gov.uk', port=443): Max retries exceeded with url: /cmis/CouncillorsAtoZ/tabid/39/ScreenMode/Ward/Default.aspx (Caused by NewConnectionError('<urllib3.connection.HTTPSConnection object at 0x7fcd2f802220>: Failed to establish a new connection: [Errno -5] No address associated with hostname'))
</dd>
      </div>
    </dl>
  </div>
  </div>

  <h3>Run log</h3>
  <pre>[14:07:03] Fetching Scraper for: WAW                              handlers.py:23
           Begin attempting to scrape: WAW                        handlers.py:27
           Deleting existing data...                                 base.py:230
[14:07:04] Getting all files in WAW...                               base.py:182
           ...found 1 files in WAW                                   base.py:198
           Deleting batch no. 1 consisting of 1 files                base.py:207
[14:07:05] ...data deleted.                                          base.py:237
           Scraping from https://estates4.warwickdc.gov.uk/cmis/Counc base.py:42
           illorsAtoZ/tabid/39/ScreenMode/Ward/Default.aspx                     
           HTTPSConnectionPool(host='estates4.warwickdc.gov.uk',  handlers.py:36
           port=443): Max retries exceeded with url: /cmis/Counci               
           llorsAtoZ/tabid/39/ScreenMode/Ward/Default.aspx                      
           (Caused by NewConnectionError('<urllib3.connection.HTT               
           PSConnection object at 0x7fcd2f802220>: Failed to                    
           establish a new connection: [Errno -5] No address                    
           associated with hostname'))                                          
           Finished attempting to scrape: WAW                        base.py:315
</pre>
  

  


  <h2 id="2022-05-03-12-53">2022-05-03</h2>
  <div class="ds-card">
  <div class="ds-card-body">
    <dl class="ds-descriptions">
      <div>
        <dt>Duration</dt>
        <dd>2 seconds</dd>
      </div>
      <div>
        <dt>Start</dt>
        <dd>2022-05-03 12:53:20.174546</dd>
      </div>
      <div>
        <dt>End</dt>
        <dd>2022-05-03 12:53:22.745051</dd>
      </div>
      <div>
        <dt>Status code</dt>
        <dd>1</dd>
      </div>
      <div>
        <dt>Error</dt>
        <dd>Traceback (most recent call last):
  File "/opt/python/urllib3/connection.py", line 174, in _new_conn
    conn = connection.create_connection(
  File "/opt/python/urllib3/util/connection.py", line 72, in create_connection
    for res in socket.getaddrinfo(host, port, family, socket.SOCK_STREAM):
  File "/var/lang/lib/python3.8/socket.py", line 918, in getaddrinfo
    for res in _socket.getaddrinfo(host, port, family, type, proto, flags):
socket.gaierror: [Errno -5] No address associated with hostname

During handling of the above exception, another exception occurred:

Traceback (most recent call last):
  File "/opt/python/urllib3/connectionpool.py", line 703, in urlopen
    httplib_response = self._make_request(
  File "/opt/python/urllib3/connectionpool.py", line 386, in _make_request
    self._validate_conn(conn)
  File "/opt/python/urllib3/connectionpool.py", line 1040, in _validate_conn
    conn.connect()
  File "/opt/python/urllib3/connection.py", line 358, in connect
    conn = self._new_conn()
  File "/opt/python/urllib3/connection.py", line 186, in _new_conn
    raise NewConnectionError(
urllib3.exceptions.NewConnectionError: <urllib3.connection.HTTPSConnection object at 0x7fe132ed3e50>: Failed to establish a new connection: [Errno -5] No address associated with hostname

During handling of the above exception, another exception occurred:

Traceback (most recent call last):
  File "/opt/python/requests/adapters.py", line 440, in send
    resp = conn.urlopen(
  File "/opt/python/urllib3/connectionpool.py", line 785, in urlopen
    retries = retries.increment(
  File "/opt/python/urllib3/util/retry.py", line 592, in increment
    raise MaxRetryError(_pool, url, error or ResponseError(cause))
urllib3.exceptions.MaxRetryError: HTTPSConnectionPool(host='estates4.warwickdc.gov.uk', port=443): Max retries exceeded with url: /cmis/CouncillorsAtoZ/tabid/39/ScreenMode/Ward/Default.aspx (Caused by NewConnectionError('<urllib3.connection.HTTPSConnection object at 0x7fe132ed3e50>: Failed to establish a new connection: [Errno -5] No address associated with hostname'))

During handling of the above exception, another exception occurred:

Traceback (most recent call last):
  File "/var/task/lgsf/aws_lambda/handlers.py", line 32, in scraper_worker_handler
    scraper.run(run_log)
  File "/var/task/lgsf/councillors/scrapers.py", line 46, in run
    for councillor_html in self.get_councillors():
  File "/var/task/lgsf/councillors/scrapers.py", line 242, in get_councillors
    req = self.get(self.base_url, extra_headers=self.extra_headers)
  File "/var/task/lgsf/scrapers/base.py", line 48, in get
    response = self.requests_session.get(url, headers=headers, verify=verify)
  File "/opt/python/requests/sessions.py", line 542, in get
    return self.request('GET', url, **kwargs)
  File "/opt/python/requests/sessions.py", line 529, in request
    resp = self.send(prep, **send_kwargs)
  File "/opt/python/requests/sessions.py", line 645, in send
    r = adapter.send(request, **kwargs)
  File "/opt/python/requests/adapters.py", line 519, in send
    raise ConnectionError(e, request=request)
requests.exceptions.ConnectionError: HTTPSConnectionPool(host='estates4.warwickdc.gov.uk', port=443): Max retries exceeded with url: /cmis/CouncillorsAtoZ/tabid/39/ScreenMode/Ward/Default.aspx (Caused by NewConnectionError('<urllib3.connection.HTTPSConnection object at 0x7fe132ed3e50>: Failed to establish a new connection: [Errno -5] No address associated with hostname'))
</dd>
      </div>
    </dl>
  </div>
  </div>

  <h3>Run log</h3>
  <pre>[12:53:20] Fetching Scraper for: WAW                              handlers.py:23
           Begin attempting to scrape: WAW                        handlers.py:27
           Deleting existing data...                                 base.py:230
           Getting all files in WAW...                               base.py:182
[12:53:21] ...found 1 files in WAW                                   base.py:198
           Deleting batch no. 1 consisting of 1 files                base.py:207
[12:53:22] ...data deleted.                                          base.py:237
           Scraping from https://estates4.warwickdc.gov.uk/cmis/Counc base.py:42
           illorsAtoZ/tabid/39/ScreenMode/Ward/Default.aspx                     
           HTTPSConnectionPool(host='estates4.warwickdc.gov.uk',  handlers.py:36
           port=443): Max retries exceeded with url: /cmis/Counci               
           llorsAtoZ/tabid/39/ScreenMode/Ward/Default.aspx                      
           (Caused by NewConnectionError('<urllib3.connection.HTT               
           PSConnection object at 0x7fe132ed3e50>: Failed to                    
           establish a new connection: [Errno -5] No address                    
           associated with hostname'))                                          
           Finished attempting to scrape: WAW                        base.py:315
</pre>
  

  


  <h2 id="2022-05-02-11-44">2022-05-02</h2>
  <div class="ds-card">
  <div class="ds-card-body">
    <dl class="ds-descriptions">
      <div>
        <dt>Duration</dt>
        <dd>2 seconds</dd>
      </div>
      <div>
        <dt>Start</dt>
        <dd>2022-05-02 11:44:24.425065</dd>
      </div>
      <div>
        <dt>End</dt>
        <dd>2022-05-02 11:44:26.611541</dd>
      </div>
      <div>
        <dt>Status code</dt>
        <dd>1</dd>
      </div>
      <div>
        <dt>Error</dt>
        <dd>Traceback (most recent call last):
  File "/opt/python/urllib3/connection.py", line 174, in _new_conn
    conn = connection.create_connection(
  File "/opt/python/urllib3/util/connection.py", line 72, in create_connection
    for res in socket.getaddrinfo(host, port, family, socket.SOCK_STREAM):
  File "/var/lang/lib/python3.8/socket.py", line 918, in getaddrinfo
    for res in _socket.getaddrinfo(host, port, family, type, proto, flags):
socket.gaierror: [Errno -5] No address associated with hostname

During handling of the above exception, another exception occurred:

Traceback (most recent call last):
  File "/opt/python/urllib3/connectionpool.py", line 703, in urlopen
    httplib_response = self._make_request(
  File "/opt/python/urllib3/connectionpool.py", line 386, in _make_request
    self._validate_conn(conn)
  File "/opt/python/urllib3/connectionpool.py", line 1040, in _validate_conn
    conn.connect()
  File "/opt/python/urllib3/connection.py", line 358, in connect
    conn = self._new_conn()
  File "/opt/python/urllib3/connection.py", line 186, in _new_conn
    raise NewConnectionError(
urllib3.exceptions.NewConnectionError: <urllib3.connection.HTTPSConnection object at 0x7f0397d5faf0>: Failed to establish a new connection: [Errno -5] No address associated with hostname

During handling of the above exception, another exception occurred:

Traceback (most recent call last):
  File "/opt/python/requests/adapters.py", line 440, in send
    resp = conn.urlopen(
  File "/opt/python/urllib3/connectionpool.py", line 785, in urlopen
    retries = retries.increment(
  File "/opt/python/urllib3/util/retry.py", line 592, in increment
    raise MaxRetryError(_pool, url, error or ResponseError(cause))
urllib3.exceptions.MaxRetryError: HTTPSConnectionPool(host='estates4.warwickdc.gov.uk', port=443): Max retries exceeded with url: /cmis/CouncillorsAtoZ/tabid/39/ScreenMode/Ward/Default.aspx (Caused by NewConnectionError('<urllib3.connection.HTTPSConnection object at 0x7f0397d5faf0>: Failed to establish a new connection: [Errno -5] No address associated with hostname'))

During handling of the above exception, another exception occurred:

Traceback (most recent call last):
  File "/var/task/lgsf/aws_lambda/handlers.py", line 32, in scraper_worker_handler
    scraper.run(run_log)
  File "/var/task/lgsf/councillors/scrapers.py", line 46, in run
    for councillor_html in self.get_councillors():
  File "/var/task/lgsf/councillors/scrapers.py", line 242, in get_councillors
    req = self.get(self.base_url, extra_headers=self.extra_headers)
  File "/var/task/lgsf/scrapers/base.py", line 48, in get
    response = self.requests_session.get(url, headers=headers, verify=verify)
  File "/opt/python/requests/sessions.py", line 542, in get
    return self.request('GET', url, **kwargs)
  File "/opt/python/requests/sessions.py", line 529, in request
    resp = self.send(prep, **send_kwargs)
  File "/opt/python/requests/sessions.py", line 645, in send
    r = adapter.send(request, **kwargs)
  File "/opt/python/requests/adapters.py", line 519, in send
    raise ConnectionError(e, request=request)
requests.exceptions.ConnectionError: HTTPSConnectionPool(host='estates4.warwickdc.gov.uk', port=443): Max retries exceeded with url: /cmis/CouncillorsAtoZ/tabid/39/ScreenMode/Ward/Default.aspx (Caused by NewConnectionError('<urllib3.connection.HTTPSConnection object at 0x7f0397d5faf0>: Failed to establish a new connection: [Errno -5] No address associated with hostname'))
</dd>
      </div>
    </dl>
  </div>
  </div>

  <h3>Run log</h3>
  <pre>[11:44:24] Fetching Scraper for: WAW                              handlers.py:23
           Begin attempting to scrape: WAW                        handlers.py:27
           Deleting existing data...                                 base.py:230
[11:44:25] Getting all files in WAW...                               base.py:182
           ...found 1 files in WAW                                   base.py:198
           Deleting batch no. 1 consisting of 1 files                base.py:207
[11:44:26] ...data deleted.                                          base.py:237
           Scraping from https://estates4.warwickdc.gov.uk/cmis/Counc base.py:42
           illorsAtoZ/tabid/39/ScreenMode/Ward/Default.aspx                     
           HTTPSConnectionPool(host='estates4.warwickdc.gov.uk',  handlers.py:36
           port=443): Max retries exceeded with url: /cmis/Counci               
           llorsAtoZ/tabid/39/ScreenMode/Ward/Default.aspx                      
           (Caused by NewConnectionError('<urllib3.connection.HTT               
           PSConnection object at 0x7f0397d5faf0>: Failed to                    
           establish a new connection: [Errno -5] No address                    
           associated with hostname'))                                          
           Finished attempting to scrape: WAW                        base.py:315
</pre>
  

  


  <h2 id="2022-05-01-13-10">2022-05-01</h2>
  <div class="ds-card">
  <div class="ds-card-body">
    <dl class="ds-descriptions">
      <div>
        <dt>Duration</dt>
        <dd>2 seconds</dd>
      </div>
      <div>
        <dt>Start</dt>
        <dd>2022-05-01 13:10:41.349610</dd>
      </div>
      <div>
        <dt>End</dt>
        <dd>2022-05-01 13:10:43.738358</dd>
      </div>
      <div>
        <dt>Status code</dt>
        <dd>1</dd>
      </div>
      <div>
        <dt>Error</dt>
        <dd>Traceback (most recent call last):
  File "/opt/python/urllib3/connection.py", line 174, in _new_conn
    conn = connection.create_connection(
  File "/opt/python/urllib3/util/connection.py", line 72, in create_connection
    for res in socket.getaddrinfo(host, port, family, socket.SOCK_STREAM):
  File "/var/lang/lib/python3.8/socket.py", line 918, in getaddrinfo
    for res in _socket.getaddrinfo(host, port, family, type, proto, flags):
socket.gaierror: [Errno -5] No address associated with hostname

During handling of the above exception, another exception occurred:

Traceback (most recent call last):
  File "/opt/python/urllib3/connectionpool.py", line 703, in urlopen
    httplib_response = self._make_request(
  File "/opt/python/urllib3/connectionpool.py", line 386, in _make_request
    self._validate_conn(conn)
  File "/opt/python/urllib3/connectionpool.py", line 1040, in _validate_conn
    conn.connect()
  File "/opt/python/urllib3/connection.py", line 358, in connect
    conn = self._new_conn()
  File "/opt/python/urllib3/connection.py", line 186, in _new_conn
    raise NewConnectionError(
urllib3.exceptions.NewConnectionError: <urllib3.connection.HTTPSConnection object at 0x7fe3f445b3d0>: Failed to establish a new connection: [Errno -5] No address associated with hostname

During handling of the above exception, another exception occurred:

Traceback (most recent call last):
  File "/opt/python/requests/adapters.py", line 440, in send
    resp = conn.urlopen(
  File "/opt/python/urllib3/connectionpool.py", line 785, in urlopen
    retries = retries.increment(
  File "/opt/python/urllib3/util/retry.py", line 592, in increment
    raise MaxRetryError(_pool, url, error or ResponseError(cause))
urllib3.exceptions.MaxRetryError: HTTPSConnectionPool(host='estates4.warwickdc.gov.uk', port=443): Max retries exceeded with url: /cmis/CouncillorsAtoZ/tabid/39/ScreenMode/Ward/Default.aspx (Caused by NewConnectionError('<urllib3.connection.HTTPSConnection object at 0x7fe3f445b3d0>: Failed to establish a new connection: [Errno -5] No address associated with hostname'))

During handling of the above exception, another exception occurred:

Traceback (most recent call last):
  File "/var/task/lgsf/aws_lambda/handlers.py", line 32, in scraper_worker_handler
    scraper.run(run_log)
  File "/var/task/lgsf/councillors/scrapers.py", line 46, in run
    for councillor_html in self.get_councillors():
  File "/var/task/lgsf/councillors/scrapers.py", line 242, in get_councillors
    req = self.get(self.base_url, extra_headers=self.extra_headers)
  File "/var/task/lgsf/scrapers/base.py", line 48, in get
    response = self.requests_session.get(url, headers=headers, verify=verify)
  File "/opt/python/requests/sessions.py", line 542, in get
    return self.request('GET', url, **kwargs)
  File "/opt/python/requests/sessions.py", line 529, in request
    resp = self.send(prep, **send_kwargs)
  File "/opt/python/requests/sessions.py", line 645, in send
    r = adapter.send(request, **kwargs)
  File "/opt/python/requests/adapters.py", line 519, in send
    raise ConnectionError(e, request=request)
requests.exceptions.ConnectionError: HTTPSConnectionPool(host='estates4.warwickdc.gov.uk', port=443): Max retries exceeded with url: /cmis/CouncillorsAtoZ/tabid/39/ScreenMode/Ward/Default.aspx (Caused by NewConnectionError('<urllib3.connection.HTTPSConnection object at 0x7fe3f445b3d0>: Failed to establish a new connection: [Errno -5] No address associated with hostname'))
</dd>
      </div>
    </dl>
  </div>
  </div>

  <h3>Run log</h3>
  <pre>[13:10:41] Fetching Scraper for: WAW                              handlers.py:23
           Begin attempting to scrape: WAW                        handlers.py:27
           Deleting existing data...                                 base.py:230
[13:10:42] Getting all files in WAW...                               base.py:182
           ...found 1 files in WAW                                   base.py:198
           Deleting batch no. 1 consisting of 1 files                base.py:207
[13:10:43] ...data deleted.                                          base.py:237
           Scraping from https://estates4.warwickdc.gov.uk/cmis/Counc base.py:42
           illorsAtoZ/tabid/39/ScreenMode/Ward/Default.aspx                     
           HTTPSConnectionPool(host='estates4.warwickdc.gov.uk',  handlers.py:36
           port=443): Max retries exceeded with url: /cmis/Counci               
           llorsAtoZ/tabid/39/ScreenMode/Ward/Default.aspx                      
           (Caused by NewConnectionError('<urllib3.connection.HTT               
           PSConnection object at 0x7fe3f445b3d0>: Failed to                    
           establish a new connection: [Errno -5] No address                    
           associated with hostname'))                                          
           Finished attempting to scrape: WAW                        base.py:315
</pre>
  

  


  <h2 id="2022-04-30-13-00">2022-04-30</h2>
  <div class="ds-card">
  <div class="ds-card-body">
    <dl class="ds-descriptions">
      <div>
        <dt>Duration</dt>
        <dd>2 seconds</dd>
      </div>
      <div>
        <dt>Start</dt>
        <dd>2022-04-30 13:00:09.401661</dd>
      </div>
      <div>
        <dt>End</dt>
        <dd>2022-04-30 13:00:11.517708</dd>
      </div>
      <div>
        <dt>Status code</dt>
        <dd>1</dd>
      </div>
      <div>
        <dt>Error</dt>
        <dd>Traceback (most recent call last):
  File "/opt/python/urllib3/connection.py", line 174, in _new_conn
    conn = connection.create_connection(
  File "/opt/python/urllib3/util/connection.py", line 72, in create_connection
    for res in socket.getaddrinfo(host, port, family, socket.SOCK_STREAM):
  File "/var/lang/lib/python3.8/socket.py", line 918, in getaddrinfo
    for res in _socket.getaddrinfo(host, port, family, type, proto, flags):
socket.gaierror: [Errno -5] No address associated with hostname

During handling of the above exception, another exception occurred:

Traceback (most recent call last):
  File "/opt/python/urllib3/connectionpool.py", line 703, in urlopen
    httplib_response = self._make_request(
  File "/opt/python/urllib3/connectionpool.py", line 386, in _make_request
    self._validate_conn(conn)
  File "/opt/python/urllib3/connectionpool.py", line 1040, in _validate_conn
    conn.connect()
  File "/opt/python/urllib3/connection.py", line 358, in connect
    conn = self._new_conn()
  File "/opt/python/urllib3/connection.py", line 186, in _new_conn
    raise NewConnectionError(
urllib3.exceptions.NewConnectionError: <urllib3.connection.HTTPSConnection object at 0x7fea02f0efd0>: Failed to establish a new connection: [Errno -5] No address associated with hostname

During handling of the above exception, another exception occurred:

Traceback (most recent call last):
  File "/opt/python/requests/adapters.py", line 440, in send
    resp = conn.urlopen(
  File "/opt/python/urllib3/connectionpool.py", line 785, in urlopen
    retries = retries.increment(
  File "/opt/python/urllib3/util/retry.py", line 592, in increment
    raise MaxRetryError(_pool, url, error or ResponseError(cause))
urllib3.exceptions.MaxRetryError: HTTPSConnectionPool(host='estates4.warwickdc.gov.uk', port=443): Max retries exceeded with url: /cmis/CouncillorsAtoZ/tabid/39/ScreenMode/Ward/Default.aspx (Caused by NewConnectionError('<urllib3.connection.HTTPSConnection object at 0x7fea02f0efd0>: Failed to establish a new connection: [Errno -5] No address associated with hostname'))

During handling of the above exception, another exception occurred:

Traceback (most recent call last):
  File "/var/task/lgsf/aws_lambda/handlers.py", line 32, in scraper_worker_handler
    scraper.run(run_log)
  File "/var/task/lgsf/councillors/scrapers.py", line 46, in run
    for councillor_html in self.get_councillors():
  File "/var/task/lgsf/councillors/scrapers.py", line 242, in get_councillors
    req = self.get(self.base_url, extra_headers=self.extra_headers)
  File "/var/task/lgsf/scrapers/base.py", line 48, in get
    response = self.requests_session.get(url, headers=headers, verify=verify)
  File "/opt/python/requests/sessions.py", line 542, in get
    return self.request('GET', url, **kwargs)
  File "/opt/python/requests/sessions.py", line 529, in request
    resp = self.send(prep, **send_kwargs)
  File "/opt/python/requests/sessions.py", line 645, in send
    r = adapter.send(request, **kwargs)
  File "/opt/python/requests/adapters.py", line 519, in send
    raise ConnectionError(e, request=request)
requests.exceptions.ConnectionError: HTTPSConnectionPool(host='estates4.warwickdc.gov.uk', port=443): Max retries exceeded with url: /cmis/CouncillorsAtoZ/tabid/39/ScreenMode/Ward/Default.aspx (Caused by NewConnectionError('<urllib3.connection.HTTPSConnection object at 0x7fea02f0efd0>: Failed to establish a new connection: [Errno -5] No address associated with hostname'))
</dd>
      </div>
    </dl>
  </div>
  </div>

  <h3>Run log</h3>
  <pre>[13:00:09] Fetching Scraper for: WAW                              handlers.py:23
           Begin attempting to scrape: WAW                        handlers.py:27
           Deleting existing data...                                 base.py:230
[13:00:10] Getting all files in WAW...                               base.py:182
           ...found 1 files in WAW                                   base.py:198
           Deleting batch no. 1 consisting of 1 files                base.py:207
[13:00:11] ...data deleted.                                          base.py:237
           Scraping from https://estates4.warwickdc.gov.uk/cmis/Counc base.py:42
           illorsAtoZ/tabid/39/ScreenMode/Ward/Default.aspx                     
           HTTPSConnectionPool(host='estates4.warwickdc.gov.uk',  handlers.py:36
           port=443): Max retries exceeded with url: /cmis/Counci               
           llorsAtoZ/tabid/39/ScreenMode/Ward/Default.aspx                      
           (Caused by NewConnectionError('<urllib3.connection.HTT               
           PSConnection object at 0x7fea02f0efd0>: Failed to                    
           establish a new connection: [Errno -5] No address                    
           associated with hostname'))                                          
           Finished attempting to scrape: WAW                        base.py:315
</pre>
  

  


  <h2 id="2022-04-29-14-05">2022-04-29</h2>
  <div class="ds-card">
  <div class="ds-card-body">
    <dl class="ds-descriptions">
      <div>
        <dt>Duration</dt>
        <dd>2 seconds</dd>
      </div>
      <div>
        <dt>Start</dt>
        <dd>2022-04-29 14:05:23.418895</dd>
      </div>
      <div>
        <dt>End</dt>
        <dd>2022-04-29 14:05:25.687216</dd>
      </div>
      <div>
        <dt>Status code</dt>
        <dd>1</dd>
      </div>
      <div>
        <dt>Error</dt>
        <dd>Traceback (most recent call last):
  File "/opt/python/urllib3/connection.py", line 174, in _new_conn
    conn = connection.create_connection(
  File "/opt/python/urllib3/util/connection.py", line 72, in create_connection
    for res in socket.getaddrinfo(host, port, family, socket.SOCK_STREAM):
  File "/var/lang/lib/python3.8/socket.py", line 918, in getaddrinfo
    for res in _socket.getaddrinfo(host, port, family, type, proto, flags):
socket.gaierror: [Errno -5] No address associated with hostname

During handling of the above exception, another exception occurred:

Traceback (most recent call last):
  File "/opt/python/urllib3/connectionpool.py", line 703, in urlopen
    httplib_response = self._make_request(
  File "/opt/python/urllib3/connectionpool.py", line 386, in _make_request
    self._validate_conn(conn)
  File "/opt/python/urllib3/connectionpool.py", line 1040, in _validate_conn
    conn.connect()
  File "/opt/python/urllib3/connection.py", line 358, in connect
    conn = self._new_conn()
  File "/opt/python/urllib3/connection.py", line 186, in _new_conn
    raise NewConnectionError(
urllib3.exceptions.NewConnectionError: <urllib3.connection.HTTPSConnection object at 0x7fa8153a1940>: Failed to establish a new connection: [Errno -5] No address associated with hostname

During handling of the above exception, another exception occurred:

Traceback (most recent call last):
  File "/opt/python/requests/adapters.py", line 440, in send
    resp = conn.urlopen(
  File "/opt/python/urllib3/connectionpool.py", line 785, in urlopen
    retries = retries.increment(
  File "/opt/python/urllib3/util/retry.py", line 592, in increment
    raise MaxRetryError(_pool, url, error or ResponseError(cause))
urllib3.exceptions.MaxRetryError: HTTPSConnectionPool(host='estates4.warwickdc.gov.uk', port=443): Max retries exceeded with url: /cmis/CouncillorsAtoZ/tabid/39/ScreenMode/Ward/Default.aspx (Caused by NewConnectionError('<urllib3.connection.HTTPSConnection object at 0x7fa8153a1940>: Failed to establish a new connection: [Errno -5] No address associated with hostname'))

During handling of the above exception, another exception occurred:

Traceback (most recent call last):
  File "/var/task/lgsf/aws_lambda/handlers.py", line 32, in scraper_worker_handler
    scraper.run(run_log)
  File "/var/task/lgsf/councillors/scrapers.py", line 46, in run
    for councillor_html in self.get_councillors():
  File "/var/task/lgsf/councillors/scrapers.py", line 242, in get_councillors
    req = self.get(self.base_url, extra_headers=self.extra_headers)
  File "/var/task/lgsf/scrapers/base.py", line 48, in get
    response = self.requests_session.get(url, headers=headers, verify=verify)
  File "/opt/python/requests/sessions.py", line 542, in get
    return self.request('GET', url, **kwargs)
  File "/opt/python/requests/sessions.py", line 529, in request
    resp = self.send(prep, **send_kwargs)
  File "/opt/python/requests/sessions.py", line 645, in send
    r = adapter.send(request, **kwargs)
  File "/opt/python/requests/adapters.py", line 519, in send
    raise ConnectionError(e, request=request)
requests.exceptions.ConnectionError: HTTPSConnectionPool(host='estates4.warwickdc.gov.uk', port=443): Max retries exceeded with url: /cmis/CouncillorsAtoZ/tabid/39/ScreenMode/Ward/Default.aspx (Caused by NewConnectionError('<urllib3.connection.HTTPSConnection object at 0x7fa8153a1940>: Failed to establish a new connection: [Errno -5] No address associated with hostname'))
</dd>
      </div>
    </dl>
  </div>
  </div>

  <h3>Run log</h3>
  <pre>[14:05:23] Fetching Scraper for: WAW                              handlers.py:23
           Begin attempting to scrape: WAW                        handlers.py:27
           Deleting existing data...                                 base.py:230
[14:05:24] Getting all files in WAW...                               base.py:182
           ...found 1 files in WAW                                   base.py:198
           Deleting batch no. 1 consisting of 1 files                base.py:207
[14:05:25] ...data deleted.                                          base.py:237
           Scraping from https://estates4.warwickdc.gov.uk/cmis/Counc base.py:42
           illorsAtoZ/tabid/39/ScreenMode/Ward/Default.aspx                     
           HTTPSConnectionPool(host='estates4.warwickdc.gov.uk',  handlers.py:36
           port=443): Max retries exceeded with url: /cmis/Counci               
           llorsAtoZ/tabid/39/ScreenMode/Ward/Default.aspx                      
           (Caused by NewConnectionError('<urllib3.connection.HTT               
           PSConnection object at 0x7fa8153a1940>: Failed to                    
           establish a new connection: [Errno -5] No address                    
           associated with hostname'))                                          
           Finished attempting to scrape: WAW                        base.py:315
</pre>
  

  


  <h2 id="2022-04-28-12-26">2022-04-28</h2>
  <div class="ds-card">
  <div class="ds-card-body">
    <dl class="ds-descriptions">
      <div>
        <dt>Duration</dt>
        <dd>2 seconds</dd>
      </div>
      <div>
        <dt>Start</dt>
        <dd>2022-04-28 12:26:27.002298</dd>
      </div>
      <div>
        <dt>End</dt>
        <dd>2022-04-28 12:26:29.264028</dd>
      </div>
      <div>
        <dt>Status code</dt>
        <dd>1</dd>
      </div>
      <div>
        <dt>Error</dt>
        <dd>Traceback (most recent call last):
  File "/opt/python/urllib3/connection.py", line 174, in _new_conn
    conn = connection.create_connection(
  File "/opt/python/urllib3/util/connection.py", line 72, in create_connection
    for res in socket.getaddrinfo(host, port, family, socket.SOCK_STREAM):
  File "/var/lang/lib/python3.8/socket.py", line 918, in getaddrinfo
    for res in _socket.getaddrinfo(host, port, family, type, proto, flags):
socket.gaierror: [Errno -5] No address associated with hostname

During handling of the above exception, another exception occurred:

Traceback (most recent call last):
  File "/opt/python/urllib3/connectionpool.py", line 703, in urlopen
    httplib_response = self._make_request(
  File "/opt/python/urllib3/connectionpool.py", line 386, in _make_request
    self._validate_conn(conn)
  File "/opt/python/urllib3/connectionpool.py", line 1040, in _validate_conn
    conn.connect()
  File "/opt/python/urllib3/connection.py", line 358, in connect
    conn = self._new_conn()
  File "/opt/python/urllib3/connection.py", line 186, in _new_conn
    raise NewConnectionError(
urllib3.exceptions.NewConnectionError: <urllib3.connection.HTTPSConnection object at 0x7fe5997df490>: Failed to establish a new connection: [Errno -5] No address associated with hostname

During handling of the above exception, another exception occurred:

Traceback (most recent call last):
  File "/opt/python/requests/adapters.py", line 440, in send
    resp = conn.urlopen(
  File "/opt/python/urllib3/connectionpool.py", line 785, in urlopen
    retries = retries.increment(
  File "/opt/python/urllib3/util/retry.py", line 592, in increment
    raise MaxRetryError(_pool, url, error or ResponseError(cause))
urllib3.exceptions.MaxRetryError: HTTPSConnectionPool(host='estates4.warwickdc.gov.uk', port=443): Max retries exceeded with url: /cmis/CouncillorsAtoZ/tabid/39/ScreenMode/Ward/Default.aspx (Caused by NewConnectionError('<urllib3.connection.HTTPSConnection object at 0x7fe5997df490>: Failed to establish a new connection: [Errno -5] No address associated with hostname'))

During handling of the above exception, another exception occurred:

Traceback (most recent call last):
  File "/var/task/lgsf/aws_lambda/handlers.py", line 32, in scraper_worker_handler
    scraper.run(run_log)
  File "/var/task/lgsf/councillors/scrapers.py", line 46, in run
    for councillor_html in self.get_councillors():
  File "/var/task/lgsf/councillors/scrapers.py", line 242, in get_councillors
    req = self.get(self.base_url, extra_headers=self.extra_headers)
  File "/var/task/lgsf/scrapers/base.py", line 48, in get
    response = self.requests_session.get(url, headers=headers, verify=verify)
  File "/opt/python/requests/sessions.py", line 542, in get
    return self.request('GET', url, **kwargs)
  File "/opt/python/requests/sessions.py", line 529, in request
    resp = self.send(prep, **send_kwargs)
  File "/opt/python/requests/sessions.py", line 645, in send
    r = adapter.send(request, **kwargs)
  File "/opt/python/requests/adapters.py", line 519, in send
    raise ConnectionError(e, request=request)
requests.exceptions.ConnectionError: HTTPSConnectionPool(host='estates4.warwickdc.gov.uk', port=443): Max retries exceeded with url: /cmis/CouncillorsAtoZ/tabid/39/ScreenMode/Ward/Default.aspx (Caused by NewConnectionError('<urllib3.connection.HTTPSConnection object at 0x7fe5997df490>: Failed to establish a new connection: [Errno -5] No address associated with hostname'))
</dd>
      </div>
    </dl>
  </div>
  </div>

  <h3>Run log</h3>
  <pre>[12:26:27] Fetching Scraper for: WAW                              handlers.py:23
           Begin attempting to scrape: WAW                        handlers.py:27
           Deleting existing data...                                 base.py:230
           Getting all files in WAW...                               base.py:182
           ...found 1 files in WAW                                   base.py:198
[12:26:28] Deleting batch no. 1 consisting of 1 files                base.py:207
[12:26:29] ...data deleted.                                          base.py:237
           Scraping from https://estates4.warwickdc.gov.uk/cmis/Counc base.py:42
           illorsAtoZ/tabid/39/ScreenMode/Ward/Default.aspx                     
           HTTPSConnectionPool(host='estates4.warwickdc.gov.uk',  handlers.py:36
           port=443): Max retries exceeded with url: /cmis/Counci               
           llorsAtoZ/tabid/39/ScreenMode/Ward/Default.aspx                      
           (Caused by NewConnectionError('<urllib3.connection.HTT               
           PSConnection object at 0x7fe5997df490>: Failed to                    
           establish a new connection: [Errno -5] No address                    
           associated with hostname'))                                          
           Finished attempting to scrape: WAW                        base.py:315
</pre>
  

  


  <h2 id="2022-04-27-14-30">2022-04-27</h2>
  <div class="ds-card">
  <div class="ds-card-body">
    <dl class="ds-descriptions">
      <div>
        <dt>Duration</dt>
        <dd>2 seconds</dd>
      </div>
      <div>
        <dt>Start</dt>
        <dd>2022-04-27 14:30:06.632773</dd>
      </div>
      <div>
        <dt>End</dt>
        <dd>2022-04-27 14:30:08.723634</dd>
      </div>
      <div>
        <dt>Status code</dt>
        <dd>1</dd>
      </div>
      <div>
        <dt>Error</dt>
        <dd>Traceback (most recent call last):
  File "/opt/python/urllib3/connection.py", line 174, in _new_conn
    conn = connection.create_connection(
  File "/opt/python/urllib3/util/connection.py", line 72, in create_connection
    for res in socket.getaddrinfo(host, port, family, socket.SOCK_STREAM):
  File "/var/lang/lib/python3.8/socket.py", line 918, in getaddrinfo
    for res in _socket.getaddrinfo(host, port, family, type, proto, flags):
socket.gaierror: [Errno -5] No address associated with hostname

During handling of the above exception, another exception occurred:

Traceback (most recent call last):
  File "/opt/python/urllib3/connectionpool.py", line 703, in urlopen
    httplib_response = self._make_request(
  File "/opt/python/urllib3/connectionpool.py", line 386, in _make_request
    self._validate_conn(conn)
  File "/opt/python/urllib3/connectionpool.py", line 1040, in _validate_conn
    conn.connect()
  File "/opt/python/urllib3/connection.py", line 358, in connect
    conn = self._new_conn()
  File "/opt/python/urllib3/connection.py", line 186, in _new_conn
    raise NewConnectionError(
urllib3.exceptions.NewConnectionError: <urllib3.connection.HTTPSConnection object at 0x7f23b05e4940>: Failed to establish a new connection: [Errno -5] No address associated with hostname

During handling of the above exception, another exception occurred:

Traceback (most recent call last):
  File "/opt/python/requests/adapters.py", line 440, in send
    resp = conn.urlopen(
  File "/opt/python/urllib3/connectionpool.py", line 785, in urlopen
    retries = retries.increment(
  File "/opt/python/urllib3/util/retry.py", line 592, in increment
    raise MaxRetryError(_pool, url, error or ResponseError(cause))
urllib3.exceptions.MaxRetryError: HTTPSConnectionPool(host='estates4.warwickdc.gov.uk', port=443): Max retries exceeded with url: /cmis/CouncillorsAtoZ/tabid/39/ScreenMode/Ward/Default.aspx (Caused by NewConnectionError('<urllib3.connection.HTTPSConnection object at 0x7f23b05e4940>: Failed to establish a new connection: [Errno -5] No address associated with hostname'))

During handling of the above exception, another exception occurred:

Traceback (most recent call last):
  File "/var/task/lgsf/aws_lambda/handlers.py", line 32, in scraper_worker_handler
    scraper.run(run_log)
  File "/var/task/lgsf/councillors/scrapers.py", line 46, in run
    for councillor_html in self.get_councillors():
  File "/var/task/lgsf/councillors/scrapers.py", line 242, in get_councillors
    req = self.get(self.base_url, extra_headers=self.extra_headers)
  File "/var/task/lgsf/scrapers/base.py", line 48, in get
    response = self.requests_session.get(url, headers=headers, verify=verify)
  File "/opt/python/requests/sessions.py", line 542, in get
    return self.request('GET', url, **kwargs)
  File "/opt/python/requests/sessions.py", line 529, in request
    resp = self.send(prep, **send_kwargs)
  File "/opt/python/requests/sessions.py", line 645, in send
    r = adapter.send(request, **kwargs)
  File "/opt/python/requests/adapters.py", line 519, in send
    raise ConnectionError(e, request=request)
requests.exceptions.ConnectionError: HTTPSConnectionPool(host='estates4.warwickdc.gov.uk', port=443): Max retries exceeded with url: /cmis/CouncillorsAtoZ/tabid/39/ScreenMode/Ward/Default.aspx (Caused by NewConnectionError('<urllib3.connection.HTTPSConnection object at 0x7f23b05e4940>: Failed to establish a new connection: [Errno -5] No address associated with hostname'))
</dd>
      </div>
    </dl>
  </div>
  </div>

  <h3>Run log</h3>
  <pre>[14:30:06] Fetching Scraper for: WAW                              handlers.py:23
           Begin attempting to scrape: WAW                        handlers.py:27
           Deleting existing data...                                 base.py:230
[14:30:07] Getting all files in WAW...                               base.py:182
           ...found 1 files in WAW                                   base.py:198
           Deleting batch no. 1 consisting of 1 files                base.py:207
[14:30:08] ...data deleted.                                          base.py:237
           Scraping from https://estates4.warwickdc.gov.uk/cmis/Counc base.py:42
           illorsAtoZ/tabid/39/ScreenMode/Ward/Default.aspx                     
           HTTPSConnectionPool(host='estates4.warwickdc.gov.uk',  handlers.py:36
           port=443): Max retries exceeded with url: /cmis/Counci               
           llorsAtoZ/tabid/39/ScreenMode/Ward/Default.aspx                      
           (Caused by NewConnectionError('<urllib3.connection.HTT               
           PSConnection object at 0x7f23b05e4940>: Failed to                    
           establish a new connection: [Errno -5] No address                    
           associated with hostname'))                                          
           Finished attempting to scrape: WAW                        base.py:315
</pre>
  

  


  <h2 id="2022-04-26-12-38">2022-04-26</h2>
  <div class="ds-card">
  <div class="ds-card-body">
    <dl class="ds-descriptions">
      <div>
        <dt>Duration</dt>
        <dd>2 seconds</dd>
      </div>
      <div>
        <dt>Start</dt>
        <dd>2022-04-26 12:38:02.053006</dd>
      </div>
      <div>
        <dt>End</dt>
        <dd>2022-04-26 12:38:04.408831</dd>
      </div>
      <div>
        <dt>Status code</dt>
        <dd>1</dd>
      </div>
      <div>
        <dt>Error</dt>
        <dd>Traceback (most recent call last):
  File "/opt/python/urllib3/connection.py", line 174, in _new_conn
    conn = connection.create_connection(
  File "/opt/python/urllib3/util/connection.py", line 72, in create_connection
    for res in socket.getaddrinfo(host, port, family, socket.SOCK_STREAM):
  File "/var/lang/lib/python3.8/socket.py", line 918, in getaddrinfo
    for res in _socket.getaddrinfo(host, port, family, type, proto, flags):
socket.gaierror: [Errno -5] No address associated with hostname

During handling of the above exception, another exception occurred:

Traceback (most recent call last):
  File "/opt/python/urllib3/connectionpool.py", line 703, in urlopen
    httplib_response = self._make_request(
  File "/opt/python/urllib3/connectionpool.py", line 386, in _make_request
    self._validate_conn(conn)
  File "/opt/python/urllib3/connectionpool.py", line 1040, in _validate_conn
    conn.connect()
  File "/opt/python/urllib3/connection.py", line 358, in connect
    conn = self._new_conn()
  File "/opt/python/urllib3/connection.py", line 186, in _new_conn
    raise NewConnectionError(
urllib3.exceptions.NewConnectionError: <urllib3.connection.HTTPSConnection object at 0x7fdbacac6400>: Failed to establish a new connection: [Errno -5] No address associated with hostname

During handling of the above exception, another exception occurred:

Traceback (most recent call last):
  File "/opt/python/requests/adapters.py", line 440, in send
    resp = conn.urlopen(
  File "/opt/python/urllib3/connectionpool.py", line 785, in urlopen
    retries = retries.increment(
  File "/opt/python/urllib3/util/retry.py", line 592, in increment
    raise MaxRetryError(_pool, url, error or ResponseError(cause))
urllib3.exceptions.MaxRetryError: HTTPSConnectionPool(host='estates4.warwickdc.gov.uk', port=443): Max retries exceeded with url: /cmis/CouncillorsAtoZ/tabid/39/ScreenMode/Ward/Default.aspx (Caused by NewConnectionError('<urllib3.connection.HTTPSConnection object at 0x7fdbacac6400>: Failed to establish a new connection: [Errno -5] No address associated with hostname'))

During handling of the above exception, another exception occurred:

Traceback (most recent call last):
  File "/var/task/lgsf/aws_lambda/handlers.py", line 32, in scraper_worker_handler
    scraper.run(run_log)
  File "/var/task/lgsf/councillors/scrapers.py", line 46, in run
    for councillor_html in self.get_councillors():
  File "/var/task/lgsf/councillors/scrapers.py", line 242, in get_councillors
    req = self.get(self.base_url, extra_headers=self.extra_headers)
  File "/var/task/lgsf/scrapers/base.py", line 48, in get
    response = self.requests_session.get(url, headers=headers, verify=verify)
  File "/opt/python/requests/sessions.py", line 542, in get
    return self.request('GET', url, **kwargs)
  File "/opt/python/requests/sessions.py", line 529, in request
    resp = self.send(prep, **send_kwargs)
  File "/opt/python/requests/sessions.py", line 645, in send
    r = adapter.send(request, **kwargs)
  File "/opt/python/requests/adapters.py", line 519, in send
    raise ConnectionError(e, request=request)
requests.exceptions.ConnectionError: HTTPSConnectionPool(host='estates4.warwickdc.gov.uk', port=443): Max retries exceeded with url: /cmis/CouncillorsAtoZ/tabid/39/ScreenMode/Ward/Default.aspx (Caused by NewConnectionError('<urllib3.connection.HTTPSConnection object at 0x7fdbacac6400>: Failed to establish a new connection: [Errno -5] No address associated with hostname'))
</dd>
      </div>
    </dl>
  </div>
  </div>

  <h3>Run log</h3>
  <pre>[12:38:02] Fetching Scraper for: WAW                              handlers.py:23
           Begin attempting to scrape: WAW                        handlers.py:27
           Deleting existing data...                                 base.py:230
           Getting all files in WAW...                               base.py:182
[12:38:03] ...found 1 files in WAW                                   base.py:198
           Deleting batch no. 1 consisting of 1 files                base.py:207
[12:38:04] ...data deleted.                                          base.py:237
           Scraping from https://estates4.warwickdc.gov.uk/cmis/Counc base.py:42
           illorsAtoZ/tabid/39/ScreenMode/Ward/Default.aspx                     
           HTTPSConnectionPool(host='estates4.warwickdc.gov.uk',  handlers.py:36
           port=443): Max retries exceeded with url: /cmis/Counci               
           llorsAtoZ/tabid/39/ScreenMode/Ward/Default.aspx                      
           (Caused by NewConnectionError('<urllib3.connection.HTT               
           PSConnection object at 0x7fdbacac6400>: Failed to                    
           establish a new connection: [Errno -5] No address                    
           associated with hostname'))                                          
           Finished attempting to scrape: WAW                        base.py:315
</pre>
  

  


  <h2 id="2022-04-25-12-14">2022-04-25</h2>
  <div class="ds-card">
  <div class="ds-card-body">
    <dl class="ds-descriptions">
      <div>
        <dt>Duration</dt>
        <dd>2 seconds</dd>
      </div>
      <div>
        <dt>Start</dt>
        <dd>2022-04-25 12:14:03.825680</dd>
      </div>
      <div>
        <dt>End</dt>
        <dd>2022-04-25 12:14:06.147045</dd>
      </div>
      <div>
        <dt>Status code</dt>
        <dd>1</dd>
      </div>
      <div>
        <dt>Error</dt>
        <dd>Traceback (most recent call last):
  File "/opt/python/urllib3/connection.py", line 174, in _new_conn
    conn = connection.create_connection(
  File "/opt/python/urllib3/util/connection.py", line 72, in create_connection
    for res in socket.getaddrinfo(host, port, family, socket.SOCK_STREAM):
  File "/var/lang/lib/python3.8/socket.py", line 918, in getaddrinfo
    for res in _socket.getaddrinfo(host, port, family, type, proto, flags):
socket.gaierror: [Errno -5] No address associated with hostname

During handling of the above exception, another exception occurred:

Traceback (most recent call last):
  File "/opt/python/urllib3/connectionpool.py", line 703, in urlopen
    httplib_response = self._make_request(
  File "/opt/python/urllib3/connectionpool.py", line 386, in _make_request
    self._validate_conn(conn)
  File "/opt/python/urllib3/connectionpool.py", line 1040, in _validate_conn
    conn.connect()
  File "/opt/python/urllib3/connection.py", line 358, in connect
    conn = self._new_conn()
  File "/opt/python/urllib3/connection.py", line 186, in _new_conn
    raise NewConnectionError(
urllib3.exceptions.NewConnectionError: <urllib3.connection.HTTPSConnection object at 0x7fea020b55b0>: Failed to establish a new connection: [Errno -5] No address associated with hostname

During handling of the above exception, another exception occurred:

Traceback (most recent call last):
  File "/opt/python/requests/adapters.py", line 440, in send
    resp = conn.urlopen(
  File "/opt/python/urllib3/connectionpool.py", line 785, in urlopen
    retries = retries.increment(
  File "/opt/python/urllib3/util/retry.py", line 592, in increment
    raise MaxRetryError(_pool, url, error or ResponseError(cause))
urllib3.exceptions.MaxRetryError: HTTPSConnectionPool(host='estates4.warwickdc.gov.uk', port=443): Max retries exceeded with url: /cmis/CouncillorsAtoZ/tabid/39/ScreenMode/Ward/Default.aspx (Caused by NewConnectionError('<urllib3.connection.HTTPSConnection object at 0x7fea020b55b0>: Failed to establish a new connection: [Errno -5] No address associated with hostname'))

During handling of the above exception, another exception occurred:

Traceback (most recent call last):
  File "/var/task/lgsf/aws_lambda/handlers.py", line 32, in scraper_worker_handler
    scraper.run(run_log)
  File "/var/task/lgsf/councillors/scrapers.py", line 46, in run
    for councillor_html in self.get_councillors():
  File "/var/task/lgsf/councillors/scrapers.py", line 242, in get_councillors
    req = self.get(self.base_url, extra_headers=self.extra_headers)
  File "/var/task/lgsf/scrapers/base.py", line 48, in get
    response = self.requests_session.get(url, headers=headers, verify=verify)
  File "/opt/python/requests/sessions.py", line 542, in get
    return self.request('GET', url, **kwargs)
  File "/opt/python/requests/sessions.py", line 529, in request
    resp = self.send(prep, **send_kwargs)
  File "/opt/python/requests/sessions.py", line 645, in send
    r = adapter.send(request, **kwargs)
  File "/opt/python/requests/adapters.py", line 519, in send
    raise ConnectionError(e, request=request)
requests.exceptions.ConnectionError: HTTPSConnectionPool(host='estates4.warwickdc.gov.uk', port=443): Max retries exceeded with url: /cmis/CouncillorsAtoZ/tabid/39/ScreenMode/Ward/Default.aspx (Caused by NewConnectionError('<urllib3.connection.HTTPSConnection object at 0x7fea020b55b0>: Failed to establish a new connection: [Errno -5] No address associated with hostname'))
</dd>
      </div>
    </dl>
  </div>
  </div>

  <h3>Run log</h3>
  <pre>[12:14:03] Fetching Scraper for: WAW                              handlers.py:23
           Begin attempting to scrape: WAW                        handlers.py:27
           Deleting existing data...                                 base.py:230
[12:14:04] Getting all files in WAW...                               base.py:182
           ...found 1 files in WAW                                   base.py:198
           Deleting batch no. 1 consisting of 1 files                base.py:207
[12:14:05] ...data deleted.                                          base.py:237
           Scraping from https://estates4.warwickdc.gov.uk/cmis/Counc base.py:42
           illorsAtoZ/tabid/39/ScreenMode/Ward/Default.aspx                     
           HTTPSConnectionPool(host='estates4.warwickdc.gov.uk',  handlers.py:36
           port=443): Max retries exceeded with url: /cmis/Counci               
           llorsAtoZ/tabid/39/ScreenMode/Ward/Default.aspx                      
           (Caused by NewConnectionError('<urllib3.connection.HTT               
           PSConnection object at 0x7fea020b55b0>: Failed to                    
           establish a new connection: [Errno -5] No address                    
           associated with hostname'))                                          
[12:14:06] Finished attempting to scrape: WAW                        base.py:315
</pre>
  

  


  <h2 id="2022-04-24-17-34">2022-04-24</h2>
  <div class="ds-card">
  <div class="ds-card-body">
    <dl class="ds-descriptions">
      <div>
        <dt>Duration</dt>
        <dd>2 seconds</dd>
      </div>
      <div>
        <dt>Start</dt>
        <dd>2022-04-24 17:34:27.640513</dd>
      </div>
      <div>
        <dt>End</dt>
        <dd>2022-04-24 17:34:29.894027</dd>
      </div>
      <div>
        <dt>Status code</dt>
        <dd>1</dd>
      </div>
      <div>
        <dt>Error</dt>
        <dd>Traceback (most recent call last):
  File "/opt/python/urllib3/connection.py", line 174, in _new_conn
    conn = connection.create_connection(
  File "/opt/python/urllib3/util/connection.py", line 72, in create_connection
    for res in socket.getaddrinfo(host, port, family, socket.SOCK_STREAM):
  File "/var/lang/lib/python3.8/socket.py", line 918, in getaddrinfo
    for res in _socket.getaddrinfo(host, port, family, type, proto, flags):
socket.gaierror: [Errno -5] No address associated with hostname

During handling of the above exception, another exception occurred:

Traceback (most recent call last):
  File "/opt/python/urllib3/connectionpool.py", line 703, in urlopen
    httplib_response = self._make_request(
  File "/opt/python/urllib3/connectionpool.py", line 386, in _make_request
    self._validate_conn(conn)
  File "/opt/python/urllib3/connectionpool.py", line 1040, in _validate_conn
    conn.connect()
  File "/opt/python/urllib3/connection.py", line 358, in connect
    conn = self._new_conn()
  File "/opt/python/urllib3/connection.py", line 186, in _new_conn
    raise NewConnectionError(
urllib3.exceptions.NewConnectionError: <urllib3.connection.HTTPSConnection object at 0x7f77e3ca5c40>: Failed to establish a new connection: [Errno -5] No address associated with hostname

During handling of the above exception, another exception occurred:

Traceback (most recent call last):
  File "/opt/python/requests/adapters.py", line 440, in send
    resp = conn.urlopen(
  File "/opt/python/urllib3/connectionpool.py", line 785, in urlopen
    retries = retries.increment(
  File "/opt/python/urllib3/util/retry.py", line 592, in increment
    raise MaxRetryError(_pool, url, error or ResponseError(cause))
urllib3.exceptions.MaxRetryError: HTTPSConnectionPool(host='estates4.warwickdc.gov.uk', port=443): Max retries exceeded with url: /cmis/CouncillorsAtoZ/tabid/39/ScreenMode/Ward/Default.aspx (Caused by NewConnectionError('<urllib3.connection.HTTPSConnection object at 0x7f77e3ca5c40>: Failed to establish a new connection: [Errno -5] No address associated with hostname'))

During handling of the above exception, another exception occurred:

Traceback (most recent call last):
  File "/var/task/lgsf/aws_lambda/handlers.py", line 32, in scraper_worker_handler
    scraper.run(run_log)
  File "/var/task/lgsf/councillors/scrapers.py", line 46, in run
    for councillor_html in self.get_councillors():
  File "/var/task/lgsf/councillors/scrapers.py", line 242, in get_councillors
    req = self.get(self.base_url, extra_headers=self.extra_headers)
  File "/var/task/lgsf/scrapers/base.py", line 48, in get
    response = self.requests_session.get(url, headers=headers, verify=verify)
  File "/opt/python/requests/sessions.py", line 542, in get
    return self.request('GET', url, **kwargs)
  File "/opt/python/requests/sessions.py", line 529, in request
    resp = self.send(prep, **send_kwargs)
  File "/opt/python/requests/sessions.py", line 645, in send
    r = adapter.send(request, **kwargs)
  File "/opt/python/requests/adapters.py", line 519, in send
    raise ConnectionError(e, request=request)
requests.exceptions.ConnectionError: HTTPSConnectionPool(host='estates4.warwickdc.gov.uk', port=443): Max retries exceeded with url: /cmis/CouncillorsAtoZ/tabid/39/ScreenMode/Ward/Default.aspx (Caused by NewConnectionError('<urllib3.connection.HTTPSConnection object at 0x7f77e3ca5c40>: Failed to establish a new connection: [Errno -5] No address associated with hostname'))
</dd>
      </div>
    </dl>
  </div>
  </div>

  <h3>Run log</h3>
  <pre>[17:34:27] Fetching Scraper for: WAW                              handlers.py:23
           Begin attempting to scrape: WAW                        handlers.py:27
           Deleting existing data...                                 base.py:230
[17:34:28] Getting all files in WAW...                               base.py:182
           ...found 1 files in WAW                                   base.py:198
           Deleting batch no. 1 consisting of 1 files                base.py:207
[17:34:29] ...data deleted.                                          base.py:237
           Scraping from https://estates4.warwickdc.gov.uk/cmis/Counc base.py:42
           illorsAtoZ/tabid/39/ScreenMode/Ward/Default.aspx                     
           HTTPSConnectionPool(host='estates4.warwickdc.gov.uk',  handlers.py:36
           port=443): Max retries exceeded with url: /cmis/Counci               
           llorsAtoZ/tabid/39/ScreenMode/Ward/Default.aspx                      
           (Caused by NewConnectionError('<urllib3.connection.HTT               
           PSConnection object at 0x7f77e3ca5c40>: Failed to                    
           establish a new connection: [Errno -5] No address                    
           associated with hostname'))                                          
           Finished attempting to scrape: WAW                        base.py:315
</pre>
  

  


  <h2 id="2022-04-23-12-32">2022-04-23</h2>
  <div class="ds-card">
  <div class="ds-card-body">
    <dl class="ds-descriptions">
      <div>
        <dt>Duration</dt>
        <dd>2 seconds</dd>
      </div>
      <div>
        <dt>Start</dt>
        <dd>2022-04-23 12:32:23.149268</dd>
      </div>
      <div>
        <dt>End</dt>
        <dd>2022-04-23 12:32:25.532179</dd>
      </div>
      <div>
        <dt>Status code</dt>
        <dd>1</dd>
      </div>
      <div>
        <dt>Error</dt>
        <dd>Traceback (most recent call last):
  File "/opt/python/urllib3/connection.py", line 174, in _new_conn
    conn = connection.create_connection(
  File "/opt/python/urllib3/util/connection.py", line 72, in create_connection
    for res in socket.getaddrinfo(host, port, family, socket.SOCK_STREAM):
  File "/var/lang/lib/python3.8/socket.py", line 918, in getaddrinfo
    for res in _socket.getaddrinfo(host, port, family, type, proto, flags):
socket.gaierror: [Errno -5] No address associated with hostname

During handling of the above exception, another exception occurred:

Traceback (most recent call last):
  File "/opt/python/urllib3/connectionpool.py", line 703, in urlopen
    httplib_response = self._make_request(
  File "/opt/python/urllib3/connectionpool.py", line 386, in _make_request
    self._validate_conn(conn)
  File "/opt/python/urllib3/connectionpool.py", line 1040, in _validate_conn
    conn.connect()
  File "/opt/python/urllib3/connection.py", line 358, in connect
    conn = self._new_conn()
  File "/opt/python/urllib3/connection.py", line 186, in _new_conn
    raise NewConnectionError(
urllib3.exceptions.NewConnectionError: <urllib3.connection.HTTPSConnection object at 0x7f243e2792b0>: Failed to establish a new connection: [Errno -5] No address associated with hostname

During handling of the above exception, another exception occurred:

Traceback (most recent call last):
  File "/opt/python/requests/adapters.py", line 440, in send
    resp = conn.urlopen(
  File "/opt/python/urllib3/connectionpool.py", line 785, in urlopen
    retries = retries.increment(
  File "/opt/python/urllib3/util/retry.py", line 592, in increment
    raise MaxRetryError(_pool, url, error or ResponseError(cause))
urllib3.exceptions.MaxRetryError: HTTPSConnectionPool(host='estates4.warwickdc.gov.uk', port=443): Max retries exceeded with url: /cmis/CouncillorsAtoZ/tabid/39/ScreenMode/Ward/Default.aspx (Caused by NewConnectionError('<urllib3.connection.HTTPSConnection object at 0x7f243e2792b0>: Failed to establish a new connection: [Errno -5] No address associated with hostname'))

During handling of the above exception, another exception occurred:

Traceback (most recent call last):
  File "/var/task/lgsf/aws_lambda/handlers.py", line 32, in scraper_worker_handler
    scraper.run(run_log)
  File "/var/task/lgsf/councillors/scrapers.py", line 46, in run
    for councillor_html in self.get_councillors():
  File "/var/task/lgsf/councillors/scrapers.py", line 243, in get_councillors
    req = self.get(self.base_url)
  File "/var/task/lgsf/scrapers/base.py", line 46, in get
    response = requests.get(url, headers=headers, verify=verify)
  File "/opt/python/requests/api.py", line 75, in get
    return request('get', url, params=params, **kwargs)
  File "/opt/python/requests/api.py", line 61, in request
    return session.request(method=method, url=url, **kwargs)
  File "/opt/python/requests/sessions.py", line 529, in request
    resp = self.send(prep, **send_kwargs)
  File "/opt/python/requests/sessions.py", line 645, in send
    r = adapter.send(request, **kwargs)
  File "/opt/python/requests/adapters.py", line 519, in send
    raise ConnectionError(e, request=request)
requests.exceptions.ConnectionError: HTTPSConnectionPool(host='estates4.warwickdc.gov.uk', port=443): Max retries exceeded with url: /cmis/CouncillorsAtoZ/tabid/39/ScreenMode/Ward/Default.aspx (Caused by NewConnectionError('<urllib3.connection.HTTPSConnection object at 0x7f243e2792b0>: Failed to establish a new connection: [Errno -5] No address associated with hostname'))
</dd>
      </div>
    </dl>
  </div>
  </div>

  <h3>Run log</h3>
  <pre>[12:32:23] Fetching Scraper for: WAW                              handlers.py:23
           Begin attempting to scrape: WAW                        handlers.py:27
           Deleting existing data...                                 base.py:228
           Getting all files in WAW...                               base.py:180
[12:32:24] ...found 1 files in WAW                                   base.py:196
           Deleting batch no. 1 consisting of 1 files                base.py:205
[12:32:25] ...data deleted.                                          base.py:235
           Scraping from https://estates4.warwickdc.gov.uk/cmis/Counc base.py:40
           illorsAtoZ/tabid/39/ScreenMode/Ward/Default.aspx                     
           HTTPSConnectionPool(host='estates4.warwickdc.gov.uk',  handlers.py:36
           port=443): Max retries exceeded with url: /cmis/Counci               
           llorsAtoZ/tabid/39/ScreenMode/Ward/Default.aspx                      
           (Caused by NewConnectionError('<urllib3.connection.HTT               
           PSConnection object at 0x7f243e2792b0>: Failed to                    
           establish a new connection: [Errno -5] No address                    
           associated with hostname'))                                          
           Finished attempting to scrape: WAW                        base.py:313
</pre>
  

  


  <h2 id="2022-04-22-13-18">2022-04-22</h2>
  <div class="ds-card">
  <div class="ds-card-body">
    <dl class="ds-descriptions">
      <div>
        <dt>Duration</dt>
        <dd>2 seconds</dd>
      </div>
      <div>
        <dt>Start</dt>
        <dd>2022-04-22 13:18:32.775080</dd>
      </div>
      <div>
        <dt>End</dt>
        <dd>2022-04-22 13:18:34.969929</dd>
      </div>
      <div>
        <dt>Status code</dt>
        <dd>1</dd>
      </div>
      <div>
        <dt>Error</dt>
        <dd>Traceback (most recent call last):
  File "/opt/python/urllib3/connection.py", line 174, in _new_conn
    conn = connection.create_connection(
  File "/opt/python/urllib3/util/connection.py", line 72, in create_connection
    for res in socket.getaddrinfo(host, port, family, socket.SOCK_STREAM):
  File "/var/lang/lib/python3.8/socket.py", line 918, in getaddrinfo
    for res in _socket.getaddrinfo(host, port, family, type, proto, flags):
socket.gaierror: [Errno -5] No address associated with hostname

During handling of the above exception, another exception occurred:

Traceback (most recent call last):
  File "/opt/python/urllib3/connectionpool.py", line 703, in urlopen
    httplib_response = self._make_request(
  File "/opt/python/urllib3/connectionpool.py", line 386, in _make_request
    self._validate_conn(conn)
  File "/opt/python/urllib3/connectionpool.py", line 1040, in _validate_conn
    conn.connect()
  File "/opt/python/urllib3/connection.py", line 358, in connect
    conn = self._new_conn()
  File "/opt/python/urllib3/connection.py", line 186, in _new_conn
    raise NewConnectionError(
urllib3.exceptions.NewConnectionError: <urllib3.connection.HTTPSConnection object at 0x7f942d5a0e80>: Failed to establish a new connection: [Errno -5] No address associated with hostname

During handling of the above exception, another exception occurred:

Traceback (most recent call last):
  File "/opt/python/requests/adapters.py", line 440, in send
    resp = conn.urlopen(
  File "/opt/python/urllib3/connectionpool.py", line 785, in urlopen
    retries = retries.increment(
  File "/opt/python/urllib3/util/retry.py", line 592, in increment
    raise MaxRetryError(_pool, url, error or ResponseError(cause))
urllib3.exceptions.MaxRetryError: HTTPSConnectionPool(host='estates4.warwickdc.gov.uk', port=443): Max retries exceeded with url: /cmis/CouncillorsAtoZ/tabid/39/ScreenMode/Ward/Default.aspx (Caused by NewConnectionError('<urllib3.connection.HTTPSConnection object at 0x7f942d5a0e80>: Failed to establish a new connection: [Errno -5] No address associated with hostname'))

During handling of the above exception, another exception occurred:

Traceback (most recent call last):
  File "/var/task/lgsf/aws_lambda/handlers.py", line 32, in scraper_worker_handler
    scraper.run(run_log)
  File "/var/task/lgsf/councillors/scrapers.py", line 46, in run
    for councillor_html in self.get_councillors():
  File "/var/task/lgsf/councillors/scrapers.py", line 243, in get_councillors
    req = self.get(self.base_url)
  File "/var/task/lgsf/scrapers/base.py", line 46, in get
    response = requests.get(url, headers=headers, verify=verify)
  File "/opt/python/requests/api.py", line 75, in get
    return request('get', url, params=params, **kwargs)
  File "/opt/python/requests/api.py", line 61, in request
    return session.request(method=method, url=url, **kwargs)
  File "/opt/python/requests/sessions.py", line 529, in request
    resp = self.send(prep, **send_kwargs)
  File "/opt/python/requests/sessions.py", line 645, in send
    r = adapter.send(request, **kwargs)
  File "/opt/python/requests/adapters.py", line 519, in send
    raise ConnectionError(e, request=request)
requests.exceptions.ConnectionError: HTTPSConnectionPool(host='estates4.warwickdc.gov.uk', port=443): Max retries exceeded with url: /cmis/CouncillorsAtoZ/tabid/39/ScreenMode/Ward/Default.aspx (Caused by NewConnectionError('<urllib3.connection.HTTPSConnection object at 0x7f942d5a0e80>: Failed to establish a new connection: [Errno -5] No address associated with hostname'))
</dd>
      </div>
    </dl>
  </div>
  </div>

  <h3>Run log</h3>
  <pre>[13:18:32] Fetching Scraper for: WAW                              handlers.py:23
           Begin attempting to scrape: WAW                        handlers.py:27
           Deleting existing data...                                 base.py:228
[13:18:33] Getting all files in WAW...                               base.py:180
           ...found 1 files in WAW                                   base.py:196
           Deleting batch no. 1 consisting of 1 files                base.py:205
[13:18:34] ...data deleted.                                          base.py:235
           Scraping from https://estates4.warwickdc.gov.uk/cmis/Counc base.py:40
           illorsAtoZ/tabid/39/ScreenMode/Ward/Default.aspx                     
           HTTPSConnectionPool(host='estates4.warwickdc.gov.uk',  handlers.py:36
           port=443): Max retries exceeded with url: /cmis/Counci               
           llorsAtoZ/tabid/39/ScreenMode/Ward/Default.aspx                      
           (Caused by NewConnectionError('<urllib3.connection.HTT               
           PSConnection object at 0x7f942d5a0e80>: Failed to                    
           establish a new connection: [Errno -5] No address                    
           associated with hostname'))                                          
           Finished attempting to scrape: WAW                        base.py:313
</pre>
  

  


  <h2 id="2022-04-21-13-29">2022-04-21</h2>
  <div class="ds-card">
  <div class="ds-card-body">
    <dl class="ds-descriptions">
      <div>
        <dt>Duration</dt>
        <dd>2 seconds</dd>
      </div>
      <div>
        <dt>Start</dt>
        <dd>2022-04-21 13:29:45.938361</dd>
      </div>
      <div>
        <dt>End</dt>
        <dd>2022-04-21 13:29:48.164003</dd>
      </div>
      <div>
        <dt>Status code</dt>
        <dd>1</dd>
      </div>
      <div>
        <dt>Error</dt>
        <dd>Traceback (most recent call last):
  File "/opt/python/urllib3/connection.py", line 174, in _new_conn
    conn = connection.create_connection(
  File "/opt/python/urllib3/util/connection.py", line 72, in create_connection
    for res in socket.getaddrinfo(host, port, family, socket.SOCK_STREAM):
  File "/var/lang/lib/python3.8/socket.py", line 918, in getaddrinfo
    for res in _socket.getaddrinfo(host, port, family, type, proto, flags):
socket.gaierror: [Errno -5] No address associated with hostname

During handling of the above exception, another exception occurred:

Traceback (most recent call last):
  File "/opt/python/urllib3/connectionpool.py", line 703, in urlopen
    httplib_response = self._make_request(
  File "/opt/python/urllib3/connectionpool.py", line 386, in _make_request
    self._validate_conn(conn)
  File "/opt/python/urllib3/connectionpool.py", line 1040, in _validate_conn
    conn.connect()
  File "/opt/python/urllib3/connection.py", line 358, in connect
    conn = self._new_conn()
  File "/opt/python/urllib3/connection.py", line 186, in _new_conn
    raise NewConnectionError(
urllib3.exceptions.NewConnectionError: <urllib3.connection.HTTPSConnection object at 0x7fea713be040>: Failed to establish a new connection: [Errno -5] No address associated with hostname

During handling of the above exception, another exception occurred:

Traceback (most recent call last):
  File "/opt/python/requests/adapters.py", line 440, in send
    resp = conn.urlopen(
  File "/opt/python/urllib3/connectionpool.py", line 785, in urlopen
    retries = retries.increment(
  File "/opt/python/urllib3/util/retry.py", line 592, in increment
    raise MaxRetryError(_pool, url, error or ResponseError(cause))
urllib3.exceptions.MaxRetryError: HTTPSConnectionPool(host='estates4.warwickdc.gov.uk', port=443): Max retries exceeded with url: /cmis/CouncillorsAtoZ/tabid/39/ScreenMode/Ward/Default.aspx (Caused by NewConnectionError('<urllib3.connection.HTTPSConnection object at 0x7fea713be040>: Failed to establish a new connection: [Errno -5] No address associated with hostname'))

During handling of the above exception, another exception occurred:

Traceback (most recent call last):
  File "/var/task/lgsf/aws_lambda/handlers.py", line 32, in scraper_worker_handler
    scraper.run(run_log)
  File "/var/task/lgsf/councillors/scrapers.py", line 46, in run
    for councillor_html in self.get_councillors():
  File "/var/task/lgsf/councillors/scrapers.py", line 235, in get_councillors
    req = self.get(self.base_url)
  File "/var/task/lgsf/scrapers/base.py", line 46, in get
    response = requests.get(url, headers=headers, verify=verify)
  File "/opt/python/requests/api.py", line 75, in get
    return request('get', url, params=params, **kwargs)
  File "/opt/python/requests/api.py", line 61, in request
    return session.request(method=method, url=url, **kwargs)
  File "/opt/python/requests/sessions.py", line 529, in request
    resp = self.send(prep, **send_kwargs)
  File "/opt/python/requests/sessions.py", line 645, in send
    r = adapter.send(request, **kwargs)
  File "/opt/python/requests/adapters.py", line 519, in send
    raise ConnectionError(e, request=request)
requests.exceptions.ConnectionError: HTTPSConnectionPool(host='estates4.warwickdc.gov.uk', port=443): Max retries exceeded with url: /cmis/CouncillorsAtoZ/tabid/39/ScreenMode/Ward/Default.aspx (Caused by NewConnectionError('<urllib3.connection.HTTPSConnection object at 0x7fea713be040>: Failed to establish a new connection: [Errno -5] No address associated with hostname'))
</dd>
      </div>
    </dl>
  </div>
  </div>

  <h3>Run log</h3>
  <pre>[13:29:45] Fetching Scraper for: WAW                              handlers.py:23
           Begin attempting to scrape: WAW                        handlers.py:27
[13:29:46] Deleting existing data...                                 base.py:228
           Getting all files in WAW...                               base.py:180
           ...found 1 files in WAW                                   base.py:196
           Deleting batch no. 1 consisting of 1 files                base.py:205
[13:29:47] ...data deleted.                                          base.py:235
           Scraping from https://estates4.warwickdc.gov.uk/cmis/Counc base.py:40
           illorsAtoZ/tabid/39/ScreenMode/Ward/Default.aspx                     
           HTTPSConnectionPool(host='estates4.warwickdc.gov.uk',  handlers.py:36
           port=443): Max retries exceeded with url: /cmis/Counci               
           llorsAtoZ/tabid/39/ScreenMode/Ward/Default.aspx                      
           (Caused by NewConnectionError('<urllib3.connection.HTT               
           PSConnection object at 0x7fea713be040>: Failed to                    
           establish a new connection: [Errno -5] No address                    
           associated with hostname'))                                          
[13:29:48] Finished attempting to scrape: WAW                        base.py:313
</pre>
  

  


  <h2 id="2022-04-20-13-44">2022-04-20</h2>
  <div class="ds-card">
  <div class="ds-card-body">
    <dl class="ds-descriptions">
      <div>
        <dt>Duration</dt>
        <dd>2 seconds</dd>
      </div>
      <div>
        <dt>Start</dt>
        <dd>2022-04-20 13:44:36.617334</dd>
      </div>
      <div>
        <dt>End</dt>
        <dd>2022-04-20 13:44:38.900162</dd>
      </div>
      <div>
        <dt>Status code</dt>
        <dd>1</dd>
      </div>
      <div>
        <dt>Error</dt>
        <dd>Traceback (most recent call last):
  File "/opt/python/urllib3/connection.py", line 174, in _new_conn
    conn = connection.create_connection(
  File "/opt/python/urllib3/util/connection.py", line 72, in create_connection
    for res in socket.getaddrinfo(host, port, family, socket.SOCK_STREAM):
  File "/var/lang/lib/python3.8/socket.py", line 918, in getaddrinfo
    for res in _socket.getaddrinfo(host, port, family, type, proto, flags):
socket.gaierror: [Errno -5] No address associated with hostname

During handling of the above exception, another exception occurred:

Traceback (most recent call last):
  File "/opt/python/urllib3/connectionpool.py", line 703, in urlopen
    httplib_response = self._make_request(
  File "/opt/python/urllib3/connectionpool.py", line 386, in _make_request
    self._validate_conn(conn)
  File "/opt/python/urllib3/connectionpool.py", line 1040, in _validate_conn
    conn.connect()
  File "/opt/python/urllib3/connection.py", line 358, in connect
    conn = self._new_conn()
  File "/opt/python/urllib3/connection.py", line 186, in _new_conn
    raise NewConnectionError(
urllib3.exceptions.NewConnectionError: <urllib3.connection.HTTPSConnection object at 0x7fd6efe8c100>: Failed to establish a new connection: [Errno -5] No address associated with hostname

During handling of the above exception, another exception occurred:

Traceback (most recent call last):
  File "/opt/python/requests/adapters.py", line 440, in send
    resp = conn.urlopen(
  File "/opt/python/urllib3/connectionpool.py", line 785, in urlopen
    retries = retries.increment(
  File "/opt/python/urllib3/util/retry.py", line 592, in increment
    raise MaxRetryError(_pool, url, error or ResponseError(cause))
urllib3.exceptions.MaxRetryError: HTTPSConnectionPool(host='estates4.warwickdc.gov.uk', port=443): Max retries exceeded with url: /cmis/CouncillorsAtoZ/tabid/39/ScreenMode/Ward/Default.aspx (Caused by NewConnectionError('<urllib3.connection.HTTPSConnection object at 0x7fd6efe8c100>: Failed to establish a new connection: [Errno -5] No address associated with hostname'))

During handling of the above exception, another exception occurred:

Traceback (most recent call last):
  File "/var/task/lgsf/aws_lambda/handlers.py", line 32, in scraper_worker_handler
    scraper.run(run_log)
  File "/var/task/lgsf/councillors/scrapers.py", line 46, in run
    for councillor_html in self.get_councillors():
  File "/var/task/lgsf/councillors/scrapers.py", line 235, in get_councillors
    req = self.get(self.base_url)
  File "/var/task/lgsf/scrapers/base.py", line 46, in get
    response = requests.get(url, headers=headers, verify=verify)
  File "/opt/python/requests/api.py", line 75, in get
    return request('get', url, params=params, **kwargs)
  File "/opt/python/requests/api.py", line 61, in request
    return session.request(method=method, url=url, **kwargs)
  File "/opt/python/requests/sessions.py", line 529, in request
    resp = self.send(prep, **send_kwargs)
  File "/opt/python/requests/sessions.py", line 645, in send
    r = adapter.send(request, **kwargs)
  File "/opt/python/requests/adapters.py", line 519, in send
    raise ConnectionError(e, request=request)
requests.exceptions.ConnectionError: HTTPSConnectionPool(host='estates4.warwickdc.gov.uk', port=443): Max retries exceeded with url: /cmis/CouncillorsAtoZ/tabid/39/ScreenMode/Ward/Default.aspx (Caused by NewConnectionError('<urllib3.connection.HTTPSConnection object at 0x7fd6efe8c100>: Failed to establish a new connection: [Errno -5] No address associated with hostname'))
</dd>
      </div>
    </dl>
  </div>
  </div>

  <h3>Run log</h3>
  <pre>[13:44:36] Fetching Scraper for: WAW                              handlers.py:23
           Begin attempting to scrape: WAW                        handlers.py:27
           Deleting existing data...                                 base.py:228
[13:44:37] Getting all files in WAW...                               base.py:180
           ...found 1 files in WAW                                   base.py:196
           Deleting batch no. 1 consisting of 1 files                base.py:205
[13:44:38] ...data deleted.                                          base.py:235
           Scraping from https://estates4.warwickdc.gov.uk/cmis/Counc base.py:40
           illorsAtoZ/tabid/39/ScreenMode/Ward/Default.aspx                     
           HTTPSConnectionPool(host='estates4.warwickdc.gov.uk',  handlers.py:36
           port=443): Max retries exceeded with url: /cmis/Counci               
           llorsAtoZ/tabid/39/ScreenMode/Ward/Default.aspx                      
           (Caused by NewConnectionError('<urllib3.connection.HTT               
           PSConnection object at 0x7fd6efe8c100>: Failed to                    
           establish a new connection: [Errno -5] No address                    
           associated with hostname'))                                          
           Finished attempting to scrape: WAW                        base.py:313
</pre>
  

  


  <h2 id="2022-04-19-13-32">2022-04-19</h2>
  <div class="ds-card">
  <div class="ds-card-body">
    <dl class="ds-descriptions">
      <div>
        <dt>Duration</dt>
        <dd>2 seconds</dd>
      </div>
      <div>
        <dt>Start</dt>
        <dd>2022-04-19 13:32:22.817204</dd>
      </div>
      <div>
        <dt>End</dt>
        <dd>2022-04-19 13:32:25.127195</dd>
      </div>
      <div>
        <dt>Status code</dt>
        <dd>1</dd>
      </div>
      <div>
        <dt>Error</dt>
        <dd>Traceback (most recent call last):
  File "/opt/python/urllib3/connection.py", line 174, in _new_conn
    conn = connection.create_connection(
  File "/opt/python/urllib3/util/connection.py", line 72, in create_connection
    for res in socket.getaddrinfo(host, port, family, socket.SOCK_STREAM):
  File "/var/lang/lib/python3.8/socket.py", line 918, in getaddrinfo
    for res in _socket.getaddrinfo(host, port, family, type, proto, flags):
socket.gaierror: [Errno -5] No address associated with hostname

During handling of the above exception, another exception occurred:

Traceback (most recent call last):
  File "/opt/python/urllib3/connectionpool.py", line 703, in urlopen
    httplib_response = self._make_request(
  File "/opt/python/urllib3/connectionpool.py", line 386, in _make_request
    self._validate_conn(conn)
  File "/opt/python/urllib3/connectionpool.py", line 1040, in _validate_conn
    conn.connect()
  File "/opt/python/urllib3/connection.py", line 358, in connect
    conn = self._new_conn()
  File "/opt/python/urllib3/connection.py", line 186, in _new_conn
    raise NewConnectionError(
urllib3.exceptions.NewConnectionError: <urllib3.connection.HTTPSConnection object at 0x7f3238d6b220>: Failed to establish a new connection: [Errno -5] No address associated with hostname

During handling of the above exception, another exception occurred:

Traceback (most recent call last):
  File "/opt/python/requests/adapters.py", line 440, in send
    resp = conn.urlopen(
  File "/opt/python/urllib3/connectionpool.py", line 785, in urlopen
    retries = retries.increment(
  File "/opt/python/urllib3/util/retry.py", line 592, in increment
    raise MaxRetryError(_pool, url, error or ResponseError(cause))
urllib3.exceptions.MaxRetryError: HTTPSConnectionPool(host='estates4.warwickdc.gov.uk', port=443): Max retries exceeded with url: /cmis/CouncillorsAtoZ/tabid/39/ScreenMode/Ward/Default.aspx (Caused by NewConnectionError('<urllib3.connection.HTTPSConnection object at 0x7f3238d6b220>: Failed to establish a new connection: [Errno -5] No address associated with hostname'))

During handling of the above exception, another exception occurred:

Traceback (most recent call last):
  File "/var/task/lgsf/aws_lambda/handlers.py", line 32, in scraper_worker_handler
    scraper.run(run_log)
  File "/var/task/lgsf/councillors/scrapers.py", line 46, in run
    for councillor_html in self.get_councillors():
  File "/var/task/lgsf/councillors/scrapers.py", line 235, in get_councillors
    req = self.get(self.base_url)
  File "/var/task/lgsf/scrapers/base.py", line 46, in get
    response = requests.get(url, headers=headers, verify=verify)
  File "/opt/python/requests/api.py", line 75, in get
    return request('get', url, params=params, **kwargs)
  File "/opt/python/requests/api.py", line 61, in request
    return session.request(method=method, url=url, **kwargs)
  File "/opt/python/requests/sessions.py", line 529, in request
    resp = self.send(prep, **send_kwargs)
  File "/opt/python/requests/sessions.py", line 645, in send
    r = adapter.send(request, **kwargs)
  File "/opt/python/requests/adapters.py", line 519, in send
    raise ConnectionError(e, request=request)
requests.exceptions.ConnectionError: HTTPSConnectionPool(host='estates4.warwickdc.gov.uk', port=443): Max retries exceeded with url: /cmis/CouncillorsAtoZ/tabid/39/ScreenMode/Ward/Default.aspx (Caused by NewConnectionError('<urllib3.connection.HTTPSConnection object at 0x7f3238d6b220>: Failed to establish a new connection: [Errno -5] No address associated with hostname'))
</dd>
      </div>
    </dl>
  </div>
  </div>

  <h3>Run log</h3>
  <pre>[13:32:22] Fetching Scraper for: WAW                              handlers.py:23
           Begin attempting to scrape: WAW                        handlers.py:27
           Deleting existing data...                                 base.py:228
[13:32:23] Getting all files in WAW...                               base.py:180
           ...found 1 files in WAW                                   base.py:196
           Deleting batch no. 1 consisting of 1 files                base.py:205
[13:32:24] ...data deleted.                                          base.py:235
           Scraping from https://estates4.warwickdc.gov.uk/cmis/Counc base.py:40
           illorsAtoZ/tabid/39/ScreenMode/Ward/Default.aspx                     
           HTTPSConnectionPool(host='estates4.warwickdc.gov.uk',  handlers.py:36
           port=443): Max retries exceeded with url: /cmis/Counci               
           llorsAtoZ/tabid/39/ScreenMode/Ward/Default.aspx                      
           (Caused by NewConnectionError('<urllib3.connection.HTT               
           PSConnection object at 0x7f3238d6b220>: Failed to                    
           establish a new connection: [Errno -5] No address                    
           associated with hostname'))                                          
[13:32:25] Finished attempting to scrape: WAW                        base.py:313
</pre>
  

  


  <h2 id="2022-04-18-11-40">2022-04-18</h2>
  <div class="ds-card">
  <div class="ds-card-body">
    <dl class="ds-descriptions">
      <div>
        <dt>Duration</dt>
        <dd>2 seconds</dd>
      </div>
      <div>
        <dt>Start</dt>
        <dd>2022-04-18 11:40:20.968499</dd>
      </div>
      <div>
        <dt>End</dt>
        <dd>2022-04-18 11:40:23.274059</dd>
      </div>
      <div>
        <dt>Status code</dt>
        <dd>1</dd>
      </div>
      <div>
        <dt>Error</dt>
        <dd>Traceback (most recent call last):
  File "/opt/python/urllib3/connection.py", line 174, in _new_conn
    conn = connection.create_connection(
  File "/opt/python/urllib3/util/connection.py", line 72, in create_connection
    for res in socket.getaddrinfo(host, port, family, socket.SOCK_STREAM):
  File "/var/lang/lib/python3.8/socket.py", line 918, in getaddrinfo
    for res in _socket.getaddrinfo(host, port, family, type, proto, flags):
socket.gaierror: [Errno -5] No address associated with hostname

During handling of the above exception, another exception occurred:

Traceback (most recent call last):
  File "/opt/python/urllib3/connectionpool.py", line 703, in urlopen
    httplib_response = self._make_request(
  File "/opt/python/urllib3/connectionpool.py", line 386, in _make_request
    self._validate_conn(conn)
  File "/opt/python/urllib3/connectionpool.py", line 1040, in _validate_conn
    conn.connect()
  File "/opt/python/urllib3/connection.py", line 358, in connect
    conn = self._new_conn()
  File "/opt/python/urllib3/connection.py", line 186, in _new_conn
    raise NewConnectionError(
urllib3.exceptions.NewConnectionError: <urllib3.connection.HTTPSConnection object at 0x7f2527d66610>: Failed to establish a new connection: [Errno -5] No address associated with hostname

During handling of the above exception, another exception occurred:

Traceback (most recent call last):
  File "/opt/python/requests/adapters.py", line 440, in send
    resp = conn.urlopen(
  File "/opt/python/urllib3/connectionpool.py", line 785, in urlopen
    retries = retries.increment(
  File "/opt/python/urllib3/util/retry.py", line 592, in increment
    raise MaxRetryError(_pool, url, error or ResponseError(cause))
urllib3.exceptions.MaxRetryError: HTTPSConnectionPool(host='estates4.warwickdc.gov.uk', port=443): Max retries exceeded with url: /cmis/CouncillorsAtoZ/tabid/39/ScreenMode/Ward/Default.aspx (Caused by NewConnectionError('<urllib3.connection.HTTPSConnection object at 0x7f2527d66610>: Failed to establish a new connection: [Errno -5] No address associated with hostname'))

During handling of the above exception, another exception occurred:

Traceback (most recent call last):
  File "/var/task/lgsf/aws_lambda/handlers.py", line 32, in scraper_worker_handler
    scraper.run(run_log)
  File "/var/task/lgsf/councillors/scrapers.py", line 46, in run
    for councillor_html in self.get_councillors():
  File "/var/task/lgsf/councillors/scrapers.py", line 235, in get_councillors
    req = self.get(self.base_url)
  File "/var/task/lgsf/scrapers/base.py", line 46, in get
    response = requests.get(url, headers=headers, verify=verify)
  File "/opt/python/requests/api.py", line 75, in get
    return request('get', url, params=params, **kwargs)
  File "/opt/python/requests/api.py", line 61, in request
    return session.request(method=method, url=url, **kwargs)
  File "/opt/python/requests/sessions.py", line 529, in request
    resp = self.send(prep, **send_kwargs)
  File "/opt/python/requests/sessions.py", line 645, in send
    r = adapter.send(request, **kwargs)
  File "/opt/python/requests/adapters.py", line 519, in send
    raise ConnectionError(e, request=request)
requests.exceptions.ConnectionError: HTTPSConnectionPool(host='estates4.warwickdc.gov.uk', port=443): Max retries exceeded with url: /cmis/CouncillorsAtoZ/tabid/39/ScreenMode/Ward/Default.aspx (Caused by NewConnectionError('<urllib3.connection.HTTPSConnection object at 0x7f2527d66610>: Failed to establish a new connection: [Errno -5] No address associated with hostname'))
</dd>
      </div>
    </dl>
  </div>
  </div>

  <h3>Run log</h3>
  <pre>[11:40:20] Fetching Scraper for: WAW                              handlers.py:23
[11:40:21] Begin attempting to scrape: WAW                        handlers.py:27
           Deleting existing data...                                 base.py:228
           Getting all files in WAW...                               base.py:180
           ...found 1 files in WAW                                   base.py:196
           Deleting batch no. 1 consisting of 1 files                base.py:205
[11:40:22] ...data deleted.                                          base.py:235
           Scraping from https://estates4.warwickdc.gov.uk/cmis/Counc base.py:40
           illorsAtoZ/tabid/39/ScreenMode/Ward/Default.aspx                     
[11:40:23] HTTPSConnectionPool(host='estates4.warwickdc.gov.uk',  handlers.py:36
           port=443): Max retries exceeded with url: /cmis/Counci               
           llorsAtoZ/tabid/39/ScreenMode/Ward/Default.aspx                      
           (Caused by NewConnectionError('<urllib3.connection.HTT               
           PSConnection object at 0x7f2527d66610>: Failed to                    
           establish a new connection: [Errno -5] No address                    
           associated with hostname'))                                          
           Finished attempting to scrape: WAW                        base.py:313
</pre>
  

  


  <h2 id="2022-04-17-12-33">2022-04-17</h2>
  <div class="ds-card">
  <div class="ds-card-body">
    <dl class="ds-descriptions">
      <div>
        <dt>Duration</dt>
        <dd>2 seconds</dd>
      </div>
      <div>
        <dt>Start</dt>
        <dd>2022-04-17 12:33:37.311775</dd>
      </div>
      <div>
        <dt>End</dt>
        <dd>2022-04-17 12:33:39.580270</dd>
      </div>
      <div>
        <dt>Status code</dt>
        <dd>1</dd>
      </div>
      <div>
        <dt>Error</dt>
        <dd>Traceback (most recent call last):
  File "/opt/python/urllib3/connection.py", line 174, in _new_conn
    conn = connection.create_connection(
  File "/opt/python/urllib3/util/connection.py", line 72, in create_connection
    for res in socket.getaddrinfo(host, port, family, socket.SOCK_STREAM):
  File "/var/lang/lib/python3.8/socket.py", line 918, in getaddrinfo
    for res in _socket.getaddrinfo(host, port, family, type, proto, flags):
socket.gaierror: [Errno -5] No address associated with hostname

During handling of the above exception, another exception occurred:

Traceback (most recent call last):
  File "/opt/python/urllib3/connectionpool.py", line 703, in urlopen
    httplib_response = self._make_request(
  File "/opt/python/urllib3/connectionpool.py", line 386, in _make_request
    self._validate_conn(conn)
  File "/opt/python/urllib3/connectionpool.py", line 1040, in _validate_conn
    conn.connect()
  File "/opt/python/urllib3/connection.py", line 358, in connect
    conn = self._new_conn()
  File "/opt/python/urllib3/connection.py", line 186, in _new_conn
    raise NewConnectionError(
urllib3.exceptions.NewConnectionError: <urllib3.connection.HTTPSConnection object at 0x7fc48f4aa7c0>: Failed to establish a new connection: [Errno -5] No address associated with hostname

During handling of the above exception, another exception occurred:

Traceback (most recent call last):
  File "/opt/python/requests/adapters.py", line 440, in send
    resp = conn.urlopen(
  File "/opt/python/urllib3/connectionpool.py", line 785, in urlopen
    retries = retries.increment(
  File "/opt/python/urllib3/util/retry.py", line 592, in increment
    raise MaxRetryError(_pool, url, error or ResponseError(cause))
urllib3.exceptions.MaxRetryError: HTTPSConnectionPool(host='estates4.warwickdc.gov.uk', port=443): Max retries exceeded with url: /cmis/CouncillorsAtoZ/tabid/39/ScreenMode/Ward/Default.aspx (Caused by NewConnectionError('<urllib3.connection.HTTPSConnection object at 0x7fc48f4aa7c0>: Failed to establish a new connection: [Errno -5] No address associated with hostname'))

During handling of the above exception, another exception occurred:

Traceback (most recent call last):
  File "/var/task/lgsf/aws_lambda/handlers.py", line 32, in scraper_worker_handler
    scraper.run(run_log)
  File "/var/task/lgsf/councillors/scrapers.py", line 46, in run
    for councillor_html in self.get_councillors():
  File "/var/task/lgsf/councillors/scrapers.py", line 235, in get_councillors
    req = self.get(self.base_url)
  File "/var/task/lgsf/scrapers/base.py", line 46, in get
    response = requests.get(url, headers=headers, verify=verify)
  File "/opt/python/requests/api.py", line 75, in get
    return request('get', url, params=params, **kwargs)
  File "/opt/python/requests/api.py", line 61, in request
    return session.request(method=method, url=url, **kwargs)
  File "/opt/python/requests/sessions.py", line 529, in request
    resp = self.send(prep, **send_kwargs)
  File "/opt/python/requests/sessions.py", line 645, in send
    r = adapter.send(request, **kwargs)
  File "/opt/python/requests/adapters.py", line 519, in send
    raise ConnectionError(e, request=request)
requests.exceptions.ConnectionError: HTTPSConnectionPool(host='estates4.warwickdc.gov.uk', port=443): Max retries exceeded with url: /cmis/CouncillorsAtoZ/tabid/39/ScreenMode/Ward/Default.aspx (Caused by NewConnectionError('<urllib3.connection.HTTPSConnection object at 0x7fc48f4aa7c0>: Failed to establish a new connection: [Errno -5] No address associated with hostname'))
</dd>
      </div>
    </dl>
  </div>
  </div>

  <h3>Run log</h3>
  <pre>[12:33:37] Fetching Scraper for: WAW                              handlers.py:23
           Begin attempting to scrape: WAW                        handlers.py:27
           Deleting existing data...                                 base.py:228
[12:33:38] Getting all files in WAW...                               base.py:180
           ...found 1 files in WAW                                   base.py:196
           Deleting batch no. 1 consisting of 1 files                base.py:205
[12:33:39] ...data deleted.                                          base.py:235
           Scraping from https://estates4.warwickdc.gov.uk/cmis/Counc base.py:40
           illorsAtoZ/tabid/39/ScreenMode/Ward/Default.aspx                     
           HTTPSConnectionPool(host='estates4.warwickdc.gov.uk',  handlers.py:36
           port=443): Max retries exceeded with url: /cmis/Counci               
           llorsAtoZ/tabid/39/ScreenMode/Ward/Default.aspx                      
           (Caused by NewConnectionError('<urllib3.connection.HTT               
           PSConnection object at 0x7fc48f4aa7c0>: Failed to                    
           establish a new connection: [Errno -5] No address                    
           associated with hostname'))                                          
           Finished attempting to scrape: WAW                        base.py:313
</pre>
  


      </main>
      <footer class="ds-footer">...</footer>
    </div>
  </body>
