<!doctype html>
<html>
  <head>
    <title>LGSF Dashboard</title>
    <link rel="stylesheet"  href="/lgsf-dashboard/assets/css/styles.css">
    <link rel="shortcut icon" href="https://democracyclub.org.uk/static/images/logo_icon.png">
  </head>
  <body>
    <div class="ds-page">
      <a class="ds-skip-link" href="#main">skip to content</a>

      <header class="ds-header">
        <a class="ds-skip-link" href="#main">skip to content</a>
        <a class="ds-logo" href="/lgsf-dashboard/">
          <img src="https://DemocracyClub.github.io/design-system/images/logo_icon.svg" alt="" />
          <span>LGSF Logbooks</span>
        </a>

      </header>


      <main id="main" tabindex="-1" class="ds-stack">

        
<style>

    pre {
        height:400px;
        overflow-x: scroll;
        width:100%
    }
</style>




  


  <h2 id="2022-06-11-11-29">2022-06-11</h2>
  <div class="ds-card">
  <div class="ds-card-body">
    <dl class="ds-descriptions">
      <div>
        <dt>Duration</dt>
        <dd>2 seconds</dd>
      </div>
      <div>
        <dt>Start</dt>
        <dd>2022-06-11 11:29:40.670428</dd>
      </div>
      <div>
        <dt>End</dt>
        <dd>2022-06-11 11:29:43.042879</dd>
      </div>
      <div>
        <dt>Status code</dt>
        <dd>1</dd>
      </div>
      <div>
        <dt>Error</dt>
        <dd>Traceback (most recent call last):
  File "/opt/python/urllib3/connection.py", line 174, in _new_conn
    conn = connection.create_connection(
  File "/opt/python/urllib3/util/connection.py", line 72, in create_connection
    for res in socket.getaddrinfo(host, port, family, socket.SOCK_STREAM):
  File "/var/lang/lib/python3.8/socket.py", line 918, in getaddrinfo
    for res in _socket.getaddrinfo(host, port, family, type, proto, flags):
socket.gaierror: [Errno -5] No address associated with hostname

During handling of the above exception, another exception occurred:

Traceback (most recent call last):
  File "/opt/python/urllib3/connectionpool.py", line 703, in urlopen
    httplib_response = self._make_request(
  File "/opt/python/urllib3/connectionpool.py", line 386, in _make_request
    self._validate_conn(conn)
  File "/opt/python/urllib3/connectionpool.py", line 1040, in _validate_conn
    conn.connect()
  File "/opt/python/urllib3/connection.py", line 358, in connect
    conn = self._new_conn()
  File "/opt/python/urllib3/connection.py", line 186, in _new_conn
    raise NewConnectionError(
urllib3.exceptions.NewConnectionError: <urllib3.connection.HTTPSConnection object at 0x7face4cea2b0>: Failed to establish a new connection: [Errno -5] No address associated with hostname

During handling of the above exception, another exception occurred:

Traceback (most recent call last):
  File "/opt/python/requests/adapters.py", line 440, in send
    resp = conn.urlopen(
  File "/opt/python/urllib3/connectionpool.py", line 785, in urlopen
    retries = retries.increment(
  File "/opt/python/urllib3/util/retry.py", line 592, in increment
    raise MaxRetryError(_pool, url, error or ResponseError(cause))
urllib3.exceptions.MaxRetryError: HTTPSConnectionPool(host='estates4.warwickdc.gov.uk', port=443): Max retries exceeded with url: /cmis/CouncillorsAtoZ/tabid/39/ScreenMode/Ward/Default.aspx (Caused by NewConnectionError('<urllib3.connection.HTTPSConnection object at 0x7face4cea2b0>: Failed to establish a new connection: [Errno -5] No address associated with hostname'))

During handling of the above exception, another exception occurred:

Traceback (most recent call last):
  File "/var/task/lgsf/aws_lambda/handlers.py", line 32, in scraper_worker_handler
    scraper.run(run_log)
  File "/var/task/lgsf/councillors/scrapers.py", line 46, in run
    for councillor_html in self.get_councillors():
  File "/var/task/lgsf/councillors/scrapers.py", line 242, in get_councillors
    req = self.get(self.base_url, extra_headers=self.extra_headers)
  File "/var/task/lgsf/scrapers/base.py", line 48, in get
    response = self.requests_session.get(url, headers=headers, verify=verify)
  File "/opt/python/requests/sessions.py", line 542, in get
    return self.request('GET', url, **kwargs)
  File "/opt/python/requests/sessions.py", line 529, in request
    resp = self.send(prep, **send_kwargs)
  File "/opt/python/requests/sessions.py", line 645, in send
    r = adapter.send(request, **kwargs)
  File "/opt/python/requests/adapters.py", line 519, in send
    raise ConnectionError(e, request=request)
requests.exceptions.ConnectionError: HTTPSConnectionPool(host='estates4.warwickdc.gov.uk', port=443): Max retries exceeded with url: /cmis/CouncillorsAtoZ/tabid/39/ScreenMode/Ward/Default.aspx (Caused by NewConnectionError('<urllib3.connection.HTTPSConnection object at 0x7face4cea2b0>: Failed to establish a new connection: [Errno -5] No address associated with hostname'))
</dd>
      </div>
    </dl>
  </div>
  </div>

  <h3>Run log</h3>
  <pre>[11:29:40] Fetching Scraper for: WAW                              handlers.py:23
           Begin attempting to scrape: WAW                        handlers.py:27
           Deleting existing data...                                 base.py:230
[11:29:41] Getting all files in WAW...                               base.py:182
           ...found 1 files in WAW                                   base.py:198
           Deleting batch no. 1 consisting of 1 files                base.py:207
[11:29:42] ...data deleted.                                          base.py:237
           Scraping from https://estates4.warwickdc.gov.uk/cmis/Counc base.py:42
           illorsAtoZ/tabid/39/ScreenMode/Ward/Default.aspx                     
           HTTPSConnectionPool(host='estates4.warwickdc.gov.uk',  handlers.py:36
           port=443): Max retries exceeded with url: /cmis/Counci               
           llorsAtoZ/tabid/39/ScreenMode/Ward/Default.aspx                      
           (Caused by NewConnectionError('<urllib3.connection.HTT               
           PSConnection object at 0x7face4cea2b0>: Failed to                    
           establish a new connection: [Errno -5] No address                    
           associated with hostname'))                                          
[11:29:43] Finished attempting to scrape: WAW                        base.py:315
</pre>
  

  


  <h2 id="2022-06-10-12-25">2022-06-10</h2>
  <div class="ds-card">
  <div class="ds-card-body">
    <dl class="ds-descriptions">
      <div>
        <dt>Duration</dt>
        <dd>2 seconds</dd>
      </div>
      <div>
        <dt>Start</dt>
        <dd>2022-06-10 12:25:04.596257</dd>
      </div>
      <div>
        <dt>End</dt>
        <dd>2022-06-10 12:25:06.916054</dd>
      </div>
      <div>
        <dt>Status code</dt>
        <dd>1</dd>
      </div>
      <div>
        <dt>Error</dt>
        <dd>Traceback (most recent call last):
  File "/opt/python/urllib3/connection.py", line 174, in _new_conn
    conn = connection.create_connection(
  File "/opt/python/urllib3/util/connection.py", line 72, in create_connection
    for res in socket.getaddrinfo(host, port, family, socket.SOCK_STREAM):
  File "/var/lang/lib/python3.8/socket.py", line 918, in getaddrinfo
    for res in _socket.getaddrinfo(host, port, family, type, proto, flags):
socket.gaierror: [Errno -5] No address associated with hostname

During handling of the above exception, another exception occurred:

Traceback (most recent call last):
  File "/opt/python/urllib3/connectionpool.py", line 703, in urlopen
    httplib_response = self._make_request(
  File "/opt/python/urllib3/connectionpool.py", line 386, in _make_request
    self._validate_conn(conn)
  File "/opt/python/urllib3/connectionpool.py", line 1040, in _validate_conn
    conn.connect()
  File "/opt/python/urllib3/connection.py", line 358, in connect
    conn = self._new_conn()
  File "/opt/python/urllib3/connection.py", line 186, in _new_conn
    raise NewConnectionError(
urllib3.exceptions.NewConnectionError: <urllib3.connection.HTTPSConnection object at 0x7fc8a25779a0>: Failed to establish a new connection: [Errno -5] No address associated with hostname

During handling of the above exception, another exception occurred:

Traceback (most recent call last):
  File "/opt/python/requests/adapters.py", line 440, in send
    resp = conn.urlopen(
  File "/opt/python/urllib3/connectionpool.py", line 785, in urlopen
    retries = retries.increment(
  File "/opt/python/urllib3/util/retry.py", line 592, in increment
    raise MaxRetryError(_pool, url, error or ResponseError(cause))
urllib3.exceptions.MaxRetryError: HTTPSConnectionPool(host='estates4.warwickdc.gov.uk', port=443): Max retries exceeded with url: /cmis/CouncillorsAtoZ/tabid/39/ScreenMode/Ward/Default.aspx (Caused by NewConnectionError('<urllib3.connection.HTTPSConnection object at 0x7fc8a25779a0>: Failed to establish a new connection: [Errno -5] No address associated with hostname'))

During handling of the above exception, another exception occurred:

Traceback (most recent call last):
  File "/var/task/lgsf/aws_lambda/handlers.py", line 32, in scraper_worker_handler
    scraper.run(run_log)
  File "/var/task/lgsf/councillors/scrapers.py", line 46, in run
    for councillor_html in self.get_councillors():
  File "/var/task/lgsf/councillors/scrapers.py", line 242, in get_councillors
    req = self.get(self.base_url, extra_headers=self.extra_headers)
  File "/var/task/lgsf/scrapers/base.py", line 48, in get
    response = self.requests_session.get(url, headers=headers, verify=verify)
  File "/opt/python/requests/sessions.py", line 542, in get
    return self.request('GET', url, **kwargs)
  File "/opt/python/requests/sessions.py", line 529, in request
    resp = self.send(prep, **send_kwargs)
  File "/opt/python/requests/sessions.py", line 645, in send
    r = adapter.send(request, **kwargs)
  File "/opt/python/requests/adapters.py", line 519, in send
    raise ConnectionError(e, request=request)
requests.exceptions.ConnectionError: HTTPSConnectionPool(host='estates4.warwickdc.gov.uk', port=443): Max retries exceeded with url: /cmis/CouncillorsAtoZ/tabid/39/ScreenMode/Ward/Default.aspx (Caused by NewConnectionError('<urllib3.connection.HTTPSConnection object at 0x7fc8a25779a0>: Failed to establish a new connection: [Errno -5] No address associated with hostname'))
</dd>
      </div>
    </dl>
  </div>
  </div>

  <h3>Run log</h3>
  <pre>[12:25:04] Fetching Scraper for: WAW                              handlers.py:23
           Begin attempting to scrape: WAW                        handlers.py:27
           Deleting existing data...                                 base.py:230
[12:25:05] Getting all files in WAW...                               base.py:182
           ...found 1 files in WAW                                   base.py:198
           Deleting batch no. 1 consisting of 1 files                base.py:207
[12:25:06] ...data deleted.                                          base.py:237
           Scraping from https://estates4.warwickdc.gov.uk/cmis/Counc base.py:42
           illorsAtoZ/tabid/39/ScreenMode/Ward/Default.aspx                     
           HTTPSConnectionPool(host='estates4.warwickdc.gov.uk',  handlers.py:36
           port=443): Max retries exceeded with url: /cmis/Counci               
           llorsAtoZ/tabid/39/ScreenMode/Ward/Default.aspx                      
           (Caused by NewConnectionError('<urllib3.connection.HTT               
           PSConnection object at 0x7fc8a25779a0>: Failed to                    
           establish a new connection: [Errno -5] No address                    
           associated with hostname'))                                          
           Finished attempting to scrape: WAW                        base.py:315
</pre>
  

  


  <h2 id="2022-06-09-12-30">2022-06-09</h2>
  <div class="ds-card">
  <div class="ds-card-body">
    <dl class="ds-descriptions">
      <div>
        <dt>Duration</dt>
        <dd>2 seconds</dd>
      </div>
      <div>
        <dt>Start</dt>
        <dd>2022-06-09 12:30:53.352190</dd>
      </div>
      <div>
        <dt>End</dt>
        <dd>2022-06-09 12:30:55.748354</dd>
      </div>
      <div>
        <dt>Status code</dt>
        <dd>1</dd>
      </div>
      <div>
        <dt>Error</dt>
        <dd>Traceback (most recent call last):
  File "/opt/python/urllib3/connection.py", line 174, in _new_conn
    conn = connection.create_connection(
  File "/opt/python/urllib3/util/connection.py", line 72, in create_connection
    for res in socket.getaddrinfo(host, port, family, socket.SOCK_STREAM):
  File "/var/lang/lib/python3.8/socket.py", line 918, in getaddrinfo
    for res in _socket.getaddrinfo(host, port, family, type, proto, flags):
socket.gaierror: [Errno -5] No address associated with hostname

During handling of the above exception, another exception occurred:

Traceback (most recent call last):
  File "/opt/python/urllib3/connectionpool.py", line 703, in urlopen
    httplib_response = self._make_request(
  File "/opt/python/urllib3/connectionpool.py", line 386, in _make_request
    self._validate_conn(conn)
  File "/opt/python/urllib3/connectionpool.py", line 1040, in _validate_conn
    conn.connect()
  File "/opt/python/urllib3/connection.py", line 358, in connect
    conn = self._new_conn()
  File "/opt/python/urllib3/connection.py", line 186, in _new_conn
    raise NewConnectionError(
urllib3.exceptions.NewConnectionError: <urllib3.connection.HTTPSConnection object at 0x7fad49914370>: Failed to establish a new connection: [Errno -5] No address associated with hostname

During handling of the above exception, another exception occurred:

Traceback (most recent call last):
  File "/opt/python/requests/adapters.py", line 440, in send
    resp = conn.urlopen(
  File "/opt/python/urllib3/connectionpool.py", line 785, in urlopen
    retries = retries.increment(
  File "/opt/python/urllib3/util/retry.py", line 592, in increment
    raise MaxRetryError(_pool, url, error or ResponseError(cause))
urllib3.exceptions.MaxRetryError: HTTPSConnectionPool(host='estates4.warwickdc.gov.uk', port=443): Max retries exceeded with url: /cmis/CouncillorsAtoZ/tabid/39/ScreenMode/Ward/Default.aspx (Caused by NewConnectionError('<urllib3.connection.HTTPSConnection object at 0x7fad49914370>: Failed to establish a new connection: [Errno -5] No address associated with hostname'))

During handling of the above exception, another exception occurred:

Traceback (most recent call last):
  File "/var/task/lgsf/aws_lambda/handlers.py", line 32, in scraper_worker_handler
    scraper.run(run_log)
  File "/var/task/lgsf/councillors/scrapers.py", line 46, in run
    for councillor_html in self.get_councillors():
  File "/var/task/lgsf/councillors/scrapers.py", line 242, in get_councillors
    req = self.get(self.base_url, extra_headers=self.extra_headers)
  File "/var/task/lgsf/scrapers/base.py", line 48, in get
    response = self.requests_session.get(url, headers=headers, verify=verify)
  File "/opt/python/requests/sessions.py", line 542, in get
    return self.request('GET', url, **kwargs)
  File "/opt/python/requests/sessions.py", line 529, in request
    resp = self.send(prep, **send_kwargs)
  File "/opt/python/requests/sessions.py", line 645, in send
    r = adapter.send(request, **kwargs)
  File "/opt/python/requests/adapters.py", line 519, in send
    raise ConnectionError(e, request=request)
requests.exceptions.ConnectionError: HTTPSConnectionPool(host='estates4.warwickdc.gov.uk', port=443): Max retries exceeded with url: /cmis/CouncillorsAtoZ/tabid/39/ScreenMode/Ward/Default.aspx (Caused by NewConnectionError('<urllib3.connection.HTTPSConnection object at 0x7fad49914370>: Failed to establish a new connection: [Errno -5] No address associated with hostname'))
</dd>
      </div>
    </dl>
  </div>
  </div>

  <h3>Run log</h3>
  <pre>[12:30:53] Fetching Scraper for: WAW                              handlers.py:23
           Begin attempting to scrape: WAW                        handlers.py:27
           Deleting existing data...                                 base.py:230
[12:30:54] Getting all files in WAW...                               base.py:182
           ...found 1 files in WAW                                   base.py:198
           Deleting batch no. 1 consisting of 1 files                base.py:207
[12:30:55] ...data deleted.                                          base.py:237
           Scraping from https://estates4.warwickdc.gov.uk/cmis/Counc base.py:42
           illorsAtoZ/tabid/39/ScreenMode/Ward/Default.aspx                     
           HTTPSConnectionPool(host='estates4.warwickdc.gov.uk',  handlers.py:36
           port=443): Max retries exceeded with url: /cmis/Counci               
           llorsAtoZ/tabid/39/ScreenMode/Ward/Default.aspx                      
           (Caused by NewConnectionError('<urllib3.connection.HTT               
           PSConnection object at 0x7fad49914370>: Failed to                    
           establish a new connection: [Errno -5] No address                    
           associated with hostname'))                                          
           Finished attempting to scrape: WAW                        base.py:315
</pre>
  

  


  <h2 id="2022-06-08-14-29">2022-06-08</h2>
  <div class="ds-card">
  <div class="ds-card-body">
    <dl class="ds-descriptions">
      <div>
        <dt>Duration</dt>
        <dd>2 seconds</dd>
      </div>
      <div>
        <dt>Start</dt>
        <dd>2022-06-08 14:29:35.661024</dd>
      </div>
      <div>
        <dt>End</dt>
        <dd>2022-06-08 14:29:37.927049</dd>
      </div>
      <div>
        <dt>Status code</dt>
        <dd>1</dd>
      </div>
      <div>
        <dt>Error</dt>
        <dd>Traceback (most recent call last):
  File "/opt/python/urllib3/connection.py", line 174, in _new_conn
    conn = connection.create_connection(
  File "/opt/python/urllib3/util/connection.py", line 72, in create_connection
    for res in socket.getaddrinfo(host, port, family, socket.SOCK_STREAM):
  File "/var/lang/lib/python3.8/socket.py", line 918, in getaddrinfo
    for res in _socket.getaddrinfo(host, port, family, type, proto, flags):
socket.gaierror: [Errno -5] No address associated with hostname

During handling of the above exception, another exception occurred:

Traceback (most recent call last):
  File "/opt/python/urllib3/connectionpool.py", line 703, in urlopen
    httplib_response = self._make_request(
  File "/opt/python/urllib3/connectionpool.py", line 386, in _make_request
    self._validate_conn(conn)
  File "/opt/python/urllib3/connectionpool.py", line 1040, in _validate_conn
    conn.connect()
  File "/opt/python/urllib3/connection.py", line 358, in connect
    conn = self._new_conn()
  File "/opt/python/urllib3/connection.py", line 186, in _new_conn
    raise NewConnectionError(
urllib3.exceptions.NewConnectionError: <urllib3.connection.HTTPSConnection object at 0x7f0bc75880a0>: Failed to establish a new connection: [Errno -5] No address associated with hostname

During handling of the above exception, another exception occurred:

Traceback (most recent call last):
  File "/opt/python/requests/adapters.py", line 440, in send
    resp = conn.urlopen(
  File "/opt/python/urllib3/connectionpool.py", line 785, in urlopen
    retries = retries.increment(
  File "/opt/python/urllib3/util/retry.py", line 592, in increment
    raise MaxRetryError(_pool, url, error or ResponseError(cause))
urllib3.exceptions.MaxRetryError: HTTPSConnectionPool(host='estates4.warwickdc.gov.uk', port=443): Max retries exceeded with url: /cmis/CouncillorsAtoZ/tabid/39/ScreenMode/Ward/Default.aspx (Caused by NewConnectionError('<urllib3.connection.HTTPSConnection object at 0x7f0bc75880a0>: Failed to establish a new connection: [Errno -5] No address associated with hostname'))

During handling of the above exception, another exception occurred:

Traceback (most recent call last):
  File "/var/task/lgsf/aws_lambda/handlers.py", line 32, in scraper_worker_handler
    scraper.run(run_log)
  File "/var/task/lgsf/councillors/scrapers.py", line 46, in run
    for councillor_html in self.get_councillors():
  File "/var/task/lgsf/councillors/scrapers.py", line 242, in get_councillors
    req = self.get(self.base_url, extra_headers=self.extra_headers)
  File "/var/task/lgsf/scrapers/base.py", line 48, in get
    response = self.requests_session.get(url, headers=headers, verify=verify)
  File "/opt/python/requests/sessions.py", line 542, in get
    return self.request('GET', url, **kwargs)
  File "/opt/python/requests/sessions.py", line 529, in request
    resp = self.send(prep, **send_kwargs)
  File "/opt/python/requests/sessions.py", line 645, in send
    r = adapter.send(request, **kwargs)
  File "/opt/python/requests/adapters.py", line 519, in send
    raise ConnectionError(e, request=request)
requests.exceptions.ConnectionError: HTTPSConnectionPool(host='estates4.warwickdc.gov.uk', port=443): Max retries exceeded with url: /cmis/CouncillorsAtoZ/tabid/39/ScreenMode/Ward/Default.aspx (Caused by NewConnectionError('<urllib3.connection.HTTPSConnection object at 0x7f0bc75880a0>: Failed to establish a new connection: [Errno -5] No address associated with hostname'))
</dd>
      </div>
    </dl>
  </div>
  </div>

  <h3>Run log</h3>
  <pre>[14:29:35] Fetching Scraper for: WAW                              handlers.py:23
           Begin attempting to scrape: WAW                        handlers.py:27
           Deleting existing data...                                 base.py:230
[14:29:36] Getting all files in WAW...                               base.py:182
           ...found 1 files in WAW                                   base.py:198
           Deleting batch no. 1 consisting of 1 files                base.py:207
[14:29:37] ...data deleted.                                          base.py:237
           Scraping from https://estates4.warwickdc.gov.uk/cmis/Counc base.py:42
           illorsAtoZ/tabid/39/ScreenMode/Ward/Default.aspx                     
           HTTPSConnectionPool(host='estates4.warwickdc.gov.uk',  handlers.py:36
           port=443): Max retries exceeded with url: /cmis/Counci               
           llorsAtoZ/tabid/39/ScreenMode/Ward/Default.aspx                      
           (Caused by NewConnectionError('<urllib3.connection.HTT               
           PSConnection object at 0x7f0bc75880a0>: Failed to                    
           establish a new connection: [Errno -5] No address                    
           associated with hostname'))                                          
           Finished attempting to scrape: WAW                        base.py:315
</pre>
  

  


  <h2 id="2022-06-07-11-32">2022-06-07</h2>
  <div class="ds-card">
  <div class="ds-card-body">
    <dl class="ds-descriptions">
      <div>
        <dt>Duration</dt>
        <dd>2 seconds</dd>
      </div>
      <div>
        <dt>Start</dt>
        <dd>2022-06-07 11:32:44.976386</dd>
      </div>
      <div>
        <dt>End</dt>
        <dd>2022-06-07 11:32:47.272452</dd>
      </div>
      <div>
        <dt>Status code</dt>
        <dd>1</dd>
      </div>
      <div>
        <dt>Error</dt>
        <dd>Traceback (most recent call last):
  File "/opt/python/urllib3/connection.py", line 174, in _new_conn
    conn = connection.create_connection(
  File "/opt/python/urllib3/util/connection.py", line 72, in create_connection
    for res in socket.getaddrinfo(host, port, family, socket.SOCK_STREAM):
  File "/var/lang/lib/python3.8/socket.py", line 918, in getaddrinfo
    for res in _socket.getaddrinfo(host, port, family, type, proto, flags):
socket.gaierror: [Errno -5] No address associated with hostname

During handling of the above exception, another exception occurred:

Traceback (most recent call last):
  File "/opt/python/urllib3/connectionpool.py", line 703, in urlopen
    httplib_response = self._make_request(
  File "/opt/python/urllib3/connectionpool.py", line 386, in _make_request
    self._validate_conn(conn)
  File "/opt/python/urllib3/connectionpool.py", line 1040, in _validate_conn
    conn.connect()
  File "/opt/python/urllib3/connection.py", line 358, in connect
    conn = self._new_conn()
  File "/opt/python/urllib3/connection.py", line 186, in _new_conn
    raise NewConnectionError(
urllib3.exceptions.NewConnectionError: <urllib3.connection.HTTPSConnection object at 0x7f94c8d75490>: Failed to establish a new connection: [Errno -5] No address associated with hostname

During handling of the above exception, another exception occurred:

Traceback (most recent call last):
  File "/opt/python/requests/adapters.py", line 440, in send
    resp = conn.urlopen(
  File "/opt/python/urllib3/connectionpool.py", line 785, in urlopen
    retries = retries.increment(
  File "/opt/python/urllib3/util/retry.py", line 592, in increment
    raise MaxRetryError(_pool, url, error or ResponseError(cause))
urllib3.exceptions.MaxRetryError: HTTPSConnectionPool(host='estates4.warwickdc.gov.uk', port=443): Max retries exceeded with url: /cmis/CouncillorsAtoZ/tabid/39/ScreenMode/Ward/Default.aspx (Caused by NewConnectionError('<urllib3.connection.HTTPSConnection object at 0x7f94c8d75490>: Failed to establish a new connection: [Errno -5] No address associated with hostname'))

During handling of the above exception, another exception occurred:

Traceback (most recent call last):
  File "/var/task/lgsf/aws_lambda/handlers.py", line 32, in scraper_worker_handler
    scraper.run(run_log)
  File "/var/task/lgsf/councillors/scrapers.py", line 46, in run
    for councillor_html in self.get_councillors():
  File "/var/task/lgsf/councillors/scrapers.py", line 242, in get_councillors
    req = self.get(self.base_url, extra_headers=self.extra_headers)
  File "/var/task/lgsf/scrapers/base.py", line 48, in get
    response = self.requests_session.get(url, headers=headers, verify=verify)
  File "/opt/python/requests/sessions.py", line 542, in get
    return self.request('GET', url, **kwargs)
  File "/opt/python/requests/sessions.py", line 529, in request
    resp = self.send(prep, **send_kwargs)
  File "/opt/python/requests/sessions.py", line 645, in send
    r = adapter.send(request, **kwargs)
  File "/opt/python/requests/adapters.py", line 519, in send
    raise ConnectionError(e, request=request)
requests.exceptions.ConnectionError: HTTPSConnectionPool(host='estates4.warwickdc.gov.uk', port=443): Max retries exceeded with url: /cmis/CouncillorsAtoZ/tabid/39/ScreenMode/Ward/Default.aspx (Caused by NewConnectionError('<urllib3.connection.HTTPSConnection object at 0x7f94c8d75490>: Failed to establish a new connection: [Errno -5] No address associated with hostname'))
</dd>
      </div>
    </dl>
  </div>
  </div>

  <h3>Run log</h3>
  <pre>[11:32:44] Fetching Scraper for: WAW                              handlers.py:23
           Begin attempting to scrape: WAW                        handlers.py:27
[11:32:45] Deleting existing data...                                 base.py:230
           Getting all files in WAW...                               base.py:182
           ...found 1 files in WAW                                   base.py:198
           Deleting batch no. 1 consisting of 1 files                base.py:207
[11:32:46] ...data deleted.                                          base.py:237
           Scraping from https://estates4.warwickdc.gov.uk/cmis/Counc base.py:42
           illorsAtoZ/tabid/39/ScreenMode/Ward/Default.aspx                     
[11:32:47] HTTPSConnectionPool(host='estates4.warwickdc.gov.uk',  handlers.py:36
           port=443): Max retries exceeded with url: /cmis/Counci               
           llorsAtoZ/tabid/39/ScreenMode/Ward/Default.aspx                      
           (Caused by NewConnectionError('<urllib3.connection.HTT               
           PSConnection object at 0x7f94c8d75490>: Failed to                    
           establish a new connection: [Errno -5] No address                    
           associated with hostname'))                                          
           Finished attempting to scrape: WAW                        base.py:315
</pre>
  

  


  <h2 id="2022-06-06-13-58">2022-06-06</h2>
  <div class="ds-card">
  <div class="ds-card-body">
    <dl class="ds-descriptions">
      <div>
        <dt>Duration</dt>
        <dd>2 seconds</dd>
      </div>
      <div>
        <dt>Start</dt>
        <dd>2022-06-06 13:58:41.441967</dd>
      </div>
      <div>
        <dt>End</dt>
        <dd>2022-06-06 13:58:43.732331</dd>
      </div>
      <div>
        <dt>Status code</dt>
        <dd>1</dd>
      </div>
      <div>
        <dt>Error</dt>
        <dd>Traceback (most recent call last):
  File "/opt/python/urllib3/connection.py", line 174, in _new_conn
    conn = connection.create_connection(
  File "/opt/python/urllib3/util/connection.py", line 72, in create_connection
    for res in socket.getaddrinfo(host, port, family, socket.SOCK_STREAM):
  File "/var/lang/lib/python3.8/socket.py", line 918, in getaddrinfo
    for res in _socket.getaddrinfo(host, port, family, type, proto, flags):
socket.gaierror: [Errno -5] No address associated with hostname

During handling of the above exception, another exception occurred:

Traceback (most recent call last):
  File "/opt/python/urllib3/connectionpool.py", line 703, in urlopen
    httplib_response = self._make_request(
  File "/opt/python/urllib3/connectionpool.py", line 386, in _make_request
    self._validate_conn(conn)
  File "/opt/python/urllib3/connectionpool.py", line 1040, in _validate_conn
    conn.connect()
  File "/opt/python/urllib3/connection.py", line 358, in connect
    conn = self._new_conn()
  File "/opt/python/urllib3/connection.py", line 186, in _new_conn
    raise NewConnectionError(
urllib3.exceptions.NewConnectionError: <urllib3.connection.HTTPSConnection object at 0x7ff226ec6a00>: Failed to establish a new connection: [Errno -5] No address associated with hostname

During handling of the above exception, another exception occurred:

Traceback (most recent call last):
  File "/opt/python/requests/adapters.py", line 440, in send
    resp = conn.urlopen(
  File "/opt/python/urllib3/connectionpool.py", line 785, in urlopen
    retries = retries.increment(
  File "/opt/python/urllib3/util/retry.py", line 592, in increment
    raise MaxRetryError(_pool, url, error or ResponseError(cause))
urllib3.exceptions.MaxRetryError: HTTPSConnectionPool(host='estates4.warwickdc.gov.uk', port=443): Max retries exceeded with url: /cmis/CouncillorsAtoZ/tabid/39/ScreenMode/Ward/Default.aspx (Caused by NewConnectionError('<urllib3.connection.HTTPSConnection object at 0x7ff226ec6a00>: Failed to establish a new connection: [Errno -5] No address associated with hostname'))

During handling of the above exception, another exception occurred:

Traceback (most recent call last):
  File "/var/task/lgsf/aws_lambda/handlers.py", line 32, in scraper_worker_handler
    scraper.run(run_log)
  File "/var/task/lgsf/councillors/scrapers.py", line 46, in run
    for councillor_html in self.get_councillors():
  File "/var/task/lgsf/councillors/scrapers.py", line 242, in get_councillors
    req = self.get(self.base_url, extra_headers=self.extra_headers)
  File "/var/task/lgsf/scrapers/base.py", line 48, in get
    response = self.requests_session.get(url, headers=headers, verify=verify)
  File "/opt/python/requests/sessions.py", line 542, in get
    return self.request('GET', url, **kwargs)
  File "/opt/python/requests/sessions.py", line 529, in request
    resp = self.send(prep, **send_kwargs)
  File "/opt/python/requests/sessions.py", line 645, in send
    r = adapter.send(request, **kwargs)
  File "/opt/python/requests/adapters.py", line 519, in send
    raise ConnectionError(e, request=request)
requests.exceptions.ConnectionError: HTTPSConnectionPool(host='estates4.warwickdc.gov.uk', port=443): Max retries exceeded with url: /cmis/CouncillorsAtoZ/tabid/39/ScreenMode/Ward/Default.aspx (Caused by NewConnectionError('<urllib3.connection.HTTPSConnection object at 0x7ff226ec6a00>: Failed to establish a new connection: [Errno -5] No address associated with hostname'))
</dd>
      </div>
    </dl>
  </div>
  </div>

  <h3>Run log</h3>
  <pre>[13:58:41] Fetching Scraper for: WAW                              handlers.py:23
           Begin attempting to scrape: WAW                        handlers.py:27
           Deleting existing data...                                 base.py:230
[13:58:42] Getting all files in WAW...                               base.py:182
           ...found 1 files in WAW                                   base.py:198
           Deleting batch no. 1 consisting of 1 files                base.py:207
[13:58:43] ...data deleted.                                          base.py:237
           Scraping from https://estates4.warwickdc.gov.uk/cmis/Counc base.py:42
           illorsAtoZ/tabid/39/ScreenMode/Ward/Default.aspx                     
           HTTPSConnectionPool(host='estates4.warwickdc.gov.uk',  handlers.py:36
           port=443): Max retries exceeded with url: /cmis/Counci               
           llorsAtoZ/tabid/39/ScreenMode/Ward/Default.aspx                      
           (Caused by NewConnectionError('<urllib3.connection.HTT               
           PSConnection object at 0x7ff226ec6a00>: Failed to                    
           establish a new connection: [Errno -5] No address                    
           associated with hostname'))                                          
           Finished attempting to scrape: WAW                        base.py:315
</pre>
  

  


  <h2 id="2022-06-05-13-50">2022-06-05</h2>
  <div class="ds-card">
  <div class="ds-card-body">
    <dl class="ds-descriptions">
      <div>
        <dt>Duration</dt>
        <dd>2 seconds</dd>
      </div>
      <div>
        <dt>Start</dt>
        <dd>2022-06-05 13:50:29.497120</dd>
      </div>
      <div>
        <dt>End</dt>
        <dd>2022-06-05 13:50:31.725554</dd>
      </div>
      <div>
        <dt>Status code</dt>
        <dd>1</dd>
      </div>
      <div>
        <dt>Error</dt>
        <dd>Traceback (most recent call last):
  File "/opt/python/urllib3/connection.py", line 174, in _new_conn
    conn = connection.create_connection(
  File "/opt/python/urllib3/util/connection.py", line 72, in create_connection
    for res in socket.getaddrinfo(host, port, family, socket.SOCK_STREAM):
  File "/var/lang/lib/python3.8/socket.py", line 918, in getaddrinfo
    for res in _socket.getaddrinfo(host, port, family, type, proto, flags):
socket.gaierror: [Errno -5] No address associated with hostname

During handling of the above exception, another exception occurred:

Traceback (most recent call last):
  File "/opt/python/urllib3/connectionpool.py", line 703, in urlopen
    httplib_response = self._make_request(
  File "/opt/python/urllib3/connectionpool.py", line 386, in _make_request
    self._validate_conn(conn)
  File "/opt/python/urllib3/connectionpool.py", line 1040, in _validate_conn
    conn.connect()
  File "/opt/python/urllib3/connection.py", line 358, in connect
    conn = self._new_conn()
  File "/opt/python/urllib3/connection.py", line 186, in _new_conn
    raise NewConnectionError(
urllib3.exceptions.NewConnectionError: <urllib3.connection.HTTPSConnection object at 0x7fbbe73b9cd0>: Failed to establish a new connection: [Errno -5] No address associated with hostname

During handling of the above exception, another exception occurred:

Traceback (most recent call last):
  File "/opt/python/requests/adapters.py", line 440, in send
    resp = conn.urlopen(
  File "/opt/python/urllib3/connectionpool.py", line 785, in urlopen
    retries = retries.increment(
  File "/opt/python/urllib3/util/retry.py", line 592, in increment
    raise MaxRetryError(_pool, url, error or ResponseError(cause))
urllib3.exceptions.MaxRetryError: HTTPSConnectionPool(host='estates4.warwickdc.gov.uk', port=443): Max retries exceeded with url: /cmis/CouncillorsAtoZ/tabid/39/ScreenMode/Ward/Default.aspx (Caused by NewConnectionError('<urllib3.connection.HTTPSConnection object at 0x7fbbe73b9cd0>: Failed to establish a new connection: [Errno -5] No address associated with hostname'))

During handling of the above exception, another exception occurred:

Traceback (most recent call last):
  File "/var/task/lgsf/aws_lambda/handlers.py", line 32, in scraper_worker_handler
    scraper.run(run_log)
  File "/var/task/lgsf/councillors/scrapers.py", line 46, in run
    for councillor_html in self.get_councillors():
  File "/var/task/lgsf/councillors/scrapers.py", line 242, in get_councillors
    req = self.get(self.base_url, extra_headers=self.extra_headers)
  File "/var/task/lgsf/scrapers/base.py", line 48, in get
    response = self.requests_session.get(url, headers=headers, verify=verify)
  File "/opt/python/requests/sessions.py", line 542, in get
    return self.request('GET', url, **kwargs)
  File "/opt/python/requests/sessions.py", line 529, in request
    resp = self.send(prep, **send_kwargs)
  File "/opt/python/requests/sessions.py", line 645, in send
    r = adapter.send(request, **kwargs)
  File "/opt/python/requests/adapters.py", line 519, in send
    raise ConnectionError(e, request=request)
requests.exceptions.ConnectionError: HTTPSConnectionPool(host='estates4.warwickdc.gov.uk', port=443): Max retries exceeded with url: /cmis/CouncillorsAtoZ/tabid/39/ScreenMode/Ward/Default.aspx (Caused by NewConnectionError('<urllib3.connection.HTTPSConnection object at 0x7fbbe73b9cd0>: Failed to establish a new connection: [Errno -5] No address associated with hostname'))
</dd>
      </div>
    </dl>
  </div>
  </div>

  <h3>Run log</h3>
  <pre>[13:50:29] Fetching Scraper for: WAW                              handlers.py:23
           Begin attempting to scrape: WAW                        handlers.py:27
           Deleting existing data...                                 base.py:230
[13:50:30] Getting all files in WAW...                               base.py:182
           ...found 1 files in WAW                                   base.py:198
           Deleting batch no. 1 consisting of 1 files                base.py:207
[13:50:31] ...data deleted.                                          base.py:237
           Scraping from https://estates4.warwickdc.gov.uk/cmis/Counc base.py:42
           illorsAtoZ/tabid/39/ScreenMode/Ward/Default.aspx                     
           HTTPSConnectionPool(host='estates4.warwickdc.gov.uk',  handlers.py:36
           port=443): Max retries exceeded with url: /cmis/Counci               
           llorsAtoZ/tabid/39/ScreenMode/Ward/Default.aspx                      
           (Caused by NewConnectionError('<urllib3.connection.HTT               
           PSConnection object at 0x7fbbe73b9cd0>: Failed to                    
           establish a new connection: [Errno -5] No address                    
           associated with hostname'))                                          
           Finished attempting to scrape: WAW                        base.py:315
</pre>
  

  


  <h2 id="2022-06-04-13-44">2022-06-04</h2>
  <div class="ds-card">
  <div class="ds-card-body">
    <dl class="ds-descriptions">
      <div>
        <dt>Duration</dt>
        <dd>2 seconds</dd>
      </div>
      <div>
        <dt>Start</dt>
        <dd>2022-06-04 13:44:08.917246</dd>
      </div>
      <div>
        <dt>End</dt>
        <dd>2022-06-04 13:44:10.994213</dd>
      </div>
      <div>
        <dt>Status code</dt>
        <dd>1</dd>
      </div>
      <div>
        <dt>Error</dt>
        <dd>Traceback (most recent call last):
  File "/opt/python/urllib3/connection.py", line 174, in _new_conn
    conn = connection.create_connection(
  File "/opt/python/urllib3/util/connection.py", line 72, in create_connection
    for res in socket.getaddrinfo(host, port, family, socket.SOCK_STREAM):
  File "/var/lang/lib/python3.8/socket.py", line 918, in getaddrinfo
    for res in _socket.getaddrinfo(host, port, family, type, proto, flags):
socket.gaierror: [Errno -5] No address associated with hostname

During handling of the above exception, another exception occurred:

Traceback (most recent call last):
  File "/opt/python/urllib3/connectionpool.py", line 703, in urlopen
    httplib_response = self._make_request(
  File "/opt/python/urllib3/connectionpool.py", line 386, in _make_request
    self._validate_conn(conn)
  File "/opt/python/urllib3/connectionpool.py", line 1040, in _validate_conn
    conn.connect()
  File "/opt/python/urllib3/connection.py", line 358, in connect
    conn = self._new_conn()
  File "/opt/python/urllib3/connection.py", line 186, in _new_conn
    raise NewConnectionError(
urllib3.exceptions.NewConnectionError: <urllib3.connection.HTTPSConnection object at 0x7f4b442dd0a0>: Failed to establish a new connection: [Errno -5] No address associated with hostname

During handling of the above exception, another exception occurred:

Traceback (most recent call last):
  File "/opt/python/requests/adapters.py", line 440, in send
    resp = conn.urlopen(
  File "/opt/python/urllib3/connectionpool.py", line 785, in urlopen
    retries = retries.increment(
  File "/opt/python/urllib3/util/retry.py", line 592, in increment
    raise MaxRetryError(_pool, url, error or ResponseError(cause))
urllib3.exceptions.MaxRetryError: HTTPSConnectionPool(host='estates4.warwickdc.gov.uk', port=443): Max retries exceeded with url: /cmis/CouncillorsAtoZ/tabid/39/ScreenMode/Ward/Default.aspx (Caused by NewConnectionError('<urllib3.connection.HTTPSConnection object at 0x7f4b442dd0a0>: Failed to establish a new connection: [Errno -5] No address associated with hostname'))

During handling of the above exception, another exception occurred:

Traceback (most recent call last):
  File "/var/task/lgsf/aws_lambda/handlers.py", line 32, in scraper_worker_handler
    scraper.run(run_log)
  File "/var/task/lgsf/councillors/scrapers.py", line 46, in run
    for councillor_html in self.get_councillors():
  File "/var/task/lgsf/councillors/scrapers.py", line 242, in get_councillors
    req = self.get(self.base_url, extra_headers=self.extra_headers)
  File "/var/task/lgsf/scrapers/base.py", line 48, in get
    response = self.requests_session.get(url, headers=headers, verify=verify)
  File "/opt/python/requests/sessions.py", line 542, in get
    return self.request('GET', url, **kwargs)
  File "/opt/python/requests/sessions.py", line 529, in request
    resp = self.send(prep, **send_kwargs)
  File "/opt/python/requests/sessions.py", line 645, in send
    r = adapter.send(request, **kwargs)
  File "/opt/python/requests/adapters.py", line 519, in send
    raise ConnectionError(e, request=request)
requests.exceptions.ConnectionError: HTTPSConnectionPool(host='estates4.warwickdc.gov.uk', port=443): Max retries exceeded with url: /cmis/CouncillorsAtoZ/tabid/39/ScreenMode/Ward/Default.aspx (Caused by NewConnectionError('<urllib3.connection.HTTPSConnection object at 0x7f4b442dd0a0>: Failed to establish a new connection: [Errno -5] No address associated with hostname'))
</dd>
      </div>
    </dl>
  </div>
  </div>

  <h3>Run log</h3>
  <pre>[13:44:08] Fetching Scraper for: WAW                              handlers.py:23
           Begin attempting to scrape: WAW                        handlers.py:27
[13:44:09] Deleting existing data...                                 base.py:230
           Getting all files in WAW...                               base.py:182
           ...found 1 files in WAW                                   base.py:198
           Deleting batch no. 1 consisting of 1 files                base.py:207
[13:44:10] ...data deleted.                                          base.py:237
           Scraping from https://estates4.warwickdc.gov.uk/cmis/Counc base.py:42
           illorsAtoZ/tabid/39/ScreenMode/Ward/Default.aspx                     
           HTTPSConnectionPool(host='estates4.warwickdc.gov.uk',  handlers.py:36
           port=443): Max retries exceeded with url: /cmis/Counci               
           llorsAtoZ/tabid/39/ScreenMode/Ward/Default.aspx                      
           (Caused by NewConnectionError('<urllib3.connection.HTT               
           PSConnection object at 0x7f4b442dd0a0>: Failed to                    
           establish a new connection: [Errno -5] No address                    
           associated with hostname'))                                          
           Finished attempting to scrape: WAW                        base.py:315
</pre>
  

  


  <h2 id="2022-06-03-11-43">2022-06-03</h2>
  <div class="ds-card">
  <div class="ds-card-body">
    <dl class="ds-descriptions">
      <div>
        <dt>Duration</dt>
        <dd>2 seconds</dd>
      </div>
      <div>
        <dt>Start</dt>
        <dd>2022-06-03 11:43:52.469679</dd>
      </div>
      <div>
        <dt>End</dt>
        <dd>2022-06-03 11:43:54.717714</dd>
      </div>
      <div>
        <dt>Status code</dt>
        <dd>1</dd>
      </div>
      <div>
        <dt>Error</dt>
        <dd>Traceback (most recent call last):
  File "/opt/python/urllib3/connection.py", line 174, in _new_conn
    conn = connection.create_connection(
  File "/opt/python/urllib3/util/connection.py", line 72, in create_connection
    for res in socket.getaddrinfo(host, port, family, socket.SOCK_STREAM):
  File "/var/lang/lib/python3.8/socket.py", line 918, in getaddrinfo
    for res in _socket.getaddrinfo(host, port, family, type, proto, flags):
socket.gaierror: [Errno -5] No address associated with hostname

During handling of the above exception, another exception occurred:

Traceback (most recent call last):
  File "/opt/python/urllib3/connectionpool.py", line 703, in urlopen
    httplib_response = self._make_request(
  File "/opt/python/urllib3/connectionpool.py", line 386, in _make_request
    self._validate_conn(conn)
  File "/opt/python/urllib3/connectionpool.py", line 1040, in _validate_conn
    conn.connect()
  File "/opt/python/urllib3/connection.py", line 358, in connect
    conn = self._new_conn()
  File "/opt/python/urllib3/connection.py", line 186, in _new_conn
    raise NewConnectionError(
urllib3.exceptions.NewConnectionError: <urllib3.connection.HTTPSConnection object at 0x7f6cb662d4c0>: Failed to establish a new connection: [Errno -5] No address associated with hostname

During handling of the above exception, another exception occurred:

Traceback (most recent call last):
  File "/opt/python/requests/adapters.py", line 440, in send
    resp = conn.urlopen(
  File "/opt/python/urllib3/connectionpool.py", line 785, in urlopen
    retries = retries.increment(
  File "/opt/python/urllib3/util/retry.py", line 592, in increment
    raise MaxRetryError(_pool, url, error or ResponseError(cause))
urllib3.exceptions.MaxRetryError: HTTPSConnectionPool(host='estates4.warwickdc.gov.uk', port=443): Max retries exceeded with url: /cmis/CouncillorsAtoZ/tabid/39/ScreenMode/Ward/Default.aspx (Caused by NewConnectionError('<urllib3.connection.HTTPSConnection object at 0x7f6cb662d4c0>: Failed to establish a new connection: [Errno -5] No address associated with hostname'))

During handling of the above exception, another exception occurred:

Traceback (most recent call last):
  File "/var/task/lgsf/aws_lambda/handlers.py", line 32, in scraper_worker_handler
    scraper.run(run_log)
  File "/var/task/lgsf/councillors/scrapers.py", line 46, in run
    for councillor_html in self.get_councillors():
  File "/var/task/lgsf/councillors/scrapers.py", line 242, in get_councillors
    req = self.get(self.base_url, extra_headers=self.extra_headers)
  File "/var/task/lgsf/scrapers/base.py", line 48, in get
    response = self.requests_session.get(url, headers=headers, verify=verify)
  File "/opt/python/requests/sessions.py", line 542, in get
    return self.request('GET', url, **kwargs)
  File "/opt/python/requests/sessions.py", line 529, in request
    resp = self.send(prep, **send_kwargs)
  File "/opt/python/requests/sessions.py", line 645, in send
    r = adapter.send(request, **kwargs)
  File "/opt/python/requests/adapters.py", line 519, in send
    raise ConnectionError(e, request=request)
requests.exceptions.ConnectionError: HTTPSConnectionPool(host='estates4.warwickdc.gov.uk', port=443): Max retries exceeded with url: /cmis/CouncillorsAtoZ/tabid/39/ScreenMode/Ward/Default.aspx (Caused by NewConnectionError('<urllib3.connection.HTTPSConnection object at 0x7f6cb662d4c0>: Failed to establish a new connection: [Errno -5] No address associated with hostname'))
</dd>
      </div>
    </dl>
  </div>
  </div>

  <h3>Run log</h3>
  <pre>[11:43:52] Fetching Scraper for: WAW                              handlers.py:23
           Begin attempting to scrape: WAW                        handlers.py:27
           Deleting existing data...                                 base.py:230
[11:43:53] Getting all files in WAW...                               base.py:182
           ...found 1 files in WAW                                   base.py:198
           Deleting batch no. 1 consisting of 1 files                base.py:207
[11:43:54] ...data deleted.                                          base.py:237
           Scraping from https://estates4.warwickdc.gov.uk/cmis/Counc base.py:42
           illorsAtoZ/tabid/39/ScreenMode/Ward/Default.aspx                     
           HTTPSConnectionPool(host='estates4.warwickdc.gov.uk',  handlers.py:36
           port=443): Max retries exceeded with url: /cmis/Counci               
           llorsAtoZ/tabid/39/ScreenMode/Ward/Default.aspx                      
           (Caused by NewConnectionError('<urllib3.connection.HTT               
           PSConnection object at 0x7f6cb662d4c0>: Failed to                    
           establish a new connection: [Errno -5] No address                    
           associated with hostname'))                                          
           Finished attempting to scrape: WAW                        base.py:315
</pre>
  

  


  <h2 id="2022-06-02-13-00">2022-06-02</h2>
  <div class="ds-card">
  <div class="ds-card-body">
    <dl class="ds-descriptions">
      <div>
        <dt>Duration</dt>
        <dd>2 seconds</dd>
      </div>
      <div>
        <dt>Start</dt>
        <dd>2022-06-02 13:00:50.587078</dd>
      </div>
      <div>
        <dt>End</dt>
        <dd>2022-06-02 13:00:52.800512</dd>
      </div>
      <div>
        <dt>Status code</dt>
        <dd>1</dd>
      </div>
      <div>
        <dt>Error</dt>
        <dd>Traceback (most recent call last):
  File "/opt/python/urllib3/connection.py", line 174, in _new_conn
    conn = connection.create_connection(
  File "/opt/python/urllib3/util/connection.py", line 72, in create_connection
    for res in socket.getaddrinfo(host, port, family, socket.SOCK_STREAM):
  File "/var/lang/lib/python3.8/socket.py", line 918, in getaddrinfo
    for res in _socket.getaddrinfo(host, port, family, type, proto, flags):
socket.gaierror: [Errno -5] No address associated with hostname

During handling of the above exception, another exception occurred:

Traceback (most recent call last):
  File "/opt/python/urllib3/connectionpool.py", line 703, in urlopen
    httplib_response = self._make_request(
  File "/opt/python/urllib3/connectionpool.py", line 386, in _make_request
    self._validate_conn(conn)
  File "/opt/python/urllib3/connectionpool.py", line 1040, in _validate_conn
    conn.connect()
  File "/opt/python/urllib3/connection.py", line 358, in connect
    conn = self._new_conn()
  File "/opt/python/urllib3/connection.py", line 186, in _new_conn
    raise NewConnectionError(
urllib3.exceptions.NewConnectionError: <urllib3.connection.HTTPSConnection object at 0x7fc34b09ce50>: Failed to establish a new connection: [Errno -5] No address associated with hostname

During handling of the above exception, another exception occurred:

Traceback (most recent call last):
  File "/opt/python/requests/adapters.py", line 440, in send
    resp = conn.urlopen(
  File "/opt/python/urllib3/connectionpool.py", line 785, in urlopen
    retries = retries.increment(
  File "/opt/python/urllib3/util/retry.py", line 592, in increment
    raise MaxRetryError(_pool, url, error or ResponseError(cause))
urllib3.exceptions.MaxRetryError: HTTPSConnectionPool(host='estates4.warwickdc.gov.uk', port=443): Max retries exceeded with url: /cmis/CouncillorsAtoZ/tabid/39/ScreenMode/Ward/Default.aspx (Caused by NewConnectionError('<urllib3.connection.HTTPSConnection object at 0x7fc34b09ce50>: Failed to establish a new connection: [Errno -5] No address associated with hostname'))

During handling of the above exception, another exception occurred:

Traceback (most recent call last):
  File "/var/task/lgsf/aws_lambda/handlers.py", line 32, in scraper_worker_handler
    scraper.run(run_log)
  File "/var/task/lgsf/councillors/scrapers.py", line 46, in run
    for councillor_html in self.get_councillors():
  File "/var/task/lgsf/councillors/scrapers.py", line 242, in get_councillors
    req = self.get(self.base_url, extra_headers=self.extra_headers)
  File "/var/task/lgsf/scrapers/base.py", line 48, in get
    response = self.requests_session.get(url, headers=headers, verify=verify)
  File "/opt/python/requests/sessions.py", line 542, in get
    return self.request('GET', url, **kwargs)
  File "/opt/python/requests/sessions.py", line 529, in request
    resp = self.send(prep, **send_kwargs)
  File "/opt/python/requests/sessions.py", line 645, in send
    r = adapter.send(request, **kwargs)
  File "/opt/python/requests/adapters.py", line 519, in send
    raise ConnectionError(e, request=request)
requests.exceptions.ConnectionError: HTTPSConnectionPool(host='estates4.warwickdc.gov.uk', port=443): Max retries exceeded with url: /cmis/CouncillorsAtoZ/tabid/39/ScreenMode/Ward/Default.aspx (Caused by NewConnectionError('<urllib3.connection.HTTPSConnection object at 0x7fc34b09ce50>: Failed to establish a new connection: [Errno -5] No address associated with hostname'))
</dd>
      </div>
    </dl>
  </div>
  </div>

  <h3>Run log</h3>
  <pre>[13:00:50] Fetching Scraper for: WAW                              handlers.py:23
           Begin attempting to scrape: WAW                        handlers.py:27
           Deleting existing data...                                 base.py:230
[13:00:51] Getting all files in WAW...                               base.py:182
           ...found 1 files in WAW                                   base.py:198
           Deleting batch no. 1 consisting of 1 files                base.py:207
[13:00:52] ...data deleted.                                          base.py:237
           Scraping from https://estates4.warwickdc.gov.uk/cmis/Counc base.py:42
           illorsAtoZ/tabid/39/ScreenMode/Ward/Default.aspx                     
           HTTPSConnectionPool(host='estates4.warwickdc.gov.uk',  handlers.py:36
           port=443): Max retries exceeded with url: /cmis/Counci               
           llorsAtoZ/tabid/39/ScreenMode/Ward/Default.aspx                      
           (Caused by NewConnectionError('<urllib3.connection.HTT               
           PSConnection object at 0x7fc34b09ce50>: Failed to                    
           establish a new connection: [Errno -5] No address                    
           associated with hostname'))                                          
           Finished attempting to scrape: WAW                        base.py:315
</pre>
  

  


  <h2 id="2022-06-01-14-02">2022-06-01</h2>
  <div class="ds-card">
  <div class="ds-card-body">
    <dl class="ds-descriptions">
      <div>
        <dt>Duration</dt>
        <dd>2 seconds</dd>
      </div>
      <div>
        <dt>Start</dt>
        <dd>2022-06-01 14:02:48.140134</dd>
      </div>
      <div>
        <dt>End</dt>
        <dd>2022-06-01 14:02:50.506834</dd>
      </div>
      <div>
        <dt>Status code</dt>
        <dd>1</dd>
      </div>
      <div>
        <dt>Error</dt>
        <dd>Traceback (most recent call last):
  File "/opt/python/urllib3/connection.py", line 174, in _new_conn
    conn = connection.create_connection(
  File "/opt/python/urllib3/util/connection.py", line 72, in create_connection
    for res in socket.getaddrinfo(host, port, family, socket.SOCK_STREAM):
  File "/var/lang/lib/python3.8/socket.py", line 918, in getaddrinfo
    for res in _socket.getaddrinfo(host, port, family, type, proto, flags):
socket.gaierror: [Errno -5] No address associated with hostname

During handling of the above exception, another exception occurred:

Traceback (most recent call last):
  File "/opt/python/urllib3/connectionpool.py", line 703, in urlopen
    httplib_response = self._make_request(
  File "/opt/python/urllib3/connectionpool.py", line 386, in _make_request
    self._validate_conn(conn)
  File "/opt/python/urllib3/connectionpool.py", line 1040, in _validate_conn
    conn.connect()
  File "/opt/python/urllib3/connection.py", line 358, in connect
    conn = self._new_conn()
  File "/opt/python/urllib3/connection.py", line 186, in _new_conn
    raise NewConnectionError(
urllib3.exceptions.NewConnectionError: <urllib3.connection.HTTPSConnection object at 0x7f3644e689a0>: Failed to establish a new connection: [Errno -5] No address associated with hostname

During handling of the above exception, another exception occurred:

Traceback (most recent call last):
  File "/opt/python/requests/adapters.py", line 440, in send
    resp = conn.urlopen(
  File "/opt/python/urllib3/connectionpool.py", line 785, in urlopen
    retries = retries.increment(
  File "/opt/python/urllib3/util/retry.py", line 592, in increment
    raise MaxRetryError(_pool, url, error or ResponseError(cause))
urllib3.exceptions.MaxRetryError: HTTPSConnectionPool(host='estates4.warwickdc.gov.uk', port=443): Max retries exceeded with url: /cmis/CouncillorsAtoZ/tabid/39/ScreenMode/Ward/Default.aspx (Caused by NewConnectionError('<urllib3.connection.HTTPSConnection object at 0x7f3644e689a0>: Failed to establish a new connection: [Errno -5] No address associated with hostname'))

During handling of the above exception, another exception occurred:

Traceback (most recent call last):
  File "/var/task/lgsf/aws_lambda/handlers.py", line 32, in scraper_worker_handler
    scraper.run(run_log)
  File "/var/task/lgsf/councillors/scrapers.py", line 46, in run
    for councillor_html in self.get_councillors():
  File "/var/task/lgsf/councillors/scrapers.py", line 242, in get_councillors
    req = self.get(self.base_url, extra_headers=self.extra_headers)
  File "/var/task/lgsf/scrapers/base.py", line 48, in get
    response = self.requests_session.get(url, headers=headers, verify=verify)
  File "/opt/python/requests/sessions.py", line 542, in get
    return self.request('GET', url, **kwargs)
  File "/opt/python/requests/sessions.py", line 529, in request
    resp = self.send(prep, **send_kwargs)
  File "/opt/python/requests/sessions.py", line 645, in send
    r = adapter.send(request, **kwargs)
  File "/opt/python/requests/adapters.py", line 519, in send
    raise ConnectionError(e, request=request)
requests.exceptions.ConnectionError: HTTPSConnectionPool(host='estates4.warwickdc.gov.uk', port=443): Max retries exceeded with url: /cmis/CouncillorsAtoZ/tabid/39/ScreenMode/Ward/Default.aspx (Caused by NewConnectionError('<urllib3.connection.HTTPSConnection object at 0x7f3644e689a0>: Failed to establish a new connection: [Errno -5] No address associated with hostname'))
</dd>
      </div>
    </dl>
  </div>
  </div>

  <h3>Run log</h3>
  <pre>[14:02:48] Fetching Scraper for: WAW                              handlers.py:23
           Begin attempting to scrape: WAW                        handlers.py:27
           Deleting existing data...                                 base.py:230
           Getting all files in WAW...                               base.py:182
[14:02:49] ...found 1 files in WAW                                   base.py:198
           Deleting batch no. 1 consisting of 1 files                base.py:207
[14:02:50] ...data deleted.                                          base.py:237
           Scraping from https://estates4.warwickdc.gov.uk/cmis/Counc base.py:42
           illorsAtoZ/tabid/39/ScreenMode/Ward/Default.aspx                     
           HTTPSConnectionPool(host='estates4.warwickdc.gov.uk',  handlers.py:36
           port=443): Max retries exceeded with url: /cmis/Counci               
           llorsAtoZ/tabid/39/ScreenMode/Ward/Default.aspx                      
           (Caused by NewConnectionError('<urllib3.connection.HTT               
           PSConnection object at 0x7f3644e689a0>: Failed to                    
           establish a new connection: [Errno -5] No address                    
           associated with hostname'))                                          
           Finished attempting to scrape: WAW                        base.py:315
</pre>
  

  


  <h2 id="2022-05-31-12-02">2022-05-31</h2>
  <div class="ds-card">
  <div class="ds-card-body">
    <dl class="ds-descriptions">
      <div>
        <dt>Duration</dt>
        <dd>2 seconds</dd>
      </div>
      <div>
        <dt>Start</dt>
        <dd>2022-05-31 12:02:41.814385</dd>
      </div>
      <div>
        <dt>End</dt>
        <dd>2022-05-31 12:02:44.045506</dd>
      </div>
      <div>
        <dt>Status code</dt>
        <dd>1</dd>
      </div>
      <div>
        <dt>Error</dt>
        <dd>Traceback (most recent call last):
  File "/opt/python/urllib3/connection.py", line 174, in _new_conn
    conn = connection.create_connection(
  File "/opt/python/urllib3/util/connection.py", line 72, in create_connection
    for res in socket.getaddrinfo(host, port, family, socket.SOCK_STREAM):
  File "/var/lang/lib/python3.8/socket.py", line 918, in getaddrinfo
    for res in _socket.getaddrinfo(host, port, family, type, proto, flags):
socket.gaierror: [Errno -5] No address associated with hostname

During handling of the above exception, another exception occurred:

Traceback (most recent call last):
  File "/opt/python/urllib3/connectionpool.py", line 703, in urlopen
    httplib_response = self._make_request(
  File "/opt/python/urllib3/connectionpool.py", line 386, in _make_request
    self._validate_conn(conn)
  File "/opt/python/urllib3/connectionpool.py", line 1040, in _validate_conn
    conn.connect()
  File "/opt/python/urllib3/connection.py", line 358, in connect
    conn = self._new_conn()
  File "/opt/python/urllib3/connection.py", line 186, in _new_conn
    raise NewConnectionError(
urllib3.exceptions.NewConnectionError: <urllib3.connection.HTTPSConnection object at 0x7f59b7d58460>: Failed to establish a new connection: [Errno -5] No address associated with hostname

During handling of the above exception, another exception occurred:

Traceback (most recent call last):
  File "/opt/python/requests/adapters.py", line 440, in send
    resp = conn.urlopen(
  File "/opt/python/urllib3/connectionpool.py", line 785, in urlopen
    retries = retries.increment(
  File "/opt/python/urllib3/util/retry.py", line 592, in increment
    raise MaxRetryError(_pool, url, error or ResponseError(cause))
urllib3.exceptions.MaxRetryError: HTTPSConnectionPool(host='estates4.warwickdc.gov.uk', port=443): Max retries exceeded with url: /cmis/CouncillorsAtoZ/tabid/39/ScreenMode/Ward/Default.aspx (Caused by NewConnectionError('<urllib3.connection.HTTPSConnection object at 0x7f59b7d58460>: Failed to establish a new connection: [Errno -5] No address associated with hostname'))

During handling of the above exception, another exception occurred:

Traceback (most recent call last):
  File "/var/task/lgsf/aws_lambda/handlers.py", line 32, in scraper_worker_handler
    scraper.run(run_log)
  File "/var/task/lgsf/councillors/scrapers.py", line 46, in run
    for councillor_html in self.get_councillors():
  File "/var/task/lgsf/councillors/scrapers.py", line 242, in get_councillors
    req = self.get(self.base_url, extra_headers=self.extra_headers)
  File "/var/task/lgsf/scrapers/base.py", line 48, in get
    response = self.requests_session.get(url, headers=headers, verify=verify)
  File "/opt/python/requests/sessions.py", line 542, in get
    return self.request('GET', url, **kwargs)
  File "/opt/python/requests/sessions.py", line 529, in request
    resp = self.send(prep, **send_kwargs)
  File "/opt/python/requests/sessions.py", line 645, in send
    r = adapter.send(request, **kwargs)
  File "/opt/python/requests/adapters.py", line 519, in send
    raise ConnectionError(e, request=request)
requests.exceptions.ConnectionError: HTTPSConnectionPool(host='estates4.warwickdc.gov.uk', port=443): Max retries exceeded with url: /cmis/CouncillorsAtoZ/tabid/39/ScreenMode/Ward/Default.aspx (Caused by NewConnectionError('<urllib3.connection.HTTPSConnection object at 0x7f59b7d58460>: Failed to establish a new connection: [Errno -5] No address associated with hostname'))
</dd>
      </div>
    </dl>
  </div>
  </div>

  <h3>Run log</h3>
  <pre>[12:02:41] Fetching Scraper for: WAW                              handlers.py:23
           Begin attempting to scrape: WAW                        handlers.py:27
           Deleting existing data...                                 base.py:230
[12:02:42] Getting all files in WAW...                               base.py:182
           ...found 1 files in WAW                                   base.py:198
           Deleting batch no. 1 consisting of 1 files                base.py:207
[12:02:43] ...data deleted.                                          base.py:237
           Scraping from https://estates4.warwickdc.gov.uk/cmis/Counc base.py:42
           illorsAtoZ/tabid/39/ScreenMode/Ward/Default.aspx                     
           HTTPSConnectionPool(host='estates4.warwickdc.gov.uk',  handlers.py:36
           port=443): Max retries exceeded with url: /cmis/Counci               
           llorsAtoZ/tabid/39/ScreenMode/Ward/Default.aspx                      
           (Caused by NewConnectionError('<urllib3.connection.HTT               
           PSConnection object at 0x7f59b7d58460>: Failed to                    
           establish a new connection: [Errno -5] No address                    
           associated with hostname'))                                          
[12:02:44] Finished attempting to scrape: WAW                        base.py:315
</pre>
  

  


  <h2 id="2022-05-30-12-50">2022-05-30</h2>
  <div class="ds-card">
  <div class="ds-card-body">
    <dl class="ds-descriptions">
      <div>
        <dt>Duration</dt>
        <dd>2 seconds</dd>
      </div>
      <div>
        <dt>Start</dt>
        <dd>2022-05-30 12:50:27.934485</dd>
      </div>
      <div>
        <dt>End</dt>
        <dd>2022-05-30 12:50:30.064859</dd>
      </div>
      <div>
        <dt>Status code</dt>
        <dd>1</dd>
      </div>
      <div>
        <dt>Error</dt>
        <dd>Traceback (most recent call last):
  File "/opt/python/urllib3/connection.py", line 174, in _new_conn
    conn = connection.create_connection(
  File "/opt/python/urllib3/util/connection.py", line 72, in create_connection
    for res in socket.getaddrinfo(host, port, family, socket.SOCK_STREAM):
  File "/var/lang/lib/python3.8/socket.py", line 918, in getaddrinfo
    for res in _socket.getaddrinfo(host, port, family, type, proto, flags):
socket.gaierror: [Errno -5] No address associated with hostname

During handling of the above exception, another exception occurred:

Traceback (most recent call last):
  File "/opt/python/urllib3/connectionpool.py", line 703, in urlopen
    httplib_response = self._make_request(
  File "/opt/python/urllib3/connectionpool.py", line 386, in _make_request
    self._validate_conn(conn)
  File "/opt/python/urllib3/connectionpool.py", line 1040, in _validate_conn
    conn.connect()
  File "/opt/python/urllib3/connection.py", line 358, in connect
    conn = self._new_conn()
  File "/opt/python/urllib3/connection.py", line 186, in _new_conn
    raise NewConnectionError(
urllib3.exceptions.NewConnectionError: <urllib3.connection.HTTPSConnection object at 0x7f2a7269e100>: Failed to establish a new connection: [Errno -5] No address associated with hostname

During handling of the above exception, another exception occurred:

Traceback (most recent call last):
  File "/opt/python/requests/adapters.py", line 440, in send
    resp = conn.urlopen(
  File "/opt/python/urllib3/connectionpool.py", line 785, in urlopen
    retries = retries.increment(
  File "/opt/python/urllib3/util/retry.py", line 592, in increment
    raise MaxRetryError(_pool, url, error or ResponseError(cause))
urllib3.exceptions.MaxRetryError: HTTPSConnectionPool(host='estates4.warwickdc.gov.uk', port=443): Max retries exceeded with url: /cmis/CouncillorsAtoZ/tabid/39/ScreenMode/Ward/Default.aspx (Caused by NewConnectionError('<urllib3.connection.HTTPSConnection object at 0x7f2a7269e100>: Failed to establish a new connection: [Errno -5] No address associated with hostname'))

During handling of the above exception, another exception occurred:

Traceback (most recent call last):
  File "/var/task/lgsf/aws_lambda/handlers.py", line 32, in scraper_worker_handler
    scraper.run(run_log)
  File "/var/task/lgsf/councillors/scrapers.py", line 46, in run
    for councillor_html in self.get_councillors():
  File "/var/task/lgsf/councillors/scrapers.py", line 242, in get_councillors
    req = self.get(self.base_url, extra_headers=self.extra_headers)
  File "/var/task/lgsf/scrapers/base.py", line 48, in get
    response = self.requests_session.get(url, headers=headers, verify=verify)
  File "/opt/python/requests/sessions.py", line 542, in get
    return self.request('GET', url, **kwargs)
  File "/opt/python/requests/sessions.py", line 529, in request
    resp = self.send(prep, **send_kwargs)
  File "/opt/python/requests/sessions.py", line 645, in send
    r = adapter.send(request, **kwargs)
  File "/opt/python/requests/adapters.py", line 519, in send
    raise ConnectionError(e, request=request)
requests.exceptions.ConnectionError: HTTPSConnectionPool(host='estates4.warwickdc.gov.uk', port=443): Max retries exceeded with url: /cmis/CouncillorsAtoZ/tabid/39/ScreenMode/Ward/Default.aspx (Caused by NewConnectionError('<urllib3.connection.HTTPSConnection object at 0x7f2a7269e100>: Failed to establish a new connection: [Errno -5] No address associated with hostname'))
</dd>
      </div>
    </dl>
  </div>
  </div>

  <h3>Run log</h3>
  <pre>[12:50:27] Fetching Scraper for: WAW                              handlers.py:23
           Begin attempting to scrape: WAW                        handlers.py:27
[12:50:28] Deleting existing data...                                 base.py:230
           Getting all files in WAW...                               base.py:182
           ...found 1 files in WAW                                   base.py:198
           Deleting batch no. 1 consisting of 1 files                base.py:207
[12:50:29] ...data deleted.                                          base.py:237
           Scraping from https://estates4.warwickdc.gov.uk/cmis/Counc base.py:42
           illorsAtoZ/tabid/39/ScreenMode/Ward/Default.aspx                     
           HTTPSConnectionPool(host='estates4.warwickdc.gov.uk',  handlers.py:36
           port=443): Max retries exceeded with url: /cmis/Counci               
           llorsAtoZ/tabid/39/ScreenMode/Ward/Default.aspx                      
           (Caused by NewConnectionError('<urllib3.connection.HTT               
           PSConnection object at 0x7f2a7269e100>: Failed to                    
           establish a new connection: [Errno -5] No address                    
           associated with hostname'))                                          
[12:50:30] Finished attempting to scrape: WAW                        base.py:315
</pre>
  

  


  <h2 id="2022-05-29-12-57">2022-05-29</h2>
  <div class="ds-card">
  <div class="ds-card-body">
    <dl class="ds-descriptions">
      <div>
        <dt>Duration</dt>
        <dd>2 seconds</dd>
      </div>
      <div>
        <dt>Start</dt>
        <dd>2022-05-29 12:57:02.790157</dd>
      </div>
      <div>
        <dt>End</dt>
        <dd>2022-05-29 12:57:05.780376</dd>
      </div>
      <div>
        <dt>Status code</dt>
        <dd>1</dd>
      </div>
      <div>
        <dt>Error</dt>
        <dd>Traceback (most recent call last):
  File "/opt/python/urllib3/connection.py", line 174, in _new_conn
    conn = connection.create_connection(
  File "/opt/python/urllib3/util/connection.py", line 72, in create_connection
    for res in socket.getaddrinfo(host, port, family, socket.SOCK_STREAM):
  File "/var/lang/lib/python3.8/socket.py", line 918, in getaddrinfo
    for res in _socket.getaddrinfo(host, port, family, type, proto, flags):
socket.gaierror: [Errno -5] No address associated with hostname

During handling of the above exception, another exception occurred:

Traceback (most recent call last):
  File "/opt/python/urllib3/connectionpool.py", line 703, in urlopen
    httplib_response = self._make_request(
  File "/opt/python/urllib3/connectionpool.py", line 386, in _make_request
    self._validate_conn(conn)
  File "/opt/python/urllib3/connectionpool.py", line 1040, in _validate_conn
    conn.connect()
  File "/opt/python/urllib3/connection.py", line 358, in connect
    conn = self._new_conn()
  File "/opt/python/urllib3/connection.py", line 186, in _new_conn
    raise NewConnectionError(
urllib3.exceptions.NewConnectionError: <urllib3.connection.HTTPSConnection object at 0x7fcd05b92e80>: Failed to establish a new connection: [Errno -5] No address associated with hostname

During handling of the above exception, another exception occurred:

Traceback (most recent call last):
  File "/opt/python/requests/adapters.py", line 440, in send
    resp = conn.urlopen(
  File "/opt/python/urllib3/connectionpool.py", line 785, in urlopen
    retries = retries.increment(
  File "/opt/python/urllib3/util/retry.py", line 592, in increment
    raise MaxRetryError(_pool, url, error or ResponseError(cause))
urllib3.exceptions.MaxRetryError: HTTPSConnectionPool(host='estates4.warwickdc.gov.uk', port=443): Max retries exceeded with url: /cmis/CouncillorsAtoZ/tabid/39/ScreenMode/Ward/Default.aspx (Caused by NewConnectionError('<urllib3.connection.HTTPSConnection object at 0x7fcd05b92e80>: Failed to establish a new connection: [Errno -5] No address associated with hostname'))

During handling of the above exception, another exception occurred:

Traceback (most recent call last):
  File "/var/task/lgsf/aws_lambda/handlers.py", line 32, in scraper_worker_handler
    scraper.run(run_log)
  File "/var/task/lgsf/councillors/scrapers.py", line 46, in run
    for councillor_html in self.get_councillors():
  File "/var/task/lgsf/councillors/scrapers.py", line 242, in get_councillors
    req = self.get(self.base_url, extra_headers=self.extra_headers)
  File "/var/task/lgsf/scrapers/base.py", line 48, in get
    response = self.requests_session.get(url, headers=headers, verify=verify)
  File "/opt/python/requests/sessions.py", line 542, in get
    return self.request('GET', url, **kwargs)
  File "/opt/python/requests/sessions.py", line 529, in request
    resp = self.send(prep, **send_kwargs)
  File "/opt/python/requests/sessions.py", line 645, in send
    r = adapter.send(request, **kwargs)
  File "/opt/python/requests/adapters.py", line 519, in send
    raise ConnectionError(e, request=request)
requests.exceptions.ConnectionError: HTTPSConnectionPool(host='estates4.warwickdc.gov.uk', port=443): Max retries exceeded with url: /cmis/CouncillorsAtoZ/tabid/39/ScreenMode/Ward/Default.aspx (Caused by NewConnectionError('<urllib3.connection.HTTPSConnection object at 0x7fcd05b92e80>: Failed to establish a new connection: [Errno -5] No address associated with hostname'))
</dd>
      </div>
    </dl>
  </div>
  </div>

  <h3>Run log</h3>
  <pre>[12:57:02] Fetching Scraper for: WAW                              handlers.py:23
           Begin attempting to scrape: WAW                        handlers.py:27
[12:57:03] Deleting existing data...                                 base.py:230
[12:57:04] Getting all files in WAW...                               base.py:182
           ...found 1 files in WAW                                   base.py:198
           Deleting batch no. 1 consisting of 1 files                base.py:207
[12:57:05] ...data deleted.                                          base.py:237
           Scraping from https://estates4.warwickdc.gov.uk/cmis/Counc base.py:42
           illorsAtoZ/tabid/39/ScreenMode/Ward/Default.aspx                     
           HTTPSConnectionPool(host='estates4.warwickdc.gov.uk',  handlers.py:36
           port=443): Max retries exceeded with url: /cmis/Counci               
           llorsAtoZ/tabid/39/ScreenMode/Ward/Default.aspx                      
           (Caused by NewConnectionError('<urllib3.connection.HTT               
           PSConnection object at 0x7fcd05b92e80>: Failed to                    
           establish a new connection: [Errno -5] No address                    
           associated with hostname'))                                          
           Finished attempting to scrape: WAW                        base.py:315
</pre>
  

  


  <h2 id="2022-05-28-11-53">2022-05-28</h2>
  <div class="ds-card">
  <div class="ds-card-body">
    <dl class="ds-descriptions">
      <div>
        <dt>Duration</dt>
        <dd>2 seconds</dd>
      </div>
      <div>
        <dt>Start</dt>
        <dd>2022-05-28 11:53:54.316339</dd>
      </div>
      <div>
        <dt>End</dt>
        <dd>2022-05-28 11:53:56.562425</dd>
      </div>
      <div>
        <dt>Status code</dt>
        <dd>1</dd>
      </div>
      <div>
        <dt>Error</dt>
        <dd>Traceback (most recent call last):
  File "/opt/python/urllib3/connection.py", line 174, in _new_conn
    conn = connection.create_connection(
  File "/opt/python/urllib3/util/connection.py", line 72, in create_connection
    for res in socket.getaddrinfo(host, port, family, socket.SOCK_STREAM):
  File "/var/lang/lib/python3.8/socket.py", line 918, in getaddrinfo
    for res in _socket.getaddrinfo(host, port, family, type, proto, flags):
socket.gaierror: [Errno -5] No address associated with hostname

During handling of the above exception, another exception occurred:

Traceback (most recent call last):
  File "/opt/python/urllib3/connectionpool.py", line 703, in urlopen
    httplib_response = self._make_request(
  File "/opt/python/urllib3/connectionpool.py", line 386, in _make_request
    self._validate_conn(conn)
  File "/opt/python/urllib3/connectionpool.py", line 1040, in _validate_conn
    conn.connect()
  File "/opt/python/urllib3/connection.py", line 358, in connect
    conn = self._new_conn()
  File "/opt/python/urllib3/connection.py", line 186, in _new_conn
    raise NewConnectionError(
urllib3.exceptions.NewConnectionError: <urllib3.connection.HTTPSConnection object at 0x7fdb41fbd460>: Failed to establish a new connection: [Errno -5] No address associated with hostname

During handling of the above exception, another exception occurred:

Traceback (most recent call last):
  File "/opt/python/requests/adapters.py", line 440, in send
    resp = conn.urlopen(
  File "/opt/python/urllib3/connectionpool.py", line 785, in urlopen
    retries = retries.increment(
  File "/opt/python/urllib3/util/retry.py", line 592, in increment
    raise MaxRetryError(_pool, url, error or ResponseError(cause))
urllib3.exceptions.MaxRetryError: HTTPSConnectionPool(host='estates4.warwickdc.gov.uk', port=443): Max retries exceeded with url: /cmis/CouncillorsAtoZ/tabid/39/ScreenMode/Ward/Default.aspx (Caused by NewConnectionError('<urllib3.connection.HTTPSConnection object at 0x7fdb41fbd460>: Failed to establish a new connection: [Errno -5] No address associated with hostname'))

During handling of the above exception, another exception occurred:

Traceback (most recent call last):
  File "/var/task/lgsf/aws_lambda/handlers.py", line 32, in scraper_worker_handler
    scraper.run(run_log)
  File "/var/task/lgsf/councillors/scrapers.py", line 46, in run
    for councillor_html in self.get_councillors():
  File "/var/task/lgsf/councillors/scrapers.py", line 242, in get_councillors
    req = self.get(self.base_url, extra_headers=self.extra_headers)
  File "/var/task/lgsf/scrapers/base.py", line 48, in get
    response = self.requests_session.get(url, headers=headers, verify=verify)
  File "/opt/python/requests/sessions.py", line 542, in get
    return self.request('GET', url, **kwargs)
  File "/opt/python/requests/sessions.py", line 529, in request
    resp = self.send(prep, **send_kwargs)
  File "/opt/python/requests/sessions.py", line 645, in send
    r = adapter.send(request, **kwargs)
  File "/opt/python/requests/adapters.py", line 519, in send
    raise ConnectionError(e, request=request)
requests.exceptions.ConnectionError: HTTPSConnectionPool(host='estates4.warwickdc.gov.uk', port=443): Max retries exceeded with url: /cmis/CouncillorsAtoZ/tabid/39/ScreenMode/Ward/Default.aspx (Caused by NewConnectionError('<urllib3.connection.HTTPSConnection object at 0x7fdb41fbd460>: Failed to establish a new connection: [Errno -5] No address associated with hostname'))
</dd>
      </div>
    </dl>
  </div>
  </div>

  <h3>Run log</h3>
  <pre>[11:53:54] Fetching Scraper for: WAW                              handlers.py:23
           Begin attempting to scrape: WAW                        handlers.py:27
           Deleting existing data...                                 base.py:230
[11:53:55] Getting all files in WAW...                               base.py:182
           ...found 1 files in WAW                                   base.py:198
           Deleting batch no. 1 consisting of 1 files                base.py:207
[11:53:56] ...data deleted.                                          base.py:237
           Scraping from https://estates4.warwickdc.gov.uk/cmis/Counc base.py:42
           illorsAtoZ/tabid/39/ScreenMode/Ward/Default.aspx                     
           HTTPSConnectionPool(host='estates4.warwickdc.gov.uk',  handlers.py:36
           port=443): Max retries exceeded with url: /cmis/Counci               
           llorsAtoZ/tabid/39/ScreenMode/Ward/Default.aspx                      
           (Caused by NewConnectionError('<urllib3.connection.HTT               
           PSConnection object at 0x7fdb41fbd460>: Failed to                    
           establish a new connection: [Errno -5] No address                    
           associated with hostname'))                                          
           Finished attempting to scrape: WAW                        base.py:315
</pre>
  

  


  <h2 id="2022-05-27-13-29">2022-05-27</h2>
  <div class="ds-card">
  <div class="ds-card-body">
    <dl class="ds-descriptions">
      <div>
        <dt>Duration</dt>
        <dd>2 seconds</dd>
      </div>
      <div>
        <dt>Start</dt>
        <dd>2022-05-27 13:29:07.106035</dd>
      </div>
      <div>
        <dt>End</dt>
        <dd>2022-05-27 13:29:09.395988</dd>
      </div>
      <div>
        <dt>Status code</dt>
        <dd>1</dd>
      </div>
      <div>
        <dt>Error</dt>
        <dd>Traceback (most recent call last):
  File "/opt/python/urllib3/connection.py", line 174, in _new_conn
    conn = connection.create_connection(
  File "/opt/python/urllib3/util/connection.py", line 72, in create_connection
    for res in socket.getaddrinfo(host, port, family, socket.SOCK_STREAM):
  File "/var/lang/lib/python3.8/socket.py", line 918, in getaddrinfo
    for res in _socket.getaddrinfo(host, port, family, type, proto, flags):
socket.gaierror: [Errno -5] No address associated with hostname

During handling of the above exception, another exception occurred:

Traceback (most recent call last):
  File "/opt/python/urllib3/connectionpool.py", line 703, in urlopen
    httplib_response = self._make_request(
  File "/opt/python/urllib3/connectionpool.py", line 386, in _make_request
    self._validate_conn(conn)
  File "/opt/python/urllib3/connectionpool.py", line 1040, in _validate_conn
    conn.connect()
  File "/opt/python/urllib3/connection.py", line 358, in connect
    conn = self._new_conn()
  File "/opt/python/urllib3/connection.py", line 186, in _new_conn
    raise NewConnectionError(
urllib3.exceptions.NewConnectionError: <urllib3.connection.HTTPSConnection object at 0x7f38a3541c70>: Failed to establish a new connection: [Errno -5] No address associated with hostname

During handling of the above exception, another exception occurred:

Traceback (most recent call last):
  File "/opt/python/requests/adapters.py", line 440, in send
    resp = conn.urlopen(
  File "/opt/python/urllib3/connectionpool.py", line 785, in urlopen
    retries = retries.increment(
  File "/opt/python/urllib3/util/retry.py", line 592, in increment
    raise MaxRetryError(_pool, url, error or ResponseError(cause))
urllib3.exceptions.MaxRetryError: HTTPSConnectionPool(host='estates4.warwickdc.gov.uk', port=443): Max retries exceeded with url: /cmis/CouncillorsAtoZ/tabid/39/ScreenMode/Ward/Default.aspx (Caused by NewConnectionError('<urllib3.connection.HTTPSConnection object at 0x7f38a3541c70>: Failed to establish a new connection: [Errno -5] No address associated with hostname'))

During handling of the above exception, another exception occurred:

Traceback (most recent call last):
  File "/var/task/lgsf/aws_lambda/handlers.py", line 32, in scraper_worker_handler
    scraper.run(run_log)
  File "/var/task/lgsf/councillors/scrapers.py", line 46, in run
    for councillor_html in self.get_councillors():
  File "/var/task/lgsf/councillors/scrapers.py", line 242, in get_councillors
    req = self.get(self.base_url, extra_headers=self.extra_headers)
  File "/var/task/lgsf/scrapers/base.py", line 48, in get
    response = self.requests_session.get(url, headers=headers, verify=verify)
  File "/opt/python/requests/sessions.py", line 542, in get
    return self.request('GET', url, **kwargs)
  File "/opt/python/requests/sessions.py", line 529, in request
    resp = self.send(prep, **send_kwargs)
  File "/opt/python/requests/sessions.py", line 645, in send
    r = adapter.send(request, **kwargs)
  File "/opt/python/requests/adapters.py", line 519, in send
    raise ConnectionError(e, request=request)
requests.exceptions.ConnectionError: HTTPSConnectionPool(host='estates4.warwickdc.gov.uk', port=443): Max retries exceeded with url: /cmis/CouncillorsAtoZ/tabid/39/ScreenMode/Ward/Default.aspx (Caused by NewConnectionError('<urllib3.connection.HTTPSConnection object at 0x7f38a3541c70>: Failed to establish a new connection: [Errno -5] No address associated with hostname'))
</dd>
      </div>
    </dl>
  </div>
  </div>

  <h3>Run log</h3>
  <pre>[13:29:07] Fetching Scraper for: WAW                              handlers.py:23
           Begin attempting to scrape: WAW                        handlers.py:27
           Deleting existing data...                                 base.py:230
           Getting all files in WAW...                               base.py:182
[13:29:08] ...found 1 files in WAW                                   base.py:198
           Deleting batch no. 1 consisting of 1 files                base.py:207
[13:29:09] ...data deleted.                                          base.py:237
           Scraping from https://estates4.warwickdc.gov.uk/cmis/Counc base.py:42
           illorsAtoZ/tabid/39/ScreenMode/Ward/Default.aspx                     
           HTTPSConnectionPool(host='estates4.warwickdc.gov.uk',  handlers.py:36
           port=443): Max retries exceeded with url: /cmis/Counci               
           llorsAtoZ/tabid/39/ScreenMode/Ward/Default.aspx                      
           (Caused by NewConnectionError('<urllib3.connection.HTT               
           PSConnection object at 0x7f38a3541c70>: Failed to                    
           establish a new connection: [Errno -5] No address                    
           associated with hostname'))                                          
           Finished attempting to scrape: WAW                        base.py:315
</pre>
  

  


  <h2 id="2022-05-26-15-06">2022-05-26</h2>
  <div class="ds-card">
  <div class="ds-card-body">
    <dl class="ds-descriptions">
      <div>
        <dt>Duration</dt>
        <dd>2 seconds</dd>
      </div>
      <div>
        <dt>Start</dt>
        <dd>2022-05-26 15:06:03.771681</dd>
      </div>
      <div>
        <dt>End</dt>
        <dd>2022-05-26 15:06:06.189157</dd>
      </div>
      <div>
        <dt>Status code</dt>
        <dd>1</dd>
      </div>
      <div>
        <dt>Error</dt>
        <dd>Traceback (most recent call last):
  File "/opt/python/urllib3/connection.py", line 174, in _new_conn
    conn = connection.create_connection(
  File "/opt/python/urllib3/util/connection.py", line 72, in create_connection
    for res in socket.getaddrinfo(host, port, family, socket.SOCK_STREAM):
  File "/var/lang/lib/python3.8/socket.py", line 918, in getaddrinfo
    for res in _socket.getaddrinfo(host, port, family, type, proto, flags):
socket.gaierror: [Errno -5] No address associated with hostname

During handling of the above exception, another exception occurred:

Traceback (most recent call last):
  File "/opt/python/urllib3/connectionpool.py", line 703, in urlopen
    httplib_response = self._make_request(
  File "/opt/python/urllib3/connectionpool.py", line 386, in _make_request
    self._validate_conn(conn)
  File "/opt/python/urllib3/connectionpool.py", line 1040, in _validate_conn
    conn.connect()
  File "/opt/python/urllib3/connection.py", line 358, in connect
    conn = self._new_conn()
  File "/opt/python/urllib3/connection.py", line 186, in _new_conn
    raise NewConnectionError(
urllib3.exceptions.NewConnectionError: <urllib3.connection.HTTPSConnection object at 0x7f07c778af40>: Failed to establish a new connection: [Errno -5] No address associated with hostname

During handling of the above exception, another exception occurred:

Traceback (most recent call last):
  File "/opt/python/requests/adapters.py", line 440, in send
    resp = conn.urlopen(
  File "/opt/python/urllib3/connectionpool.py", line 785, in urlopen
    retries = retries.increment(
  File "/opt/python/urllib3/util/retry.py", line 592, in increment
    raise MaxRetryError(_pool, url, error or ResponseError(cause))
urllib3.exceptions.MaxRetryError: HTTPSConnectionPool(host='estates4.warwickdc.gov.uk', port=443): Max retries exceeded with url: /cmis/CouncillorsAtoZ/tabid/39/ScreenMode/Ward/Default.aspx (Caused by NewConnectionError('<urllib3.connection.HTTPSConnection object at 0x7f07c778af40>: Failed to establish a new connection: [Errno -5] No address associated with hostname'))

During handling of the above exception, another exception occurred:

Traceback (most recent call last):
  File "/var/task/lgsf/aws_lambda/handlers.py", line 32, in scraper_worker_handler
    scraper.run(run_log)
  File "/var/task/lgsf/councillors/scrapers.py", line 46, in run
    for councillor_html in self.get_councillors():
  File "/var/task/lgsf/councillors/scrapers.py", line 242, in get_councillors
    req = self.get(self.base_url, extra_headers=self.extra_headers)
  File "/var/task/lgsf/scrapers/base.py", line 48, in get
    response = self.requests_session.get(url, headers=headers, verify=verify)
  File "/opt/python/requests/sessions.py", line 542, in get
    return self.request('GET', url, **kwargs)
  File "/opt/python/requests/sessions.py", line 529, in request
    resp = self.send(prep, **send_kwargs)
  File "/opt/python/requests/sessions.py", line 645, in send
    r = adapter.send(request, **kwargs)
  File "/opt/python/requests/adapters.py", line 519, in send
    raise ConnectionError(e, request=request)
requests.exceptions.ConnectionError: HTTPSConnectionPool(host='estates4.warwickdc.gov.uk', port=443): Max retries exceeded with url: /cmis/CouncillorsAtoZ/tabid/39/ScreenMode/Ward/Default.aspx (Caused by NewConnectionError('<urllib3.connection.HTTPSConnection object at 0x7f07c778af40>: Failed to establish a new connection: [Errno -5] No address associated with hostname'))
</dd>
      </div>
    </dl>
  </div>
  </div>

  <h3>Run log</h3>
  <pre>[15:06:03] Fetching Scraper for: WAW                              handlers.py:23
           Begin attempting to scrape: WAW                        handlers.py:27
           Deleting existing data...                                 base.py:230
[15:06:04] Getting all files in WAW...                               base.py:182
           ...found 1 files in WAW                                   base.py:198
           Deleting batch no. 1 consisting of 1 files                base.py:207
[15:06:05] ...data deleted.                                          base.py:237
           Scraping from https://estates4.warwickdc.gov.uk/cmis/Counc base.py:42
           illorsAtoZ/tabid/39/ScreenMode/Ward/Default.aspx                     
           HTTPSConnectionPool(host='estates4.warwickdc.gov.uk',  handlers.py:36
           port=443): Max retries exceeded with url: /cmis/Counci               
           llorsAtoZ/tabid/39/ScreenMode/Ward/Default.aspx                      
           (Caused by NewConnectionError('<urllib3.connection.HTT               
           PSConnection object at 0x7f07c778af40>: Failed to                    
           establish a new connection: [Errno -5] No address                    
           associated with hostname'))                                          
[15:06:06] Finished attempting to scrape: WAW                        base.py:315
</pre>
  

  


  <h2 id="2022-05-25-13-02">2022-05-25</h2>
  <div class="ds-card">
  <div class="ds-card-body">
    <dl class="ds-descriptions">
      <div>
        <dt>Duration</dt>
        <dd>3 seconds</dd>
      </div>
      <div>
        <dt>Start</dt>
        <dd>2022-05-25 13:02:00.170263</dd>
      </div>
      <div>
        <dt>End</dt>
        <dd>2022-05-25 13:02:03.625995</dd>
      </div>
      <div>
        <dt>Status code</dt>
        <dd>1</dd>
      </div>
      <div>
        <dt>Error</dt>
        <dd>Traceback (most recent call last):
  File "/opt/python/urllib3/connection.py", line 174, in _new_conn
    conn = connection.create_connection(
  File "/opt/python/urllib3/util/connection.py", line 72, in create_connection
    for res in socket.getaddrinfo(host, port, family, socket.SOCK_STREAM):
  File "/var/lang/lib/python3.8/socket.py", line 918, in getaddrinfo
    for res in _socket.getaddrinfo(host, port, family, type, proto, flags):
socket.gaierror: [Errno -5] No address associated with hostname

During handling of the above exception, another exception occurred:

Traceback (most recent call last):
  File "/opt/python/urllib3/connectionpool.py", line 703, in urlopen
    httplib_response = self._make_request(
  File "/opt/python/urllib3/connectionpool.py", line 386, in _make_request
    self._validate_conn(conn)
  File "/opt/python/urllib3/connectionpool.py", line 1040, in _validate_conn
    conn.connect()
  File "/opt/python/urllib3/connection.py", line 358, in connect
    conn = self._new_conn()
  File "/opt/python/urllib3/connection.py", line 186, in _new_conn
    raise NewConnectionError(
urllib3.exceptions.NewConnectionError: <urllib3.connection.HTTPSConnection object at 0x7f4892103100>: Failed to establish a new connection: [Errno -5] No address associated with hostname

During handling of the above exception, another exception occurred:

Traceback (most recent call last):
  File "/opt/python/requests/adapters.py", line 440, in send
    resp = conn.urlopen(
  File "/opt/python/urllib3/connectionpool.py", line 785, in urlopen
    retries = retries.increment(
  File "/opt/python/urllib3/util/retry.py", line 592, in increment
    raise MaxRetryError(_pool, url, error or ResponseError(cause))
urllib3.exceptions.MaxRetryError: HTTPSConnectionPool(host='estates4.warwickdc.gov.uk', port=443): Max retries exceeded with url: /cmis/CouncillorsAtoZ/tabid/39/ScreenMode/Ward/Default.aspx (Caused by NewConnectionError('<urllib3.connection.HTTPSConnection object at 0x7f4892103100>: Failed to establish a new connection: [Errno -5] No address associated with hostname'))

During handling of the above exception, another exception occurred:

Traceback (most recent call last):
  File "/var/task/lgsf/aws_lambda/handlers.py", line 32, in scraper_worker_handler
    scraper.run(run_log)
  File "/var/task/lgsf/councillors/scrapers.py", line 46, in run
    for councillor_html in self.get_councillors():
  File "/var/task/lgsf/councillors/scrapers.py", line 242, in get_councillors
    req = self.get(self.base_url, extra_headers=self.extra_headers)
  File "/var/task/lgsf/scrapers/base.py", line 48, in get
    response = self.requests_session.get(url, headers=headers, verify=verify)
  File "/opt/python/requests/sessions.py", line 542, in get
    return self.request('GET', url, **kwargs)
  File "/opt/python/requests/sessions.py", line 529, in request
    resp = self.send(prep, **send_kwargs)
  File "/opt/python/requests/sessions.py", line 645, in send
    r = adapter.send(request, **kwargs)
  File "/opt/python/requests/adapters.py", line 519, in send
    raise ConnectionError(e, request=request)
requests.exceptions.ConnectionError: HTTPSConnectionPool(host='estates4.warwickdc.gov.uk', port=443): Max retries exceeded with url: /cmis/CouncillorsAtoZ/tabid/39/ScreenMode/Ward/Default.aspx (Caused by NewConnectionError('<urllib3.connection.HTTPSConnection object at 0x7f4892103100>: Failed to establish a new connection: [Errno -5] No address associated with hostname'))
</dd>
      </div>
    </dl>
  </div>
  </div>

  <h3>Run log</h3>
  <pre>[13:02:00] Fetching Scraper for: WAW                              handlers.py:23
           Begin attempting to scrape: WAW                        handlers.py:27
[13:02:01] Deleting existing data...                                 base.py:230
[13:02:02] Getting all files in WAW...                               base.py:182
           ...found 1 files in WAW                                   base.py:198
           Deleting batch no. 1 consisting of 1 files                base.py:207
[13:02:03] ...data deleted.                                          base.py:237
           Scraping from https://estates4.warwickdc.gov.uk/cmis/Counc base.py:42
           illorsAtoZ/tabid/39/ScreenMode/Ward/Default.aspx                     
           HTTPSConnectionPool(host='estates4.warwickdc.gov.uk',  handlers.py:36
           port=443): Max retries exceeded with url: /cmis/Counci               
           llorsAtoZ/tabid/39/ScreenMode/Ward/Default.aspx                      
           (Caused by NewConnectionError('<urllib3.connection.HTT               
           PSConnection object at 0x7f4892103100>: Failed to                    
           establish a new connection: [Errno -5] No address                    
           associated with hostname'))                                          
           Finished attempting to scrape: WAW                        base.py:315
</pre>
  

  


  <h2 id="2022-05-24-14-58">2022-05-24</h2>
  <div class="ds-card">
  <div class="ds-card-body">
    <dl class="ds-descriptions">
      <div>
        <dt>Duration</dt>
        <dd>2 seconds</dd>
      </div>
      <div>
        <dt>Start</dt>
        <dd>2022-05-24 14:58:44.366669</dd>
      </div>
      <div>
        <dt>End</dt>
        <dd>2022-05-24 14:58:46.565927</dd>
      </div>
      <div>
        <dt>Status code</dt>
        <dd>1</dd>
      </div>
      <div>
        <dt>Error</dt>
        <dd>Traceback (most recent call last):
  File "/opt/python/urllib3/connection.py", line 174, in _new_conn
    conn = connection.create_connection(
  File "/opt/python/urllib3/util/connection.py", line 72, in create_connection
    for res in socket.getaddrinfo(host, port, family, socket.SOCK_STREAM):
  File "/var/lang/lib/python3.8/socket.py", line 918, in getaddrinfo
    for res in _socket.getaddrinfo(host, port, family, type, proto, flags):
socket.gaierror: [Errno -5] No address associated with hostname

During handling of the above exception, another exception occurred:

Traceback (most recent call last):
  File "/opt/python/urllib3/connectionpool.py", line 703, in urlopen
    httplib_response = self._make_request(
  File "/opt/python/urllib3/connectionpool.py", line 386, in _make_request
    self._validate_conn(conn)
  File "/opt/python/urllib3/connectionpool.py", line 1040, in _validate_conn
    conn.connect()
  File "/opt/python/urllib3/connection.py", line 358, in connect
    conn = self._new_conn()
  File "/opt/python/urllib3/connection.py", line 186, in _new_conn
    raise NewConnectionError(
urllib3.exceptions.NewConnectionError: <urllib3.connection.HTTPSConnection object at 0x7f11a8ea1df0>: Failed to establish a new connection: [Errno -5] No address associated with hostname

During handling of the above exception, another exception occurred:

Traceback (most recent call last):
  File "/opt/python/requests/adapters.py", line 440, in send
    resp = conn.urlopen(
  File "/opt/python/urllib3/connectionpool.py", line 785, in urlopen
    retries = retries.increment(
  File "/opt/python/urllib3/util/retry.py", line 592, in increment
    raise MaxRetryError(_pool, url, error or ResponseError(cause))
urllib3.exceptions.MaxRetryError: HTTPSConnectionPool(host='estates4.warwickdc.gov.uk', port=443): Max retries exceeded with url: /cmis/CouncillorsAtoZ/tabid/39/ScreenMode/Ward/Default.aspx (Caused by NewConnectionError('<urllib3.connection.HTTPSConnection object at 0x7f11a8ea1df0>: Failed to establish a new connection: [Errno -5] No address associated with hostname'))

During handling of the above exception, another exception occurred:

Traceback (most recent call last):
  File "/var/task/lgsf/aws_lambda/handlers.py", line 32, in scraper_worker_handler
    scraper.run(run_log)
  File "/var/task/lgsf/councillors/scrapers.py", line 46, in run
    for councillor_html in self.get_councillors():
  File "/var/task/lgsf/councillors/scrapers.py", line 242, in get_councillors
    req = self.get(self.base_url, extra_headers=self.extra_headers)
  File "/var/task/lgsf/scrapers/base.py", line 48, in get
    response = self.requests_session.get(url, headers=headers, verify=verify)
  File "/opt/python/requests/sessions.py", line 542, in get
    return self.request('GET', url, **kwargs)
  File "/opt/python/requests/sessions.py", line 529, in request
    resp = self.send(prep, **send_kwargs)
  File "/opt/python/requests/sessions.py", line 645, in send
    r = adapter.send(request, **kwargs)
  File "/opt/python/requests/adapters.py", line 519, in send
    raise ConnectionError(e, request=request)
requests.exceptions.ConnectionError: HTTPSConnectionPool(host='estates4.warwickdc.gov.uk', port=443): Max retries exceeded with url: /cmis/CouncillorsAtoZ/tabid/39/ScreenMode/Ward/Default.aspx (Caused by NewConnectionError('<urllib3.connection.HTTPSConnection object at 0x7f11a8ea1df0>: Failed to establish a new connection: [Errno -5] No address associated with hostname'))
</dd>
      </div>
    </dl>
  </div>
  </div>

  <h3>Run log</h3>
  <pre>[14:58:44] Fetching Scraper for: WAW                              handlers.py:23
           Begin attempting to scrape: WAW                        handlers.py:27
           Deleting existing data...                                 base.py:230
[14:58:45] Getting all files in WAW...                               base.py:182
           ...found 1 files in WAW                                   base.py:198
           Deleting batch no. 1 consisting of 1 files                base.py:207
[14:58:46] ...data deleted.                                          base.py:237
           Scraping from https://estates4.warwickdc.gov.uk/cmis/Counc base.py:42
           illorsAtoZ/tabid/39/ScreenMode/Ward/Default.aspx                     
           HTTPSConnectionPool(host='estates4.warwickdc.gov.uk',  handlers.py:36
           port=443): Max retries exceeded with url: /cmis/Counci               
           llorsAtoZ/tabid/39/ScreenMode/Ward/Default.aspx                      
           (Caused by NewConnectionError('<urllib3.connection.HTT               
           PSConnection object at 0x7f11a8ea1df0>: Failed to                    
           establish a new connection: [Errno -5] No address                    
           associated with hostname'))                                          
           Finished attempting to scrape: WAW                        base.py:315
</pre>
  

  


  <h2 id="2022-05-23-13-14">2022-05-23</h2>
  <div class="ds-card">
  <div class="ds-card-body">
    <dl class="ds-descriptions">
      <div>
        <dt>Duration</dt>
        <dd>2 seconds</dd>
      </div>
      <div>
        <dt>Start</dt>
        <dd>2022-05-23 13:14:39.911636</dd>
      </div>
      <div>
        <dt>End</dt>
        <dd>2022-05-23 13:14:42.535762</dd>
      </div>
      <div>
        <dt>Status code</dt>
        <dd>1</dd>
      </div>
      <div>
        <dt>Error</dt>
        <dd>Traceback (most recent call last):
  File "/opt/python/urllib3/connection.py", line 174, in _new_conn
    conn = connection.create_connection(
  File "/opt/python/urllib3/util/connection.py", line 72, in create_connection
    for res in socket.getaddrinfo(host, port, family, socket.SOCK_STREAM):
  File "/var/lang/lib/python3.8/socket.py", line 918, in getaddrinfo
    for res in _socket.getaddrinfo(host, port, family, type, proto, flags):
socket.gaierror: [Errno -5] No address associated with hostname

During handling of the above exception, another exception occurred:

Traceback (most recent call last):
  File "/opt/python/urllib3/connectionpool.py", line 703, in urlopen
    httplib_response = self._make_request(
  File "/opt/python/urllib3/connectionpool.py", line 386, in _make_request
    self._validate_conn(conn)
  File "/opt/python/urllib3/connectionpool.py", line 1040, in _validate_conn
    conn.connect()
  File "/opt/python/urllib3/connection.py", line 358, in connect
    conn = self._new_conn()
  File "/opt/python/urllib3/connection.py", line 186, in _new_conn
    raise NewConnectionError(
urllib3.exceptions.NewConnectionError: <urllib3.connection.HTTPSConnection object at 0x7efcb7ef2940>: Failed to establish a new connection: [Errno -5] No address associated with hostname

During handling of the above exception, another exception occurred:

Traceback (most recent call last):
  File "/opt/python/requests/adapters.py", line 440, in send
    resp = conn.urlopen(
  File "/opt/python/urllib3/connectionpool.py", line 785, in urlopen
    retries = retries.increment(
  File "/opt/python/urllib3/util/retry.py", line 592, in increment
    raise MaxRetryError(_pool, url, error or ResponseError(cause))
urllib3.exceptions.MaxRetryError: HTTPSConnectionPool(host='estates4.warwickdc.gov.uk', port=443): Max retries exceeded with url: /cmis/CouncillorsAtoZ/tabid/39/ScreenMode/Ward/Default.aspx (Caused by NewConnectionError('<urllib3.connection.HTTPSConnection object at 0x7efcb7ef2940>: Failed to establish a new connection: [Errno -5] No address associated with hostname'))

During handling of the above exception, another exception occurred:

Traceback (most recent call last):
  File "/var/task/lgsf/aws_lambda/handlers.py", line 32, in scraper_worker_handler
    scraper.run(run_log)
  File "/var/task/lgsf/councillors/scrapers.py", line 46, in run
    for councillor_html in self.get_councillors():
  File "/var/task/lgsf/councillors/scrapers.py", line 242, in get_councillors
    req = self.get(self.base_url, extra_headers=self.extra_headers)
  File "/var/task/lgsf/scrapers/base.py", line 48, in get
    response = self.requests_session.get(url, headers=headers, verify=verify)
  File "/opt/python/requests/sessions.py", line 542, in get
    return self.request('GET', url, **kwargs)
  File "/opt/python/requests/sessions.py", line 529, in request
    resp = self.send(prep, **send_kwargs)
  File "/opt/python/requests/sessions.py", line 645, in send
    r = adapter.send(request, **kwargs)
  File "/opt/python/requests/adapters.py", line 519, in send
    raise ConnectionError(e, request=request)
requests.exceptions.ConnectionError: HTTPSConnectionPool(host='estates4.warwickdc.gov.uk', port=443): Max retries exceeded with url: /cmis/CouncillorsAtoZ/tabid/39/ScreenMode/Ward/Default.aspx (Caused by NewConnectionError('<urllib3.connection.HTTPSConnection object at 0x7efcb7ef2940>: Failed to establish a new connection: [Errno -5] No address associated with hostname'))
</dd>
      </div>
    </dl>
  </div>
  </div>

  <h3>Run log</h3>
  <pre>[13:14:39] Fetching Scraper for: WAW                              handlers.py:23
           Begin attempting to scrape: WAW                        handlers.py:27
[13:14:40] Deleting existing data...                                 base.py:230
           Getting all files in WAW...                               base.py:182
           ...found 1 files in WAW                                   base.py:198
           Deleting batch no. 1 consisting of 1 files                base.py:207
[13:14:42] ...data deleted.                                          base.py:237
           Scraping from https://estates4.warwickdc.gov.uk/cmis/Counc base.py:42
           illorsAtoZ/tabid/39/ScreenMode/Ward/Default.aspx                     
           HTTPSConnectionPool(host='estates4.warwickdc.gov.uk',  handlers.py:36
           port=443): Max retries exceeded with url: /cmis/Counci               
           llorsAtoZ/tabid/39/ScreenMode/Ward/Default.aspx                      
           (Caused by NewConnectionError('<urllib3.connection.HTT               
           PSConnection object at 0x7efcb7ef2940>: Failed to                    
           establish a new connection: [Errno -5] No address                    
           associated with hostname'))                                          
           Finished attempting to scrape: WAW                        base.py:315
</pre>
  


      </main>
      <footer class="ds-footer">
        <div class="ds-block-centered ds-text-centered ds-stack">
          <div class="ds-cluster-center">
            <ul>
              <li><a href="/lgsf-dashboard/api/failing.json">Failing JSON</a></li>
            </ul>
          </div>
          <div class="ds-copyright">
            <a href="https://democracyclub.org.uk/">
              <img src="https://DemocracyClub.github.io/design-system/images/logo_white_text.svg" alt="Democracy Club Home" />
            </a>
            <p>Copyright © 2021 Democracy Club</p>
            <p>Community Interest Company</p>
            <p>Company No: <a href="https://beta.companieshouse.gov.uk/company/09461226">09461226</a></p>
          </div>
        </div>
      </footer>
    </div>
  </body>
